Workbook

Sheet Mẫu số 11C. Bảng tổng hợp giá d
A1: MẪU SỐ 11C. BẢNG TỔNG HỢP GIÁ DỰ THẦU
A5: STT | B5: Id | C5: Mô tả công việc mời thầu | D5: Yêu cầu kỹ thuật/Chỉ dẫn kỹ thuật chính | E5: Khối lượng mời thầu | F5: Đơn vị tính | G5: Đơn giá dự thầu | H5: Thành tiền
A6: 1 | B6: 1 | C6: NỀN MẶT ĐƯỜNG TUYẾN CHÍNH (ĐOẠN QUA ĐỊA PHẬN TT BÚT SƠN) | D6: Theo quy định tại Chương V | H6: 0
A7: 1.1 | B7: 2 | C7: Dọn dẹp mặt bằng | D7: Theo quy định tại Chương V | E7: 91424 | F7: m2 | G7: =+'[1]Dự thầu'!$G$6 -> 646 | H7: =+ROUND(G7*E7,0) -> 59059904
A8: 1.2 | B8: 3 | C8: Đào khuôn đường bằng máy - Cấp đất II | D8: Theo quy định tại Chương V | E8: 501 | F8: m3 | G8: =+'[1]Dự thầu'!$G$8 -> 20072 | H8: =+ROUND(G8*E8,0) -> 10056072
A9: 1.3 | B9: 4 | C9: Đào mặt đường cũ bằng máy - Cấp đất IV | D9: Theo quy định tại Chương V | E9: 264 | F9: m3 | G9: =+'[1]Dự thầu'!$G$9 -> 30610 | H9: =+ROUND(G9*E9,0) -> 8081040
A10: 1.4 | B10: 5 | C10: Xáo xới nền đường K95 | D10: Theo quy định tại Chương V | E10: 923 | F10: m3 | G10: =+'[1]Dự thầu'!$G$10 -> 12342 | H10: =+ROUND(G10*E10,0) -> 11391666
A11: 1.5 | B11: 6 | C11: Lu lèn 30cm mặt đường đã xới xáo | D11: Theo quy định tại Chương V | E11: 923 | F11: m3 | G11: =+'[1]Dự thầu'!$G$11 -> 12936 | H11: =+ROUND(G11*E11,0) -> 11939928
A12: 1.6 | B12: 7 | C12: Đào đất hữu cơ | D12: Theo quy định tại Chương V | E12: 5871.7 | F12: m3 | G12: =+'[1]Dự thầu'!$G$12 -> 8251 | H12: =+ROUND(G12*E12,0) -> 48447397
A13: 1.7 | B13: 8 | C13: Đắp nền đường bằng máy lu bánh thép 25T, máy ủi 110CV, độ chặt Y/C K = 0,95 | D13: Theo quy định tại Chương V | E13: 170279 | F13: m3 | G13: =+'[1]Dự thầu'!$G$13 -> 12936 | H13: =+ROUND(G13*E13,0) -> 2202729144
A14: 1.8 | B14: 9 | C14: Đắp giải đất dự trữ bằng đất tận dụng K95 | D14: Theo quy định tại Chương V | E14: 28834 | F14: m3 | G14: =+'[1]Dự thầu'!$G$14 -> 12936 | H14: =+ROUND(G14*E14,0) -> 372996624
A15: 1.9 | B15: 10 | C15: Đắp nền đường bằng máy lu bánh thép 25T, máy ủi 110CV, độ chặt Y/C K = 0,98 | D15: Theo quy định tại Chương V | E15: 14978 | F15: m3 | G15: =+'[1]Dự thầu'!$G$15 -> 15775 | H15: =+ROUND(G15*E15,0) -> 236277950
A16: 1.10 | B16: 11 | C16: Mua đất để đắp K95 | D16: Theo quy định tại Chương V | E16: 246897.46 | F16: m3 | G16: =+'[1]Dự thầu'!$G$16 -> 50585 | H16: =+ROUND(G16*E16,0) -> 12489308014
A17: 1.11 | B17: 12 | C17: Mua đất để đắp K98 | D17: Theo quy định tại Chương V | E17: 21023.12 | F17: m3 | G17: =+'[1]Dự thầu'!$G$17 -> 54405 | H17: =+ROUND(G17*E17,0) -> 1143762844
A18: 1.12 | B18: 13 | C18: Vận chuyển đất | D18: Theo quy định tại Chương V | E18: 26792.06 | F18: 10m³/1km | G18: =+'[1]Dự thầu'!$G$18+'[1]Dự thầu'!$G$19+'[1]Dự thầu'!$G$20 -> 940826 | H18: =+ROUND(G18*E18,0) -> 25206666642
A19: 1.13 | B19: 14 | C19: Vận chuyển đất đắp gia tải tận dụng bên cầu đắp dải dự trữ 3km | D19: Theo quy định tại Chương V | E19: 4230 | F19: m3 | G19: =+'[1]Dự thầu'!$G$21 -> 39661 | H19: =+ROUND(G19*E19,0) -> 167766030
A20: 1.14 | B20: 15 | C20: Vận chuyển đất không thích hợp đất cấp I | D20: Theo quy định tại Chương V | E20: 61617.46 | F20: m3 | G20: =+'[1]Dự thầu'!$G$25 -> 40424 | H20: =+ROUND(G20*E20,0) -> 2490824203
A21: 1.15 | B21: 16 | C21: Vận chuyển đất không thích hợp đất cấp II | D21: Theo quy định tại Chương V | E21: 1686.7 | F21: m3 | G21: =+'[1]Dự thầu'!$G$29 -> 45382 | H21: =+ROUND(G21*E21,0) -> 76545819
A22: 1.16 | B22: 17 | C22: Vận chuyển đất không thích hợp bằng ôtô tự đổ, đất cấp IV | D22: Theo quy định tại Chương V | E22: 858 | F22: m3 | G22: =+'[1]Dự thầu'!$G$33 -> 56948 | H22: =+ROUND(G22*E22,0) -> 48861384
A23: 1.17 | B23: 18 | C23: San đất bãi thải bằng máy ủi 110CV | D23: Theo quy định tại Chương V | E23: 32081.08 | F23: m3 | G23: =+'[1]Dự thầu'!$G$37 -> 2096 | H23: =+ROUND(G23*E23,0) -> 67241944
A24: 1.18 | B24: 19 | C24: Đào đất không thích hợp bằng máy đào - Cấp đất I | D24: Theo quy định tại Chương V | E24: 93677 | F24: m3 | G24: =+'[1]Dự thầu'!$G$38 -> 8251 | H24: =+ROUND(G24*E24,0) -> 772928927
A25: 1.19 | B25: 20 | C25: Rải vải địa kỹ thuật không dệt ART12 (12kN/m) | D25: Theo quy định tại Chương V | E25: 88349 | F25: m2 | G25: =+'[1]Dự thầu'!$G$40 -> 20017 | H25: =+ROUND(G25*E25,0) -> 1768481933
A26: 1.20 | B26: 21 | C26: Rải lưới địa kỹ thuật dệt cường độ 200Kn/m | D26: Theo quy định tại Chương V | E26: 29119.1 | F26: m2 | G26: =+'[1]Dự thầu'!$G$41 -> 36456 | H26: =+ROUND(G26*E26,0) -> 1061565910
A27: 1.21 | B27: 22 | C27: Đắp đất bù lún K95 | D27: Theo quy định tại Chương V | E27: 10294 | F27: m3 | G27: =+'[1]Dự thầu'!$G$44 -> 12936 | H27: =+ROUND(G27*E27,0) -> 133163184
A28: 1.22 | B28: 23 | C28: Đắp đất gia tải K95 (không vật liệu) | D28: Theo quy định tại Chương V | E28: 2898.6 | F28: m3 | G28: =+'[1]Dự thầu'!$G$45 -> 12936 | H28: =+ROUND(G28*E28,0) -> 37496290
A29: 1.23 | B29: 24 | C29: Đào dỡ tải | D29: Theo quy định tại Chương V | E29: 2898.6 | F29: m3 | G29: =+'[1]Dự thầu'!$G$46 -> 12342 | H29: =+ROUND(G29*E29,0) -> 35774521
A30: 1.24 | B30: 25 | C30: Vận chuyển đất tận dụng | D30: Theo quy định tại Chương V | E30: 3275.42 | F30: m³/1km | G30: =+'[1]Dự thầu'!$G$47 -> 6611 | H30: =+ROUND(G30*E30,0) -> 21653802
A31: 1.25 | B31: 26 | C31: Đắp đất quy đổi kết cấu, bù kết cấu K95 (không vật liệu) | D31: Theo quy định tại Chương V | E31: 13855.64 | F31: m3 | G31: =+'[1]Dự thầu'!$G$48 -> 12936 | H31: =+ROUND(G31*E31,0) -> 179236559
A32: 1.26 | B32: 27 | C32: Đào dỡ tải | D32: Theo quy định tại Chương V | E32: 13855.64 | F32: m3 | G32: =+'[1]Dự thầu'!$G$49 -> 12342 | H32: =+ROUND(G32*E32,0) -> 171006309
A33: 1.27 | B33: 28 | C33: Vận chuyển đất tận dụng | D33: Theo quy định tại Chương V | E33: 15656.87 | F33: m³/1km | G33: =+'[1]Dự thầu'!$G$50 -> 6611 | H33: =+ROUND(G33*E33,0) -> 103507568
A34: 1.28 | B34: 29 | C34: Đá dăm 1x2cm làm cửa thoát nước | D34: Theo quy định tại Chương V | E34: 74 | F34: m3 | G34: =+'[1]Dự thầu'!$G$51 -> 868453 | H34: =+ROUND(G34*E34,0) -> 64265522
A35: 1.29 | B35: 30 | C35: Rải vải địa kỹ thuật 15kN/m | D35: Theo quy định tại Chương V | E35: 672 | F35: m2 | G35: =+'[1]Dự thầu'!$G$52 -> 26716 | H35: =+ROUND(G35*E35,0) -> 17953152
A36: 1.30 | B36: 31 | C36: Đắp đất K90 bảo vệ vải địa kỹ thuật | D36: Theo quy định tại Chương V | E36: 247 | F36: m3 | G36: =+'[1]Dự thầu'!$G$53 -> 32141 | H36: =+ROUND(G36*E36,0) -> 7938827
A37: 1.31 | B37: 32 | C37: Cấy bấc thấm bằng máy | D37: Theo quy định tại Chương V | E37: 83518.1 | F37: m | G37: =+'[1]Dự thầu'!$G$54 -> 7813 | H37: =+ROUND(G37*E37,0) -> 652526915
A38: 1.32 | B38: 33 | C38: Đệm cát hạt trung bằng máy, độ chặt yêu cầu K=0,95 | D38: Theo quy định tại Chương V | E38: 15182 | F38: m3 | G38: =+'[1]Dự thầu'!$G$56 -> 267174 | H38: =+ROUND(G38*E38,0) -> 4056235668
A39: 1.33 | B39: 34 | C39: Đào rãnh bằng máy, đất cấp II | D39: Theo quy định tại Chương V | E39: 1035 | F39: m3 | G39: =+'[1]Dự thầu'!$G$58 -> 20867 | H39: =+ROUND(G39*E39,0) -> 21597345
A40: 1.34 | B40: 35 | C40: Đắp trả rãnh đất thi công giếng cát | D40: Theo quy định tại Chương V | E40: 1035 | F40: m3 | G40: =+'[1]Dự thầu'!$G$59 -> 12936 | H40: =+ROUND(G40*E40,0) -> 13388760
A41: 1.35 | B41: 36 | C41: Lắp đặt ống nhựa- Đường kính 200mm | D41: Theo quy định tại Chương V | E41: 27 | F41: m | G41: =+'[1]Dự thầu'!$G$60 -> 301142 | H41: =+ROUND(G41*E41,0) -> 8130834
A42: 1.36 | B42: 37 | C42: Lắp đặt ống thép d=50mm | D42: Theo quy định tại Chương V | E42: 295 | F42: m | G42: =+'[1]Dự thầu'!$G$61 -> 191443 | H42: =+ROUND(G42*E42,0) -> 56475685
A43: 1.37 | B43: 38 | C43: Lắp đặt ống nhựa d150 | D43: Theo quy định tại Chương V | E43: 295 | F43: m | G43: =+'[1]Dự thầu'!$G$62 -> 184138 | H43: =+ROUND(G43*E43,0) -> 54320710
...

Sheet BIỂU HỢP ĐỒNG
B1: PHỤ LỤC 1: BẢNG TÔNG HỢP KHỐI LƯỢNG, ĐƠN GIÁ, GIÁ TRỊ HỢP ĐỒNG (Phụ lục kèm theo hợp đồng thi công xây dựng số: 12/06/2023 /HĐTCXD ngày 12/6/2023 GÓI THẦU 06: THI CÔNG XÂY DỰNG + BẢO HIỂM CÔNG TRÌNH THUỘC DỰ ÁN: ĐƯỜNG TỪ QUỐC LỘ 10 ĐI KHU DU LỊCH HẢI TIẾN, HUYỆN HOĂNG HÓA (GIAI ĐOẠN I)
B4: STT | D4: Nội Dung Công Việc | F4: Khối lượng | I4: Đơn vị tính | J4: Đơn giá hợp đồng | K4: Thành Tiền
C5: Id | E5: Yêu cầu kỹ thuật/Chỉ dẫn kỹ thuật chính | F5: Tổng cộng | G5: Công ty Tuấn Linh | H5: Công ty Hoàng Tuấn | K5: Tổng cộng | L5: Công ty Tuấn Linh | M5: Công ty Hoàng Tuấn
A6: TL | B6: 1 | C6: 1 | D6: NỀN MẶT ĐƯỜNG TUYẾN CHÍNH (ĐOẠN QUA ĐỊA PHẬN TT BÚT SƠN) | E6: Theo quy định tại Chương V
A7: =A6 -> TL | B7: 1.1 | C7: 2 | D7: Dọn dẹp mặt bằng | E7: Theo quy định tại Chương V | F7: 91424 | G7: =+F7 -> 91424 | I7: m2 | J7: =+'[1]Dự thầu'!$G$6 -> 646 | K7: =+ROUND(J7*F7,0) -> 59059904 | L7: =+ROUND(G7*J7,0) -> 59059904 | M7: =+ROUND(H7*J7,0) -> 0
A8: =A7 -> TL | B8: 1.2 | C8: 3 | D8: Đào khuôn đường bằng máy - Cấp đất II | E8: Theo quy định tại Chương V | F8: 501 | G8: =+F8 -> 501 | I8: m3 | J8: =+'[1]Dự thầu'!$G$8 -> 20072 | K8: =+ROUND(J8*F8,0) -> 10056072 | L8: =+ROUND(G8*J8,0) -> 10056072 | M8: =+ROUND(H8*J8,0) -> 0
A9: =A8 -> TL | B9: 1.3 | C9: 4 | D9: Đào mặt đường cũ bằng máy - Cấp đất IV | E9: Theo quy định tại Chương V | F9: 264 | G9: =+F9 -> 264 | I9: m3 | J9: =+'[1]Dự thầu'!$G$9 -> 30610 | K9: =+ROUND(J9*F9,0) -> 8081040 | L9: =+ROUND(G9*J9,0) -> 8081040 | M9: =+ROUND(H9*J9,0) -> 0
A10: =A9 -> TL | B10: 1.4 | C10: 5 | D10: Xáo xới nền đường K95 | E10: Theo quy định tại Chương V | F10: 923 | G10: =+F10 -> 923 | I10: m3 | J10: =+'[1]Dự thầu'!$G$10 -> 12342 | K10: =+ROUND(J10*F10,0) -> 11391666 | L10: =+ROUND(G10*J10,0) -> 11391666 | M10: =+ROUND(H10*J10,0) -> 0
A11: =A10 -> TL | B11: 1.5 | C11: 6 | D11: Lu lèn 30cm mặt đường đã xới xáo | E11: Theo quy định tại Chương V | F11: 923 | G11: =+F11 -> 923 | I11: m3 | J11: =+'[1]Dự thầu'!$G$11 -> 12936 | K11: =+ROUND(J11*F11,0) -> 11939928 | L11: =+ROUND(G11*J11,0) -> 11939928 | M11: =+ROUND(H11*J11,0) -> 0
A12: =A11 -> TL | B12: 1.6 | C12: 7 | D12: Đào đất hữu cơ | E12: Theo quy định tại Chương V | F12: 5871.7 | G12: =+F12 -> 5871.7 | I12: m3 | J12: =+'[1]Dự thầu'!$G$12 -> 8251 | K12: =+ROUND(J12*F12,0) -> 48447397 | L12: =+ROUND(G12*J12,0) -> 48447397 | M12: =+ROUND(H12*J12,0) -> 0
A13: =A12 -> TL | B13: 1.7 | C13: 8 | D13: Đắp nền đường bằng máy lu bánh thép 25T, máy ủi 110CV, độ chặt Y/C K = 0,95 | E13: Theo quy định tại Chương V | F13: 170279 | G13: =+F13 -> 170279 | I13: m3 | J13: =+'[1]Dự thầu'!$G$13 -> 12936 | K13: =+ROUND(J13*F13,0) -> 2202729144 | L13: =+ROUND(G13*J13,0) -> 2202729144 | M13: =+ROUND(H13*J13,0) -> 0
A14: =A13 -> TL | B14: 1.8 | C14: 9 | D14: Đắp giải đất dự trữ bằng đất tận dụng K95 | E14: Theo quy định tại Chương V | F14: 28834 | G14: =+F14 -> 28834 | I14: m3 | J14: =+'[1]Dự thầu'!$G$14 -> 12936 | K14: =+ROUND(J14*F14,0) -> 372996624 | L14: =+ROUND(G14*J14,0) -> 372996624 | M14: =+ROUND(H14*J14,0) -> 0
A15: =A14 -> TL | B15: 1.9 | C15: 10 | D15: Đắp nền đường bằng máy lu bánh thép 25T, máy ủi 110CV, độ chặt Y/C K = 0,98 | E15: Theo quy định tại Chương V | F15: 14978 | G15: =+F15 -> 14978 | I15: m3 | J15: =+'[1]Dự thầu'!$G$15 -> 15775 | K15: =+ROUND(J15*F15,0) -> 236277950 | L15: =+ROUND(G15*J15,0) -> 236277950 | M15: =+ROUND(H15*J15,0) -> 0
A16: =A15 -> TL | B16: 1.10 | C16: 11 | D16: Mua đất để đắp K95 | E16: Theo quy định tại Chương V | F16: 246897.46 | G16: =+F16 -> 246897.46 | I16: m3 | J16: =+'[1]Dự thầu'!$G$16 -> 50585 | K16: =+ROUND(J16*F16,0) -> 12489308014 | L16: =+ROUND(G16*J16,0) -> 12489308014 | M16: =+ROUND(H16*J16,0) -> 0
A17: =A16 -> TL | B17: 1.11 | C17: 12 | D17: Mua đất để đắp K98 | E17: Theo quy định tại Chương V | F17: 21023.12 | G17: =+F17 -> 21023.12 | I17: m3 | J17: =+'[1]Dự thầu'!$G$17 -> 54405 | K17: =+ROUND(J17*F17,0) -> 1143762844 | L17: =+ROUND(G17*J17,0) -> 1143762844 | M17: =+ROUND(H17*J17,0) -> 0
A18: =A17 -> TL | B18: 1.12 | C18: 13 | D18: Vận chuyển đất | E18: Theo quy định tại Chương V | F18: 26792.06 | G18: =+F18 -> 26792.06 | I18: 10m³/1km | J18: =+'[1]Dự thầu'!$G$18+'[1]Dự thầu'!$G$19+'[1]Dự thầu'!$G$20 -> 940826 | K18: =+ROUND(J18*F18,0) -> 25206666642 | L18: =+ROUND(G18*J18,0) -> 25206666642 | M18: =+ROUND(H18*J18,0) -> 0
A19: =A18 -> TL | B19: 1.13 | C19: 14 | D19: Vận chuyển đất đắp gia tải tận dụng bên cầu đắp dải dự trữ 3km | E19: Theo quy định tại Chương V | F19: 4230 | G19: =+F19 -> 4230 | I19: m3 | J19: =+'[1]Dự thầu'!$G$21 -> 39661 | K19: =+ROUND(J19*F19,0) -> 167766030 | L19: =+ROUND(G19*J19,0) -> 167766030 | M19: =+ROUND(H19*J19,0) -> 0
A20: =A19 -> TL | B20: 1.14 | C20: 15 | D20: Vận chuyển đất không thích hợp đất cấp I | E20: Theo quy định tại Chương V | F20: 61617.46 | G20: =+F20 -> 61617.46 | I20: m3 | J20: =+'[1]Dự thầu'!$G$25 -> 40424 | K20: =+ROUND(J20*F20,0) -> 2490824203 | L20: =+ROUND(G20*J20,0) -> 2490824203 | M20: =+ROUND(H20*J20,0) -> 0
A21: =A20 -> TL | B21: 1.15 | C21: 16 | D21: Vận chuyển đất không thích hợp đất cấp II | E21: Theo quy định tại Chương V | F21: 1686.7 | G21: =+F21 -> 1686.7 | I21: m3 | J21: =+'[1]Dự thầu'!$G$29 -> 45382 | K21: =+ROUND(J21*F21,0) -> 76545819 | L21: =+ROUND(G21*J21,0) -> 76545819 | M21: =+ROUND(H21*J21,0) -> 0
A22: =A21 -> TL | B22: 1.16 | C22: 17 | D22: Vận chuyển đất không thích hợp bằng ôtô tự đổ, đất cấp IV | E22: Theo quy định tại Chương V | F22: 858 | G22: =+F22 -> 858 | I22: m3 | J22: =+'[1]Dự thầu'!$G$33 -> 56948 | K22: =+ROUND(J22*F22,0) -> 48861384 | L22: =+ROUND(G22*J22,0) -> 48861384 | M22: =+ROUND(H22*J22,0) -> 0
A23: =A22 -> TL | B23: 1.17 | C23: 18 | D23: San đất bãi thải bằng máy ủi 110CV | E23: Theo quy định tại Chương V | F23: 32081.08 | G23: =+F23 -> 32081.08 | I23: m3 | J23: =+'[1]Dự thầu'!$G$37 -> 2096 | K23: =+ROUND(J23*F23,0) -> 67241944 | L23: =+ROUND(G23*J23,0) -> 67241944 | M23: =+ROUND(H23*J23,0) -> 0
A24: =A23 -> TL | B24: 1.18 | C24: 19 | D24: Đào đất không thích hợp bằng máy đào - Cấp đất I | E24: Theo quy định tại Chương V | F24: 93677 | G24: =+F24 -> 93677 | I24: m3 | J24: =+'[1]Dự thầu'!$G$38 -> 8251 | K24: =+ROUND(J24*F24,0) -> 772928927 | L24: =+ROUND(G24*J24,0) -> 772928927 | M24: =+ROUND(H24*J24,0) -> 0
A25: =A24 -> TL | B25: 1.19 | C25: 20 | D25: Rải vải địa kỹ thuật không dệt ART12 (12kN/m) | E25: Theo quy định tại Chương V | F25: 88349 | G25: =+F25 -> 88349 | I25: m2 | J25: =+'[1]Dự thầu'!$G$40 -> 20017 | K25: =+ROUND(J25*F25,0) -> 1768481933 | L25: =+ROUND(G25*J25,0) -> 1768481933 | M25: =+ROUND(H25*J25,0) -> 0
A26: =A25 -> TL | B26: 1.20 | C26: 21 | D26: Rải lưới địa kỹ thuật dệt cường độ 200Kn/m | E26: Theo quy định tại Chương V | F26: 29119.1 | G26: =+F26 -> 29119.1 | I26: m2 | J26: =+'[1]Dự thầu'!$G$41 -> 36456 | K26: =+ROUND(J26*F26,0) -> 1061565910 | L26: =+ROUND(G26*J26,0) -> 1061565910 | M26: =+ROUND(H26*J26,0) -> 0
A27: =A26 -> TL | B27: 1.21 | C27: 22 | D27: Đắp đất bù lún K95 | E27: Theo quy định tại Chương V | F27: 10294 | G27: =+F27 -> 10294 | I27: m3 | J27: =+'[1]Dự thầu'!$G$44 -> 12936 | K27: =+ROUND(J27*F27,0) -> 133163184 | L27: =+ROUND(G27*J27,0) -> 133163184 | M27: =+ROUND(H27*J27,0) -> 0
A28: =A27 -> TL | B28: 1.22 | C28: 23 | D28: Đắp đất gia tải K95 (không vật liệu) | E28: Theo quy định tại Chương V | F28: 2898.6 | G28: =+F28 -> 2898.6 | I28: m3 | J28: =+'[1]Dự thầu'!$G$45 -> 12936 | K28: =+ROUND(J28*F28,0) -> 37496290 | L28: =+ROUND(G28*J28,0) -> 37496290 | M28: =+ROUND(H28*J28,0) -> 0
A29: =A28 -> TL | B29: 1.23 | C29: 24 | D29: Đào dỡ tải | E29: Theo quy định tại Chương V | F29: 2898.6 | G29: =+F29 -> 2898.6 | I29: m3 | J29: =+'[1]Dự thầu'!$G$46 -> 12342 | K29: =+ROUND(J29*F29,0) -> 35774521 | L29: =+ROUND(G29*J29,0) -> 35774521 | M29: =+ROUND(H29*J29,0) -> 0
A30: =A29 -> TL | B30: 1.24 | C30: 25 | D30: Vận chuyển đất tận dụng | E30: Theo quy định tại Chương V | F30: 3275.42 | G30: =+F30 -> 3275.42 | I30: m³/1km | J30: =+'[1]Dự thầu'!$G$47 -> 6611 | K30: =+ROUND(J30*F30,0) -> 21653802 | L30: =+ROUND(G30*J30,0) -> 21653802 | M30: =+ROUND(H30*J30,0) -> 0
A31: =A30 -> TL | B31: 1.25 | C31: 26 | D31: Đắp đất quy đổi kết cấu, bù kết cấu K95 (không vật liệu) | E31: Theo quy định tại Chương V | F31: 13855.64 | G31: =+F31 -> 13855.64 | I31: m3 | J31: =+'[1]Dự thầu'!$G$48 -> 12936 | K31: =+ROUND(J31*F31,0) -> 179236559 | L31: =+ROUND(G31*J31,0) -> 179236559 | M31: =+ROUND(H31*J31,0) -> 0
A32: =A31 -> TL | B32: 1.26 | C32: 27 | D32: Đào dỡ tải | E32: Theo quy định tại Chương V | F32: 13855.64 | G32: =+F32 -> 13855.64 | I32: m3 | J32: =+'[1]Dự thầu'!$G$49 -> 12342 | K32: =+ROUND(J32*F32,0) -> 171006309 | L32: =+ROUND(G32*J32,0) -> 171006309 | M32: =+ROUND(H32*J32,0) -> 0
A33: =A32 -> TL | B33: 1.27 | C33: 28 | D33: Vận chuyển đất tận dụng | E33: Theo quy định tại Chương V | F33: 15656.87 | G33: =+F33 -> 15656.87 | I33: m³/1km | J33: =+'[1]Dự thầu'!$G$50 -> 6611 | K33: =+ROUND(J33*F33,0) -> 103507568 | L33: =+ROUND(G33*J33,0) -> 103507568 | M33: =+ROUND(H33*J33,0) -> 0
A34: =A33 -> TL | B34: 1.28 | C34: 29 | D34: Đá dăm 1x2cm làm cửa thoát nước | E34: Theo quy định tại Chương V | F34: 74 | G34: =+F34 -> 74 | I34: m3 | J34: =+'[1]Dự thầu'!$G$51 -> 868453 | K34: =+ROUND(J34*F34,0) -> 64265522 | L34: =+ROUND(G34*J34,0) -> 64265522 | M34: =+ROUND(H34*J34,0) -> 0
A35: =A34 -> TL | B35: 1.29 | C35: 30 | D35: Rải vải địa kỹ thuật 15kN/m | E35: Theo quy định tại Chương V | F35: 672 | G35: =+F35 -> 672 | I35: m2 | J35: =+'[1]Dự thầu'!$G$52 -> 26716 | K35: =+ROUND(J35*F35,0) -> 17953152 | L35: =+ROUND(G35*J35,0) -> 17953152 | M35: =+ROUND(H35*J35,0) -> 0
A36: =A35 -> TL | B36: 1.30 | C36: 31 | D36: Đắp đất K90 bảo vệ vải địa kỹ thuật | E36: Theo quy định tại Chương V | F36: 247 | G36: =+F36 -> 247 | I36: m3 | J36: =+'[1]Dự thầu'!$G$53 -> 32141 | K36: =+ROUND(J36*F36,0) -> 7938827 | L36: =+ROUND(G36*J36,0) -> 7938827 | M36: =+ROUND(H36*J36,0) -> 0
A37: =A36 -> TL | B37: 1.31 | C37: 32 | D37: Cấy bấc thấm bằng máy | E37: Theo quy định tại Chương V | F37: 83518.1 | G37: =+F37 -> 83518.1 | I37: m | J37: =+'[1]Dự thầu'!$G$54 -> 7813 | K37: =+ROUND(J37*F37,0) -> 652526915 | L37: =+ROUND(G37*J37,0) -> 652526915 | M37: =+ROUND(H37*J37,0) -> 0
A38: =A37 -> TL | B38: 1.32 | C38: 33 | D38: Đệm cát hạt trung bằng máy, độ chặt yêu cầu K=0,95 | E38: Theo quy định tại Chương V | F38: 15182 | G38: =+F38 -> 15182 | I38: m3 | J38: =+'[1]Dự thầu'!$G$56 -> 267174 | K38: =+ROUND(J38*F38,0) -> 4056235668 | L38: =+ROUND(G38*J38,0) -> 4056235668 | M38: =+ROUND(H38*J38,0) -> 0
A39: =A38 -> TL | B39: 1.33 | C39: 34 | D39: Đào rãnh bằng máy, đất cấp II | E39: Theo quy định tại Chương V | F39: 1035 | G39: =+F39 -> 1035 | I39: m3 | J39: =+'[1]Dự thầu'!$G$58 -> 20867 | K39: =+ROUND(J39*F39,0) -> 21597345 | L39: =+ROUND(G39*J39,0) -> 21597345 | M39: =+ROUND(H39*J39,0) -> 0
A40: =A39 -> TL | B40: 1.34 | C40: 35 | D40: Đắp trả rãnh đất thi công giếng cát | E40: Theo quy định tại Chương V | F40: 1035 | G40: =+F40 -> 1035 | I40: m3 | J40: =+'[1]Dự thầu'!$G$59 -> 12936 | K40: =+ROUND(J40*F40,0) -> 13388760 | L40: =+ROUND(G40*J40,0) -> 13388760 | M40: =+ROUND(H40*J40,0) -> 0
A41: =A40 -> TL | B41: 1.35 | C41: 36 | D41: Lắp đặt ống nhựa- Đường kính 200mm | E41: Theo quy định tại Chương V | F41: 27 | G41: =+F41 -> 27 | I41: m | J41: =+'[1]Dự thầu'!$G$60 -> 301142 | K41: =+ROUND(J41*F41,0) -> 8130834 | L41: =+ROUND(G41*J41,0) -> 8130834 | M41: =+ROUND(H41*J41,0) -> 0
A42: =A41 -> TL | B42: 1.36 | C42: 37 | D42: Lắp đặt ống thép d=50mm | E42: Theo quy định tại Chương V | F42: 295 | G42: =+F42 -> 295 | I42: m | J42: =+'[1]Dự thầu'!$G$61 -> 191443 | K42: =+ROUND(J42*F42,0) -> 56475685 | L42: =+ROUND(G42*J42,0) -> 56475685 | M42: =+ROUND(H42*J42,0) -> 0
...

Sheet PLHĐ PS
B1: PHỤ LỤC 1: BẢNG TÔNG HỢP KHỐI LƯỢNG, ĐƠN GIÁ, GIÁ TRỊ HỢP ĐỒNG (Phụ lục kèm theo hợp đồng thi công xây dựng số: 12/06/2023 /HĐTCXD ngày 12/6/2023 GÓI THẦU 06: THI CÔNG XÂY DỰNG + BẢO HIỂM CÔNG TRÌNH THUỘC DỰ ÁN: ĐƯỜNG TỪ QUỐC LỘ 10 ĐI KHU DU LỊCH HẢI TIẾN, HUYỆN HOĂNG HÓA (GIAI ĐOẠN I)
B4: STT | C4: Nội Dung Công Việc | D4: Đơn vị | E4: Khối lượng | J4: Đơn giá | L4: Thành Tiền
E5: Hợp đồng số 12/06/2023/HĐTCXD ngày 12/6/2023 | F5: Quyết định điều chỉnh TKBVTC-DT, số 5892/QĐ-UBND, ngày 31/12/2024 | G5: Biên bản xác nhận số liệu và tình hình kiểm toán ngày 21/5/2025 | H5: Điều chỉnh, bổ sung (lần này) theo QĐ số 408/QĐ-BQLDANN, ngày 11/9/2026 và số 422/QĐ-BQLDANN ngày 16/9/2026 | I5: Sau điều chỉnh, bổ sung | J5: Theo Hợp đồng | K5: Điều chỉnh, bổ sung | L5: =E5 -> Hợp đồng số 12/06/2023/HĐTCXD ngày 12/6/2023 | M5: =F5 -> Quyết định điều chỉnh TKBVTC-DT, số 5892/QĐ-UBND, ngày 31/12/2024 | N5: =G5 -> Biên bản xác nhận số liệu và tình hình kiểm toán ngày 21/5/2025 | O5: =H5 -> Điều chỉnh, bổ sung (lần này) theo QĐ số 408/QĐ-BQLDANN, ngày 11/9/2026 và số 422/QĐ-BQLDANN ngày 16/9/2026 | P5: =I5 -> Sau điều chỉnh, bổ sung
A6: TL | B6: A | C6: THÀNH VIÊN ĐỨNG ĐẦU LIÊN DANH: CÔNG TY CỔ PHẦN ĐẦU TƯ VÀ XÂY DỰNG TUẤN LINH | L6: =ROUND(SUM(L7:L694),-3) -> 129648647000 | M6: =ROUND(SUM(M7:M694),-3) -> 203765000 | N6: =ROUND(SUM(N7:N695),-3) -> -4496723000 | O6: =ROUND(SUM(O7:O694),-3) -> 0 | P6: =ROUND(SUM(P7:P695),-3) -> 125355689000
A7: =A6 -> TL | B7: 1 | C7: NỀN MẶT ĐƯỜNG TUYẾN CHÍNH (ĐOẠN QUA ĐỊA PHẬN TT BÚT SƠN)
A8: =A7 -> TL | B8: 1.1 | C8: Dọn dẹp mặt bằng | D8: m2 | E8: 91424 | F8: ='[4]PHỤ LỤC GIÁ HỢP ĐỒNG'!$K$10 -> -471.1437 | I8: =SUM(E8:H8) -> 90952.856 | J8: ='BIỂU HỢP ĐỒNG'!J7 -> 646 | L8: =+ROUND(J8*E8,0) -> 59059904 | M8: =+ROUND(F8*J8,0) -> -304359 | N8: =+ROUND(G8*J8,0) -> 0 | O8: =+ROUND(H8*J8,0) -> 0 | P8: =SUM(L8:O8) -> 58755545
A9: =A8 -> TL | B9: 1.2 | C9: Đào khuôn đường bằng máy - Cấp đất II | D9: m3 | E9: 500 | F9: ='[4]PHỤ LỤC GIÁ HỢP ĐỒNG'!$K$12 -> -157.9023 | I9: =SUM(E9:H9) -> 342.0977 | J9: ='BIỂU HỢP ĐỒNG'!J8 -> 20072 | L9: =+ROUND(J9*E9,0) -> 10036000 | M9: =+ROUND(F9*J9,0) -> -3169415 | N9: =+ROUND(G9*J9,0) -> 0 | O9: =+ROUND(H9*J9,0) -> 0 | P9: =SUM(L9:O9) -> 6866585
A10: =A9 -> TL | B10: 1.3 | C10: Đào mặt đường cũ bằng máy - Cấp đất IV | D10: m3 | E10: 264 | F10: ='[4]PHỤ LỤC GIÁ HỢP ĐỒNG'!$K$118 -> 146.13615 | I10: =SUM(E10:H10) -> 410.13615 | J10: ='BIỂU HỢP ĐỒNG'!J9 -> 30610 | L10: =+ROUND(J10*E10,0) -> 8081040 | M10: =+ROUND(F10*J10,0) -> 4473228 | N10: =+ROUND(G10*J10,0) -> 0 | O10: =+ROUND(H10*J10,0) -> 0 | P10: =SUM(L10:O10) -> 12554268
A11: =A10 -> TL | B11: 1.4 | C11: Xáo xới nền đường K95 | D11: m3 | E11: 923 | F11: ='[4]PHỤ LỤC GIÁ HỢP ĐỒNG'!$K$14 -> -765.48185 | I11: =SUM(E11:H11) -> 157.51815 | J11: ='BIỂU HỢP ĐỒNG'!J10 -> 12342 | L11: =+ROUND(J11*E11,0) -> 11391666 | M11: =+ROUND(F11*J11,0) -> -9447577 | N11: =+ROUND(G11*J11,0) -> 0 | O11: =+ROUND(H11*J11,0) -> 0 | P11: =SUM(L11:O11) -> 1944089
A12: =A11 -> TL | B12: 1.5 | C12: Lu lèn 30cm mặt đường đã xới xáo | D12: m3 | E12: 923 | F12: ='[4]PHỤ LỤC GIÁ HỢP ĐỒNG'!$K$15 -> -765.48185 | I12: =SUM(E12:H12) -> 157.51815 | J12: ='BIỂU HỢP ĐỒNG'!J11 -> 12936 | L12: =+ROUND(J12*E12,0) -> 11939928 | M12: =+ROUND(F12*J12,0) -> -9902273 | N12: =+ROUND(G12*J12,0) -> 0 | O12: =+ROUND(H12*J12,0) -> 0 | P12: =SUM(L12:O12) -> 2037655
A13: =A12 -> TL | B13: 1.6 | C13: Đào đất hữu cơ | D13: m3 | E13: 5871.7 | F13: ='[4]PHỤ LỤC GIÁ HỢP ĐỒNG'!$K$13 -> -4255.8554 | I13: =SUM(E13:H13) -> 1615.8446 | J13: ='BIỂU HỢP ĐỒNG'!J12 -> 8251 | L13: =+ROUND(J13*E13,0) -> 48447397 | M13: =+ROUND(F13*J13,0) -> -35115062 | N13: =+ROUND(G13*J13,0) -> 0 | O13: =+ROUND(H13*J13,0) -> 0 | P13: =SUM(L13:O13) -> 13332335
A14: =A13 -> TL | B14: 1.7 | C14: Đắp nền đường bằng máy lu bánh thép 25T, máy ủi 110CV, độ chặt Y/C K = 0,95 | D14: m3 | E14: 170279 | I14: =SUM(E14:H14) -> 170279 | J14: ='BIỂU HỢP ĐỒNG'!J13 -> 12936 | L14: =+ROUND(J14*E14,0) -> 2202729144 | M14: =+ROUND(F14*J14,0) -> 0 | N14: =+ROUND(G14*J14,0) -> 0 | O14: =+ROUND(H14*J14,0) -> 0 | P14: =SUM(L14:O14) -> 2202729144
A15: =A14 -> TL | B15: 1.8 | C15: Đắp giải đất dự trữ bằng đất tận dụng K95 | D15: m3 | E15: 28834 | F15: ='[4]PHỤ LỤC GIÁ HỢP ĐỒNG'!$K$17 -> -3133.9909 | I15: =SUM(E15:H15) -> 25700.009 | J15: ='BIỂU HỢP ĐỒNG'!J14 -> 12936 | L15: =+ROUND(J15*E15,0) -> 372996624 | M15: =+ROUND(F15*J15,0) -> -40541307 | N15: =+ROUND(G15*J15,0) -> 0 | O15: =+ROUND(H15*J15,0) -> 0 | P15: =SUM(L15:O15) -> 332455317
A16: =A15 -> TL | B16: 1.9 | C16: Đắp nền đường bằng máy lu bánh thép 25T, máy ủi 110CV, độ chặt Y/C K = 0,98 | D16: m3 | E16: 14978 | F16: ='[4]PHỤ LỤC GIÁ HỢP ĐỒNG'!$K$16 -> -15.50115 | I16: =SUM(E16:H16) -> 14962.499 | J16: ='BIỂU HỢP ĐỒNG'!J15 -> 15775 | L16: =+ROUND(J16*E16,0) -> 236277950 | M16: =+ROUND(F16*12936,0) -> -200523 | N16: =+ROUND(G16*J16,0) -> 0 | O16: =+ROUND(H16*J16,0) -> 0 | P16: =SUM(L16:O16) -> 236077427
A17: =A16 -> TL | B17: 1.10 | C17: Mua đất để đắp K95 | D17: m3 | E17: 246897.46 | F17: ='[4]PHỤ LỤC GIÁ HỢP ĐỒNG'!$K$18 -> -4285.1058 | I17: =SUM(E17:H17) -> 242612.35 | J17: ='BIỂU HỢP ĐỒNG'!J16 -> 50585 | L17: =+ROUND(J17*E17,0) -> 12489308014 | M17: =+ROUND(F17*J17,0) -> -216762078 | N17: =+ROUND(G17*J17,0) -> 0 | O17: =+ROUND(H17*J17,0) -> 0 | P17: =SUM(L17:O17) -> 12272545936
A18: =A17 -> TL | B18: 1.11 | C18: Mua đất để đắp K98 | D18: m3 | E18: 21023.12 | F18: ='[4]PHỤ LỤC GIÁ HỢP ĐỒNG'!$K$19 -> -21.757414 | I18: =SUM(E18:H18) -> 21001.363 | J18: ='BIỂU HỢP ĐỒNG'!J17 -> 54405 | L18: =+ROUND(J18*E18,0) -> 1143762844 | M18: =+ROUND(F18*J18,0) -> -1183712 | N18: =+ROUND(G18*J18,0) -> 0 | O18: =+ROUND(H18*J18,0) -> 0 | P18: =SUM(L18:O18) -> 1142579132
A19: =A18 -> TL | B19: 1.12 | C19: Vận chuyển đất | D19: 10m³/1km | E19: 26792.06 | F19: ='[4]PHỤ LỤC GIÁ HỢP ĐỒNG'!$K$20 -> -430.68632 | I19: =SUM(E19:H19) -> 26361.374 | J19: ='BIỂU HỢP ĐỒNG'!J18 -> 940826 | L19: =+ROUND(J19*E19,0) -> 25206666642 | M19: =+ROUND(F19*J19,0) -> -405200891 | N19: =+ROUND(G19*J19,0) -> 0 | O19: =+ROUND(H19*J19,0) -> 0 | P19: =SUM(L19:O19) -> 24801465751
A20: =A19 -> TL | B20: 1.13 | C20: Vận chuyển đất đắp gia tải tận dụng bên cầu đắp dải dự trữ 3km | D20: m3 | E20: 4230 | I20: =SUM(E20:H20) -> 4230 | J20: ='BIỂU HỢP ĐỒNG'!J19 -> 39661 | L20: =+ROUND(J20*E20,0) -> 167766030 | M20: =+ROUND(F20*J20,0) -> 0 | N20: =+ROUND(G20*J20,0) -> 0 | O20: =+ROUND(H20*J20,0) -> 0 | P20: =SUM(L20:O20) -> 167766030
A21: =A20 -> TL | B21: 1.14 | C21: Vận chuyển đất không thích hợp đất cấp I | D21: m3 | E21: 61617.46 | F21: ='[4]PHỤ LỤC GIÁ HỢP ĐỒNG'!$K$21 -> -3944.4936 | I21: =SUM(E21:H21) -> 57672.966 | J21: ='BIỂU HỢP ĐỒNG'!J20 -> 40424 | L21: =+ROUND(J21*E21,0) -> 2490824203 | M21: =+ROUND(F21*J21,0) -> -159452207 | N21: =+ROUND(G21*J21,0) -> 0 | O21: =+ROUND(H21*J21,0) -> 0 | P21: =SUM(L21:O21) -> 2331371996
A22: =A21 -> TL | B22: 1.15 | C22: Vận chuyển đất không thích hợp đất cấp II | D22: m3 | E22: 1686.7 | F22: ='[4]PHỤ LỤC GIÁ HỢP ĐỒNG'!$K$22 -> -157.9023 | I22: =SUM(E22:H22) -> 1528.7977 | J22: ='BIỂU HỢP ĐỒNG'!J21 -> 45382 | L22: =+ROUND(J22*E22,0) -> 76545819 | M22: =+ROUND(F22*J22,0) -> -7165922 | N22: =+ROUND(G22*J22,0) -> 0 | O22: =+ROUND(H22*J22,0) -> 0 | P22: =SUM(L22:O22) -> 69379897
A23: =A22 -> TL | B23: 1.16 | C23: Vận chuyển đất không thích hợp bằng ôtô tự đổ, đất cấp IV | D23: m3 | E23: 858 | F23: ='[4]PHỤ LỤC GIÁ HỢP ĐỒNG'!$K$120 -> 146.13615 | I23: =SUM(E23:H23) -> 1004.1362 | J23: ='BIỂU HỢP ĐỒNG'!J22 -> 56948 | L23: =+ROUND(J23*E23,0) -> 48861384 | M23: =+ROUND(F23*J23,0) -> 8322161 | N23: =+ROUND(G23*J23,0) -> 0 | O23: =+ROUND(H23*J23,0) -> 0 | P23: =SUM(L23:O23) -> 57183545
A24: =A23 -> TL | B24: 1.17 | C24: San đất bãi thải bằng máy ủi 110CV | D24: m3 | E24: 32081.08 | F24: ='[4]PHỤ LỤC GIÁ HỢP ĐỒNG'!$K$23 -> -3956.2597 | I24: =SUM(E24:H24) -> 28124.82 | J24: ='BIỂU HỢP ĐỒNG'!J23 -> 2096 | L24: =+ROUND(J24*E24,0) -> 67241944 | M24: =+ROUND(F24*J24,0) -> -8292320 | N24: =+ROUND(G24*J24,0) -> 0 | O24: =+ROUND(H24*J24,0) -> 0 | P24: =SUM(L24:O24) -> 58949624
A25: =A24 -> TL | B25: 1.18 | C25: Đào đất không thích hợp bằng máy đào - Cấp đất I | D25: m3 | E25: 93677 | F25: ='[4]PHỤ LỤC GIÁ HỢP ĐỒNG'!$K$119+'[4]PHỤ LỤC GIÁ HỢP ĐỒNG'!$K$122 -> 7005.9216 | I25: =SUM(E25:H25) -> 100682.92 | J25: ='BIỂU HỢP ĐỒNG'!J24 -> 8251 | L25: =+ROUND(J25*E25,0) -> 772928927 | M25: =+ROUND(F25*J25,0) -> 57805860 | N25: =+ROUND(G25*J25,0) -> 0 | O25: =+ROUND(H25*J25,0) -> 0 | P25: =SUM(L25:O25) -> 830734787
A26: =A25 -> TL | B26: 1.19 | C26: Rải vải địa kỹ thuật không dệt ART12 (12kN/m) | D26: m2 | E26: 88349 | F26: ='[4]PHỤ LỤC GIÁ HỢP ĐỒNG'!$K$125 -> 10433.62 | I26: =SUM(E26:H26) -> 98782.62 | J26: ='BIỂU HỢP ĐỒNG'!J25 -> 20017 | L26: =+ROUND(J26*E26,0) -> 1768481933 | M26: =+ROUND(F26*J26,0) -> 208849778 | N26: =+ROUND(G26*J26,0) -> 0 | O26: =+ROUND(H26*J26,0) -> 0 | P26: =SUM(L26:O26) -> 1977331711
A27: =A26 -> TL | B27: 1.20 | C27: Rải lưới địa kỹ thuật dệt cường độ 200Kn/m | D27: m2 | E27: 29119.1 | I27: =SUM(E27:H27) -> 29119.1 | J27: ='BIỂU HỢP ĐỒNG'!J26 -> 36456 | L27: =+ROUND(J27*E27,0) -> 1061565910 | M27: =+ROUND(F27*J27,0) -> 0 | N27: =+ROUND(G27*J27,0) -> 0 | O27: =+ROUND(H27*J27,0) -> 0 | P27: =SUM(L27:O27) -> 1061565910
A28: =A27 -> TL | B28: 1.21 | C28: Đắp đất bù lún K95 | D28: m3 | E28: 10294 | I28: =SUM(E28:H28) -> 10294 | J28: ='BIỂU HỢP ĐỒNG'!J27 -> 12936 | L28: =+ROUND(J28*E28,0) -> 133163184 | M28: =+ROUND(F28*J28,0) -> 0 | N28: =+ROUND(G28*J28,0) -> 0 | O28: =+ROUND(H28*J28,0) -> 0 | P28: =SUM(L28:O28) -> 133163184
A29: =A28 -> TL | B29: 1.22 | C29: Đắp đất gia tải K95 (không vật liệu) | D29: m3 | E29: 2898.6 | I29: =SUM(E29:H29) -> 2898.6 | J29: ='BIỂU HỢP ĐỒNG'!J28 -> 12936 | L29: =+ROUND(J29*E29,0) -> 37496290 | M29: =+ROUND(F29*J29,0) -> 0 | N29: =+ROUND(G29*J29,0) -> 0 | O29: =+ROUND(H29*J29,0) -> 0 | P29: =SUM(L29:O29) -> 37496290
A30: =A29 -> TL | B30: 1.23 | C30: Đào dỡ tải | D30: m3 | E30: 2898.6 | I30: =SUM(E30:H30) -> 2898.6 | J30: ='BIỂU HỢP ĐỒNG'!J29 -> 12342 | L30: =+ROUND(J30*E30,0) -> 35774521 | M30: =+ROUND(F30*J30,0) -> 0 | N30: =+ROUND(G30*J30,0) -> 0 | O30: =+ROUND(H30*J30,0) -> 0 | P30: =SUM(L30:O30) -> 35774521
A31: =A30 -> TL | B31: 1.24 | C31: Vận chuyển đất tận dụng | D31: m³/1km | E31: 3275.42 | F31: ='[4]PHỤ LỤC GIÁ HỢP ĐỒNG'!$K$123 -> 6694.5598 | I31: =SUM(E31:H31) -> 9969.9798 | J31: ='BIỂU HỢP ĐỒNG'!J30 -> 6611 | L31: =+ROUND(J31*E31,0) -> 21653802 | M31: =+ROUND(F31*J31,0) -> 44257735 | N31: =+ROUND(G31*J31,0) -> 0 | O31: =+ROUND(H31*J31,0) -> 0 | P31: =SUM(L31:O31) -> 65911537
A32: =A31 -> TL | B32: 1.25 | C32: Đắp đất quy đổi kết cấu, bù kết cấu K95 (không vật liệu) | D32: m3 | E32: 13855.64 | I32: =SUM(E32:H32) -> 13855.64 | J32: ='BIỂU HỢP ĐỒNG'!J31 -> 12936 | L32: =+ROUND(J32*E32,0) -> 179236559 | M32: =+ROUND(F32*J32,0) -> 0 | N32: =+ROUND(G32*J32,0) -> 0 | O32: =+ROUND(H32*J32,0) -> 0 | P32: =SUM(L32:O32) -> 179236559
A33: =A32 -> TL | B33: 1.26 | C33: Đào dỡ tải | D33: m3 | E33: 13855.64 | I33: =SUM(E33:H33) -> 13855.64 | J33: ='BIỂU HỢP ĐỒNG'!J32 -> 12342 | L33: =+ROUND(J33*E33,0) -> 171006309 | M33: =+ROUND(F33*J33,0) -> 0 | N33: =+ROUND(G33*J33,0) -> 0 | O33: =+ROUND(H33*J33,0) -> 0 | P33: =SUM(L33:O33) -> 171006309
A34: =A33 -> TL | B34: 1.27 | C34: Vận chuyển đất tận dụng | D34: m³/1km | E34: 15656.87 | I34: =SUM(E34:H34) -> 15656.87 | J34: ='BIỂU HỢP ĐỒNG'!J33 -> 6611 | L34: =+ROUND(J34*E34,0) -> 103507568 | M34: =+ROUND(F34*J34,0) -> 0 | N34: =+ROUND(G34*J34,0) -> 0 | O34: =+ROUND(H34*J34,0) -> 0 | P34: =SUM(L34:O34) -> 103507568
A35: =A34 -> TL | B35: 1.28 | C35: Đá dăm 1x2cm làm cửa thoát nước | D35: m3 | E35: 74 | I35: =SUM(E35:H35) -> 74 | J35: ='BIỂU HỢP ĐỒNG'!J34 -> 868453 | L35: =+ROUND(J35*E35,0) -> 64265522 | M35: =+ROUND(F35*J35,0) -> 0 | N35: =+ROUND(G35*J35,0) -> 0 | O35: =+ROUND(H35*J35,0) -> 0 | P35: =SUM(L35:O35) -> 64265522
A36: =A35 -> TL | B36: 1.29 | C36: Rải vải địa kỹ thuật 15kN/m | D36: m2 | E36: 672 | I36: =SUM(E36:H36) -> 672 | J36: ='BIỂU HỢP ĐỒNG'!J35 -> 26716 | L36: =+ROUND(J36*E36,0) -> 17953152 | M36: =+ROUND(F36*J36,0) -> 0 | N36: =+ROUND(G36*J36,0) -> 0 | O36: =+ROUND(H36*J36,0) -> 0 | P36: =SUM(L36:O36) -> 17953152
A37: =A36 -> TL | B37: 1.30 | C37: Đắp đất K90 bảo vệ vải địa kỹ thuật | D37: m3 | E37: 247 | I37: =SUM(E37:H37) -> 247 | J37: ='BIỂU HỢP ĐỒNG'!J36 -> 32141 | L37: =+ROUND(J37*E37,0) -> 7938827 | M37: =+ROUND(F37*J37,0) -> 0 | N37: =+ROUND(G37*J37,0) -> 0 | O37: =+ROUND(H37*J37,0) -> 0 | P37: =SUM(L37:O37) -> 7938827
A38: =A37 -> TL | B38: 1.31 | C38: Cấy bấc thấm bằng máy | D38: m | E38: 83518.1 | I38: =SUM(E38:H38) -> 83518.1 | J38: ='BIỂU HỢP ĐỒNG'!J37 -> 7813 | L38: =+ROUND(J38*E38,0) -> 652526915 | M38: =+ROUND(F38*J38,0) -> 0 | N38: =+ROUND(G38*J38,0) -> 0 | O38: =+ROUND(H38*J38,0) -> 0 | P38: =SUM(L38:O38) -> 652526915
A39: =A38 -> TL | B39: 1.32 | C39: Đệm cát hạt trung bằng máy, độ chặt yêu cầu K=0,95 | D39: m3 | E39: 15182 | F39: ='[4]PHỤ LỤC GIÁ HỢP ĐỒNG'!$K$124 -> 3791.6134 | I39: =SUM(E39:H39) -> 18973.613 | J39: ='BIỂU HỢP ĐỒNG'!J38 -> 267174 | L39: =+ROUND(J39*E39,0) -> 4056235668 | M39: =+ROUND(F39*J39,0) -> 1013020532 | N39: =+ROUND(G39*J39,0) -> 0 | O39: =+ROUND(H39*J39,0) -> 0 | P39: =SUM(L39:O39) -> 5069256200
A40: =A39 -> TL | B40: 1.33 | C40: Đào rãnh bằng máy, đất cấp II | D40: m3 | E40: 1035 | I40: =SUM(E40:H40) -> 1035 | J40: ='BIỂU HỢP ĐỒNG'!J39 -> 20867 | L40: =+ROUND(J40*E40,0) -> 21597345 | M40: =+ROUND(F40*J40,0) -> 0 | N40: =+ROUND(G40*J40,0) -> 0 | O40: =+ROUND(H40*J40,0) -> 0 | P40: =SUM(L40:O40) -> 21597345
A41: =A40 -> TL | B41: 1.34 | C41: Đắp trả rãnh đất thi công giếng cát | D41: m3 | E41: 1035 | I41: =SUM(E41:H41) -> 1035 | J41: ='BIỂU HỢP ĐỒNG'!J40 -> 12936 | L41: =+ROUND(J41*E41,0) -> 13388760 | M41: =+ROUND(F41*J41,0) -> 0 | N41: =+ROUND(G41*J41,0) -> 0 | O41: =+ROUND(H41*J41,0) -> 0 | P41: =SUM(L41:O41) -> 13388760
A42: =A41 -> TL | B42: 1.35 | C42: Lắp đặt ống nhựa- Đường kính 200mm | D42: m | E42: 27 | I42: =SUM(E42:H42) -> 27 | J42: ='BIỂU HỢP ĐỒNG'!J41 -> 301142 | L42: =+ROUND(J42*E42,0) -> 8130834 | M42: =+ROUND(F42*J42,0) -> 0 | N42: =+ROUND(G42*J42,0) -> 0 | O42: =+ROUND(H42*J42,0) -> 0 | P42: =SUM(L42:O42) -> 8130834
...

Sheet Sheet1
