Workbook

Sheet Tong hop vat tu
A1: BẢNG TỔNG HỢP VẬT TƯ CÁC TUYẾN
A2: Dự án: Xử lý khẩn cấp kè biển khu du lịch Hải Tiến, xã Hoằng Tiến
A3: Nguồn số liệu: Du_toan_Hoang_Tien_26.08.2026_TAC.xlsx, sheet 'Vật liệu'
A5: STT | B5: Tên vật tư | C5: Đơn vị | D5: Khối lượng vật tư theo từng tuyến / hạng mục | L5: Thành tiền (đ) | M5: Đơn giá bình quân (đ)
D6: Thanh thải | E6: Kè bờ tuyến 1 | F6: Kè bờ tuyến 2A | G6: Kè bờ tuyến 2B | H6: Kè bờ tuyến 2C | I6: Kè bờ tuyến 3 | J6: Bãi đúc cấu kiện | K6: Tổng khối lượng
A7: 1 | B7: Bó vỉa đá 100x20x38cm | C7: m | D7: =SUMIFS('Thanh thai'!$E$6:$E$10,'Thanh thai'!$H$6:$H$10,"Bó vỉa đá 100x20x38cm|m") -> 0 | E7: =SUMIFS('Tuyen 1'!$E$6:$E$321,'Tuyen 1'!$H$6:$H$321,"Bó vỉa đá 100x20x38cm|m") -> 149.65 | F7: =SUMIFS('Tuyen 2A'!$E$6:$E$347,'Tuyen 2A'!$H$6:$H$347,"Bó vỉa đá 100x20x38cm|m") -> 61.5 | G7: =SUMIFS('Tuyen 2B'!$E$6:$E$277,'Tuyen 2B'!$H$6:$H$277,"Bó vỉa đá 100x20x38cm|m") -> 468.425 | H7: =SUMIFS('Tuyen 2C'!$E$6:$E$306,'Tuyen 2C'!$H$6:$H$306,"Bó vỉa đá 100x20x38cm|m") -> 0 | I7: =SUMIFS('Tuyen 3'!$E$6:$E$281,'Tuyen 3'!$H$6:$H$281,"Bó vỉa đá 100x20x38cm|m") -> 0 | J7: =SUMIFS('Bai duc CK'!$E$6:$E$27,'Bai duc CK'!$H$6:$H$27,"Bó vỉa đá 100x20x38cm|m") -> 0 | K7: =SUM(D7:J7) -> 679.575 | L7: =SUMIFS('Thanh thai'!$G$6:$G$10,'Thanh thai'!$H$6:$H$10,"Bó vỉa đá 100x20x38cm|m")+SUMIFS('Tuyen 1'!$G$6:$G$321,'Tuyen 1'!$H$6:$H$321,"Bó vỉa đá 100x20x38cm|m")+SUMIFS('Tuyen 2A'!$G$6:$G$347,'Tuyen 2A'!$H$6:$H$347,"Bó vỉa đá 100x20x38cm|m")+SUMIFS('Tuyen 2B'!$G$6:$G$277,'Tuyen 2B'!$H$6:$H$277,"Bó vỉa đá 100x20x38cm|m")+SUMIFS('Tuyen 2C'!$G$6:$G$306,'Tuyen 2C'!$H$6:$H$306,"Bó vỉa đá 100x20x38cm|m")+SUMIFS('Tuyen 3'!$G$6:$G$281,'Tuyen 3'!$H$6:$H$281,"Bó vỉa đá 100x20x38cm|m")+SUMIFS('Bai duc CK'!$G$6:$G$27,'Bai duc CK'!$H$6:$H$27,"Bó vỉa đá 100x20x38cm|m") -> 356776875 | M7: =IF(K7=0,0,L7/K7) -> 525000
A8: 2 | B8: Bột đá (4,75%) | C8: kg | D8: =SUMIFS('Thanh thai'!$E$6:$E$10,'Thanh thai'!$H$6:$H$10,"Bột đá (4,75%)|kg") -> 0 | E8: =SUMIFS('Tuyen 1'!$E$6:$E$321,'Tuyen 1'!$H$6:$H$321,"Bột đá (4,75%)|kg") -> 14187.491 | F8: =SUMIFS('Tuyen 2A'!$E$6:$E$347,'Tuyen 2A'!$H$6:$H$347,"Bột đá (4,75%)|kg") -> 1505.0413 | G8: =SUMIFS('Tuyen 2B'!$E$6:$E$277,'Tuyen 2B'!$H$6:$H$277,"Bột đá (4,75%)|kg") -> 9113.4739 | H8: =SUMIFS('Tuyen 2C'!$E$6:$E$306,'Tuyen 2C'!$H$6:$H$306,"Bột đá (4,75%)|kg") -> 0 | I8: =SUMIFS('Tuyen 3'!$E$6:$E$281,'Tuyen 3'!$H$6:$H$281,"Bột đá (4,75%)|kg") -> 0 | J8: =SUMIFS('Bai duc CK'!$E$6:$E$27,'Bai duc CK'!$H$6:$H$27,"Bột đá (4,75%)|kg") -> 0 | K8: =SUM(D8:J8) -> 24806.007 | L8: =SUMIFS('Thanh thai'!$G$6:$G$10,'Thanh thai'!$H$6:$H$10,"Bột đá (4,75%)|kg")+SUMIFS('Tuyen 1'!$G$6:$G$321,'Tuyen 1'!$H$6:$H$321,"Bột đá (4,75%)|kg")+SUMIFS('Tuyen 2A'!$G$6:$G$347,'Tuyen 2A'!$H$6:$H$347,"Bột đá (4,75%)|kg")+SUMIFS('Tuyen 2B'!$G$6:$G$277,'Tuyen 2B'!$H$6:$H$277,"Bột đá (4,75%)|kg")+SUMIFS('Tuyen 2C'!$G$6:$G$306,'Tuyen 2C'!$H$6:$H$306,"Bột đá (4,75%)|kg")+SUMIFS('Tuyen 3'!$G$6:$G$281,'Tuyen 3'!$H$6:$H$281,"Bột đá (4,75%)|kg")+SUMIFS('Bai duc CK'!$G$6:$G$27,'Bai duc CK'!$H$6:$H$27,"Bột đá (4,75%)|kg") -> 17885131 | M8: =IF(K8=0,0,L8/K8) -> 721
A9: 3 | B9: Bu lông | C9: cái | D9: =SUMIFS('Thanh thai'!$E$6:$E$10,'Thanh thai'!$H$6:$H$10,"Bu lông|cái") -> 0 | E9: =SUMIFS('Tuyen 1'!$E$6:$E$321,'Tuyen 1'!$H$6:$H$321,"Bu lông|cái") -> 0 | F9: =SUMIFS('Tuyen 2A'!$E$6:$E$347,'Tuyen 2A'!$H$6:$H$347,"Bu lông|cái") -> 25.71528 | G9: =SUMIFS('Tuyen 2B'!$E$6:$E$277,'Tuyen 2B'!$H$6:$H$277,"Bu lông|cái") -> 0 | H9: =SUMIFS('Tuyen 2C'!$E$6:$E$306,'Tuyen 2C'!$H$6:$H$306,"Bu lông|cái") -> 25.71528 | I9: =SUMIFS('Tuyen 3'!$E$6:$E$281,'Tuyen 3'!$H$6:$H$281,"Bu lông|cái") -> 25.71528 | J9: =SUMIFS('Bai duc CK'!$E$6:$E$27,'Bai duc CK'!$H$6:$H$27,"Bu lông|cái") -> 0 | K9: =SUM(D9:J9) -> 77.14584 | L9: =SUMIFS('Thanh thai'!$G$6:$G$10,'Thanh thai'!$H$6:$H$10,"Bu lông|cái")+SUMIFS('Tuyen 1'!$G$6:$G$321,'Tuyen 1'!$H$6:$H$321,"Bu lông|cái")+SUMIFS('Tuyen 2A'!$G$6:$G$347,'Tuyen 2A'!$H$6:$H$347,"Bu lông|cái")+SUMIFS('Tuyen 2B'!$G$6:$G$277,'Tuyen 2B'!$H$6:$H$277,"Bu lông|cái")+SUMIFS('Tuyen 2C'!$G$6:$G$306,'Tuyen 2C'!$H$6:$H$306,"Bu lông|cái")+SUMIFS('Tuyen 3'!$G$6:$G$281,'Tuyen 3'!$H$6:$H$281,"Bu lông|cái")+SUMIFS('Bai duc CK'!$G$6:$G$27,'Bai duc CK'!$H$6:$H$27,"Bu lông|cái") -> 192864.6 | M9: =IF(K9=0,0,L9/K9) -> 2500
A10: 4 | B10: Cấp phối đá dăm loại 1 | C10: m3 | D10: =SUMIFS('Thanh thai'!$E$6:$E$10,'Thanh thai'!$H$6:$H$10,"Cấp phối đá dăm loại 1|m3") -> 0 | E10: =SUMIFS('Tuyen 1'!$E$6:$E$321,'Tuyen 1'!$H$6:$H$321,"Cấp phối đá dăm loại 1|m3") -> 0 | F10: =SUMIFS('Tuyen 2A'!$E$6:$E$347,'Tuyen 2A'!$H$6:$H$347,"Cấp phối đá dăm loại 1|m3") -> 39.0744 | G10: =SUMIFS('Tuyen 2B'!$E$6:$E$277,'Tuyen 2B'!$H$6:$H$277,"Cấp phối đá dăm loại 1|m3") -> 236.6038 | H10: =SUMIFS('Tuyen 2C'!$E$6:$E$306,'Tuyen 2C'!$H$6:$H$306,"Cấp phối đá dăm loại 1|m3") -> 0 | I10: =SUMIFS('Tuyen 3'!$E$6:$E$281,'Tuyen 3'!$H$6:$H$281,"Cấp phối đá dăm loại 1|m3") -> 0 | J10: =SUMIFS('Bai duc CK'!$E$6:$E$27,'Bai duc CK'!$H$6:$H$27,"Cấp phối đá dăm loại 1|m3") -> 211.519 | K10: =SUM(D10:J10) -> 487.1972 | L10: =SUMIFS('Thanh thai'!$G$6:$G$10,'Thanh thai'!$H$6:$H$10,"Cấp phối đá dăm loại 1|m3")+SUMIFS('Tuyen 1'!$G$6:$G$321,'Tuyen 1'!$H$6:$H$321,"Cấp phối đá dăm loại 1|m3")+SUMIFS('Tuyen 2A'!$G$6:$G$347,'Tuyen 2A'!$H$6:$H$347,"Cấp phối đá dăm loại 1|m3")+SUMIFS('Tuyen 2B'!$G$6:$G$277,'Tuyen 2B'!$H$6:$H$277,"Cấp phối đá dăm loại 1|m3")+SUMIFS('Tuyen 2C'!$G$6:$G$306,'Tuyen 2C'!$H$6:$H$306,"Cấp phối đá dăm loại 1|m3")+SUMIFS('Tuyen 3'!$G$6:$G$281,'Tuyen 3'!$H$6:$H$281,"Cấp phối đá dăm loại 1|m3")+SUMIFS('Bai duc CK'!$G$6:$G$27,'Bai duc CK'!$H$6:$H$27,"Cấp phối đá dăm loại 1|m3") -> 1.6952562e+08 | M10: =IF(K10=0,0,L10/K10) -> 347961
A11: 5 | B11: Cấp phối đá dăm loại 2 | C11: m3 | D11: =SUMIFS('Thanh thai'!$E$6:$E$10,'Thanh thai'!$H$6:$H$10,"Cấp phối đá dăm loại 2|m3") -> 0 | E11: =SUMIFS('Tuyen 1'!$E$6:$E$321,'Tuyen 1'!$H$6:$H$321,"Cấp phối đá dăm loại 2|m3") -> 0 | F11: =SUMIFS('Tuyen 2A'!$E$6:$E$347,'Tuyen 2A'!$H$6:$H$347,"Cấp phối đá dăm loại 2|m3") -> 78.1488 | G11: =SUMIFS('Tuyen 2B'!$E$6:$E$277,'Tuyen 2B'!$H$6:$H$277,"Cấp phối đá dăm loại 2|m3") -> 473.2076 | H11: =SUMIFS('Tuyen 2C'!$E$6:$E$306,'Tuyen 2C'!$H$6:$H$306,"Cấp phối đá dăm loại 2|m3") -> 0 | I11: =SUMIFS('Tuyen 3'!$E$6:$E$281,'Tuyen 3'!$H$6:$H$281,"Cấp phối đá dăm loại 2|m3") -> 0 | J11: =SUMIFS('Bai duc CK'!$E$6:$E$27,'Bai duc CK'!$H$6:$H$27,"Cấp phối đá dăm loại 2|m3") -> 1930.5648 | K11: =SUM(D11:J11) -> 2481.9212 | L11: =SUMIFS('Thanh thai'!$G$6:$G$10,'Thanh thai'!$H$6:$H$10,"Cấp phối đá dăm loại 2|m3")+SUMIFS('Tuyen 1'!$G$6:$G$321,'Tuyen 1'!$H$6:$H$321,"Cấp phối đá dăm loại 2|m3")+SUMIFS('Tuyen 2A'!$G$6:$G$347,'Tuyen 2A'!$H$6:$H$347,"Cấp phối đá dăm loại 2|m3")+SUMIFS('Tuyen 2B'!$G$6:$G$277,'Tuyen 2B'!$H$6:$H$277,"Cấp phối đá dăm loại 2|m3")+SUMIFS('Tuyen 2C'!$G$6:$G$306,'Tuyen 2C'!$H$6:$H$306,"Cấp phối đá dăm loại 2|m3")+SUMIFS('Tuyen 3'!$G$6:$G$281,'Tuyen 3'!$H$6:$H$281,"Cấp phối đá dăm loại 2|m3")+SUMIFS('Bai duc CK'!$G$6:$G$27,'Bai duc CK'!$H$6:$H$27,"Cấp phối đá dăm loại 2|m3") -> 8.1848797e+08 | M11: =IF(K11=0,0,L11/K11) -> 329780
A12: 6 | B12: Cát mịn ML=1,5÷2,0 | C12: m3 | D12: =SUMIFS('Thanh thai'!$E$6:$E$10,'Thanh thai'!$H$6:$H$10,"Cát mịn ML=1,5÷2,0|m3") -> 0 | E12: =SUMIFS('Tuyen 1'!$E$6:$E$321,'Tuyen 1'!$H$6:$H$321,"Cát mịn ML=1,5÷2,0|m3") -> 47.881433 | F12: =SUMIFS('Tuyen 2A'!$E$6:$E$347,'Tuyen 2A'!$H$6:$H$347,"Cát mịn ML=1,5÷2,0|m3") -> 53.460183 | G12: =SUMIFS('Tuyen 2B'!$E$6:$E$277,'Tuyen 2B'!$H$6:$H$277,"Cát mịn ML=1,5÷2,0|m3") -> 101.63834 | H12: =SUMIFS('Tuyen 2C'!$E$6:$E$306,'Tuyen 2C'!$H$6:$H$306,"Cát mịn ML=1,5÷2,0|m3") -> 37.73252 | I12: =SUMIFS('Tuyen 3'!$E$6:$E$281,'Tuyen 3'!$H$6:$H$281,"Cát mịn ML=1,5÷2,0|m3") -> 44.568177 | J12: =SUMIFS('Bai duc CK'!$E$6:$E$27,'Bai duc CK'!$H$6:$H$27,"Cát mịn ML=1,5÷2,0|m3") -> 0 | K12: =SUM(D12:J12) -> 285.28066 | L12: =SUMIFS('Thanh thai'!$G$6:$G$10,'Thanh thai'!$H$6:$H$10,"Cát mịn ML=1,5÷2,0|m3")+SUMIFS('Tuyen 1'!$G$6:$G$321,'Tuyen 1'!$H$6:$H$321,"Cát mịn ML=1,5÷2,0|m3")+SUMIFS('Tuyen 2A'!$G$6:$G$347,'Tuyen 2A'!$H$6:$H$347,"Cát mịn ML=1,5÷2,0|m3")+SUMIFS('Tuyen 2B'!$G$6:$G$277,'Tuyen 2B'!$H$6:$H$277,"Cát mịn ML=1,5÷2,0|m3")+SUMIFS('Tuyen 2C'!$G$6:$G$306,'Tuyen 2C'!$H$6:$H$306,"Cát mịn ML=1,5÷2,0|m3")+SUMIFS('Tuyen 3'!$G$6:$G$281,'Tuyen 3'!$H$6:$H$281,"Cát mịn ML=1,5÷2,0|m3")+SUMIFS('Bai duc CK'!$G$6:$G$27,'Bai duc CK'!$H$6:$H$27,"Cát mịn ML=1,5÷2,0|m3") -> 72723745 | M12: =IF(K12=0,0,L12/K12) -> 254920
A13: 7 | B13: Cát nền | C13: m3 | D13: =SUMIFS('Thanh thai'!$E$6:$E$10,'Thanh thai'!$H$6:$H$10,"Cát nền|m3") -> 0 | E13: =SUMIFS('Tuyen 1'!$E$6:$E$321,'Tuyen 1'!$H$6:$H$321,"Cát nền|m3") -> 0 | F13: =SUMIFS('Tuyen 2A'!$E$6:$E$347,'Tuyen 2A'!$H$6:$H$347,"Cát nền|m3") -> 0 | G13: =SUMIFS('Tuyen 2B'!$E$6:$E$277,'Tuyen 2B'!$H$6:$H$277,"Cát nền|m3") -> 0 | H13: =SUMIFS('Tuyen 2C'!$E$6:$E$306,'Tuyen 2C'!$H$6:$H$306,"Cát nền|m3") -> 21.707338 | I13: =SUMIFS('Tuyen 3'!$E$6:$E$281,'Tuyen 3'!$H$6:$H$281,"Cát nền|m3") -> 15741.355 | J13: =SUMIFS('Bai duc CK'!$E$6:$E$27,'Bai duc CK'!$H$6:$H$27,"Cát nền|m3") -> 0 | K13: =SUM(D13:J13) -> 15763.062 | L13: =SUMIFS('Thanh thai'!$G$6:$G$10,'Thanh thai'!$H$6:$H$10,"Cát nền|m3")+SUMIFS('Tuyen 1'!$G$6:$G$321,'Tuyen 1'!$H$6:$H$321,"Cát nền|m3")+SUMIFS('Tuyen 2A'!$G$6:$G$347,'Tuyen 2A'!$H$6:$H$347,"Cát nền|m3")+SUMIFS('Tuyen 2B'!$G$6:$G$277,'Tuyen 2B'!$H$6:$H$277,"Cát nền|m3")+SUMIFS('Tuyen 2C'!$G$6:$G$306,'Tuyen 2C'!$H$6:$H$306,"Cát nền|m3")+SUMIFS('Tuyen 3'!$G$6:$G$281,'Tuyen 3'!$H$6:$H$281,"Cát nền|m3")+SUMIFS('Bai duc CK'!$G$6:$G$27,'Bai duc CK'!$H$6:$H$27,"Cát nền|m3") -> 1.8915675e+09 | M13: =IF(K13=0,0,L13/K13) -> 120000
A14: 8 | B14: Cát vàng | C14: m3 | D14: =SUMIFS('Thanh thai'!$E$6:$E$10,'Thanh thai'!$H$6:$H$10,"Cát vàng|m3") -> 0 | E14: =SUMIFS('Tuyen 1'!$E$6:$E$321,'Tuyen 1'!$H$6:$H$321,"Cát vàng|m3") -> 2295.1093 | F14: =SUMIFS('Tuyen 2A'!$E$6:$E$347,'Tuyen 2A'!$H$6:$H$347,"Cát vàng|m3") -> 3281.3221 | G14: =SUMIFS('Tuyen 2B'!$E$6:$E$277,'Tuyen 2B'!$H$6:$H$277,"Cát vàng|m3") -> 3989.3966 | H14: =SUMIFS('Tuyen 2C'!$E$6:$E$306,'Tuyen 2C'!$H$6:$H$306,"Cát vàng|m3") -> 2924.3949 | I14: =SUMIFS('Tuyen 3'!$E$6:$E$281,'Tuyen 3'!$H$6:$H$281,"Cát vàng|m3") -> 3441.4248 | J14: =SUMIFS('Bai duc CK'!$E$6:$E$27,'Bai duc CK'!$H$6:$H$27,"Cát vàng|m3") -> 168.59169 | K14: =SUM(D14:J14) -> 16100.239 | L14: =SUMIFS('Thanh thai'!$G$6:$G$10,'Thanh thai'!$H$6:$H$10,"Cát vàng|m3")+SUMIFS('Tuyen 1'!$G$6:$G$321,'Tuyen 1'!$H$6:$H$321,"Cát vàng|m3")+SUMIFS('Tuyen 2A'!$G$6:$G$347,'Tuyen 2A'!$H$6:$H$347,"Cát vàng|m3")+SUMIFS('Tuyen 2B'!$G$6:$G$277,'Tuyen 2B'!$H$6:$H$277,"Cát vàng|m3")+SUMIFS('Tuyen 2C'!$G$6:$G$306,'Tuyen 2C'!$H$6:$H$306,"Cát vàng|m3")+SUMIFS('Tuyen 3'!$G$6:$G$281,'Tuyen 3'!$H$6:$H$281,"Cát vàng|m3")+SUMIFS('Bai duc CK'!$G$6:$G$27,'Bai duc CK'!$H$6:$H$27,"Cát vàng|m3") -> 8.0223468e+09 | M14: =IF(K14=0,0,L14/K14) -> 498275
A15: 9 | B15: Cọc cừ máng BT dự ứng lực, chiều cao 30-50cm | C15: m | D15: =SUMIFS('Thanh thai'!$E$6:$E$10,'Thanh thai'!$H$6:$H$10,"Cọc cừ máng BT dự ứng lực, chiều cao 30-50cm|m") -> 0 | E15: =SUMIFS('Tuyen 1'!$E$6:$E$321,'Tuyen 1'!$H$6:$H$321,"Cọc cừ máng BT dự ứng lực, chiều cao 30-50cm|m") -> 0 | F15: =SUMIFS('Tuyen 2A'!$E$6:$E$347,'Tuyen 2A'!$H$6:$H$347,"Cọc cừ máng BT dự ứng lực, chiều cao 30-50cm|m") -> 339.36 | G15: =SUMIFS('Tuyen 2B'!$E$6:$E$277,'Tuyen 2B'!$H$6:$H$277,"Cọc cừ máng BT dự ứng lực, chiều cao 30-50cm|m") -> 0 | H15: =SUMIFS('Tuyen 2C'!$E$6:$E$306,'Tuyen 2C'!$H$6:$H$306,"Cọc cừ máng BT dự ứng lực, chiều cao 30-50cm|m") -> 294.92 | I15: =SUMIFS('Tuyen 3'!$E$6:$E$281,'Tuyen 3'!$H$6:$H$281,"Cọc cừ máng BT dự ứng lực, chiều cao 30-50cm|m") -> 585.8 | J15: =SUMIFS('Bai duc CK'!$E$6:$E$27,'Bai duc CK'!$H$6:$H$27,"Cọc cừ máng BT dự ứng lực, chiều cao 30-50cm|m") -> 0 | K15: =SUM(D15:J15) -> 1220.08 | L15: =SUMIFS('Thanh thai'!$G$6:$G$10,'Thanh thai'!$H$6:$H$10,"Cọc cừ máng BT dự ứng lực, chiều cao 30-50cm|m")+SUMIFS('Tuyen 1'!$G$6:$G$321,'Tuyen 1'!$H$6:$H$321,"Cọc cừ máng BT dự ứng lực, chiều cao 30-50cm|m")+SUMIFS('Tuyen 2A'!$G$6:$G$347,'Tuyen 2A'!$H$6:$H$347,"Cọc cừ máng BT dự ứng lực, chiều cao 30-50cm|m")+SUMIFS('Tuyen 2B'!$G$6:$G$277,'Tuyen 2B'!$H$6:$H$277,"Cọc cừ máng BT dự ứng lực, chiều cao 30-50cm|m")+SUMIFS('Tuyen 2C'!$G$6:$G$306,'Tuyen 2C'!$H$6:$H$306,"Cọc cừ máng BT dự ứng lực, chiều cao 30-50cm|m")+SUMIFS('Tuyen 3'!$G$6:$G$281,'Tuyen 3'!$H$6:$H$281,"Cọc cừ máng BT dự ứng lực, chiều cao 30-50cm|m")+SUMIFS('Bai duc CK'!$G$6:$G$27,'Bai duc CK'!$H$6:$H$27,"Cọc cừ máng BT dự ứng lực, chiều cao 30-50cm|m") -> 3172208000 | M15: =IF(K15=0,0,L15/K15) -> 2600000
A16: 10 | B16: Cọc định vị | C16: kg | D16: =SUMIFS('Thanh thai'!$E$6:$E$10,'Thanh thai'!$H$6:$H$10,"Cọc định vị|kg") -> 0 | E16: =SUMIFS('Tuyen 1'!$E$6:$E$321,'Tuyen 1'!$H$6:$H$321,"Cọc định vị|kg") -> 8.83584 | F16: =SUMIFS('Tuyen 2A'!$E$6:$E$347,'Tuyen 2A'!$H$6:$H$347,"Cọc định vị|kg") -> 12.805 | G16: =SUMIFS('Tuyen 2B'!$E$6:$E$277,'Tuyen 2B'!$H$6:$H$277,"Cọc định vị|kg") -> 12.78888 | H16: =SUMIFS('Tuyen 2C'!$E$6:$E$306,'Tuyen 2C'!$H$6:$H$306,"Cọc định vị|kg") -> 11.70338 | I16: =SUMIFS('Tuyen 3'!$E$6:$E$281,'Tuyen 3'!$H$6:$H$281,"Cọc định vị|kg") -> 12.58998 | J16: =SUMIFS('Bai duc CK'!$E$6:$E$27,'Bai duc CK'!$H$6:$H$27,"Cọc định vị|kg") -> 0 | K16: =SUM(D16:J16) -> 58.72308 | L16: =SUMIFS('Thanh thai'!$G$6:$G$10,'Thanh thai'!$H$6:$H$10,"Cọc định vị|kg")+SUMIFS('Tuyen 1'!$G$6:$G$321,'Tuyen 1'!$H$6:$H$321,"Cọc định vị|kg")+SUMIFS('Tuyen 2A'!$G$6:$G$347,'Tuyen 2A'!$H$6:$H$347,"Cọc định vị|kg")+SUMIFS('Tuyen 2B'!$G$6:$G$277,'Tuyen 2B'!$H$6:$H$277,"Cọc định vị|kg")+SUMIFS('Tuyen 2C'!$G$6:$G$306,'Tuyen 2C'!$H$6:$H$306,"Cọc định vị|kg")+SUMIFS('Tuyen 3'!$G$6:$G$281,'Tuyen 3'!$H$6:$H$281,"Cọc định vị|kg")+SUMIFS('Bai duc CK'!$G$6:$G$27,'Bai duc CK'!$H$6:$H$27,"Cọc định vị|kg") -> 806267.89 | M16: =IF(K16=0,0,L16/K16) -> 13730
A17: 11 | B17: Cọc tiếp địa, thép L63x63 | C17: bộ | D17: =SUMIFS('Thanh thai'!$E$6:$E$10,'Thanh thai'!$H$6:$H$10,"Cọc tiếp địa, thép L63x63|bộ") -> 0 | E17: =SUMIFS('Tuyen 1'!$E$6:$E$321,'Tuyen 1'!$H$6:$H$321,"Cọc tiếp địa, thép L63x63|bộ") -> 4 | F17: =SUMIFS('Tuyen 2A'!$E$6:$E$347,'Tuyen 2A'!$H$6:$H$347,"Cọc tiếp địa, thép L63x63|bộ") -> 0 | G17: =SUMIFS('Tuyen 2B'!$E$6:$E$277,'Tuyen 2B'!$H$6:$H$277,"Cọc tiếp địa, thép L63x63|bộ") -> 0 | H17: =SUMIFS('Tuyen 2C'!$E$6:$E$306,'Tuyen 2C'!$H$6:$H$306,"Cọc tiếp địa, thép L63x63|bộ") -> 0 | I17: =SUMIFS('Tuyen 3'!$E$6:$E$281,'Tuyen 3'!$H$6:$H$281,"Cọc tiếp địa, thép L63x63|bộ") -> 0 | J17: =SUMIFS('Bai duc CK'!$E$6:$E$27,'Bai duc CK'!$H$6:$H$27,"Cọc tiếp địa, thép L63x63|bộ") -> 0 | K17: =SUM(D17:J17) -> 4 | L17: =SUMIFS('Thanh thai'!$G$6:$G$10,'Thanh thai'!$H$6:$H$10,"Cọc tiếp địa, thép L63x63|bộ")+SUMIFS('Tuyen 1'!$G$6:$G$321,'Tuyen 1'!$H$6:$H$321,"Cọc tiếp địa, thép L63x63|bộ")+SUMIFS('Tuyen 2A'!$G$6:$G$347,'Tuyen 2A'!$H$6:$H$347,"Cọc tiếp địa, thép L63x63|bộ")+SUMIFS('Tuyen 2B'!$G$6:$G$277,'Tuyen 2B'!$H$6:$H$277,"Cọc tiếp địa, thép L63x63|bộ")+SUMIFS('Tuyen 2C'!$G$6:$G$306,'Tuyen 2C'!$H$6:$H$306,"Cọc tiếp địa, thép L63x63|bộ")+SUMIFS('Tuyen 3'!$G$6:$G$281,'Tuyen 3'!$H$6:$H$281,"Cọc tiếp địa, thép L63x63|bộ")+SUMIFS('Bai duc CK'!$G$6:$G$27,'Bai duc CK'!$H$6:$H$27,"Cọc tiếp địa, thép L63x63|bộ") -> 3680000 | M17: =IF(K17=0,0,L17/K17) -> 920000
A18: 12 | B18: Cồn rửa | C18: kg | D18: =SUMIFS('Thanh thai'!$E$6:$E$10,'Thanh thai'!$H$6:$H$10,"Cồn rửa|kg") -> 0 | E18: =SUMIFS('Tuyen 1'!$E$6:$E$321,'Tuyen 1'!$H$6:$H$321,"Cồn rửa|kg") -> 1.208649 | F18: =SUMIFS('Tuyen 2A'!$E$6:$E$347,'Tuyen 2A'!$H$6:$H$347,"Cồn rửa|kg") -> 2.704078 | G18: =SUMIFS('Tuyen 2B'!$E$6:$E$277,'Tuyen 2B'!$H$6:$H$277,"Cồn rửa|kg") -> 3.508063 | H18: =SUMIFS('Tuyen 2C'!$E$6:$E$306,'Tuyen 2C'!$H$6:$H$306,"Cồn rửa|kg") -> 2.389595 | I18: =SUMIFS('Tuyen 3'!$E$6:$E$281,'Tuyen 3'!$H$6:$H$281,"Cồn rửa|kg") -> 2.822495 | J18: =SUMIFS('Bai duc CK'!$E$6:$E$27,'Bai duc CK'!$H$6:$H$27,"Cồn rửa|kg") -> 0 | K18: =SUM(D18:J18) -> 12.63288 | L18: =SUMIFS('Thanh thai'!$G$6:$G$10,'Thanh thai'!$H$6:$H$10,"Cồn rửa|kg")+SUMIFS('Tuyen 1'!$G$6:$G$321,'Tuyen 1'!$H$6:$H$321,"Cồn rửa|kg")+SUMIFS('Tuyen 2A'!$G$6:$G$347,'Tuyen 2A'!$H$6:$H$347,"Cồn rửa|kg")+SUMIFS('Tuyen 2B'!$G$6:$G$277,'Tuyen 2B'!$H$6:$H$277,"Cồn rửa|kg")+SUMIFS('Tuyen 2C'!$G$6:$G$306,'Tuyen 2C'!$H$6:$H$306,"Cồn rửa|kg")+SUMIFS('Tuyen 3'!$G$6:$G$281,'Tuyen 3'!$H$6:$H$281,"Cồn rửa|kg")+SUMIFS('Bai duc CK'!$G$6:$G$27,'Bai duc CK'!$H$6:$H$27,"Cồn rửa|kg") -> 189493.2 | M18: =IF(K18=0,0,L18/K18) -> 15000
A19: 13 | B19: Cột chống thép ống | C19: kg | D19: =SUMIFS('Thanh thai'!$E$6:$E$10,'Thanh thai'!$H$6:$H$10,"Cột chống thép ống|kg") -> 0 | E19: =SUMIFS('Tuyen 1'!$E$6:$E$321,'Tuyen 1'!$H$6:$H$321,"Cột chống thép ống|kg") -> 227.88776 | F19: =SUMIFS('Tuyen 2A'!$E$6:$E$347,'Tuyen 2A'!$H$6:$H$347,"Cột chống thép ống|kg") -> 373.36392 | G19: =SUMIFS('Tuyen 2B'!$E$6:$E$277,'Tuyen 2B'!$H$6:$H$277,"Cột chống thép ống|kg") -> 429.7251 | H19: =SUMIFS('Tuyen 2C'!$E$6:$E$306,'Tuyen 2C'!$H$6:$H$306,"Cột chống thép ống|kg") -> 15585.15 | I19: =SUMIFS('Tuyen 3'!$E$6:$E$281,'Tuyen 3'!$H$6:$H$281,"Cột chống thép ống|kg") -> 373.72738 | J19: =SUMIFS('Bai duc CK'!$E$6:$E$27,'Bai duc CK'!$H$6:$H$27,"Cột chống thép ống|kg") -> 0 | K19: =SUM(D19:J19) -> 16989.854 | L19: =SUMIFS('Thanh thai'!$G$6:$G$10,'Thanh thai'!$H$6:$H$10,"Cột chống thép ống|kg")+SUMIFS('Tuyen 1'!$G$6:$G$321,'Tuyen 1'!$H$6:$H$321,"Cột chống thép ống|kg")+SUMIFS('Tuyen 2A'!$G$6:$G$347,'Tuyen 2A'!$H$6:$H$347,"Cột chống thép ống|kg")+SUMIFS('Tuyen 2B'!$G$6:$G$277,'Tuyen 2B'!$H$6:$H$277,"Cột chống thép ống|kg")+SUMIFS('Tuyen 2C'!$G$6:$G$306,'Tuyen 2C'!$H$6:$H$306,"Cột chống thép ống|kg")+SUMIFS('Tuyen 3'!$G$6:$G$281,'Tuyen 3'!$H$6:$H$281,"Cột chống thép ống|kg")+SUMIFS('Bai duc CK'!$G$6:$G$27,'Bai duc CK'!$H$6:$H$27,"Cột chống thép ống|kg") -> 2.799928e+08 | M19: =IF(K19=0,0,L19/K19) -> 16480
A20: 14 | B20: Cút thép đầu cọc D34/15 | C20: cái | D20: =SUMIFS('Thanh thai'!$E$6:$E$10,'Thanh thai'!$H$6:$H$10,"Cút thép đầu cọc D34/15|cái") -> 0 | E20: =SUMIFS('Tuyen 1'!$E$6:$E$321,'Tuyen 1'!$H$6:$H$321,"Cút thép đầu cọc D34/15|cái") -> 0 | F20: =SUMIFS('Tuyen 2A'!$E$6:$E$347,'Tuyen 2A'!$H$6:$H$347,"Cút thép đầu cọc D34/15|cái") -> 1.4784 | G20: =SUMIFS('Tuyen 2B'!$E$6:$E$277,'Tuyen 2B'!$H$6:$H$277,"Cút thép đầu cọc D34/15|cái") -> 0 | H20: =SUMIFS('Tuyen 2C'!$E$6:$E$306,'Tuyen 2C'!$H$6:$H$306,"Cút thép đầu cọc D34/15|cái") -> 1.2848 | I20: =SUMIFS('Tuyen 3'!$E$6:$E$281,'Tuyen 3'!$H$6:$H$281,"Cút thép đầu cọc D34/15|cái") -> 2.552 | J20: =SUMIFS('Bai duc CK'!$E$6:$E$27,'Bai duc CK'!$H$6:$H$27,"Cút thép đầu cọc D34/15|cái") -> 0 | K20: =SUM(D20:J20) -> 5.3152 | L20: =SUMIFS('Thanh thai'!$G$6:$G$10,'Thanh thai'!$H$6:$H$10,"Cút thép đầu cọc D34/15|cái")+SUMIFS('Tuyen 1'!$G$6:$G$321,'Tuyen 1'!$H$6:$H$321,"Cút thép đầu cọc D34/15|cái")+SUMIFS('Tuyen 2A'!$G$6:$G$347,'Tuyen 2A'!$H$6:$H$347,"Cút thép đầu cọc D34/15|cái")+SUMIFS('Tuyen 2B'!$G$6:$G$277,'Tuyen 2B'!$H$6:$H$277,"Cút thép đầu cọc D34/15|cái")+SUMIFS('Tuyen 2C'!$G$6:$G$306,'Tuyen 2C'!$H$6:$H$306,"Cút thép đầu cọc D34/15|cái")+SUMIFS('Tuyen 3'!$G$6:$G$281,'Tuyen 3'!$H$6:$H$281,"Cút thép đầu cọc D34/15|cái")+SUMIFS('Bai duc CK'!$G$6:$G$27,'Bai duc CK'!$H$6:$H$27,"Cút thép đầu cọc D34/15|cái") -> 104018.46 | M20: =IF(K20=0,0,L20/K20) -> 19570
A21: 15 | B21: Đá 1x2 | C21: m3 | D21: =SUMIFS('Thanh thai'!$E$6:$E$10,'Thanh thai'!$H$6:$H$10,"Đá 1x2|m3") -> 0 | E21: =SUMIFS('Tuyen 1'!$E$6:$E$321,'Tuyen 1'!$H$6:$H$321,"Đá 1x2|m3") -> 0 | F21: =SUMIFS('Tuyen 2A'!$E$6:$E$347,'Tuyen 2A'!$H$6:$H$347,"Đá 1x2|m3") -> 0 | G21: =SUMIFS('Tuyen 2B'!$E$6:$E$277,'Tuyen 2B'!$H$6:$H$277,"Đá 1x2|m3") -> 0 | H21: =SUMIFS('Tuyen 2C'!$E$6:$E$306,'Tuyen 2C'!$H$6:$H$306,"Đá 1x2|m3") -> 0 | I21: =SUMIFS('Tuyen 3'!$E$6:$E$281,'Tuyen 3'!$H$6:$H$281,"Đá 1x2|m3") -> 0 | J21: =SUMIFS('Bai duc CK'!$E$6:$E$27,'Bai duc CK'!$H$6:$H$27,"Đá 1x2|m3") -> 0 | K21: =SUM(D21:J21) -> 0 | L21: =SUMIFS('Thanh thai'!$G$6:$G$10,'Thanh thai'!$H$6:$H$10,"Đá 1x2|m3")+SUMIFS('Tuyen 1'!$G$6:$G$321,'Tuyen 1'!$H$6:$H$321,"Đá 1x2|m3")+SUMIFS('Tuyen 2A'!$G$6:$G$347,'Tuyen 2A'!$H$6:$H$347,"Đá 1x2|m3")+SUMIFS('Tuyen 2B'!$G$6:$G$277,'Tuyen 2B'!$H$6:$H$277,"Đá 1x2|m3")+SUMIFS('Tuyen 2C'!$G$6:$G$306,'Tuyen 2C'!$H$6:$H$306,"Đá 1x2|m3")+SUMIFS('Tuyen 3'!$G$6:$G$281,'Tuyen 3'!$H$6:$H$281,"Đá 1x2|m3")+SUMIFS('Bai duc CK'!$G$6:$G$27,'Bai duc CK'!$H$6:$H$27,"Đá 1x2|m3") -> 0 | M21: =IF(K21=0,0,L21/K21) -> 0
A22: 16 | B22: Đá 2x4 | C22: m3 | D22: =SUMIFS('Thanh thai'!$E$6:$E$10,'Thanh thai'!$H$6:$H$10,"Đá 2x4|m3") -> 0 | E22: =SUMIFS('Tuyen 1'!$E$6:$E$321,'Tuyen 1'!$H$6:$H$321,"Đá 2x4|m3") -> 3723.7243 | F22: =SUMIFS('Tuyen 2A'!$E$6:$E$347,'Tuyen 2A'!$H$6:$H$347,"Đá 2x4|m3") -> 5323.7268 | G22: =SUMIFS('Tuyen 2B'!$E$6:$E$277,'Tuyen 2B'!$H$6:$H$277,"Đá 2x4|m3") -> 6472.7483 | H22: =SUMIFS('Tuyen 2C'!$E$6:$E$306,'Tuyen 2C'!$H$6:$H$306,"Đá 2x4|m3") -> 4744.5683 | I22: =SUMIFS('Tuyen 3'!$E$6:$E$281,'Tuyen 3'!$H$6:$H$281,"Đá 2x4|m3") -> 5583.4059 | J22: =SUMIFS('Bai duc CK'!$E$6:$E$27,'Bai duc CK'!$H$6:$H$27,"Đá 2x4|m3") -> 273.43566 | K22: =SUM(D22:J22) -> 26121.609 | L22: =SUMIFS('Thanh thai'!$G$6:$G$10,'Thanh thai'!$H$6:$H$10,"Đá 2x4|m3")+SUMIFS('Tuyen 1'!$G$6:$G$321,'Tuyen 1'!$H$6:$H$321,"Đá 2x4|m3")+SUMIFS('Tuyen 2A'!$G$6:$G$347,'Tuyen 2A'!$H$6:$H$347,"Đá 2x4|m3")+SUMIFS('Tuyen 2B'!$G$6:$G$277,'Tuyen 2B'!$H$6:$H$277,"Đá 2x4|m3")+SUMIFS('Tuyen 2C'!$G$6:$G$306,'Tuyen 2C'!$H$6:$H$306,"Đá 2x4|m3")+SUMIFS('Tuyen 3'!$G$6:$G$281,'Tuyen 3'!$H$6:$H$281,"Đá 2x4|m3")+SUMIFS('Bai duc CK'!$G$6:$G$27,'Bai duc CK'!$H$6:$H$27,"Đá 2x4|m3") -> 1.2300196e+10 | M22: =IF(K22=0,0,L22/K22) -> 470882.02
A23: 17 | B23: Đá 4x6 | C23: m3 | D23: =SUMIFS('Thanh thai'!$E$6:$E$10,'Thanh thai'!$H$6:$H$10,"Đá 4x6|m3") -> 0 | E23: =SUMIFS('Tuyen 1'!$E$6:$E$321,'Tuyen 1'!$H$6:$H$321,"Đá 4x6|m3") -> 2612.7431 | F23: =SUMIFS('Tuyen 2A'!$E$6:$E$347,'Tuyen 2A'!$H$6:$H$347,"Đá 4x6|m3") -> 3873.196 | G23: =SUMIFS('Tuyen 2B'!$E$6:$E$277,'Tuyen 2B'!$H$6:$H$277,"Đá 4x6|m3") -> 4940.9683 | H23: =SUMIFS('Tuyen 2C'!$E$6:$E$306,'Tuyen 2C'!$H$6:$H$306,"Đá 4x6|m3") -> 3478.728 | I23: =SUMIFS('Tuyen 3'!$E$6:$E$281,'Tuyen 3'!$H$6:$H$281,"Đá 4x6|m3") -> 4072.42 | J23: =SUMIFS('Bai duc CK'!$E$6:$E$27,'Bai duc CK'!$H$6:$H$27,"Đá 4x6|m3") -> 0 | K23: =SUM(D23:J23) -> 18978.055 | L23: =SUMIFS('Thanh thai'!$G$6:$G$10,'Thanh thai'!$H$6:$H$10,"Đá 4x6|m3")+SUMIFS('Tuyen 1'!$G$6:$G$321,'Tuyen 1'!$H$6:$H$321,"Đá 4x6|m3")+SUMIFS('Tuyen 2A'!$G$6:$G$347,'Tuyen 2A'!$H$6:$H$347,"Đá 4x6|m3")+SUMIFS('Tuyen 2B'!$G$6:$G$277,'Tuyen 2B'!$H$6:$H$277,"Đá 4x6|m3")+SUMIFS('Tuyen 2C'!$G$6:$G$306,'Tuyen 2C'!$H$6:$H$306,"Đá 4x6|m3")+SUMIFS('Tuyen 3'!$G$6:$G$281,'Tuyen 3'!$H$6:$H$281,"Đá 4x6|m3")+SUMIFS('Bai duc CK'!$G$6:$G$27,'Bai duc CK'!$H$6:$H$27,"Đá 4x6|m3") -> 7.0298323e+09 | M23: =IF(K23=0,0,L23/K23) -> 370419
A24: 18 | B24: Đá dăm 0,5x1 BTC (32,47%) | C24: m3 | D24: =SUMIFS('Thanh thai'!$E$6:$E$10,'Thanh thai'!$H$6:$H$10,"Đá dăm 0,5x1 BTC (32,47%)|m3") -> 0 | E24: =SUMIFS('Tuyen 1'!$E$6:$E$321,'Tuyen 1'!$H$6:$H$321,"Đá dăm 0,5x1 BTC (32,47%)|m3") -> 65.702898 | F24: =SUMIFS('Tuyen 2A'!$E$6:$E$347,'Tuyen 2A'!$H$6:$H$347,"Đá dăm 0,5x1 BTC (32,47%)|m3") -> 6.9699125 | G24: =SUMIFS('Tuyen 2B'!$E$6:$E$277,'Tuyen 2B'!$H$6:$H$277,"Đá dăm 0,5x1 BTC (32,47%)|m3") -> 42.2049 | H24: =SUMIFS('Tuyen 2C'!$E$6:$E$306,'Tuyen 2C'!$H$6:$H$306,"Đá dăm 0,5x1 BTC (32,47%)|m3") -> 0 | I24: =SUMIFS('Tuyen 3'!$E$6:$E$281,'Tuyen 3'!$H$6:$H$281,"Đá dăm 0,5x1 BTC (32,47%)|m3") -> 0 | J24: =SUMIFS('Bai duc CK'!$E$6:$E$27,'Bai duc CK'!$H$6:$H$27,"Đá dăm 0,5x1 BTC (32,47%)|m3") -> 0 | K24: =SUM(D24:J24) -> 114.87771 | L24: =SUMIFS('Thanh thai'!$G$6:$G$10,'Thanh thai'!$H$6:$H$10,"Đá dăm 0,5x1 BTC (32,47%)|m3")+SUMIFS('Tuyen 1'!$G$6:$G$321,'Tuyen 1'!$H$6:$H$321,"Đá dăm 0,5x1 BTC (32,47%)|m3")+SUMIFS('Tuyen 2A'!$G$6:$G$347,'Tuyen 2A'!$H$6:$H$347,"Đá dăm 0,5x1 BTC (32,47%)|m3")+SUMIFS('Tuyen 2B'!$G$6:$G$277,'Tuyen 2B'!$H$6:$H$277,"Đá dăm 0,5x1 BTC (32,47%)|m3")+SUMIFS('Tuyen 2C'!$G$6:$G$306,'Tuyen 2C'!$H$6:$H$306,"Đá dăm 0,5x1 BTC (32,47%)|m3")+SUMIFS('Tuyen 3'!$G$6:$G$281,'Tuyen 3'!$H$6:$H$281,"Đá dăm 0,5x1 BTC (32,47%)|m3")+SUMIFS('Bai duc CK'!$G$6:$G$27,'Bai duc CK'!$H$6:$H$27,"Đá dăm 0,5x1 BTC (32,47%)|m3") -> 40255332 | M24: =IF(K24=0,0,L24/K24) -> 350419
A25: 19 | B25: Đá dăm 1x2 BTN (27,69%) | C25: m3 | D25: =SUMIFS('Thanh thai'!$E$6:$E$10,'Thanh thai'!$H$6:$H$10,"Đá dăm 1x2 BTN (27,69%)|m3") -> 0 | E25: =SUMIFS('Tuyen 1'!$E$6:$E$321,'Tuyen 1'!$H$6:$H$321,"Đá dăm 1x2 BTN (27,69%)|m3") -> 75.05199 | F25: =SUMIFS('Tuyen 2A'!$E$6:$E$347,'Tuyen 2A'!$H$6:$H$347,"Đá dăm 1x2 BTN (27,69%)|m3") -> 7.9616853 | G25: =SUMIFS('Tuyen 2B'!$E$6:$E$277,'Tuyen 2B'!$H$6:$H$277,"Đá dăm 1x2 BTN (27,69%)|m3") -> 48.21038 | H25: =SUMIFS('Tuyen 2C'!$E$6:$E$306,'Tuyen 2C'!$H$6:$H$306,"Đá dăm 1x2 BTN (27,69%)|m3") -> 0 | I25: =SUMIFS('Tuyen 3'!$E$6:$E$281,'Tuyen 3'!$H$6:$H$281,"Đá dăm 1x2 BTN (27,69%)|m3") -> 0 | J25: =SUMIFS('Bai duc CK'!$E$6:$E$27,'Bai duc CK'!$H$6:$H$27,"Đá dăm 1x2 BTN (27,69%)|m3") -> 0 | K25: =SUM(D25:J25) -> 131.22406 | L25: =SUMIFS('Thanh thai'!$G$6:$G$10,'Thanh thai'!$H$6:$H$10,"Đá dăm 1x2 BTN (27,69%)|m3")+SUMIFS('Tuyen 1'!$G$6:$G$321,'Tuyen 1'!$H$6:$H$321,"Đá dăm 1x2 BTN (27,69%)|m3")+SUMIFS('Tuyen 2A'!$G$6:$G$347,'Tuyen 2A'!$H$6:$H$347,"Đá dăm 1x2 BTN (27,69%)|m3")+SUMIFS('Tuyen 2B'!$G$6:$G$277,'Tuyen 2B'!$H$6:$H$277,"Đá dăm 1x2 BTN (27,69%)|m3")+SUMIFS('Tuyen 2C'!$G$6:$G$306,'Tuyen 2C'!$H$6:$H$306,"Đá dăm 1x2 BTN (27,69%)|m3")+SUMIFS('Tuyen 3'!$G$6:$G$281,'Tuyen 3'!$H$6:$H$281,"Đá dăm 1x2 BTN (27,69%)|m3")+SUMIFS('Bai duc CK'!$G$6:$G$27,'Bai duc CK'!$H$6:$H$27,"Đá dăm 1x2 BTN (27,69%)|m3") -> 52818601 | M25: =IF(K25=0,0,L25/K25) -> 402507
A26: 20 | B26: Đá hộc 100-200kg | C26: m3 | D26: =SUMIFS('Thanh thai'!$E$6:$E$10,'Thanh thai'!$H$6:$H$10,"Đá hộc 100-200kg|m3") -> 0 | E26: =SUMIFS('Tuyen 1'!$E$6:$E$321,'Tuyen 1'!$H$6:$H$321,"Đá hộc 100-200kg|m3") -> 528.5236 | F26: =SUMIFS('Tuyen 2A'!$E$6:$E$347,'Tuyen 2A'!$H$6:$H$347,"Đá hộc 100-200kg|m3") -> 806.3002 | G26: =SUMIFS('Tuyen 2B'!$E$6:$E$277,'Tuyen 2B'!$H$6:$H$277,"Đá hộc 100-200kg|m3") -> 824.7305 | H26: =SUMIFS('Tuyen 2C'!$E$6:$E$306,'Tuyen 2C'!$H$6:$H$306,"Đá hộc 100-200kg|m3") -> 743.8338 | I26: =SUMIFS('Tuyen 3'!$E$6:$E$281,'Tuyen 3'!$H$6:$H$281,"Đá hộc 100-200kg|m3") -> 1093.4784 | J26: =SUMIFS('Bai duc CK'!$E$6:$E$27,'Bai duc CK'!$H$6:$H$27,"Đá hộc 100-200kg|m3") -> 0 | K26: =SUM(D26:J26) -> 3996.8665 | L26: =SUMIFS('Thanh thai'!$G$6:$G$10,'Thanh thai'!$H$6:$H$10,"Đá hộc 100-200kg|m3")+SUMIFS('Tuyen 1'!$G$6:$G$321,'Tuyen 1'!$H$6:$H$321,"Đá hộc 100-200kg|m3")+SUMIFS('Tuyen 2A'!$G$6:$G$347,'Tuyen 2A'!$H$6:$H$347,"Đá hộc 100-200kg|m3")+SUMIFS('Tuyen 2B'!$G$6:$G$277,'Tuyen 2B'!$H$6:$H$277,"Đá hộc 100-200kg|m3")+SUMIFS('Tuyen 2C'!$G$6:$G$306,'Tuyen 2C'!$H$6:$H$306,"Đá hộc 100-200kg|m3")+SUMIFS('Tuyen 3'!$G$6:$G$281,'Tuyen 3'!$H$6:$H$281,"Đá hộc 100-200kg|m3")+SUMIFS('Bai duc CK'!$G$6:$G$27,'Bai duc CK'!$H$6:$H$27,"Đá hộc 100-200kg|m3") -> 1.516595e+09 | M26: =IF(K26=0,0,L26/K26) -> 379446
A27: 21 | B27: Đá hộc hỗn hợp | C27: m3 | D27: =SUMIFS('Thanh thai'!$E$6:$E$10,'Thanh thai'!$H$6:$H$10,"Đá hộc hỗn hợp|m3") -> 0 | E27: =SUMIFS('Tuyen 1'!$E$6:$E$321,'Tuyen 1'!$H$6:$H$321,"Đá hộc hỗn hợp|m3") -> 15301.816 | F27: =SUMIFS('Tuyen 2A'!$E$6:$E$347,'Tuyen 2A'!$H$6:$H$347,"Đá hộc hỗn hợp|m3") -> 22385.277 | G27: =SUMIFS('Tuyen 2B'!$E$6:$E$277,'Tuyen 2B'!$H$6:$H$277,"Đá hộc hỗn hợp|m3") -> 27446.491 | H27: =SUMIFS('Tuyen 2C'!$E$6:$E$306,'Tuyen 2C'!$H$6:$H$306,"Đá hộc hỗn hợp|m3") -> 20228.073 | I27: =SUMIFS('Tuyen 3'!$E$6:$E$281,'Tuyen 3'!$H$6:$H$281,"Đá hộc hỗn hợp|m3") -> 23993.233 | J27: =SUMIFS('Bai duc CK'!$E$6:$E$27,'Bai duc CK'!$H$6:$H$27,"Đá hộc hỗn hợp|m3") -> 0 | K27: =SUM(D27:J27) -> 109354.89 | L27: =SUMIFS('Thanh thai'!$G$6:$G$10,'Thanh thai'!$H$6:$H$10,"Đá hộc hỗn hợp|m3")+SUMIFS('Tuyen 1'!$G$6:$G$321,'Tuyen 1'!$H$6:$H$321,"Đá hộc hỗn hợp|m3")+SUMIFS('Tuyen 2A'!$G$6:$G$347,'Tuyen 2A'!$H$6:$H$347,"Đá hộc hỗn hợp|m3")+SUMIFS('Tuyen 2B'!$G$6:$G$277,'Tuyen 2B'!$H$6:$H$277,"Đá hộc hỗn hợp|m3")+SUMIFS('Tuyen 2C'!$G$6:$G$306,'Tuyen 2C'!$H$6:$H$306,"Đá hộc hỗn hợp|m3")+SUMIFS('Tuyen 3'!$G$6:$G$281,'Tuyen 3'!$H$6:$H$281,"Đá hộc hỗn hợp|m3")+SUMIFS('Bai duc CK'!$G$6:$G$27,'Bai duc CK'!$H$6:$H$27,"Đá hộc hỗn hợp|m3") -> 4.1494276e+10 | M27: =IF(K27=0,0,L27/K27) -> 379446
A28: 22 | B28: Đá mạt BTN (30,59) | C28: m3 | D28: =SUMIFS('Thanh thai'!$E$6:$E$10,'Thanh thai'!$H$6:$H$10,"Đá mạt BTN (30,59)|m3") -> 0 | E28: =SUMIFS('Tuyen 1'!$E$6:$E$321,'Tuyen 1'!$H$6:$H$321,"Đá mạt BTN (30,59)|m3") -> 56.031315 | F28: =SUMIFS('Tuyen 2A'!$E$6:$E$347,'Tuyen 2A'!$H$6:$H$347,"Đá mạt BTN (30,59)|m3") -> 5.943929 | G28: =SUMIFS('Tuyen 2B'!$E$6:$E$277,'Tuyen 2B'!$H$6:$H$277,"Đá mạt BTN (30,59)|m3") -> 35.992264 | H28: =SUMIFS('Tuyen 2C'!$E$6:$E$306,'Tuyen 2C'!$H$6:$H$306,"Đá mạt BTN (30,59)|m3") -> 0 | I28: =SUMIFS('Tuyen 3'!$E$6:$E$281,'Tuyen 3'!$H$6:$H$281,"Đá mạt BTN (30,59)|m3") -> 0 | J28: =SUMIFS('Bai duc CK'!$E$6:$E$27,'Bai duc CK'!$H$6:$H$27,"Đá mạt BTN (30,59)|m3") -> 0 | K28: =SUM(D28:J28) -> 97.967508 | L28: =SUMIFS('Thanh thai'!$G$6:$G$10,'Thanh thai'!$H$6:$H$10,"Đá mạt BTN (30,59)|m3")+SUMIFS('Tuyen 1'!$G$6:$G$321,'Tuyen 1'!$H$6:$H$321,"Đá mạt BTN (30,59)|m3")+SUMIFS('Tuyen 2A'!$G$6:$G$347,'Tuyen 2A'!$H$6:$H$347,"Đá mạt BTN (30,59)|m3")+SUMIFS('Tuyen 2B'!$G$6:$G$277,'Tuyen 2B'!$H$6:$H$277,"Đá mạt BTN (30,59)|m3")+SUMIFS('Tuyen 2C'!$G$6:$G$306,'Tuyen 2C'!$H$6:$H$306,"Đá mạt BTN (30,59)|m3")+SUMIFS('Tuyen 3'!$G$6:$G$281,'Tuyen 3'!$H$6:$H$281,"Đá mạt BTN (30,59)|m3")+SUMIFS('Bai duc CK'!$G$6:$G$27,'Bai duc CK'!$H$6:$H$27,"Đá mạt BTN (30,59)|m3") -> 28451626 | M28: =IF(K28=0,0,L28/K28) -> 290419
A29: 23 | B29: Đất đắp | C29: m3 | D29: =SUMIFS('Thanh thai'!$E$6:$E$10,'Thanh thai'!$H$6:$H$10,"Đất đắp|m3") -> 0 | E29: =SUMIFS('Tuyen 1'!$E$6:$E$321,'Tuyen 1'!$H$6:$H$321,"Đất đắp|m3") -> 0 | F29: =SUMIFS('Tuyen 2A'!$E$6:$E$347,'Tuyen 2A'!$H$6:$H$347,"Đất đắp|m3") -> 4.7869196 | G29: =SUMIFS('Tuyen 2B'!$E$6:$E$277,'Tuyen 2B'!$H$6:$H$277,"Đất đắp|m3") -> 5.4806537 | H29: =SUMIFS('Tuyen 2C'!$E$6:$E$306,'Tuyen 2C'!$H$6:$H$306,"Đất đắp|m3") -> 1.1601936 | I29: =SUMIFS('Tuyen 3'!$E$6:$E$281,'Tuyen 3'!$H$6:$H$281,"Đất đắp|m3") -> 5.816101 | J29: =SUMIFS('Bai duc CK'!$E$6:$E$27,'Bai duc CK'!$H$6:$H$27,"Đất đắp|m3") -> 0 | K29: =SUM(D29:J29) -> 17.243868 | L29: =SUMIFS('Thanh thai'!$G$6:$G$10,'Thanh thai'!$H$6:$H$10,"Đất đắp|m3")+SUMIFS('Tuyen 1'!$G$6:$G$321,'Tuyen 1'!$H$6:$H$321,"Đất đắp|m3")+SUMIFS('Tuyen 2A'!$G$6:$G$347,'Tuyen 2A'!$H$6:$H$347,"Đất đắp|m3")+SUMIFS('Tuyen 2B'!$G$6:$G$277,'Tuyen 2B'!$H$6:$H$277,"Đất đắp|m3")+SUMIFS('Tuyen 2C'!$G$6:$G$306,'Tuyen 2C'!$H$6:$H$306,"Đất đắp|m3")+SUMIFS('Tuyen 3'!$G$6:$G$281,'Tuyen 3'!$H$6:$H$281,"Đất đắp|m3")+SUMIFS('Bai duc CK'!$G$6:$G$27,'Bai duc CK'!$H$6:$H$27,"Đất đắp|m3") -> 862193.39 | M29: =IF(K29=0,0,L29/K29) -> 50000
A30: 24 | B30: Dầu bảo ôn | C30: lít | D30: =SUMIFS('Thanh thai'!$E$6:$E$10,'Thanh thai'!$H$6:$H$10,"Dầu bảo ôn|lít") -> 0 | E30: =SUMIFS('Tuyen 1'!$E$6:$E$321,'Tuyen 1'!$H$6:$H$321,"Dầu bảo ôn|lít") -> 134.37145 | F30: =SUMIFS('Tuyen 2A'!$E$6:$E$347,'Tuyen 2A'!$H$6:$H$347,"Dầu bảo ôn|lít") -> 14.254429 | G30: =SUMIFS('Tuyen 2B'!$E$6:$E$277,'Tuyen 2B'!$H$6:$H$277,"Dầu bảo ôn|lít") -> 86.314818 | H30: =SUMIFS('Tuyen 2C'!$E$6:$E$306,'Tuyen 2C'!$H$6:$H$306,"Dầu bảo ôn|lít") -> 0 | I30: =SUMIFS('Tuyen 3'!$E$6:$E$281,'Tuyen 3'!$H$6:$H$281,"Dầu bảo ôn|lít") -> 0 | J30: =SUMIFS('Bai duc CK'!$E$6:$E$27,'Bai duc CK'!$H$6:$H$27,"Dầu bảo ôn|lít") -> 0 | K30: =SUM(D30:J30) -> 234.9407 | L30: =SUMIFS('Thanh thai'!$G$6:$G$10,'Thanh thai'!$H$6:$H$10,"Dầu bảo ôn|lít")+SUMIFS('Tuyen 1'!$G$6:$G$321,'Tuyen 1'!$H$6:$H$321,"Dầu bảo ôn|lít")+SUMIFS('Tuyen 2A'!$G$6:$G$347,'Tuyen 2A'!$H$6:$H$347,"Dầu bảo ôn|lít")+SUMIFS('Tuyen 2B'!$G$6:$G$277,'Tuyen 2B'!$H$6:$H$277,"Dầu bảo ôn|lít")+SUMIFS('Tuyen 2C'!$G$6:$G$306,'Tuyen 2C'!$H$6:$H$306,"Dầu bảo ôn|lít")+SUMIFS('Tuyen 3'!$G$6:$G$281,'Tuyen 3'!$H$6:$H$281,"Dầu bảo ôn|lít")+SUMIFS('Bai duc CK'!$G$6:$G$27,'Bai duc CK'!$H$6:$H$27,"Dầu bảo ôn|lít") -> 8222924.5 | M30: =IF(K30=0,0,L30/K30) -> 35000
A31: 25 | B31: Dầu diezel | C31: lít | D31: =SUMIFS('Thanh thai'!$E$6:$E$10,'Thanh thai'!$H$6:$H$10,"Dầu diezel|lít") -> 0 | E31: =SUMIFS('Tuyen 1'!$E$6:$E$321,'Tuyen 1'!$H$6:$H$321,"Dầu diezel|lít") -> 474.25219 | F31: =SUMIFS('Tuyen 2A'!$E$6:$E$347,'Tuyen 2A'!$H$6:$H$347,"Dầu diezel|lít") -> 50.309748 | G31: =SUMIFS('Tuyen 2B'!$E$6:$E$277,'Tuyen 2B'!$H$6:$H$277,"Dầu diezel|lít") -> 304.64053 | H31: =SUMIFS('Tuyen 2C'!$E$6:$E$306,'Tuyen 2C'!$H$6:$H$306,"Dầu diezel|lít") -> 0 | I31: =SUMIFS('Tuyen 3'!$E$6:$E$281,'Tuyen 3'!$H$6:$H$281,"Dầu diezel|lít") -> 0 | J31: =SUMIFS('Bai duc CK'!$E$6:$E$27,'Bai duc CK'!$H$6:$H$27,"Dầu diezel|lít") -> 0 | K31: =SUM(D31:J31) -> 829.20247 | L31: =SUMIFS('Thanh thai'!$G$6:$G$10,'Thanh thai'!$H$6:$H$10,"Dầu diezel|lít")+SUMIFS('Tuyen 1'!$G$6:$G$321,'Tuyen 1'!$H$6:$H$321,"Dầu diezel|lít")+SUMIFS('Tuyen 2A'!$G$6:$G$347,'Tuyen 2A'!$H$6:$H$347,"Dầu diezel|lít")+SUMIFS('Tuyen 2B'!$G$6:$G$277,'Tuyen 2B'!$H$6:$H$277,"Dầu diezel|lít")+SUMIFS('Tuyen 2C'!$G$6:$G$306,'Tuyen 2C'!$H$6:$H$306,"Dầu diezel|lít")+SUMIFS('Tuyen 3'!$G$6:$G$281,'Tuyen 3'!$H$6:$H$281,"Dầu diezel|lít")+SUMIFS('Bai duc CK'!$G$6:$G$27,'Bai duc CK'!$H$6:$H$27,"Dầu diezel|lít") -> 23292297 | M31: =IF(K31=0,0,L31/K31) -> 28090
A32: 26 | B32: Dầu mazút | C32: lít | D32: =SUMIFS('Thanh thai'!$E$6:$E$10,'Thanh thai'!$H$6:$H$10,"Dầu mazút|lít") -> 0 | E32: =SUMIFS('Tuyen 1'!$E$6:$E$321,'Tuyen 1'!$H$6:$H$321,"Dầu mazút|lít") -> 2687.4291 | F32: =SUMIFS('Tuyen 2A'!$E$6:$E$347,'Tuyen 2A'!$H$6:$H$347,"Dầu mazút|lít") -> 285.08857 | G32: =SUMIFS('Tuyen 2B'!$E$6:$E$277,'Tuyen 2B'!$H$6:$H$277,"Dầu mazút|lít") -> 1726.2964 | H32: =SUMIFS('Tuyen 2C'!$E$6:$E$306,'Tuyen 2C'!$H$6:$H$306,"Dầu mazút|lít") -> 0 | I32: =SUMIFS('Tuyen 3'!$E$6:$E$281,'Tuyen 3'!$H$6:$H$281,"Dầu mazút|lít") -> 0 | J32: =SUMIFS('Bai duc CK'!$E$6:$E$27,'Bai duc CK'!$H$6:$H$27,"Dầu mazút|lít") -> 0 | K32: =SUM(D32:J32) -> 4698.814 | L32: =SUMIFS('Thanh thai'!$G$6:$G$10,'Thanh thai'!$H$6:$H$10,"Dầu mazút|lít")+SUMIFS('Tuyen 1'!$G$6:$G$321,'Tuyen 1'!$H$6:$H$321,"Dầu mazút|lít")+SUMIFS('Tuyen 2A'!$G$6:$G$347,'Tuyen 2A'!$H$6:$H$347,"Dầu mazút|lít")+SUMIFS('Tuyen 2B'!$G$6:$G$277,'Tuyen 2B'!$H$6:$H$277,"Dầu mazút|lít")+SUMIFS('Tuyen 2C'!$G$6:$G$306,'Tuyen 2C'!$H$6:$H$306,"Dầu mazút|lít")+SUMIFS('Tuyen 3'!$G$6:$G$281,'Tuyen 3'!$H$6:$H$281,"Dầu mazút|lít")+SUMIFS('Bai duc CK'!$G$6:$G$27,'Bai duc CK'!$H$6:$H$27,"Dầu mazút|lít") -> 68311358 | M32: =IF(K32=0,0,L32/K32) -> 14538
A33: 27 | B33: Dây thép | C33: kg | D33: =SUMIFS('Thanh thai'!$E$6:$E$10,'Thanh thai'!$H$6:$H$10,"Dây thép|kg") -> 0 | E33: =SUMIFS('Tuyen 1'!$E$6:$E$321,'Tuyen 1'!$H$6:$H$321,"Dây thép|kg") -> 213.57216 | F33: =SUMIFS('Tuyen 2A'!$E$6:$E$347,'Tuyen 2A'!$H$6:$H$347,"Dây thép|kg") -> 330.50602 | G33: =SUMIFS('Tuyen 2B'!$E$6:$E$277,'Tuyen 2B'!$H$6:$H$277,"Dây thép|kg") -> 375.20901 | H33: =SUMIFS('Tuyen 2C'!$E$6:$E$306,'Tuyen 2C'!$H$6:$H$306,"Dây thép|kg") -> 293.3747 | I33: =SUMIFS('Tuyen 3'!$E$6:$E$281,'Tuyen 3'!$H$6:$H$281,"Dây thép|kg") -> 332.7136 | J33: =SUMIFS('Bai duc CK'!$E$6:$E$27,'Bai duc CK'!$H$6:$H$27,"Dây thép|kg") -> 0 | K33: =SUM(D33:J33) -> 1545.3755 | L33: =SUMIFS('Thanh thai'!$G$6:$G$10,'Thanh thai'!$H$6:$H$10,"Dây thép|kg")+SUMIFS('Tuyen 1'!$G$6:$G$321,'Tuyen 1'!$H$6:$H$321,"Dây thép|kg")+SUMIFS('Tuyen 2A'!$G$6:$G$347,'Tuyen 2A'!$H$6:$H$347,"Dây thép|kg")+SUMIFS('Tuyen 2B'!$G$6:$G$277,'Tuyen 2B'!$H$6:$H$277,"Dây thép|kg")+SUMIFS('Tuyen 2C'!$G$6:$G$306,'Tuyen 2C'!$H$6:$H$306,"Dây thép|kg")+SUMIFS('Tuyen 3'!$G$6:$G$281,'Tuyen 3'!$H$6:$H$281,"Dây thép|kg")+SUMIFS('Bai duc CK'!$G$6:$G$27,'Bai duc CK'!$H$6:$H$27,"Dây thép|kg") -> 32218138 | M33: =IF(K33=0,0,L33/K33) -> 20848.097
A34: 28 | B34: Dây thép D10mm | C34: kg | D34: =SUMIFS('Thanh thai'!$E$6:$E$10,'Thanh thai'!$H$6:$H$10,"Dây thép D10mm|kg") -> 0 | E34: =SUMIFS('Tuyen 1'!$E$6:$E$321,'Tuyen 1'!$H$6:$H$321,"Dây thép D10mm|kg") -> 24.8 | F34: =SUMIFS('Tuyen 2A'!$E$6:$E$347,'Tuyen 2A'!$H$6:$H$347,"Dây thép D10mm|kg") -> 0 | G34: =SUMIFS('Tuyen 2B'!$E$6:$E$277,'Tuyen 2B'!$H$6:$H$277,"Dây thép D10mm|kg") -> 0 | H34: =SUMIFS('Tuyen 2C'!$E$6:$E$306,'Tuyen 2C'!$H$6:$H$306,"Dây thép D10mm|kg") -> 0 | I34: =SUMIFS('Tuyen 3'!$E$6:$E$281,'Tuyen 3'!$H$6:$H$281,"Dây thép D10mm|kg") -> 0 | J34: =SUMIFS('Bai duc CK'!$E$6:$E$27,'Bai duc CK'!$H$6:$H$27,"Dây thép D10mm|kg") -> 0 | K34: =SUM(D34:J34) -> 24.8 | L34: =SUMIFS('Thanh thai'!$G$6:$G$10,'Thanh thai'!$H$6:$H$10,"Dây thép D10mm|kg")+SUMIFS('Tuyen 1'!$G$6:$G$321,'Tuyen 1'!$H$6:$H$321,"Dây thép D10mm|kg")+SUMIFS('Tuyen 2A'!$G$6:$G$347,'Tuyen 2A'!$H$6:$H$347,"Dây thép D10mm|kg")+SUMIFS('Tuyen 2B'!$G$6:$G$277,'Tuyen 2B'!$H$6:$H$277,"Dây thép D10mm|kg")+SUMIFS('Tuyen 2C'!$G$6:$G$306,'Tuyen 2C'!$H$6:$H$306,"Dây thép D10mm|kg")+SUMIFS('Tuyen 3'!$G$6:$G$281,'Tuyen 3'!$H$6:$H$281,"Dây thép D10mm|kg")+SUMIFS('Bai duc CK'!$G$6:$G$27,'Bai duc CK'!$H$6:$H$27,"Dây thép D10mm|kg") -> 520800 | M34: =IF(K34=0,0,L34/K34) -> 21000
A35: 29 | B35: Gạch Terrazzo | C35: m2 | D35: =SUMIFS('Thanh thai'!$E$6:$E$10,'Thanh thai'!$H$6:$H$10,"Gạch Terrazzo|m2") -> 0 | E35: =SUMIFS('Tuyen 1'!$E$6:$E$321,'Tuyen 1'!$H$6:$H$321,"Gạch Terrazzo|m2") -> 1530.9075 | F35: =SUMIFS('Tuyen 2A'!$E$6:$E$347,'Tuyen 2A'!$H$6:$H$347,"Gạch Terrazzo|m2") -> 1776.0547 | G35: =SUMIFS('Tuyen 2B'!$E$6:$E$277,'Tuyen 2B'!$H$6:$H$277,"Gạch Terrazzo|m2") -> 3154.3209 | H35: =SUMIFS('Tuyen 2C'!$E$6:$E$306,'Tuyen 2C'!$H$6:$H$306,"Gạch Terrazzo|m2") -> 1281.0032 | I35: =SUMIFS('Tuyen 3'!$E$6:$E$281,'Tuyen 3'!$H$6:$H$281,"Gạch Terrazzo|m2") -> 1513.0709 | J35: =SUMIFS('Bai duc CK'!$E$6:$E$27,'Bai duc CK'!$H$6:$H$27,"Gạch Terrazzo|m2") -> 0 | K35: =SUM(D35:J35) -> 9255.3572 | L35: =SUMIFS('Thanh thai'!$G$6:$G$10,'Thanh thai'!$H$6:$H$10,"Gạch Terrazzo|m2")+SUMIFS('Tuyen 1'!$G$6:$G$321,'Tuyen 1'!$H$6:$H$321,"Gạch Terrazzo|m2")+SUMIFS('Tuyen 2A'!$G$6:$G$347,'Tuyen 2A'!$H$6:$H$347,"Gạch Terrazzo|m2")+SUMIFS('Tuyen 2B'!$G$6:$G$277,'Tuyen 2B'!$H$6:$H$277,"Gạch Terrazzo|m2")+SUMIFS('Tuyen 2C'!$G$6:$G$306,'Tuyen 2C'!$H$6:$H$306,"Gạch Terrazzo|m2")+SUMIFS('Tuyen 3'!$G$6:$G$281,'Tuyen 3'!$H$6:$H$281,"Gạch Terrazzo|m2")+SUMIFS('Bai duc CK'!$G$6:$G$27,'Bai duc CK'!$H$6:$H$27,"Gạch Terrazzo|m2") -> 1388303580 | M35: =IF(K35=0,0,L35/K35) -> 150000
A36: 30 | B36: Gỗ kê | C36: m3 | D36: =SUMIFS('Thanh thai'!$E$6:$E$10,'Thanh thai'!$H$6:$H$10,"Gỗ kê|m3") -> 0 | E36: =SUMIFS('Tuyen 1'!$E$6:$E$321,'Tuyen 1'!$H$6:$H$321,"Gỗ kê|m3") -> 0.0104 | F36: =SUMIFS('Tuyen 2A'!$E$6:$E$347,'Tuyen 2A'!$H$6:$H$347,"Gỗ kê|m3") -> 0 | G36: =SUMIFS('Tuyen 2B'!$E$6:$E$277,'Tuyen 2B'!$H$6:$H$277,"Gỗ kê|m3") -> 0 | H36: =SUMIFS('Tuyen 2C'!$E$6:$E$306,'Tuyen 2C'!$H$6:$H$306,"Gỗ kê|m3") -> 0 | I36: =SUMIFS('Tuyen 3'!$E$6:$E$281,'Tuyen 3'!$H$6:$H$281,"Gỗ kê|m3") -> 0 | J36: =SUMIFS('Bai duc CK'!$E$6:$E$27,'Bai duc CK'!$H$6:$H$27,"Gỗ kê|m3") -> 0 | K36: =SUM(D36:J36) -> 0.0104 | L36: =SUMIFS('Thanh thai'!$G$6:$G$10,'Thanh thai'!$H$6:$H$10,"Gỗ kê|m3")+SUMIFS('Tuyen 1'!$G$6:$G$321,'Tuyen 1'!$H$6:$H$321,"Gỗ kê|m3")+SUMIFS('Tuyen 2A'!$G$6:$G$347,'Tuyen 2A'!$H$6:$H$347,"Gỗ kê|m3")+SUMIFS('Tuyen 2B'!$G$6:$G$277,'Tuyen 2B'!$H$6:$H$277,"Gỗ kê|m3")+SUMIFS('Tuyen 2C'!$G$6:$G$306,'Tuyen 2C'!$H$6:$H$306,"Gỗ kê|m3")+SUMIFS('Tuyen 3'!$G$6:$G$281,'Tuyen 3'!$H$6:$H$281,"Gỗ kê|m3")+SUMIFS('Bai duc CK'!$G$6:$G$27,'Bai duc CK'!$H$6:$H$27,"Gỗ kê|m3") -> 30727.268 | M36: =IF(K36=0,0,L36/K36) -> 2954545
A37: 31 | B37: Khí gas | C37: kg | D37: =SUMIFS('Thanh thai'!$E$6:$E$10,'Thanh thai'!$H$6:$H$10,"Khí gas|kg") -> 0 | E37: =SUMIFS('Tuyen 1'!$E$6:$E$321,'Tuyen 1'!$H$6:$H$321,"Khí gas|kg") -> 20.05032 | F37: =SUMIFS('Tuyen 2A'!$E$6:$E$347,'Tuyen 2A'!$H$6:$H$347,"Khí gas|kg") -> 15.429168 | G37: =SUMIFS('Tuyen 2B'!$E$6:$E$277,'Tuyen 2B'!$H$6:$H$277,"Khí gas|kg") -> 0 | H37: =SUMIFS('Tuyen 2C'!$E$6:$E$306,'Tuyen 2C'!$H$6:$H$306,"Khí gas|kg") -> 15.429168 | I37: =SUMIFS('Tuyen 3'!$E$6:$E$281,'Tuyen 3'!$H$6:$H$281,"Khí gas|kg") -> 15.429168 | J37: =SUMIFS('Bai duc CK'!$E$6:$E$27,'Bai duc CK'!$H$6:$H$27,"Khí gas|kg") -> 0 | K37: =SUM(D37:J37) -> 66.337824 | L37: =SUMIFS('Thanh thai'!$G$6:$G$10,'Thanh thai'!$H$6:$H$10,"Khí gas|kg")+SUMIFS('Tuyen 1'!$G$6:$G$321,'Tuyen 1'!$H$6:$H$321,"Khí gas|kg")+SUMIFS('Tuyen 2A'!$G$6:$G$347,'Tuyen 2A'!$H$6:$H$347,"Khí gas|kg")+SUMIFS('Tuyen 2B'!$G$6:$G$277,'Tuyen 2B'!$H$6:$H$277,"Khí gas|kg")+SUMIFS('Tuyen 2C'!$G$6:$G$306,'Tuyen 2C'!$H$6:$H$306,"Khí gas|kg")+SUMIFS('Tuyen 3'!$G$6:$G$281,'Tuyen 3'!$H$6:$H$281,"Khí gas|kg")+SUMIFS('Bai duc CK'!$G$6:$G$27,'Bai duc CK'!$H$6:$H$27,"Khí gas|kg") -> 1276115.4 | M37: =IF(K37=0,0,L37/K37) -> 19236.618
A38: 32 | B38: Khung móng M24 | C38: bộ | D38: =SUMIFS('Thanh thai'!$E$6:$E$10,'Thanh thai'!$H$6:$H$10,"Khung móng M24|bộ") -> 0 | E38: =SUMIFS('Tuyen 1'!$E$6:$E$321,'Tuyen 1'!$H$6:$H$321,"Khung móng M24|bộ") -> 4 | F38: =SUMIFS('Tuyen 2A'!$E$6:$E$347,'Tuyen 2A'!$H$6:$H$347,"Khung móng M24|bộ") -> 0 | G38: =SUMIFS('Tuyen 2B'!$E$6:$E$277,'Tuyen 2B'!$H$6:$H$277,"Khung móng M24|bộ") -> 0 | H38: =SUMIFS('Tuyen 2C'!$E$6:$E$306,'Tuyen 2C'!$H$6:$H$306,"Khung móng M24|bộ") -> 0 | I38: =SUMIFS('Tuyen 3'!$E$6:$E$281,'Tuyen 3'!$H$6:$H$281,"Khung móng M24|bộ") -> 0 | J38: =SUMIFS('Bai duc CK'!$E$6:$E$27,'Bai duc CK'!$H$6:$H$27,"Khung móng M24|bộ") -> 0 | K38: =SUM(D38:J38) -> 4 | L38: =SUMIFS('Thanh thai'!$G$6:$G$10,'Thanh thai'!$H$6:$H$10,"Khung móng M24|bộ")+SUMIFS('Tuyen 1'!$G$6:$G$321,'Tuyen 1'!$H$6:$H$321,"Khung móng M24|bộ")+SUMIFS('Tuyen 2A'!$G$6:$G$347,'Tuyen 2A'!$H$6:$H$347,"Khung móng M24|bộ")+SUMIFS('Tuyen 2B'!$G$6:$G$277,'Tuyen 2B'!$H$6:$H$277,"Khung móng M24|bộ")+SUMIFS('Tuyen 2C'!$G$6:$G$306,'Tuyen 2C'!$H$6:$H$306,"Khung móng M24|bộ")+SUMIFS('Tuyen 3'!$G$6:$G$281,'Tuyen 3'!$H$6:$H$281,"Khung móng M24|bộ")+SUMIFS('Bai duc CK'!$G$6:$G$27,'Bai duc CK'!$H$6:$H$27,"Khung móng M24|bộ") -> 3320000 | M38: =IF(K38=0,0,L38/K38) -> 830000
A39: 33 | B39: Mua tấm đan làm bằng gang 1000x350mm | C39: 1 cấu kiện | D39: =SUMIFS('Thanh thai'!$E$6:$E$10,'Thanh thai'!$H$6:$H$10,"Mua tấm đan làm bằng gang 1000x350mm|1 cấu kiện") -> 0 | E39: =SUMIFS('Tuyen 1'!$E$6:$E$321,'Tuyen 1'!$H$6:$H$321,"Mua tấm đan làm bằng gang 1000x350mm|1 cấu kiện") -> 26 | F39: =SUMIFS('Tuyen 2A'!$E$6:$E$347,'Tuyen 2A'!$H$6:$H$347,"Mua tấm đan làm bằng gang 1000x350mm|1 cấu kiện") -> 41 | G39: =SUMIFS('Tuyen 2B'!$E$6:$E$277,'Tuyen 2B'!$H$6:$H$277,"Mua tấm đan làm bằng gang 1000x350mm|1 cấu kiện") -> 49 | H39: =SUMIFS('Tuyen 2C'!$E$6:$E$306,'Tuyen 2C'!$H$6:$H$306,"Mua tấm đan làm bằng gang 1000x350mm|1 cấu kiện") -> 36 | I39: =SUMIFS('Tuyen 3'!$E$6:$E$281,'Tuyen 3'!$H$6:$H$281,"Mua tấm đan làm bằng gang 1000x350mm|1 cấu kiện") -> 27 | J39: =SUMIFS('Bai duc CK'!$E$6:$E$27,'Bai duc CK'!$H$6:$H$27,"Mua tấm đan làm bằng gang 1000x350mm|1 cấu kiện") -> 0 | K39: =SUM(D39:J39) -> 179 | L39: =SUMIFS('Thanh thai'!$G$6:$G$10,'Thanh thai'!$H$6:$H$10,"Mua tấm đan làm bằng gang 1000x350mm|1 cấu kiện")+SUMIFS('Tuyen 1'!$G$6:$G$321,'Tuyen 1'!$H$6:$H$321,"Mua tấm đan làm bằng gang 1000x350mm|1 cấu kiện")+SUMIFS('Tuyen 2A'!$G$6:$G$347,'Tuyen 2A'!$H$6:$H$347,"Mua tấm đan làm bằng gang 1000x350mm|1 cấu kiện")+SUMIFS('Tuyen 2B'!$G$6:$G$277,'Tuyen 2B'!$H$6:$H$277,"Mua tấm đan làm bằng gang 1000x350mm|1 cấu kiện")+SUMIFS('Tuyen 2C'!$G$6:$G$306,'Tuyen 2C'!$H$6:$H$306,"Mua tấm đan làm bằng gang 1000x350mm|1 cấu kiện")+SUMIFS('Tuyen 3'!$G$6:$G$281,'Tuyen 3'!$H$6:$H$281,"Mua tấm đan làm bằng gang 1000x350mm|1 cấu kiện")+SUMIFS('Bai duc CK'!$G$6:$G$27,'Bai duc CK'!$H$6:$H$27,"Mua tấm đan làm bằng gang 1000x350mm|1 cấu kiện") -> 226435000 | M39: =IF(K39=0,0,L39/K39) -> 1265000
A40: 34 | B40: Nhựa dán | C40: kg | D40: =SUMIFS('Thanh thai'!$E$6:$E$10,'Thanh thai'!$H$6:$H$10,"Nhựa dán|kg") -> 0 | E40: =SUMIFS('Tuyen 1'!$E$6:$E$321,'Tuyen 1'!$H$6:$H$321,"Nhựa dán|kg") -> 0.408384 | F40: =SUMIFS('Tuyen 2A'!$E$6:$E$347,'Tuyen 2A'!$H$6:$H$347,"Nhựa dán|kg") -> 0.915026 | G40: =SUMIFS('Tuyen 2B'!$E$6:$E$277,'Tuyen 2B'!$H$6:$H$277,"Nhựa dán|kg") -> 1.186021 | H40: =SUMIFS('Tuyen 2C'!$E$6:$E$306,'Tuyen 2C'!$H$6:$H$306,"Nhựa dán|kg") -> 0.808786 | I40: =SUMIFS('Tuyen 3'!$E$6:$E$281,'Tuyen 3'!$H$6:$H$281,"Nhựa dán|kg") -> 0.955306 | J40: =SUMIFS('Bai duc CK'!$E$6:$E$27,'Bai duc CK'!$H$6:$H$27,"Nhựa dán|kg") -> 0 | K40: =SUM(D40:J40) -> 4.273523 | L40: =SUMIFS('Thanh thai'!$G$6:$G$10,'Thanh thai'!$H$6:$H$10,"Nhựa dán|kg")+SUMIFS('Tuyen 1'!$G$6:$G$321,'Tuyen 1'!$H$6:$H$321,"Nhựa dán|kg")+SUMIFS('Tuyen 2A'!$G$6:$G$347,'Tuyen 2A'!$H$6:$H$347,"Nhựa dán|kg")+SUMIFS('Tuyen 2B'!$G$6:$G$277,'Tuyen 2B'!$H$6:$H$277,"Nhựa dán|kg")+SUMIFS('Tuyen 2C'!$G$6:$G$306,'Tuyen 2C'!$H$6:$H$306,"Nhựa dán|kg")+SUMIFS('Tuyen 3'!$G$6:$G$281,'Tuyen 3'!$H$6:$H$281,"Nhựa dán|kg")+SUMIFS('Bai duc CK'!$G$6:$G$27,'Bai duc CK'!$H$6:$H$27,"Nhựa dán|kg") -> 504275.71 | M40: =IF(K40=0,0,L40/K40) -> 118000
A41: 35 | B41: Nhựa đường BTN (4,5%) | C41: kg | D41: =SUMIFS('Thanh thai'!$E$6:$E$10,'Thanh thai'!$H$6:$H$10,"Nhựa đường BTN (4,5%)|kg") -> 0 | E41: =SUMIFS('Tuyen 1'!$E$6:$E$321,'Tuyen 1'!$H$6:$H$321,"Nhựa đường BTN (4,5%)|kg") -> 14580.725 | F41: =SUMIFS('Tuyen 2A'!$E$6:$E$347,'Tuyen 2A'!$H$6:$H$347,"Nhựa đường BTN (4,5%)|kg") -> 1546.7564 | G41: =SUMIFS('Tuyen 2B'!$E$6:$E$277,'Tuyen 2B'!$H$6:$H$277,"Nhựa đường BTN (4,5%)|kg") -> 9366.0717 | H41: =SUMIFS('Tuyen 2C'!$E$6:$E$306,'Tuyen 2C'!$H$6:$H$306,"Nhựa đường BTN (4,5%)|kg") -> 0 | I41: =SUMIFS('Tuyen 3'!$E$6:$E$281,'Tuyen 3'!$H$6:$H$281,"Nhựa đường BTN (4,5%)|kg") -> 0 | J41: =SUMIFS('Bai duc CK'!$E$6:$E$27,'Bai duc CK'!$H$6:$H$27,"Nhựa đường BTN (4,5%)|kg") -> 0 | K41: =SUM(D41:J41) -> 25493.554 | L41: =SUMIFS('Thanh thai'!$G$6:$G$10,'Thanh thai'!$H$6:$H$10,"Nhựa đường BTN (4,5%)|kg")+SUMIFS('Tuyen 1'!$G$6:$G$321,'Tuyen 1'!$H$6:$H$321,"Nhựa đường BTN (4,5%)|kg")+SUMIFS('Tuyen 2A'!$G$6:$G$347,'Tuyen 2A'!$H$6:$H$347,"Nhựa đường BTN (4,5%)|kg")+SUMIFS('Tuyen 2B'!$G$6:$G$277,'Tuyen 2B'!$H$6:$H$277,"Nhựa đường BTN (4,5%)|kg")+SUMIFS('Tuyen 2C'!$G$6:$G$306,'Tuyen 2C'!$H$6:$H$306,"Nhựa đường BTN (4,5%)|kg")+SUMIFS('Tuyen 3'!$G$6:$G$281,'Tuyen 3'!$H$6:$H$281,"Nhựa đường BTN (4,5%)|kg")+SUMIFS('Bai duc CK'!$G$6:$G$27,'Bai duc CK'!$H$6:$H$27,"Nhựa đường BTN (4,5%)|kg") -> 5.3133664e+08 | M41: =IF(K41=0,0,L41/K41) -> 20842
...

Sheet Thanh thai
A1: BẢNG BÓC VẬT TƯ - THANH THẢI
A2: Dự án: Xử lý khẩn cấp kè biển khu du lịch Hải Tiến, xã Hoằng Tiến
A3: (Căn cứ theo Giá vật liệu xây dựng quý 4/2025 - tỉnh Thanh Hóa) - Nguồn số liệu: Du_toan_Hoang_Tien_26.08.2026_TAC.xlsx, sheet 'Vật liệu'
A5: STT | B5: Mã hiệu | C5: Tên vật tư / Công tác sử dụng | D5: Đơn vị | E5: Khối lượng | F5: Đơn giá (đ) | G5: Thành tiền (đ) | H5: Khóa tổng hợp
A6: 1 | B6: V00515 | C6: Que hàn | D6: kg | E6: =SUM(E7:E10) -> 4246.1184 | F6: 25000 | G6: =E6*F6 -> 106152960 | H6: Que hàn|kg
B7: AA.22111 | C7: - Phá dỡ ống buy D1000 có cốt thép bằng búa căn khí nén 3m3/ph | E7: 914.592 | G7: =E7*$F$6 -> 22864800
B8: AA.22111 | C8: - Phá dỡ nắp ống bê tông có cốt thép bằng búa căn khí nén 3m3/ph | E8: 838.3776 | G8: =E8*$F$6 -> 20959440
B9: AA.22111 | C9: - Phá dỡ kết cấu bê tông có cốt thép bằng búa căn khí nén 3m3/ph | E9: 1613.088 | G9: =E9*$F$6 -> 40327200
B10: AA.22111 | C10: - Phá dỡ bậc thang có cốt thép bằng búa căn khí nén 3m3/ph | E10: 880.0608 | G10: =E10*$F$6 -> 22001520
A11: TỔNG CỘNG CHI PHÍ VẬT LIỆU | G11: =SUMIFS(G6:G10,H6:H10,"?*") -> 106152960
A12: Ghi chú: dòng in đậm là vật tư (khối lượng = tổng các công tác bên dưới); dòng in nghiêng là công tác sử dụng vật tư đó. Bấm dấu [-]/[+] bên trái để thu gọn/mở chi tiết. Chữ xanh là số liệu lấy nguyên từ file dự toán.

Sheet Tuyen 1
A1: BẢNG BÓC VẬT TƯ - KÈ BỜ TUYẾN 1
A2: Dự án: Xử lý khẩn cấp kè biển khu du lịch Hải Tiến, xã Hoằng Tiến
A3: (Căn cứ theo Giá vật liệu xây dựng quý 2/2026 - tỉnh Thanh Hóa) - Nguồn số liệu: Du_toan_Hoang_Tien_26.08.2026_TAC.xlsx, sheet 'Vật liệu'
A5: STT | B5: Mã hiệu | C5: Tên vật tư / Công tác sử dụng | D5: Đơn vị | E5: Khối lượng | F5: Đơn giá (đ) | G5: Thành tiền (đ) | H5: Khóa tổng hợp
A6: 1 | B6: V00710 | C6: Bó vỉa đá 100x20x38cm | D6: m | E6: =SUM(E7:E7) -> 149.65 | F6: 525000 | G6: =E6*F6 -> 78566250 | H6: Bó vỉa đá 100x20x38cm|m
B7: AK.57121 | C7: - Bó vỉa thẳng hè, bó vỉa đá 20x30x100cm, vữa XM M25, PCB40 | E7: 149.65 | G7: =E7*$F$6 -> 78566250
A8: 2 | B8: V00091 | C8: Bột đá (4,75%) | D8: kg | E8: =SUM(E9:E9) -> 14187.491 | F8: 721 | G8: =E8*F8 -> 10229181 | H8: Bột đá (4,75%)|kg
B9: TT | C9: - Tỷ phối BTN C16 | E9: 14187.491 | G9: =E9*$F$8 -> 10229181
A10: 3 | B10: V85971 | C10: Cát mịn ML=1,5÷2,0 | D10: m3 | E10: =SUM(E11:E14) -> 47.881433 | F10: 254920 | G10: =E10*F10 -> 12205935 | H10: Cát mịn ML=1,5÷2,0|m3
B11: AK.55110 | C11: - Lát gạch xi măng, vữa XM M75, PCB40 | E11: 27.269742 | G11: =E11*$F$10 -> 6951602.8
B12: AK.55113 | C12: - Lát gạch xi măng, vữa XM M75, PCB40 | E12: 17.82382 | G12: =E12*$F$10 -> 4543648.2
B13: AK.57121 | C13: - Bó vỉa thẳng hè, bó vỉa đá 20x30x100cm, vữa XM M25, PCB40 | E13: 0.92929 | G13: =E13*$F$10 -> 236894.61
B14: AK.57121 | C14: - Tấm đan bó vỉa 50x30x5cm, vữa XM M25, PCB40 | E14: 1.85858 | G14: =E14*$F$10 -> 473789.21
A15: 4 | B15: V00112 | C15: Cát vàng | D15: m3 | E15: =SUM(E16:E33) -> 2295.1093 | F15: 498275 | G15: =E15*F15 -> 1.1435956e+09 | H15: Cát vàng|m3
B16: AF.12154 | C16: - Bê tông vai kè, đổ bằng thủ công - Chiều dày ≤45cm, chiều cao ≤6m, M300, đá 2x4, PCB40 | E16: 91.535185 | G16: =E16*$F$15 -> 45609695
B17: AG.11924 | C17: - Bê tông khối bậc thang 2T, bê tông M300, đá 2x4, PCB40 - Đổ bê tông đúc sẵn bằng thủ công (vữa bê tông sản xuất bằng máy trộn) | E17: 1365.3607 | G17: =E17*$F$15 -> 6.803251e+08
B18: AG.11924 | C18: - Bê tông khối bậc thang 2T, bê tông M300, đá 2x4, PCB40 - Đổ bê tông đúc sẵn bằng thủ công (vữa bê tông sản xuất bằng máy trộn) | E18: 21.570526 | G18: =E18*$F$15 -> 10748054
B19: AG.11924 | C19: - Bê tông khối bậc thang 2T, bê tông M300, đá 2x4, PCB40 - Đổ bê tông đúc sẵn bằng thủ công (vữa bê tông sản xuất bằng máy trộn) | E19: 24.613374 | G19: =E19*$F$15 -> 12264229
B20: AG.11924 | C20: - Bê tông khối chặn chân 1,5x1,5x0,5m, bê tông M300, đá 2x4, PCB40 - Đổ bê tông đúc sẵn bằng thủ công (vữa bê tông sản xuất bằng máy trộn) | E20: 330.99653 | G20: =E20*$F$15 -> 1.649273e+08
B21: AG.11924 | C21: - Bê tông khối vai kè 2T, bê tông thương phẩm M300, đá 2x4 - Đổ bê tông đúc sẵn bằng thủ công | E21: 74.718261 | G21: =E21*$F$15 -> 37230241
B22: AG.11924 | C22: - Bê tông khối vai kè 2T, bê tông thương phẩm M300, đá 2x4 - Đổ bê tông đúc sẵn bằng thủ công | E22: 77.449676 | G22: =E22*$F$15 -> 38591238
B23: AF.12314 | C23: - Bê tông dầm 50x50cm khóa đầu kè, đổ bằng thủ công, chiều cao ≤6m, M300, đá 2x4, PCB40 | E23: 4.3462973 | G23: =E23*$F$15 -> 2165651.3
B24: AF.24314 | C24: - Bê tông tường chắn, Chiều dày (cm) ≤45cm, bê tông M300, đá 2x4, PCB40 | E24: 44.798312 | G24: =E24*$F$15 -> 22321879
B25: AF.24314 | C25: - Bê tông tường chắn, Chiều dày (cm) ≤45cm, bê tông M300, đá 2x4, PCB40 | E25: 52.676298 | G25: =E25*$F$15 -> 26247282
B26: AF.12155A | C26: - Bê tông tường SX bằng máy trộn, đổ bằng thủ công - Chiều dày ≤45cm, chiều cao ≤6m, M300, đá 2x4, PCB30 | E26: 33.672203 | G26: =E26*$F$15 -> 16778017
B27: AF.12614 | C27: - Bê tông bậc lên xuống, đổ bằng thủ công, bê tông M300, đá 2x4, PCB40 | E27: 7.6820675 | G27: =E27*$F$15 -> 3827782.2
... B33: AF.11314 | C33: - Bê tông nền SX bằng máy trộn, đổ bằng thủ công, M200, đá 2x4, PCB40 | E33: 32.054845 | G33: =E33*$F$15 -> 15972128
A34: 5 | B34: V00649 | C34: Cọc định vị | D34: kg | E34: =SUM(E35:E35) -> 8.83584 | F34: 13730 | G34: =E34*F34 -> 121316.08 | H34: Cọc định vị|kg
B35: TT | C35: - Thi công ống địa kĩ thuật (Ống Geotube) | E35: 8.83584 | G35: =E35*$F$34 -> 121316.08
A36: 6 | B36: V18044 | C36: Cọc tiếp địa, thép L63x63 | D36: bộ | E36: =SUM(E37:E37) -> 4 | F36: 920000 | G36: =E36*F36 -> 3680000 | H36: Cọc tiếp địa, thép L63x63|bộ
B37: CS.1.06.10 | C37: - Làm tiếp địa cho cột điện | E37: 4 | G37: =E37*$F$36 -> 3680000
A38: 7 | B38: V01982 | C38: Cồn rửa | D38: kg | E38: =SUM(E39:E40) -> 1.208649 | F38: 15000 | G38: =E38*F38 -> 18129.735 | H38: Cồn rửa|kg
B39: BB.41108 | C39: - Lắp đặt ống nhựa PVC miệng bát, nối bằng p/p dán keo, đoạn ống dài 6m - Đường kính 100mm thoát nước | E39: 0.135954 | G39: =E39*$F$38 -> 2039.31
B40: BB.41111 | C40: - Lắp đặt ống nhựa PVC miệng bát, nối bằng p/p dán keo, đoạn ống dài 6m - Đường kính 200mm chứa dây điện | E40: 1.072695 | G40: =E40*$F$38 -> 16090.425
A41: 8 | B41: V00199 | C41: Cột chống thép ống | D41: kg | E41: =SUM(E42:E43) -> 227.88776 | F41: 16480 | G41: =E41*F41 -> 3755590.3 | H41: Cột chống thép ống|kg
B42: AF.86381 | C42: - Ván khuôn thép tường chắn | E42: 119.61381 | G42: =E42*$F$41 -> 1971235.6
B43: AF.86381 | C43: - Ván khuôn thép tường chắn | E43: 108.27395 | G43: =E43*$F$41 -> 1784354.7
A44: 9 | B44: V05208 | C44: Đá 2x4 | D44: m3 | E44: =SUM(E45:E60) -> 3578.2574 | F44: 473574 | G44: =E44*F44 -> 1.6945697e+09 | H44: Đá 2x4|m3
B45: AF.12154 | C45: - Bê tông vai kè, đổ bằng thủ công - Chiều dày ≤45cm, chiều cao ≤6m, M300, đá 2x4, PCB40 | E45: 148.49446 | G45: =E45*$F$44 -> 70323114
B46: AG.11924 | C46: - Bê tông khối bậc thang 2T, bê tông M300, đá 2x4, PCB40 - Đổ bê tông đúc sẵn bằng thủ công (vữa bê tông sản xuất bằng máy trộn) | E46: 2214.9788 | G46: =E46*$F$44 -> 1.0489564e+09
...

Sheet Tuyen 2A
A1: BẢNG BÓC VẬT TƯ - KÈ BỜ TUYẾN 2A
A2: Dự án: Xử lý khẩn cấp kè biển khu du lịch Hải Tiến, xã Hoằng Tiến
A3: (Căn cứ theo Giá vật liệu xây dựng quý 2/2026 - tỉnh Thanh Hóa) - Nguồn số liệu: Du_toan_Hoang_Tien_26.08.2026_TAC.xlsx, sheet 'Vật liệu'
A5: STT | B5: Mã hiệu | C5: Tên vật tư / Công tác sử dụng | D5: Đơn vị | E5: Khối lượng | F5: Đơn giá (đ) | G5: Thành tiền (đ) | H5: Khóa tổng hợp
A6: 1 | B6: V00710 | C6: Bó vỉa đá 100x20x38cm | D6: m | E6: =SUM(E7:E7) -> 61.5 | F6: 525000 | G6: =E6*F6 -> 32287500 | H6: Bó vỉa đá 100x20x38cm|m
B7: AK.57121 | C7: - Bó vỉa thẳng hè, bó vỉa đá 20x30x100cm, vữa XM M25, PCB40 | E7: 61.5 | G7: =E7*$F$6 -> 32287500
A8: 2 | B8: V00091 | C8: Bột đá (4,75%) | D8: kg | E8: =SUM(E9:E9) -> 1505.0413 | F8: 721 | G8: =E8*F8 -> 1085134.8 | H8: Bột đá (4,75%)|kg
B9: TT | C9: - Tỷ phối BTN C16 | E9: 1505.0413 | G9: =E9*$F$8 -> 1085134.8
A10: 3 | B10: V00010 | C10: Bu lông | D10: cái | E10: =SUM(E11:E11) -> 25.71528 | F10: 2500 | G10: =E10*F10 -> 64288.2 | H10: Bu lông|cái
B11: AI.63311 | C11: - Lắp dựng kết cấu thép hệ khung dàn, sàn đạo trên cạn | E11: 25.71528 | G11: =E11*$F$10 -> 64288.2
A12: 4 | B12: V03097 | C12: Cấp phối đá dăm loại 1 | D12: m3 | E12: =SUM(E13:E13) -> 39.0744 | F12: 347961 | G12: =E12*F12 -> 13596367 | H12: Cấp phối đá dăm loại 1|m3
B13: AD.11222 | C13: - Thi công móng cấp phối đá dăm loại I dày 15cm | E13: 39.0744 | G13: =E13*$F$12 -> 13596367
A14: 5 | B14: V03097 | C14: Cấp phối đá dăm loại 2 | D14: m3 | E14: =SUM(E15:E15) -> 78.1488 | F14: 329780 | G14: =E14*F14 -> 25771911 | H14: Cấp phối đá dăm loại 2|m3
B15: AD.11212 | C15: - Thi công móng cấp phối đá dăm loại II dày 30cm | E15: 78.1488 | G15: =E15*$F$14 -> 25771911
A16: 6 | B16: V85971 | C16: Cát mịn ML=1,5÷2,0 | D16: m3 | E16: =SUM(E17:E20) -> 53.460183 | F16: 254920 | G16: =E16*F16 -> 13628070 | H16: Cát mịn ML=1,5÷2,0|m3
B17: AK.55110 | C17: - Lát gạch xi măng, vữa XM M75, PCB40 | E17: 42.081375 | G17: =E17*$F$16 -> 10727384
B18: AK.55113 | C18: - Lát gạch xi măng, vữa XM M75, PCB40 | E18: 10.233107 | G18: =E18*$F$16 -> 2608623.8
B19: AK.57121 | C19: - Bó vỉa thẳng hè, bó vỉa đá 20x30x100cm, vữa XM M25, PCB40 | E19: 0.3819 | G19: =E19*$F$16 -> 97353.948
B20: AK.57121 | C20: - Tấm đan bó vỉa 50x30x5cm, vữa XM M25, PCB40 | E20: 0.7638 | G20: =E20*$F$16 -> 194707.9
A21: 7 | B21: V00112 | C21: Cát vàng | D21: m3 | E21: =SUM(E22:E37) -> 3281.3221 | F21: 498275 | G21: =E21*F21 -> 1.6350008e+09 | H21: Cát vàng|m3
B22: AF.12154 | C22: - Bê tông vai kè, đổ bằng thủ công - Chiều dày ≤45cm, chiều cao ≤6m, M300, đá 2x4, PCB40 | E22: 139.5146 | G22: =E22*$F$21 -> 69516635
B23: AG.11924 | C23: - Bê tông khối bậc thang 2T, bê tông M300, đá 2x4, PCB40 - Đổ bê tông đúc sẵn bằng thủ công (vữa bê tông sản xuất bằng máy trộn) | E23: 1981.4864 | G23: =E23*$F$21 -> 9.8732514e+08
B24: AG.11924 | C24: - Bê tông khối bậc thang loại A, bê tông M300, đá 2x4, PCB40 - Đổ bê tông đúc sẵn bằng thủ công (vữa bê tông sản xuất bằng máy trộn) | E24: 33.747025 | G24: =E24*$F$21 -> 16815299
B25: AG.11924 | C25: - Bê tông khối bậc thang loại B, bê tông M300, đá 2x4, PCB40 - Đổ bê tông đúc sẵn bằng thủ công (vữa bê tông sản xuất bằng máy trộn) | E25: 20.804709 | G25: =E25*$F$21 -> 10366466
B26: AG.11924 | C26: - Bê tông khối chặn chân 1,5x1,5x0,5m, bê tông M300, đá 2x4, PCB40 - Đổ bê tông đúc sẵn bằng thủ công (vữa bê tông sản xuất bằng máy trộn) | E26: 436.5364 | G26: =E26*$F$21 -> 2.1751517e+08
B27: AG.11924 | C27: - Bê tông khối vai kè 2T, bê tông thương phẩm M300, đá 2x4 - Đổ bê tông đúc sẵn bằng thủ công | E27: 120.19761 | G27: =E27*$F$21 -> 59891464
B28: AG.11924 | C28: - Bê tông khối vai kè 2T, bê tông thương phẩm M300, đá 2x4 - Đổ bê tông đúc sẵn bằng thủ công | E28: 117.52746 | G28: =E28*$F$21 -> 58560995
B29: AF.24314 | C29: - Bê tông tường chắn, Chiều dày (cm) ≤45cm, bê tông M300, đá 2x4, PCB40 | E29: 70.644087 | G29: =E29*$F$21 -> 35200182
B30: AF.24314 | C30: - Bê tông tường chắn, Chiều dày (cm) ≤45cm, bê tông M300, đá 2x4, PCB40 | E30: 79.986306 | G30: =E30*$F$21 -> 39855176
B31: AF.12155A | C31: - Bê tông tường SX bằng máy trộn, đổ bằng thủ công - Chiều dày ≤45cm, chiều cao ≤6m, M300, đá 2x4, PCB30 | E31: 89.364615 | G31: =E31*$F$21 -> 44528153
B32: AF.12614 | C32: - Bê tông bậc lên xuống, đổ bằng thủ công, bê tông M300, đá 2x4, PCB40 | E32: 16.647917 | G32: =E32*$F$21 -> 8295240.7
B33: AF.13226 | C33: - Bê tông rãnh nước, đổ bằng thủ công, bê tông M400, đá 2x4, PCB40 | E33: 54.483875 | G33: =E33*$F$21 -> 27147953
... B37: AF.12314 | C37: - Bê tông dầm mũ SX bằng máy trộn, đổ bằng thủ công, chiều cao ≤6m, M300, đá 2x4, PCB40 | E37: 7.9037647 | G37: =E37*$F$21 -> 3938248.4
A38: 8 | B38: V42165 | C38: Cọc cừ máng BT dự ứng lực, chiều cao 30-50cm | D38: m | E38: =SUM(E39:E42) -> 339.36 | F38: 2600000 | G38: =E38*F38 -> 882336000 | H38: Cọc cừ máng BT dự ứng lực, chiều cao 30-50cm|m
B39: AC.12411 | C39: - Đóng cọc cừ máng bê tông dự ứng lực trên cạn bằng búa rung 50kW kết hợp xói nước đầu cọc, chiều cao máng cọc 30-50cm (phần ngập đất) | E39: 171.8414 | G39: =E39*$F$38 -> 446787640
B40: AC.12411 | C40: - Đóng cọc cừ máng bê tông dự ứng lực trên cạn bằng búa rung 50kW kết hợp xói nước đầu cọc, chiều cao máng cọc 30-50cm (phần tự do) | E40: 70.5586 | G40: =E40*$F$38 -> 183452360
B41: AC.12411 | C41: - Đóng cọc cừ máng bê tông dự ứng lực trên cạn bằng búa rung 50kW kết hợp xói nước đầu cọc, chiều cao máng cọc 30-50cm (phần ngập đất) | E41: 66.3671 | G41: =E41*$F$38 -> 172554460
B42: AC.12411 | C42: - Đóng cọc cừ máng bê tông dự ứng lực trên cạn bằng búa rung 50kW kết hợp xói nước đầu cọc, chiều cao máng cọc 30-50cm (phần tự do) | E42: 30.5929 | G42: =E42*$F$38 -> 79541540
A43: 9 | B43: V00649 | C43: Cọc định vị | D43: kg | E43: =SUM(E44:E44) -> 12.805 | F43: 13730 | G43: =E43*F43 -> 175812.65 | H43: Cọc định vị|kg
B44: TT | C44: - Thi công ống địa kĩ thuật (Ống Geotube) | E44: 12.805 | G44: =E44*$F$43 -> 175812.65
...

Sheet Tuyen 2B
A1: BẢNG BÓC VẬT TƯ - KÈ BỜ TUYẾN 2B
A2: Dự án: Xử lý khẩn cấp kè biển khu du lịch Hải Tiến, xã Hoằng Tiến
A3: (Căn cứ theo Giá vật liệu xây dựng quý 2/2026 - tỉnh Thanh Hóa) - Nguồn số liệu: Du_toan_Hoang_Tien_26.08.2026_TAC.xlsx, sheet 'Vật liệu'
A5: STT | B5: Mã hiệu | C5: Tên vật tư / Công tác sử dụng | D5: Đơn vị | E5: Khối lượng | F5: Đơn giá (đ) | G5: Thành tiền (đ) | H5: Khóa tổng hợp
A6: 1 | B6: V00710 | C6: Bó vỉa đá 100x20x38cm | D6: m | E6: =SUM(E7:E7) -> 468.425 | F6: 525000 | G6: =E6*F6 -> 245923125 | H6: Bó vỉa đá 100x20x38cm|m
B7: AK.57121 | C7: - Bó vỉa thẳng hè, bó vỉa đá 20x30x100cm, vữa XM M25, PCB40 | E7: 468.425 | G7: =E7*$F$6 -> 245923125
A8: 2 | B8: V00091 | C8: Bột đá (4,75%) | D8: kg | E8: =SUM(E9:E9) -> 9113.4739 | F8: 721 | G8: =E8*F8 -> 6570814.7 | H8: Bột đá (4,75%)|kg
B9: TT | C9: - Tỷ phối BTN C16 | E9: 9113.4739 | G9: =E9*$F$8 -> 6570814.7
