Workbook

Sheet 03a TT
A1: THÔNG SỐ NHẬP (không in) – ô nền vàng
A2: Thanh toán lần thứ | C2: 1
A3: Căn cứ xác định | C3: Biên bản nghiệm thu hoàn thành giai đoạn số ....../BBNT ngày ...../...../2026
A4: Tạm ứng đã nhận theo hợp đồng (đồng) | C4: 0
A5: Tạm ứng đã thu hồi đến hết kỳ trước (đồng) | C5: 0
A6: Đã thanh toán KLHT cho nhà thầu đến hết kỳ trước (đồng) | C6: 0
A7: Tỷ lệ thanh toán tối đa khi chưa quyết toán | C7: 0.9
A8: Tạm ứng đề nghị kỳ này (đồng) | C8: 0
A9: Thu hồi tạm ứng kỳ này (đồng) – để trống thì tự tính
A12: ỦY BAN NHÂN DÂN XÃ HOẰNG PHÚ | K12: Mẫu số 03a/TT
A14: BẢNG XÁC ĐỊNH GIÁ TRỊ KHỐI LƯỢNG CÔNG VIỆC HOÀN THÀNH
A15: Tên dự án: Hạ tầng kỹ thuật Khu dân cư và công viên Cây xanh, xã Hoằng Phú, tỉnh Thanh Hoá (được UBND huyện Hoằng Hóa phê duyệt tại Quyết định số 613/QĐ-UBND ngày 21/02/2025)
A16: Tên gói thầu: Gói thầu số 03: Thi công xây dựng công trình + thiết bị
A17: Căn cứ hợp đồng số: 10/2026/HĐ-TCXD ngày 09 tháng 10 năm 2026 (giá hợp đồng trọn gói: 25.007.549.000 đồng)
A18: Chủ đầu tư: Ủy ban nhân dân xã Hoằng Phú
A19: Nhà thầu: Công ty TNHH Hoàng Tuấn
A20: ="Thanh toán lần thứ: "&'03a TT'!$C$2 -> Thanh toán lần thứ: 1
A21: ="Căn cứ xác định: "&'03a TT'!$C$3 -> Căn cứ xác định: Biên bản nghiệm thu hoàn thành giai đoạn số ....../BBNT ngày ...../...../2026
A23: STT | B23: Chỉ tiêu | E23: Giá trị hợp đồng/Dự toán | F23: Giá trị KLHT chưa thanh toán đến hết kỳ trước | G23: Giá trị KLHT nghiệm thu trong kỳ này | H23: Giá trị KLHT đề nghị thanh toán kỳ này | I23: Giá trị KLHT chưa thanh toán đến hết kỳ này | J23: Luỹ kế giá trị KLHT đã thanh toán đến hết kỳ trước | K23: Luỹ kế giá trị KLHT đã thanh toán đến hết kỳ này | L23: Ghi chú
A24: (1) | B24: (2) | E24: (3) | F24: (4) | G24: (5) | H24: (6) | I24: (7)=(4)+(5)-(6) | J24: (8) | K24: (9)=(8)+(6) | L24: (10)
A25: I | B25: Công việc thực hiện thông qua hợp đồng | E25: ='PL.3A'!I597 -> 25007549000 | F25: =MAX(0,ROUND('PL.3A'!J597-J25,0)) -> 0 | G25: ='PL.3A'!K597 -> 0 | H25: =I42+I37 -> 0 | I25: =F25+G25-H25 -> 0 | J25: =$C$6+$C$5 -> 0 | K25: =J25+H25 -> 0
A26: II | B26: Công việc thực hiện không thông qua Hợp đồng (không bao gồm chi phí quản lý dự án) | E26: 0 | F26: 0 | G26: 0 | H26: 0 | I26: 0 | J26: 0 | K26: 0 | L26: 0
A27: III | B27: Chi phí đảm bảo cho việc tổ chức thực hiện bồi thường, hỗ trợ, tái định cư | E27: 0 | F27: 0 | G27: 0 | H27: 0 | I27: 0 | J27: 0 | K27: 0 | L27: 0
A28: IV | B28: Chi phí quản lý dự án | E28: 0 | F28: 0 | G28: 0 | H28: 0 | I28: 0 | J28: 0 | K28: 0 | L28: 0
A29: Tổng cộng | E29: =SUM(E25:E28) -> 25007549000 | F29: =SUM(F25:F28) -> 0 | G29: =SUM(G25:G28) -> 0 | H29: =SUM(H25:H28) -> 0 | I29: =SUM(I25:I28) -> 0 | J29: =SUM(J25:J28) -> 0 | K29: =SUM(K25:K28) -> 0
A31: 1. | B31: Giá trị tạm ứng chưa thu hồi đến hết kỳ trước: | I31: =$C$4-$C$5 -> 0 | J31: đồng
A32: 2. | B32: Số tiền đã thanh toán khối lượng hoàn thành đến hết kỳ trước: | I32: =SUM(I33:I35) -> 0 | J32: đồng
A33: 2.1 | B33: Thanh toán cho nhà thầu: | I33: =$C$6 -> 0 | J33: đồng
A34: 2.2 | B34: Tiền bảo hành công trình (trong trường hợp không bảo lãnh bảo hành): | I34: 0 | J34: đồng
A35: 2.3 | B35: Chuyển vào tài khoản tạm giữ chờ quyết toán: | I35: 0 | J35: đồng
A36: 3. | B36: Luỹ kế giá trị khối lượng thực hiện đến hết kỳ này: | I36: ='PL.3A'!L597 -> 0 | J36: đồng
A37: 4. | B37: Thanh toán để thu hồi tạm ứng: | I37: =IF($C$9="",MIN(IF(I36>=0.8*E25,I31,MIN(I31,ROUND(G25*IF(E25=0,0,$C$4/E25),-3))),MAX(0,ROUNDDOWN(I36*$C$7-I33,-3))),$C$9) -> 0 | J37: đồng
A38: 5. | B38: Giá trị đề nghị giải ngân kỳ này: | I38: =I40+I41 -> 0 | J38: đồng
B39: Số tiền bằng chữ: ............................................................................................................
A40: + | B40: Tạm ứng: | I40: =$C$8 -> 0 | J40: đồng
A41: + | B41: Thanh toán khối lượng hoàn thành: | I41: =I42+I43+I44 -> 0 | J41: đồng
A42: + | B42: Thanh toán cho nhà thầu | I42: =MAX(0,ROUNDDOWN(I36*$C$7-I33,-3))-I37 -> 0 | J42: đồng
A43: + | B43: Tiền bảo hành công trình (trong trường hợp không bảo lãnh bảo hành) | I43: 0 | J43: đồng
A44: + | B44: Chuyển vào tài khoản tạm giữ chờ quyết toán | I44: 0 | J44: đồng
A45: 6. | B45: Luỹ kế giá trị giải ngân: | I45: =I46+I47 -> 0 | J45: đồng
...

Sheet PL.Khoi luong
A1: PHỤ LỤC KHỐI LƯỢNG NGHIỆM THU HOÀN THÀNH
A2: ="(Kèm theo "&'03a TT'!$C$3&")" -> (Kèm theo Biên bản nghiệm thu hoàn thành giai đoạn số ....../BBNT ngày ...../...../2026)
A3: Dự án: Hạ tầng kỹ thuật Khu dân cư và công viên Cây xanh, xã Hoằng Phú, tỉnh Thanh Hoá (được UBND huyện Hoằng Hóa phê duyệt tại Quyết định số 613/QĐ-UBND ngày 21/02/2025)
A5: STT | B5: Nội dung công việc | C5: Đơn vị | D5: Khối lượng | H5: Ghi chú
D6: Khối lượng theo hợp đồng | E6: Thực hiện
E7: Luỹ kế đến hết kỳ trước | F7: Thực hiện kỳ này | G7: Luỹ kế đến hết kỳ này
A8: (1) | B8: (2) | C8: (3) | D8: (4) | E8: (5) | F8: (6) | G8: (7)=(5)+(6) | H8: (8)
A9: 1 | B9: HẠNG MỤC: GIAO THÔNG
A10: 1.1 | B10: GIAO THÔNG
A11: 1.1.1 | B11: BTN C16 lớp trên | C11: 100tấn | D11: 11.2167 | E11: 0 | F11: 0 | G11: =E11+F11 -> 0 | H11: =IF(G11>D11,"Vượt KL HĐ","")
A12: 1.1.2 | B12: Sản xuất bê tông nhựa | C12: 100tấn | D12: 11.2167 | E12: 0 | F12: 0 | G12: =E12+F12 -> 0 | H12: =IF(G12>D12,"Vượt KL HĐ","")
A13: 1.1.3 | B13: Vận chuyển đá dăm đen, bê tông nhựa từ trạm trộn đến vị trí đổ | C13: 100tấn | D13: 11.2167 | E13: 0 | F13: 0 | G13: =E13+F13 -> 0 | H13: =IF(G13>D13,"Vượt KL HĐ","")
A14: 1.1.4 | B14: Rải thảm mặt đường bê tông nhựa (Loại BTNC 16) dày 7cm | C14: 100m2 | D14: 65.0131 | E14: 0 | F14: 0 | G14: =E14+F14 -> 0 | H14: =IF(G14>D14,"Vượt KL HĐ","")
A15: 1.1.5 | B15: Tưới lớp dính bám, thấm bám mặt đường | C15: 100m2 | D15: 65.0131 | E15: 0 | F15: 0 | G15: =E15+F15 -> 0 | H15: =IF(G15>D15,"Vượt KL HĐ","")
A16: 1.1.6 | B16: Móng cấp phối đá dăm loại 1 dày 15cm | C16: 100m3 | D16: 9.4043 | E16: 0 | F16: 0 | G16: =E16+F16 -> 0 | H16: =IF(G16>D16,"Vượt KL HĐ","")
A17: 1.1.7 | B17: Móng cấp phối đá dăm loại 2 dày 18cm | C17: 100m3 | D17: 11.3547 | E17: 0 | F17: 0 | G17: =E17+F17 -> 0 | H17: =IF(G17>D17,"Vượt KL HĐ","")
A18: 1.1.8 | B18: Đất đắp K98 | C18: m3 | D18: 2639.947 | E18: 0 | F18: 0 | G18: =E18+F18 -> 0 | H18: =IF(G18>D18,"Vượt KL HĐ","")
A19: 1.1.9 | B19: Đắp nền đường, độ chặt Y/C K = 0,98 | C19: 100m3 | D19: 18.8084 | E19: 0 | F19: 0 | G19: =E19+F19 -> 0 | H19: =IF(G19>D19,"Vượt KL HĐ","")
A20: 1.1.10 | B20: Đất đắp K95 | C20: m3 | D20: 23694.475 | E20: 0 | F20: 0 | G20: =E20+F20 -> 0 | H20: =IF(G20>D20,"Vượt KL HĐ","")
A21: 1.1.11 | B21: Đắp nền đường, độ chặt Y/C K = 0,95 | C21: 100m3 | D21: 174.3717 | E21: 0 | F21: 0 | G21: =E21+F21 -> 0 | H21: =IF(G21>D21,"Vượt KL HĐ","")
A22: 1.1.12 | B22: Đào nền, đào khuôn đường | C22: 100m3 | D22: 1.0778 | E22: 0 | F22: 0 | G22: =E22+F22 -> 0 | H22: =IF(G22>D22,"Vượt KL HĐ","")
A23: 1.1.13 | B23: Đào đất không thích hợp | C23: 100m3 | D23: 30.6066 | E23: 0 | F23: 0 | G23: =E23+F23 -> 0 | H23: =IF(G23>D23,"Vượt KL HĐ","")
A24: 1.2 | B24: VẠCH SƠN KẺ ĐƯỜNG
A25: 1.2.1 | B25: Sơn kẻ đường bằng sơn dẻo nhiệt phản quang | C25: m2 | D25: 470.17 | E25: 0 | F25: 0 | G25: =E25+F25 -> 0 | H25: =IF(G25>D25,"Vượt KL HĐ","")
A26: 2 | B26: HẠNG MỤC: THOÁT NƯỚC MƯA
A27: 2.1 | B27: Phần rãnh thường (xây gạch)
A28: 2.1.1 | B28: Thi công lớp đá đệm móng | C28: m3 | D28: 121.79 | E28: 0 | F28: 0 | G28: =E28+F28 -> 0 | H28: =IF(G28>D28,"Vượt KL HĐ","")
A29: 2.1.2 | B29: Bê tông móng M200, đá 1x2 | C29: m3 | D29: 182.69 | E29: 0 | F29: 0 | G29: =E29+F29 -> 0 | H29: =IF(G29>D29,"Vượt KL HĐ","")
A30: 2.1.3 | B30: Ván khuôn móng dài | C30: 100m2 | D30: 2.4856 | E30: 0 | F30: 0 | G30: =E30+F30 -> 0 | H30: =IF(G30>D30,"Vượt KL HĐ","")
A31: 2.1.4 | B31: Xây tường bằng gạch không nung, vữa XM M75 | C31: m3 | D31: 255.18 | E31: 0 | F31: 0 | G31: =E31+F31 -> 0 | H31: =IF(G31>D31,"Vượt KL HĐ","")
A32: 2.1.5 | B32: Trát tường, xây bằng gạch không nung, Vữa XM M75 | C32: m2 | D32: 1159.93 | E32: 0 | F32: 0 | G32: =E32+F32 -> 0 | H32: =IF(G32>D32,"Vượt KL HĐ","")
A33: 2.1.6 | B33: Bê tông mũ mố M250, đá 1x2 | C33: m3 | D33: 53.85 | E33: 0 | F33: 0 | G33: =E33+F33 -> 0 | H33: =IF(G33>D33,"Vượt KL HĐ","")
A34: 2.1.7 | B34: Lắp dựng cốt thép mũ mố, ĐK ≤10mm | C34: tấn | D34: 5.7168 | E34: 0 | F34: 0 | G34: =E34+F34 -> 0 | H34: =IF(G34>D34,"Vượt KL HĐ","")
A35: 2.1.8 | B35: Ván khuôn tấm đan | C35: 100m2 | D35: 3.3969 | E35: 0 | F35: 0 | G35: =E35+F35 -> 0 | H35: =IF(G35>D35,"Vượt KL HĐ","")
A36: 2.1.9 | B36: Bê tông tấm đan M250, đá 1x2 | C36: m3 | D36: 86.99 | E36: 0 | F36: 0 | G36: =E36+F36 -> 0 | H36: =IF(G36>D36,"Vượt KL HĐ","")
A37: 2.1.10 | B37: Cốt thép tấm đan ĐK ≤10mm | C37: tấn | D37: 8.0946 | E37: 0 | F37: 0 | G37: =E37+F37 -> 0 | H37: =IF(G37>D37,"Vượt KL HĐ","")
A38: 2.1.11 | B38: Cốt thép tấm đan ĐK >10mm | C38: tấn | D38: 6.1145 | E38: 0 | F38: 0 | G38: =E38+F38 -> 0 | H38: =IF(G38>D38,"Vượt KL HĐ","")
A39: 2.1.12 | B39: Lắp đặt tấm đan | C39: 1 cấu kiện | D39: 829 | E39: 0 | F39: 0 | G39: =E39+F39 -> 0 | H39: =IF(G39>D39,"Vượt KL HĐ","")
A40: 2.2 | B40: Phần rãnh chịu lực (bê tông)
A41: 2.2.1 | B41: Thi công lớp đá đệm móng | C41: m3 | D41: 25.11 | E41: 0 | F41: 0 | G41: =E41+F41 -> 0 | H41: =IF(G41>D41,"Vượt KL HĐ","")
...

Sheet PL.3A
A1: PHỤ LỤC CHI TIẾT KHỐI LƯỢNG HOÀN THÀNH
A2: Tên dự án: Hạ tầng kỹ thuật Khu dân cư và công viên Cây xanh, xã Hoằng Phú, tỉnh Thanh Hoá (được UBND huyện Hoằng Hóa phê duyệt tại Quyết định số 613/QĐ-UBND ngày 21/02/2025)
A3: Tên gói thầu: Gói thầu số 03: Thi công xây dựng công trình + thiết bị
A4: Căn cứ hợp đồng số: 10/2026/HĐ-TCXD ngày 09 tháng 10 năm 2026 (giá hợp đồng trọn gói: 25.007.549.000 đồng)
A5: Chủ đầu tư: Ủy ban nhân dân xã Hoằng Phú
A6: Nhà thầu: Công ty TNHH Hoàng Tuấn
A7: ="Thanh toán lần thứ: "&'03a TT'!$C$2 -> Thanh toán lần thứ: 1
A8: ="Căn cứ xác định: "&'03a TT'!$C$3 -> Căn cứ xác định: Biên bản nghiệm thu hoàn thành giai đoạn số ....../BBNT ngày ...../...../2026
A10: STT | B10: Nội dung công việc | C10: Đơn vị | D10: Khối lượng | H10: Đơn giá thanh toán theo HĐ | I10: Thành tiền (đồng) | M10: Ghi chú
D11: Khối lượng theo hợp đồng | E11: Thực hiện | I11: Theo hợp đồng | J11: Thực hiện
E12: Luỹ kế đến hết kỳ trước | F12: Thực hiện kỳ này | G12: Luỹ kế đến hết kỳ này | J12: Luỹ kế đến hết kỳ trước | K12: Thực hiện kỳ này | L12: Luỹ kế đến hết kỳ này
A13: (1) | B13: (2) | C13: (3) | D13: (4) | E13: (5) | F13: (6) | G13: (7) | H13: (8) | I13: (9)=(4)x(8) | J13: (10)=(5)x(8) | K13: (11)=(6)x(8) | L13: (12)=(7)x(8) | M13: (13)
A14: 1 | B14: HẠNG MỤC: GIAO THÔNG
A15: 1.1 | B15: GIAO THÔNG
A16: 1.1.1 | B16: BTN C16 lớp trên | C16: 100tấn | D16: ='PL.Khoi luong'!D11 -> 11.2167 | E16: ='PL.Khoi luong'!E11 -> 0 | F16: ='PL.Khoi luong'!F11 -> 0 | G16: =E16+F16 -> 0 | H16: 1.37463e+08 | I16: =D16*H16 -> 1541881232 | J16: =E16*H16 -> 0 | K16: =F16*H16 -> 0 | L16: =G16*H16 -> 0
A17: 1.1.2 | B17: Sản xuất bê tông nhựa | C17: 100tấn | D17: ='PL.Khoi luong'!D12 -> 11.2167 | E17: ='PL.Khoi luong'!E12 -> 0 | F17: ='PL.Khoi luong'!F12 -> 0 | G17: =E17+F17 -> 0 | H17: 32475403 | I17: =D17*H17 -> 3.6426685e+08 | J17: =E17*H17 -> 0 | K17: =F17*H17 -> 0 | L17: =G17*H17 -> 0
A18: 1.1.3 | B18: Vận chuyển đá dăm đen, bê tông nhựa từ trạm trộn đến vị trí đổ | C18: 100tấn | D18: ='PL.Khoi luong'!D13 -> 11.2167 | E18: ='PL.Khoi luong'!E13 -> 0 | F18: ='PL.Khoi luong'!F13 -> 0 | G18: =E18+F18 -> 0 | H18: 9790217 | I18: =D18*H18 -> 109813927 | J18: =E18*H18 -> 0 | K18: =F18*H18 -> 0 | L18: =G18*H18 -> 0
A19: 1.1.4 | B19: Rải thảm mặt đường bê tông nhựa (Loại BTNC 16) dày 7cm | C19: 100m2 | D19: ='PL.Khoi luong'!D14 -> 65.0131 | E19: ='PL.Khoi luong'!E14 -> 0 | F19: ='PL.Khoi luong'!F14 -> 0 | G19: =E19+F19 -> 0 | H19: 1613088 | I19: =D19*H19 -> 104871851 | J19: =E19*H19 -> 0 | K19: =F19*H19 -> 0 | L19: =G19*H19 -> 0
A20: 1.1.5 | B20: Tưới lớp dính bám, thấm bám mặt đường | C20: 100m2 | D20: ='PL.Khoi luong'!D15 -> 65.0131 | E20: ='PL.Khoi luong'!E15 -> 0 | F20: ='PL.Khoi luong'!F15 -> 0 | G20: =E20+F20 -> 0 | H20: 2852495 | I20: =D20*H20 -> 185449543 | J20: =E20*H20 -> 0 | K20: =F20*H20 -> 0 | L20: =G20*H20 -> 0
A21: 1.1.6 | B21: Móng cấp phối đá dăm loại 1 dày 15cm | C21: 100m3 | D21: ='PL.Khoi luong'!D16 -> 9.4043 | E21: ='PL.Khoi luong'!E16 -> 0 | F21: ='PL.Khoi luong'!F16 -> 0 | G21: =E21+F21 -> 0 | H21: 54574742 | I21: =D21*H21 -> 513237246 | J21: =E21*H21 -> 0 | K21: =F21*H21 -> 0 | L21: =G21*H21 -> 0
A22: 1.1.7 | B22: Móng cấp phối đá dăm loại 2 dày 18cm | C22: 100m3 | D22: ='PL.Khoi luong'!D17 -> 11.3547 | E22: ='PL.Khoi luong'!E17 -> 0 | F22: ='PL.Khoi luong'!F17 -> 0 | G22: =E22+F22 -> 0 | H22: 49026257 | I22: =D22*H22 -> 556678440 | J22: =E22*H22 -> 0 | K22: =F22*H22 -> 0 | L22: =G22*H22 -> 0
A23: 1.1.8 | B23: Đất đắp K98 | C23: m3 | D23: ='PL.Khoi luong'!D18 -> 2639.947 | E23: ='PL.Khoi luong'!E18 -> 0 | F23: ='PL.Khoi luong'!F18 -> 0 | G23: =E23+F23 -> 0 | H23: 135876 | I23: =D23*H23 -> 3.5870544e+08 | J23: =E23*H23 -> 0 | K23: =F23*H23 -> 0 | L23: =G23*H23 -> 0
A24: 1.1.9 | B24: Đắp nền đường, độ chặt Y/C K = 0,98 | C24: 100m3 | D24: ='PL.Khoi luong'!D19 -> 18.8084 | E24: ='PL.Khoi luong'!E19 -> 0 | F24: ='PL.Khoi luong'!F19 -> 0 | G24: =E24+F24 -> 0 | H24: 2039935 | I24: =D24*H24 -> 38367913 | J24: =E24*H24 -> 0 | K24: =F24*H24 -> 0 | L24: =G24*H24 -> 0
A25: 1.1.10 | B25: Đất đắp K95 | C25: m3 | D25: ='PL.Khoi luong'!D20 -> 23694.475 | E25: ='PL.Khoi luong'!E20 -> 0 | F25: ='PL.Khoi luong'!F20 -> 0 | G25: =E25+F25 -> 0 | H25: 135876 | I25: =D25*H25 -> 3.2195105e+09 | J25: =E25*H25 -> 0 | K25: =F25*H25 -> 0 | L25: =G25*H25 -> 0
A26: 1.1.11 | B26: Đắp nền đường, độ chặt Y/C K = 0,95 | C26: 100m3 | D26: ='PL.Khoi luong'!D21 -> 174.3717 | E26: ='PL.Khoi luong'!E21 -> 0 | F26: ='PL.Khoi luong'!F21 -> 0 | G26: =E26+F26 -> 0 | H26: 1662931 | I26: =D26*H26 -> 289968105 | J26: =E26*H26 -> 0 | K26: =F26*H26 -> 0 | L26: =G26*H26 -> 0
A27: 1.1.12 | B27: Đào nền, đào khuôn đường | C27: 100m3 | D27: ='PL.Khoi luong'!D22 -> 1.0778 | E27: ='PL.Khoi luong'!E22 -> 0 | F27: ='PL.Khoi luong'!F22 -> 0 | G27: =E27+F27 -> 0 | H27: 2974703.1 | I27: =D27*H27 -> 3206135 | J27: =E27*H27 -> 0 | K27: =F27*H27 -> 0 | L27: =G27*H27 -> 0
A28: 1.1.13 | B28: Đào đất không thích hợp | C28: 100m3 | D28: ='PL.Khoi luong'!D23 -> 30.6066 | E28: ='PL.Khoi luong'!E23 -> 0 | F28: ='PL.Khoi luong'!F23 -> 0 | G28: =E28+F28 -> 0 | H28: 1116283 | I28: =D28*H28 -> 34165627 | J28: =E28*H28 -> 0 | K28: =F28*H28 -> 0 | L28: =G28*H28 -> 0
A29: 1.2 | B29: VẠCH SƠN KẺ ĐƯỜNG
A30: 1.2.1 | B30: Sơn kẻ đường bằng sơn dẻo nhiệt phản quang | C30: m2 | D30: ='PL.Khoi luong'!D25 -> 470.17 | E30: ='PL.Khoi luong'!E25 -> 0 | F30: ='PL.Khoi luong'!F25 -> 0 | G30: =E30+F30 -> 0 | H30: 366453 | I30: =D30*H30 -> 172295207 | J30: =E30*H30 -> 0 | K30: =F30*H30 -> 0 | L30: =G30*H30 -> 0
A31: 2 | B31: HẠNG MỤC: THOÁT NƯỚC MƯA
A32: 2.1 | B32: Phần rãnh thường (xây gạch)
A33: 2.1.1 | B33: Thi công lớp đá đệm móng | C33: m3 | D33: ='PL.Khoi luong'!D28 -> 121.79 | E33: ='PL.Khoi luong'!E28 -> 0 | F33: ='PL.Khoi luong'!F28 -> 0 | G33: =E33+F33 -> 0 | H33: 990904 | I33: =D33*H33 -> 120682198 | J33: =E33*H33 -> 0 | K33: =F33*H33 -> 0 | L33: =G33*H33 -> 0
A34: 2.1.2 | B34: Bê tông móng M200, đá 1x2 | C34: m3 | D34: ='PL.Khoi luong'!D29 -> 182.69 | E34: ='PL.Khoi luong'!E29 -> 0 | F34: ='PL.Khoi luong'!F29 -> 0 | G34: =E34+F34 -> 0 | H34: 1516741 | I34: =D34*H34 -> 277093413 | J34: =E34*H34 -> 0 | K34: =F34*H34 -> 0 | L34: =G34*H34 -> 0
A35: 2.1.3 | B35: Ván khuôn móng dài | C35: 100m2 | D35: ='PL.Khoi luong'!D30 -> 2.4856 | E35: ='PL.Khoi luong'!E30 -> 0 | F35: ='PL.Khoi luong'!F30 -> 0 | G35: =E35+F35 -> 0 | H35: 6286550.1 | I35: =D35*H35 -> 15625849 | J35: =E35*H35 -> 0 | K35: =F35*H35 -> 0 | L35: =G35*H35 -> 0
A36: 2.1.4 | B36: Xây tường bằng gạch không nung, vữa XM M75 | C36: m3 | D36: ='PL.Khoi luong'!D31 -> 255.18 | E36: ='PL.Khoi luong'!E31 -> 0 | F36: ='PL.Khoi luong'!F31 -> 0 | G36: =E36+F36 -> 0 | H36: 1568220 | I36: =D36*H36 -> 400178380 | J36: =E36*H36 -> 0 | K36: =F36*H36 -> 0 | L36: =G36*H36 -> 0
A37: 2.1.5 | B37: Trát tường, xây bằng gạch không nung, Vữa XM M75 | C37: m2 | D37: ='PL.Khoi luong'!D32 -> 1159.93 | E37: ='PL.Khoi luong'!E32 -> 0 | F37: ='PL.Khoi luong'!F32 -> 0 | G37: =E37+F37 -> 0 | H37: 113553 | I37: =D37*H37 -> 131713531 | J37: =E37*H37 -> 0 | K37: =F37*H37 -> 0 | L37: =G37*H37 -> 0
A38: 2.1.6 | B38: Bê tông mũ mố M250, đá 1x2 | C38: m3 | D38: ='PL.Khoi luong'!D33 -> 53.85 | E38: ='PL.Khoi luong'!E33 -> 0 | F38: ='PL.Khoi luong'!F33 -> 0 | G38: =E38+F38 -> 0 | H38: 2084986 | I38: =D38*H38 -> 112276496 | J38: =E38*H38 -> 0 | K38: =F38*H38 -> 0 | L38: =G38*H38 -> 0
A39: 2.1.7 | B39: Lắp dựng cốt thép mũ mố, ĐK ≤10mm | C39: tấn | D39: ='PL.Khoi luong'!D34 -> 5.7168 | E39: ='PL.Khoi luong'!E34 -> 0 | F39: ='PL.Khoi luong'!F34 -> 0 | G39: =E39+F39 -> 0 | H39: 24438878 | I39: =D39*H39 -> 139712178 | J39: =E39*H39 -> 0 | K39: =F39*H39 -> 0 | L39: =G39*H39 -> 0
A40: 2.1.8 | B40: Ván khuôn tấm đan | C40: 100m2 | D40: ='PL.Khoi luong'!D35 -> 3.3969 | E40: ='PL.Khoi luong'!E35 -> 0 | F40: ='PL.Khoi luong'!F35 -> 0 | G40: =E40+F40 -> 0 | H40: 8587206 | I40: =D40*H40 -> 29169880 | J40: =E40*H40 -> 0 | K40: =F40*H40 -> 0 | L40: =G40*H40 -> 0
A41: 2.1.9 | B41: Bê tông tấm đan M250, đá 1x2 | C41: m3 | D41: ='PL.Khoi luong'!D36 -> 86.99 | E41: ='PL.Khoi luong'!E36 -> 0 | F41: ='PL.Khoi luong'!F36 -> 0 | G41: =E41+F41 -> 0 | H41: 1752158 | I41: =D41*H41 -> 152420224 | J41: =E41*H41 -> 0 | K41: =F41*H41 -> 0 | L41: =G41*H41 -> 0
...

Sheet KL con lai
A1: KHỐI LƯỢNG CÒN LẠI CHƯA THI CÔNG
A2: Dự án: Hạ tầng kỹ thuật Khu dân cư và công viên Cây xanh, xã Hoằng Phú, tỉnh Thanh Hoá (được UBND huyện Hoằng Hóa phê duyệt tại Quyết định số 613/QĐ-UBND ngày 21/02/2025)
A3: ="Tính đến: Thanh toán lần thứ "&'03a TT'!$C$2&" ("&'03a TT'!$C$3&")" -> Tính đến: Thanh toán lần thứ 1 (Biên bản nghiệm thu hoàn thành giai đoạn số ....../BBNT ngày ...../...../2026)
A5: STT | B5: Nội dung công việc | C5: Đơn vị | D5: Khối lượng còn lại | E5: Đơn giá theo HĐ | F5: Giá trị còn lại (đồng) | G5: Ghi chú
A6: 1 | B6: HẠNG MỤC: GIAO THÔNG
A7: 1.1 | B7: GIAO THÔNG
A8: 1.1.1 | B8: BTN C16 lớp trên | C8: 100tấn | D8: ='PL.3A'!D16-'PL.3A'!G16 -> 11.2167 | E8: ='PL.3A'!H16 -> 1.37463e+08 | F8: =D8*E8 -> 1541881232
A9: 1.1.2 | B9: Sản xuất bê tông nhựa | C9: 100tấn | D9: ='PL.3A'!D17-'PL.3A'!G17 -> 11.2167 | E9: ='PL.3A'!H17 -> 32475403 | F9: =D9*E9 -> 3.6426685e+08
A10: 1.1.3 | B10: Vận chuyển đá dăm đen, bê tông nhựa từ trạm trộn đến vị trí đổ | C10: 100tấn | D10: ='PL.3A'!D18-'PL.3A'!G18 -> 11.2167 | E10: ='PL.3A'!H18 -> 9790217 | F10: =D10*E10 -> 109813927
A11: 1.1.4 | B11: Rải thảm mặt đường bê tông nhựa (Loại BTNC 16) dày 7cm | C11: 100m2 | D11: ='PL.3A'!D19-'PL.3A'!G19 -> 65.0131 | E11: ='PL.3A'!H19 -> 1613088 | F11: =D11*E11 -> 104871851
A12: 1.1.5 | B12: Tưới lớp dính bám, thấm bám mặt đường | C12: 100m2 | D12: ='PL.3A'!D20-'PL.3A'!G20 -> 65.0131 | E12: ='PL.3A'!H20 -> 2852495 | F12: =D12*E12 -> 185449543
A13: 1.1.6 | B13: Móng cấp phối đá dăm loại 1 dày 15cm | C13: 100m3 | D13: ='PL.3A'!D21-'PL.3A'!G21 -> 9.4043 | E13: ='PL.3A'!H21 -> 54574742 | F13: =D13*E13 -> 513237246
A14: 1.1.7 | B14: Móng cấp phối đá dăm loại 2 dày 18cm | C14: 100m3 | D14: ='PL.3A'!D22-'PL.3A'!G22 -> 11.3547 | E14: ='PL.3A'!H22 -> 49026257 | F14: =D14*E14 -> 556678440
A15: 1.1.8 | B15: Đất đắp K98 | C15: m3 | D15: ='PL.3A'!D23-'PL.3A'!G23 -> 2639.947 | E15: ='PL.3A'!H23 -> 135876 | F15: =D15*E15 -> 3.5870544e+08
A16: 1.1.9 | B16: Đắp nền đường, độ chặt Y/C K = 0,98 | C16: 100m3 | D16: ='PL.3A'!D24-'PL.3A'!G24 -> 18.8084 | E16: ='PL.3A'!H24 -> 2039935 | F16: =D16*E16 -> 38367913
A17: 1.1.10 | B17: Đất đắp K95 | C17: m3 | D17: ='PL.3A'!D25-'PL.3A'!G25 -> 23694.475 | E17: ='PL.3A'!H25 -> 135876 | F17: =D17*E17 -> 3.2195105e+09
A18: 1.1.11 | B18: Đắp nền đường, độ chặt Y/C K = 0,95 | C18: 100m3 | D18: ='PL.3A'!D26-'PL.3A'!G26 -> 174.3717 | E18: ='PL.3A'!H26 -> 1662931 | F18: =D18*E18 -> 289968105
A19: 1.1.12 | B19: Đào nền, đào khuôn đường | C19: 100m3 | D19: ='PL.3A'!D27-'PL.3A'!G27 -> 1.0778 | E19: ='PL.3A'!H27 -> 2974703.1 | F19: =D19*E19 -> 3206135
A20: 1.1.13 | B20: Đào đất không thích hợp | C20: 100m3 | D20: ='PL.3A'!D28-'PL.3A'!G28 -> 30.6066 | E20: ='PL.3A'!H28 -> 1116283 | F20: =D20*E20 -> 34165627
A21: 1.2 | B21: VẠCH SƠN KẺ ĐƯỜNG
A22: 1.2.1 | B22: Sơn kẻ đường bằng sơn dẻo nhiệt phản quang | C22: m2 | D22: ='PL.3A'!D30-'PL.3A'!G30 -> 470.17 | E22: ='PL.3A'!H30 -> 366453 | F22: =D22*E22 -> 172295207
A23: 2 | B23: HẠNG MỤC: THOÁT NƯỚC MƯA
A24: 2.1 | B24: Phần rãnh thường (xây gạch)
A25: 2.1.1 | B25: Thi công lớp đá đệm móng | C25: m3 | D25: ='PL.3A'!D33-'PL.3A'!G33 -> 121.79 | E25: ='PL.3A'!H33 -> 990904 | F25: =D25*E25 -> 120682198
A26: 2.1.2 | B26: Bê tông móng M200, đá 1x2 | C26: m3 | D26: ='PL.3A'!D34-'PL.3A'!G34 -> 182.69 | E26: ='PL.3A'!H34 -> 1516741 | F26: =D26*E26 -> 277093413
A27: 2.1.3 | B27: Ván khuôn móng dài | C27: 100m2 | D27: ='PL.3A'!D35-'PL.3A'!G35 -> 2.4856 | E27: ='PL.3A'!H35 -> 6286550.1 | F27: =D27*E27 -> 15625849
A28: 2.1.4 | B28: Xây tường bằng gạch không nung, vữa XM M75 | C28: m3 | D28: ='PL.3A'!D36-'PL.3A'!G36 -> 255.18 | E28: ='PL.3A'!H36 -> 1568220 | F28: =D28*E28 -> 400178380
A29: 2.1.5 | B29: Trát tường, xây bằng gạch không nung, Vữa XM M75 | C29: m2 | D29: ='PL.3A'!D37-'PL.3A'!G37 -> 1159.93 | E29: ='PL.3A'!H37 -> 113553 | F29: =D29*E29 -> 131713531
A30: 2.1.6 | B30: Bê tông mũ mố M250, đá 1x2 | C30: m3 | D30: ='PL.3A'!D38-'PL.3A'!G38 -> 53.85 | E30: ='PL.3A'!H38 -> 2084986 | F30: =D30*E30 -> 112276496
A31: 2.1.7 | B31: Lắp dựng cốt thép mũ mố, ĐK ≤10mm | C31: tấn | D31: ='PL.3A'!D39-'PL.3A'!G39 -> 5.7168 | E31: ='PL.3A'!H39 -> 24438878 | F31: =D31*E31 -> 139712178
A32: 2.1.8 | B32: Ván khuôn tấm đan | C32: 100m2 | D32: ='PL.3A'!D40-'PL.3A'!G40 -> 3.3969 | E32: ='PL.3A'!H40 -> 8587206 | F32: =D32*E32 -> 29169880
A33: 2.1.9 | B33: Bê tông tấm đan M250, đá 1x2 | C33: m3 | D33: ='PL.3A'!D41-'PL.3A'!G41 -> 86.99 | E33: ='PL.3A'!H41 -> 1752158 | F33: =D33*E33 -> 152420224
A34: 2.1.10 | B34: Cốt thép tấm đan ĐK ≤10mm | C34: tấn | D34: ='PL.3A'!D42-'PL.3A'!G42 -> 8.0946 | E34: ='PL.3A'!H42 -> 25003382 | F34: =D34*E34 -> 202392376
A35: 2.1.11 | B35: Cốt thép tấm đan ĐK >10mm | C35: tấn | D35: ='PL.3A'!D43-'PL.3A'!G43 -> 6.1145 | E35: ='PL.3A'!H43 -> 25003382 | F35: =D35*E35 -> 152883179
A36: 2.1.12 | B36: Lắp đặt tấm đan | C36: 1 cấu kiện | D36: ='PL.3A'!D44-'PL.3A'!G44 -> 829 | E36: ='PL.3A'!H44 -> 71359 | F36: =D36*E36 -> 59156611
A37: 2.2 | B37: Phần rãnh chịu lực (bê tông)
A38: 2.2.1 | B38: Thi công lớp đá đệm móng | C38: m3 | D38: ='PL.3A'!D46-'PL.3A'!G46 -> 25.11 | E38: ='PL.3A'!H46 -> 990903.98 | F38: =D38*E38 -> 24881599
A39: 2.2.2 | B39: Bê tông móng M200, đá 1x2 | C39: m3 | D39: ='PL.3A'!D47-'PL.3A'!G47 -> 46.36 | E39: ='PL.3A'!H47 -> 1516741 | F39: =D39*E39 -> 70316113
A40: 2.2.3 | B40: Ván khuôn móng dài | C40: 100m2 | D40: ='PL.3A'!D48-'PL.3A'!G48 -> 0.7727 | E40: ='PL.3A'!H48 -> 6286549.8 | F40: =D40*E40 -> 4857617
A41: 2.2.4 | B41: Bê tông thành rãnh M200, đá 1x2 | C41: m3 | D41: ='PL.3A'!D49-'PL.3A'!G49 -> 67.61 | E41: ='PL.3A'!H49 -> 1516741 | F41: =D41*E41 -> 102546859
...
