Workbook

Sheet Trinh tu nghiem thu
A1: TRÌNH TỰ VÀ TIÊU CHUẨN NGHIỆM THU - TƯỜNG RÀO ĐẶC GIÁP NHÀ XE
A2: Ngày nghiệm thu lấy tự động từ sheet 'Tien do 50 ngay' (ngày kết thúc công việc). Thành phần NT: CĐT, TVGS, Nhà thầu thi công (TVTK khi cần).
A4: Bước | B4: Mã HM | C4: Đối tượng nghiệm thu | D4: Hình thức NT | E4: Ngày NT (thứ) | F4: Ngày NT | G4: Nội dung kiểm tra | H4: Tiêu chuẩn nghiệm thu / sai số cho phép | I4: Phương pháp, dụng cụ | J4: Tiêu chuẩn áp dụng | K4: Hồ sơ / biên bản
A5: I | B5: NGHIỆM THU VẬT LIỆU, ĐỊNH VỊ TRƯỚC KHI THI CÔNG
A6: 1 | B6: 0.1 | C6: Mặt bằng, tim trục, cao độ | D6: NT định vị công trình | E6: =MAX('Tien do 50 ngay'!G7) -> 1 | F6: ='Tien do 50 ngay'!$C$3+E6-1 -> 46328 | G6: Mốc chuẩn, tim trục tường rào, cao độ ±0.000, ranh giới giáp nhà xe; hiện trạng kết cấu cũ cần phá dỡ | H6: Sai số định vị tim trục ≤ ±10mm; cao độ ≤ ±5mm so với mốc chuẩn | I6: Máy toàn đạc / kinh vĩ, máy thủy bình, thước thép | J6: TCVN 9398:2012; TCVN 4447:2012 | K6: BB bàn giao mặt bằng, BB nghiệm thu định vị
A7: 2 | B7: 0.2 | C7: Xi măng PCB30, PCB40 | D7: NT vật liệu đầu vào | E7: =MAX('Tien do 50 ngay'!G8) -> 12 | F7: ='Tien do 50 ngay'!$C$3+E7-1 -> 46339 | G7: Chứng chỉ xuất xưởng, CO/CQ, lô hàng, hạn sử dụng (≤ 60 ngày kể từ ngày SX), bao bì nguyên vẹn, không vón cục | H7: Đạt TCVN 6260:2020; thí nghiệm cường độ, thời gian đông kết khi có nghi ngờ / theo yêu cầu TK | I7: Kiểm tra hồ sơ, quan sát; lấy mẫu thí nghiệm | J7: TCVN 6260:2020; TCVN 6016:2011; TCVN 4453:1995 mục 6.2 | K7: BB NT vật liệu + phiếu KQ thí nghiệm
A8: 3 | B8: 0.2 | C8: Cát, đá dăm 1x2, 4x6 | D8: NT vật liệu đầu vào | E8: =MAX('Tien do 50 ngay'!G8) -> 12 | F8: ='Tien do 50 ngay'!$C$3+E8-1 -> 46339 | G8: Thành phần hạt, hàm lượng bụi bùn sét, tạp chất hữu cơ, kích thước hạt lớn nhất | H8: Đạt TCVN 7570:2006 (cát BT: bụi-bùn-sét ≤ 3%; đá: ≤ 1%); cát xây trát theo TCVN 9205:2012 | I8: Lấy mẫu thí nghiệm tại phòng LAS-XD | J8: TCVN 7570:2006; TCVN 7572:2006; TCVN 9205:2012 | K8: BB NT vật liệu + phiếu KQ thí nghiệm
A9: 4 | B9: 0.2 | C9: Cốt thép (CB240-T, CB300-V…) | D9: NT vật liệu đầu vào | E9: =MAX('Tien do 50 ngay'!G8) -> 12 | F9: ='Tien do 50 ngay'!$C$3+E9-1 -> 46339 | G9: Chủng loại, đường kính, CO/CQ, bề mặt không gỉ sét, dầu mỡ; thí nghiệm kéo, uốn | H9: Giới hạn chảy, giới hạn bền, độ giãn dài, uốn nguội đạt TCVN 1651:2018; 1 tổ mẫu/lô ≤ 50 tấn/đường kính | I9: Kiểm tra hồ sơ, thước kẹp; thí nghiệm kéo-uốn | J9: TCVN 1651-1:2018; TCVN 1651-2:2018; TCVN 197-1:2014; TCVN 198:2008 | K9: BB NT vật liệu + phiếu KQ thí nghiệm
A10: 5 | B10: 0.2 | C10: Gạch không nung, gạch bê tông | D10: NT vật liệu đầu vào | E10: =MAX('Tien do 50 ngay'!G8) -> 12 | F10: ='Tien do 50 ngay'!$C$3+E10-1 -> 46339 | G10: Kích thước, khuyết tật, cường độ nén, độ hút nước | H10: Đạt TCVN 6477:2016; mác gạch ≥ thiết kế; sai lệch kích thước ±2mm (dài), ±2mm (rộng), ±3mm (cao) | I10: Thước, lấy mẫu thí nghiệm | J10: TCVN 6477:2016; TCVN 6355:2009 | K10: BB NT vật liệu + phiếu KQ thí nghiệm
A11: 6 | B11: 0.2 | C11: Nước thi công, sơn, gỗ ván khuôn | D11: NT vật liệu đầu vào | E11: =MAX('Tien do 50 ngay'!G8) -> 12 | F11: ='Tien do 50 ngay'!$C$3+E11-1 -> 46339 | G11: Nước sạch không lẫn dầu mỡ, muối; sơn đúng chủng loại, màu, CO/CQ, hạn dùng; ván khuôn đủ cứng, phẳng | H11: Nước đạt TCVN 4506:2012; sơn đạt TCVN 8652:2020 | I11: Quan sát, kiểm tra hồ sơ | J11: TCVN 4506:2012; TCVN 8652:2020 | K11: BB NT vật liệu
A12: II | B12: NGHIỆM THU PHẦN PHÁ DỠ
A13: 7 | B13: 4.1–4.4 | C13: Phá dỡ tường, cột trụ gạch, kết cấu BTCT, kết cấu gạch đá | D13: NT công việc | E13: =MAX('Tien do 50 ngay'!G13,'Tien do 50 ngay'!G12) -> 6 | F13: ='Tien do 50 ngay'!$C$3+E13-1 -> 46333 | G13: Phạm vi, khối lượng phá dỡ đúng thiết kế; không ảnh hưởng kết cấu nhà xe liền kề; vận chuyển phế thải, vệ sinh mặt bằng | H13: Không nứt, lún công trình lân cận; mặt bằng sạch, đủ điều kiện đào móng; biện pháp an toàn, che chắn bụi | I13: Quan sát, đo đạc khối lượng thực tế | J13: TCVN 5308:1991; QCVN 18:2021/BXD | K13: BB NT công việc phá dỡ, bản vẽ đo bóc khối lượng
A14: III | B14: NGHIỆM THU PHẦN MÓNG
A15: 8 | B15: 4.5 | C15: Hố móng cột, trụ (đào đất cấp III) | D15: NT công việc | E15: =MAX('Tien do 50 ngay'!G15) -> 10 | F15: ='Tien do 50 ngay'!$C$3+E15-1 -> 46337 | G15: Kích thước, cao độ đáy, tim hố móng, độ dốc mái, địa chất đáy móng, nước ngầm | H15: Cao độ đáy móng sai lệch ≤ ±50mm (đào thủ công); đáy phẳng, không đọng nước, không bùn; đất đáy đúng thiết kế | I15: Máy thủy bình, thước thép, quan sát | J15: TCVN 4447:2012 (Bảng 13); TCVN 9361:2012 | K15: BB NT hố móng (có TVTK nếu địa chất khác thiết kế)
A16: 9 | B16: 4.7, 4.8 | C16: Bê tông lót móng M100 | D16: NT công việc | E16: =MAX('Tien do 50 ngay'!G17,'Tien do 50 ngay'!G16) -> 12 | F16: ='Tien do 50 ngay'!$C$3+E16-1 -> 46339 | G16: Ván khuôn lót, chiều dày, cao độ mặt BT lót, mác vữa BT, độ phẳng | H16: Chiều dày đúng thiết kế (sai lệch ≤ 10mm); cao độ mặt ±10mm; bề mặt phẳng, không rỗ | I16: Máy thủy bình, thước | J16: TCVN 4453:1995 | K16: BB NT công việc
A17: 10 | B17: 4.11, 4.19, 4.20 | C17: Cốt thép móng, giằng móng | D17: NT công việc (trước khi đổ BT – bắt buộc) | E17: =MAX('Tien do 50 ngay'!G18,'Tien do 50 ngay'!G19,'Tien do 50 ngay'!G20) -> 15 | F17: ='Tien do 50 ngay'!$C$3+E17-1 -> 46342 | G17: Chủng loại, số lượng, đường kính, khoảng cách, chiều dài nối/neo, mối buộc, con kê lớp BT bảo vệ, vệ sinh cốt thép | H17: Sai lệch khoảng cách thanh chịu lực móng ±20mm; cốt đai ±10mm; lớp BT bảo vệ ±5mm; chiều dài nối buộc ≥ 30d (vùng kéo) | I17: Thước thép, thước kẹp, đếm, quan sát | J17: TCVN 4453:1995 mục 4 & Bảng 4; TCVN 5574:2018 | K17: BB NT cốt thép (kèm bản vẽ hoàn công)
A18: 11 | B18: 4.10 | C18: Ván khuôn móng | D18: NT công việc (trước khi đổ BT) | E18: =MAX('Tien do 50 ngay'!G21) -> 15 | F18: ='Tien do 50 ngay'!$C$3+E18-1 -> 46342 | G18: Kích thước, tim trục, cao độ, độ kín khít, độ ổn định chống đỡ, chất chống dính | H18: Sai lệch tim trục ≤ 15mm; độ phẳng (thước 2m) ≤ 5mm; độ nghiêng trên toàn chiều cao móng ≤ 20mm; kín không mất nước XM | I18: Thước, dây dọi, quả dọi, máy thủy bình | J18: TCVN 4453:1995 mục 3 & Bảng 2 | K18: BB NT ván khuôn
A19: 12 | B19: 4.9 | C19: Bê tông móng + giằng móng M200 | D19: NT công việc | E19: =MAX('Tien do 50 ngay'!G22) -> 17 | F19: ='Tien do 50 ngay'!$C$3+E19-1 -> 46344 | G19: Cấp phối, độ sụt, quy trình đổ & đầm, lấy mẫu, bảo dưỡng, kích thước & bề mặt sau tháo khuôn | H19: Độ sụt theo cấp phối (thường 6–8cm); ≥ 1 tổ 3 mẫu 15x15x15cm cho đợt đổ; R28 ≥ M200; sai lệch kích thước tiết diện +8/−5mm; không rỗ, nứt | I19: Côn Abrams, khuôn mẫu, nén mẫu tại LAS-XD; thước | J19: TCVN 4453:1995 mục 6, 7; TCVN 3105:2022; TCVN 3118:2022; TCVN 8828:2011 | K19: BB NT bê tông + KQ nén mẫu R7/R28
A20: 13 | B20: 4.16 | C20: Xây móng gạch không nung VXM M75 | D20: NT công việc | E20: =MAX('Tien do 50 ngay'!G23) -> 21 | F20: ='Tien do 50 ngay'!$C$3+E20-1 -> 46348 | G20: Kích thước, cao độ, tim trục, mạch vữa, độ thẳng đứng, liên kết, mác vữa | H20: Mạch vữa ngang 12mm (8–15mm), mạch đứng 10mm (8–15mm), không trùng mạch; sai lệch tim trục ±10mm; cao độ ±15mm | I20: Thước, dây dọi, nivô, lấy mẫu vữa | J20: TCVN 4085:2011; TCVN 4314:2022; TCVN 3121:2022 | K20: BB NT khối xây
A21: 14 | B21: 4.6 | C21: Đắp đất hố móng K = 0,90 | D21: NT công việc | E21: =MAX('Tien do 50 ngay'!G24) -> 23 | F21: ='Tien do 50 ngay'!$C$3+E21-1 -> 46350 | G21: Loại đất đắp, chiều dày lớp đầm, độ ẩm, độ chặt | H21: Đầm từng lớp ≤ 20cm (đầm cóc 70kg); độ chặt K ≥ 0,90; tối thiểu 1 điểm thí nghiệm/lớp/hạng mục | I21: Dao vòng / rót cát tại hiện trường | J21: TCVN 4447:2012 mục 4; TCVN 8729:2012; TCVN 8730:2012 | K21: BB NT đắp đất + phiếu KQ độ chặt
A22: 15 | B22: 4.5–4.16 | C22: Giai đoạn hoàn thành phần móng | D22: NT giai đoạn | E22: =MAX('Tien do 50 ngay'!G24) -> 23 | F22: ='Tien do 50 ngay'!$C$3+E22-1 -> 46350 | G22: Tổng hợp các BB NT công việc phần móng, hồ sơ chất lượng, bản vẽ hoàn công móng | H22: Đủ BB, KQ thí nghiệm đạt; không còn tồn tại | I22: Kiểm tra hồ sơ + hiện trường | J22: Nghị định 06/2021/NĐ-CP; TCVN 5637:1991 | K22: BB NT hoàn thành giai đoạn móng
A23: IV | B23: NGHIỆM THU PHẦN THÂN
A24: 16 | B24: 4.14, 4.15 | C24: Cốt thép cột, trụ | D24: NT công việc (trước khi lắp VK) | E24: =MAX('Tien do 50 ngay'!G26,'Tien do 50 ngay'!G27) -> 22 | F24: ='Tien do 50 ngay'!$C$3+E24-1 -> 46349 | G24: Chủng loại, số lượng, khoảng cách, nối chờ từ móng, cốt đai, con kê | H24: Sai lệch khoảng cách thanh chịu lực cột ±10mm; cốt đai ±10mm; lớp BT bảo vệ ±5mm (≥ 25mm theo TK) | I24: Thước thép, thước kẹp | J24: TCVN 4453:1995 Bảng 4 | K24: BB NT cốt thép
A25: 17 | B25: 4.13 | C25: Ván khuôn cột | D25: NT công việc | E25: =MAX('Tien do 50 ngay'!G28) -> 24 | F25: ='Tien do 50 ngay'!$C$3+E25-1 -> 46351 | G25: Kích thước tiết diện, độ thẳng đứng, tim trục, cửa vệ sinh, giằng chống | H25: Độ nghiêng trên 1m chiều cao ≤ 5mm; toàn chiều cao ≤ 10mm; tim trục ≤ 8mm; tiết diện +4mm | I25: Quả dọi, thước, máy kinh vĩ | J25: TCVN 4453:1995 Bảng 2 | K25: BB NT ván khuôn
A26: 18 | B26: 4.12 | C26: Bê tông cột M200 | D26: NT công việc | E26: =MAX('Tien do 50 ngay'!G29) -> 26 | F26: ='Tien do 50 ngay'!$C$3+E26-1 -> 46353 | G26: Độ sụt, chiều cao rơi tự do ≤ 1,5m (cột), đầm, lấy mẫu, bảo dưỡng, bề mặt sau tháo khuôn | H26: ≥ 1 tổ mẫu cho đợt đổ; R28 ≥ M200; độ nghiêng cột ≤ 10mm; tiết diện +8/−5mm; không rỗ, phân tầng | I26: Côn sụt, nén mẫu, quả dọi, thước | J26: TCVN 4453:1995; TCVN 3105:2022; TCVN 3118:2022; TCVN 8828:2011 | K26: BB NT bê tông + KQ nén mẫu
A27: 19 | B27: 4.21 | C27: Xây tường gạch bê tông 10,5cm VXM M75 | D27: NT công việc | E27: =MAX('Tien do 50 ngay'!G30) -> 32 | F27: ='Tien do 50 ngay'!$C$3+E27-1 -> 46359 | G27: Độ thẳng đứng, độ phẳng, mạch vữa, râu thép liên kết cột, mác vữa | H27: Độ nghiêng mặt tường ≤ 10mm/tầng; độ phẳng thước 2m ≤ 10mm; mạch ngang 12mm, mạch đứng 10mm (8–15mm); mạch đầy vữa | I27: Thước 2m, quả dọi, nivô, lấy mẫu vữa | J27: TCVN 4085:2011 (Bảng 2); TCVN 4314:2022 | K27: BB NT khối xây
A28: 20 | B28: 4.18 | C28: Ván khuôn + cốt thép xà dầm, giằng tường | D28: NT công việc (trước khi đổ BT) | E28: =MAX('Tien do 50 ngay'!G31) -> 35 | F28: ='Tien do 50 ngay'!$C$3+E28-1 -> 46362 | G28: Kích thước, cao độ đáy dầm, độ kín khít, cốt thép, lớp bảo vệ, cây chống | H28: Cao độ ±5mm; mặt phẳng ≤ 3mm/1m; cốt thép theo TCVN 4453 Bảng 4 | I28: Máy thủy bình, thước | J28: TCVN 4453:1995 mục 3, 4 | K28: BB NT ván khuôn, cốt thép
A29: 21 | B29: 4.17 | C29: Bê tông xà dầm, giằng M200 | D29: NT công việc | E29: =MAX('Tien do 50 ngay'!G32) -> 37 | F29: ='Tien do 50 ngay'!$C$3+E29-1 -> 46364 | G29: Độ sụt, đổ đầm, lấy mẫu, bảo dưỡng, kích thước, bề mặt | H29: ≥ 1 tổ mẫu; R28 ≥ M200; tiết diện +8/−5mm; tháo VK khi BT đạt cường độ quy định | I29: Côn sụt, nén mẫu, thước | J29: TCVN 4453:1995; TCVN 3105:2022; TCVN 3118:2022 | K29: BB NT bê tông + KQ nén mẫu
A30: V | B30: NGHIỆM THU HOÀN THIỆN
A31: 22 | B31: 4.22, 4.23 | C31: Trát tường ngoài, trụ cột dày 1,5cm VXM M75 | D31: NT công việc | E31: =MAX('Tien do 50 ngay'!G34,'Tien do 50 ngay'!G35) -> 43 | F31: ='Tien do 50 ngay'!$C$3+E31-1 -> 46370 | G31: Chuẩn bị bề mặt (tưới ẩm, đục nhám BT), chiều dày, độ phẳng, cạnh góc, độ bám dính | H31: Độ phẳng: khe hở với thước 2m ≤ 3mm; cạnh, góc thẳng ≤ 2mm/1m; không bong rộp, nứt chân chim; gõ không bộp | I31: Thước 2m, nivô, gõ kiểm tra | J31: TCVN 9377-2:2012 | K31: BB NT công tác trát
A32: 23 | B32: 4.24 | C32: Sơn 1 lót + 2 phủ | D32: NT công việc | E32: =MAX('Tien do 50 ngay'!G36) -> 48 | F32: ='Tien do 50 ngay'!$C$3+E32-1 -> 46375 | G32: Độ khô, độ ẩm bề mặt trát, số lớp, màu sắc, độ đồng đều, độ bám dính | H32: Bề mặt trát khô (độ ẩm ≤ 16%); đủ 1 lót + 2 phủ; màu đồng đều, không loang, chảy, bong tróc, lộ vết lăn | I32: Máy đo độ ẩm, quan sát, kiểm tra độ bám dính | J32: TCVN 5674:1992; TCVN 8652:2020 | K32: BB NT công tác sơn
A33: VI | B33: NGHIỆM THU HOÀN THÀNH HẠNG MỤC
A34: 24 | B34: 9.1 | C34: Tường rào đặc giáp nhà xe | D34: NT hoàn thành HM đưa vào sử dụng | E34: =MAX('Tien do 50 ngay'!G38) -> 50 | F34: ='Tien do 50 ngay'!$C$3+E34-1 -> 46377 | G34: Hồ sơ quản lý chất lượng, BB NT các công việc/giai đoạn, KQ thí nghiệm, bản vẽ hoàn công, nhật ký thi công; kiểm tra hiện trường | H34: Đủ hồ sơ theo Phụ lục VIB NĐ 06/2021; chất lượng đạt thiết kế & tiêu chuẩn; mặt bằng sạch | I34: Kiểm tra hồ sơ + hiện trường | J34: Nghị định 06/2021/NĐ-CP; TCVN 5640:1991 | K34: BB NT hoàn thành HM / công trình
A36: Ghi chú:
A37: 1. Trình tự: NT vật liệu đầu vào → NT từng công việc (công việc khuất lấp như hố móng, cốt thép, ván khuôn phải NT trước khi thi công bước tiếp theo) → NT giai đoạn → NT hoàn thành hạng mục.
A38: 2. Nhà thầu tự kiểm tra nội bộ (NT nội bộ) trước, sau đó gửi phiếu yêu cầu nghiệm thu cho TVGS trước ≥ 24 giờ.
A39: 3. Sai số cho phép tham khảo tiêu chuẩn hiện hành; nếu hồ sơ thiết kế / chỉ dẫn kỹ thuật quy định chặt hơn thì áp dụng theo thiết kế.
A40: 4. Số hiệu năm ban hành tiêu chuẩn cần đối chiếu lại danh mục tiêu chuẩn được duyệt trong hồ sơ dự án trước khi phát hành.
A41: 5. Cột 'Ngày NT (thứ)' (chữ xanh lá) là liên kết sang sheet tiến độ – thay đổi tiến độ thì ngày NT tự cập nhật.

Sheet Tien do 50 ngay
A1: BẢNG TIẾN ĐỘ THI CÔNG - TƯỜNG RÀO ĐẶC GIÁP NHÀ XE (50 NGÀY)
A2: Ô nền vàng là ô nhập: ngày khởi công (C3), ngày bắt đầu & số ngày từng công việc. Thanh tiến độ tự cập nhật.
A3: Ngày khởi công: | C3: 46328 | D3: Tổng thời gian: | E3: =MAX(G6:G38) -> 50 | F3: ngày
I4: =$C$3+0 -> 46328 | J4: =$C$3+1 -> 46329 | K4: =$C$3+2 -> 46330 | L4: =$C$3+3 -> 46331 | M4: =$C$3+4 -> 46332 | N4: =$C$3+5 -> 46333 | O4: =$C$3+6 -> 46334 | P4: =$C$3+7 -> 46335 | Q4: =$C$3+8 -> 46336 | R4: =$C$3+9 -> 46337 | S4: =$C$3+10 -> 46338 | T4: =$C$3+11 -> 46339 | U4: =$C$3+12 -> 46340 | V4: =$C$3+13 -> 46341 | W4: =$C$3+14 -> 46342 | X4: =$C$3+15 -> 46343 | Y4: =$C$3+16 -> 46344 | Z4: =$C$3+17 -> 46345 | AA4: =$C$3+18 -> 46346 | AB4: =$C$3+19 -> 46347 | AC4: =$C$3+20 -> 46348 | AD4: =$C$3+21 -> 46349 | AE4: =$C$3+22 -> 46350 | AF4: =$C$3+23 -> 46351 | AG4: =$C$3+24 -> 46352 | AH4: =$C$3+25 -> 46353 | AI4: =$C$3+26 -> 46354 | AJ4: =$C$3+27 -> 46355 | AK4: =$C$3+28 -> 46356 | AL4: =$C$3+29 -> 46357 | AM4: =$C$3+30 -> 46358 | AN4: =$C$3+31 -> 46359 | AO4: =$C$3+32 -> 46360 | AP4: =$C$3+33 -> 46361 | AQ4: =$C$3+34 -> 46362 | AR4: =$C$3+35 -> 46363 | AS4: =$C$3+36 -> 46364 | AT4: =$C$3+37 -> 46365 | AU4: =$C$3+38 -> 46366 | AV4: =$C$3+39 -> 46367 | AW4: =$C$3+40 -> 46368 | AX4: =$C$3+41 -> 46369 | AY4: =$C$3+42 -> 46370 | AZ4: =$C$3+43 -> 46371 | BA4: =$C$3+44 -> 46372 | BB4: =$C$3+45 -> 46373 | BC4: =$C$3+46 -> 46374 | BD4: =$C$3+47 -> 46375 | BE4: =$C$3+48 -> 46376 | BF4: =$C$3+49 -> 46377
A5: Mã HM | B5: Nội dung công việc | C5: Khối lượng | D5: Đơn vị | E5: Ngày BĐ (thứ) | F5: Số ngày | G5: Ngày KT (thứ) | H5: Nghiệm thu | I5: 1 | J5: 2 | K5: 3 | L5: 4 | M5: 5 | N5: 6 | O5: 7 | P5: 8 | Q5: 9 | R5: 10 | S5: 11 | T5: 12 | U5: 13 | V5: 14 | W5: 15 | X5: 16 | Y5: 17 | Z5: 18 | AA5: 19 | AB5: 20 | AC5: 21 | AD5: 22 | AE5: 23 | AF5: 24 | AG5: 25 | AH5: 26 | AI5: 27 | AJ5: 28 | AK5: 29 | AL5: 30 | AM5: 31 | AN5: 32 | AO5: 33 | AP5: 34 | AQ5: 35 | AR5: 36 | AS5: 37 | AT5: 38 | AU5: 39 | AV5: 40 | AW5: 41 | AX5: 42 | AY5: 43 | AZ5: 44 | BA5: 45 | BB5: 46 | BC5: 47 | BD5: 48 | BE5: 49 | BF5: 50
A6: A | B6: CHUẨN BỊ & VẬT LIỆU ĐẦU VÀO
A7: 0.1 | B7: Bàn giao mặt bằng, định vị tim trục, cốt cao độ tường rào | E7: 1 | F7: 1 | G7: =E7+F7-1 -> 1 | H7: NT định vị
A8: 0.2 | B8: Tập kết & nghiệm thu vật liệu đầu vào (xi măng PCB40, cát, đá 1x2, 4x6, thép, gạch không nung, gạch BT, sơn, nước) | E8: 1 | F8: 12 | G8: =E8+F8-1 -> 12 | H8: NT vật liệu
A9: B | B9: PHÁ DỠ
A10: 4.1 | B10: Phá dỡ tường xây gạch chiều dày ≤11cm | C10: 7.9622 | D10: m3 | E10: 2 | F10: 3 | G10: =E10+F10-1 -> 4
A11: 4.2 | B11: Phá dỡ cột, trụ gạch đá | C11: 1.3794 | D11: m3 | E11: 3 | F11: 2 | G11: =E11+F11-1 -> 4
A12: 4.3 | B12: Phá dỡ kết cấu bê tông có cốt thép bằng búa căn khí nén 3m3/ph | C12: 0.9878 | D12: m3 | E12: 4 | F12: 2 | G12: =E12+F12-1 -> 5
A13: 4.4 | B13: Phá dỡ kết cấu gạch đá bằng búa căn khí nén 3m3/ph | C13: 8.64 | D13: m3 | E13: 4 | F13: 3 | G13: =E13+F13-1 -> 6 | H13: NT phá dỡ
A14: C | B14: PHẦN MÓNG
A15: 4.5 | B15: Đào móng cột, trụ, hố kiểm tra bằng thủ công, rộng >1m, sâu >1m, đất cấp III, hệ số mở mái 1,2 | C15: 21.7728 | D15: m3 | E15: 7 | F15: 4 | G15: =E15+F15-1 -> 10 | H15: NT hố móng
A16: 4.8 | B16: Ván khuôn móng cột - Móng vuông, chữ nhật (bê tông lót) | C16: 0.0768 | D16: 100m2 | E16: 11 | F16: 1 | G16: =E16+F16-1 -> 11
A17: 4.7 | B17: Bê tông lót móng SX bằng máy trộn, đổ thủ công, rộng ≤250cm, M100, đá 4x6, PCB30 | C17: 2.304 | D17: m3 | E17: 11 | F17: 2 | G17: =E17+F17-1 -> 12 | H17: NT BT lót
A18: 4.11 | B18: Lắp dựng cốt thép móng, ĐK ≤18mm | C18: 0.2159 | D18: tấn | E18: 13 | F18: 3 | G18: =E18+F18-1 -> 15 | H18: NT cốt thép
A19: 4.19 | B19: Lắp dựng cốt thép giằng móng, ĐK ≤10mm | C19: 0.1102 | D19: tấn | E19: 13 | F19: 3 | G19: =E19+F19-1 -> 15 | H19: NT cốt thép
A20: 4.20 | B20: Lắp dựng cốt thép giằng móng, ĐK ≤18mm | C20: 0.2929 | D20: tấn | E20: 13 | F20: 3 | G20: =E20+F20-1 -> 15 | H20: NT cốt thép
A21: 4.10 | B21: Ván khuôn móng cột - Móng vuông, chữ nhật | C21: 0.16 | D21: 100m2 | E21: 14 | F21: 2 | G21: =E21+F21-1 -> 15 | H21: NT ván khuôn
A22: 4.9 | B22: Bê tông móng SX bằng máy trộn, đổ thủ công, rộng ≤250cm, M200, đá 1x2, PCB40 | C22: 5.6912 | D22: m3 | E22: 16 | F22: 2 | G22: =E22+F22-1 -> 17 | H22: NT bê tông
A23: 4.16 | B23: Xây móng bằng gạch không nung 6,5x10,5x22cm - Chiều dày ≤33cm, vữa XM M75, PCB40 | C23: 4.32 | D23: m3 | E23: 19 | F23: 3 | G23: =E23+F23-1 -> 21 | H23: NT khối xây
A24: 4.6 | B24: Đắp đất bằng đầm đất cầm tay 70kg, độ chặt Y/C K = 0,90 | C24: 0.0726 | D24: 100m3 | E24: 22 | F24: 2 | G24: =E24+F24-1 -> 23 | H24: NT đắp đất
A25: D | B25: PHẦN THÂN
A26: 4.14 | B26: Lắp dựng cốt thép cột, trụ, ĐK ≤10mm, chiều cao ≤6m | C26: 0.0838 | D26: tấn | E26: 20 | F26: 3 | G26: =E26+F26-1 -> 22 | H26: NT cốt thép
A27: 4.15 | B27: Lắp dựng cốt thép cột, trụ, ĐK ≤18mm, chiều cao ≤6m | C27: 0.3283 | D27: tấn | E27: 20 | F27: 3 | G27: =E27+F27-1 -> 22 | H27: NT cốt thép
A28: 4.13 | B28: Ván khuôn cột - Cột vuông, chữ nhật | C28: 0.352 | D28: 100m2 | E28: 23 | F28: 2 | G28: =E28+F28-1 -> 24 | H28: NT ván khuôn
A29: 4.12 | B29: Bê tông cột SX bằng máy trộn, đổ thủ công, TD ≤0,1m2, cao ≤6m, M200, đá 1x2, PCB40 | C29: 1.936 | D29: m3 | E29: 25 | F29: 2 | G29: =E29+F29-1 -> 26 | H29: NT bê tông
A30: 4.21 | B30: Xây tường thẳng gạch bê tông 10,5x6x22cm - Chiều dày 10,5cm, cao ≤6m, vữa XM M75, PCB40 | C30: 7.0098 | D30: m3 | E30: 27 | F30: 6 | G30: =E30+F30-1 -> 32 | H30: NT khối xây
A31: 4.18 | B31: Ván khuôn gỗ xà dầm, giằng (kèm lắp cốt thép giằng tường) | C31: 0.2483 | D31: 100m2 | E31: 33 | F31: 3 | G31: =E31+F31-1 -> 35 | H31: NT VK + CT
A32: 4.17 | B32: Bê tông xà dầm, giằng nhà SX bằng máy trộn, đổ thủ công, cao ≤6m, M200, đá 1x2, PCB40 | C32: 2.7311 | D32: m3 | E32: 36 | F32: 2 | G32: =E32+F32-1 -> 37 | H32: NT bê tông
A33: E | B33: HOÀN THIỆN
A34: 4.22 | B34: Trát tường ngoài dày 1,5cm, vữa XM M75, PCB40 | C34: 164.6924 | D34: m2 | E34: 38 | F34: 6 | G34: =E34+F34-1 -> 43 | H34: NT trát
A35: 4.23 | B35: Trát trụ cột, lam đứng, cầu thang, dày 1,5cm, vữa XM M75, PCB40 | C35: 28.16 | D35: m2 | E35: 39 | F35: 3 | G35: =E35+F35-1 -> 41 | H35: NT trát
A36: 4.24 | B36: Sơn dầm, trần, tường ngoài nhà không bả bằng sơn các loại 1 nước lót + 2 nước phủ | C36: 192.8524 | D36: m2 | E36: 45 | F36: 4 | G36: =E36+F36-1 -> 48 | H36: NT sơn
A37: F | B37: NGHIỆM THU HOÀN THÀNH
A38: 9.1 | B38: Vệ sinh, dọn dẹp, hoàn thiện hồ sơ, NT hoàn thành hạng mục Tường rào đặc giáp nhà xe đưa vào sử dụng | E38: 49 | F38: 2 | G38: =E38+F38-1 -> 50 | H38: NT hoàn thành
B40: Chú thích:
B41: Thời gian thi công
...

Sheet Danh muc tieu chuan
A1: DANH MỤC TIÊU CHUẨN, VĂN BẢN ÁP DỤNG
A4: STT | B4: Số hiệu | C4: Tên tiêu chuẩn / văn bản | D4: Áp dụng cho
A5: 1 | B5: Nghị định 06/2021/NĐ-CP | C5: Quy định chi tiết về quản lý chất lượng, thi công xây dựng và bảo trì công trình | D5: Toàn bộ quy trình NT, hồ sơ
A6: 2 | B6: TCVN 5637:1991 | C6: Quản lý chất lượng xây lắp công trình xây dựng – Nguyên tắc cơ bản | D6: Quản lý chất lượng
A7: 3 | B7: TCVN 5640:1991 | C7: Bàn giao công trình xây dựng – Nguyên tắc cơ bản | D7: NT hoàn thành, bàn giao
A8: 4 | B8: TCVN 9398:2012 | C8: Công tác trắc địa trong xây dựng công trình – Yêu cầu chung | D8: Định vị, cao độ
A9: 5 | B9: TCVN 5308:1991 | C9: Quy phạm kỹ thuật an toàn trong xây dựng | D9: Phá dỡ
A10: 6 | B10: QCVN 18:2021/BXD | C10: Quy chuẩn kỹ thuật quốc gia về an toàn trong thi công xây dựng | D10: An toàn thi công
A11: 7 | B11: TCVN 4447:2012 | C11: Công tác đất – Thi công và nghiệm thu | D11: Đào móng, đắp đất
A12: 8 | B12: TCVN 9361:2012 | C12: Công tác nền móng – Thi công và nghiệm thu | D12: Hố móng
A13: 9 | B13: TCVN 8729:2012 / 8730:2012 | C13: Đất xây dựng – PP xác định khối lượng thể tích / độ chặt tại hiện trường | D13: Kiểm tra K=0,90
A14: 10 | B14: TCVN 4453:1995 | C14: Kết cấu bê tông và BTCT toàn khối – Quy phạm thi công và nghiệm thu | D14: Ván khuôn, cốt thép, bê tông
A15: 11 | B15: TCVN 5574:2018 | C15: Thiết kế kết cấu bê tông và bê tông cốt thép | D15: Neo, nối cốt thép, lớp bảo vệ
A16: 12 | B16: TCVN 3105:2022 | C16: Hỗn hợp bê tông và bê tông – Lấy mẫu, chế tạo và bảo dưỡng mẫu thử | D16: Mẫu bê tông
... A31: 27 | B31: TCVN 8652:2020 | C31: Sơn tường dạng nhũ tương – Yêu cầu kỹ thuật | D31: Vật liệu sơn
