Workbook

Sheet Tong hop vat tu
A1: BẢNG TỔNG HỢP VẬT TƯ THEO HỒ SƠ NGHIỆM THU
A2: Dự án: Xử lý khẩn cấp kè biển khu du lịch Hải Tiến, xã Hoằng Tiến
A3: Kè bờ K2A (đợt 1 chân khay C16÷C2, đợt 2 đến +1,78 m), đúc cấu kiện bê tông và ống địa kỹ thuật (13.000 md)
A5: STT | B5: Tên vật tư | C5: Đơn vị | D5: Đúc cấu kiện | E5: K2A đợt 1 (C16÷C2) | F5: K2A đợt 2 (đến +1,78) | G5: Ống địa kỹ thuật | H5: Tổng cộng
A6: 1 | B6: Xi măng PCB40 rời/bền sunfat type II | C6: kg | D6: =SUMIFS('Quy doi vat tu'!$J$6:$J$29,'Quy doi vat tu'!$F$6:$F$29,$B6,'Quy doi vat tu'!$L$6:$L$29,"Đúc cấu kiện") -> 1655031.4 | E6: =SUMIFS('Quy doi vat tu'!$J$6:$J$29,'Quy doi vat tu'!$F$6:$F$29,$B6,'Quy doi vat tu'!$L$6:$L$29,"K2A đợt 1 (C16÷C2)") -> 0 | F6: =SUMIFS('Quy doi vat tu'!$J$6:$J$29,'Quy doi vat tu'!$F$6:$F$29,$B6,'Quy doi vat tu'!$L$6:$L$29,"K2A đợt 2 (đến +1,78)") -> 0 | G6: =SUMIFS('Quy doi vat tu'!$J$6:$J$29,'Quy doi vat tu'!$F$6:$F$29,$B6,'Quy doi vat tu'!$L$6:$L$29,"Ống địa kỹ thuật") -> 0 | H6: =SUM(D6:G6) -> 1655031.4
A7: 2 | B7: Cát vàng | C7: m3 | D7: =SUMIFS('Quy doi vat tu'!$J$6:$J$29,'Quy doi vat tu'!$F$6:$F$29,$B7,'Quy doi vat tu'!$L$6:$L$29,"Đúc cấu kiện") -> 2365.0022 | E7: =SUMIFS('Quy doi vat tu'!$J$6:$J$29,'Quy doi vat tu'!$F$6:$F$29,$B7,'Quy doi vat tu'!$L$6:$L$29,"K2A đợt 1 (C16÷C2)") -> 0 | F7: =SUMIFS('Quy doi vat tu'!$J$6:$J$29,'Quy doi vat tu'!$F$6:$F$29,$B7,'Quy doi vat tu'!$L$6:$L$29,"K2A đợt 2 (đến +1,78)") -> 0 | G7: =SUMIFS('Quy doi vat tu'!$J$6:$J$29,'Quy doi vat tu'!$F$6:$F$29,$B7,'Quy doi vat tu'!$L$6:$L$29,"Ống địa kỹ thuật") -> 0 | H7: =SUM(D7:G7) -> 2365.0022
A8: 3 | B8: Đá 2x4 | C8: m3 | D8: =SUMIFS('Quy doi vat tu'!$J$6:$J$29,'Quy doi vat tu'!$F$6:$F$29,$B8,'Quy doi vat tu'!$L$6:$L$29,"Đúc cấu kiện") -> 3836.6636 | E8: =SUMIFS('Quy doi vat tu'!$J$6:$J$29,'Quy doi vat tu'!$F$6:$F$29,$B8,'Quy doi vat tu'!$L$6:$L$29,"K2A đợt 1 (C16÷C2)") -> 0 | F8: =SUMIFS('Quy doi vat tu'!$J$6:$J$29,'Quy doi vat tu'!$F$6:$F$29,$B8,'Quy doi vat tu'!$L$6:$L$29,"K2A đợt 2 (đến +1,78)") -> 0 | G8: =SUMIFS('Quy doi vat tu'!$J$6:$J$29,'Quy doi vat tu'!$F$6:$F$29,$B8,'Quy doi vat tu'!$L$6:$L$29,"Ống địa kỹ thuật") -> 0 | H8: =SUM(D8:G8) -> 3836.6636
A9: 4 | B9: Nước | C9: lít | D9: =SUMIFS('Quy doi vat tu'!$J$6:$J$29,'Quy doi vat tu'!$F$6:$F$29,$B9,'Quy doi vat tu'!$L$6:$L$29,"Đúc cấu kiện") -> 702024.81 | E9: =SUMIFS('Quy doi vat tu'!$J$6:$J$29,'Quy doi vat tu'!$F$6:$F$29,$B9,'Quy doi vat tu'!$L$6:$L$29,"K2A đợt 1 (C16÷C2)") -> 0 | F9: =SUMIFS('Quy doi vat tu'!$J$6:$J$29,'Quy doi vat tu'!$F$6:$F$29,$B9,'Quy doi vat tu'!$L$6:$L$29,"K2A đợt 2 (đến +1,78)") -> 0 | G9: =SUMIFS('Quy doi vat tu'!$J$6:$J$29,'Quy doi vat tu'!$F$6:$F$29,$B9,'Quy doi vat tu'!$L$6:$L$29,"Ống địa kỹ thuật") -> 0 | H9: =SUM(D9:G9) -> 702024.81
A10: 5 | B10: Phụ gia R7 | C10: kg | D10: =SUMIFS('Quy doi vat tu'!$J$6:$J$29,'Quy doi vat tu'!$F$6:$F$29,$B10,'Quy doi vat tu'!$L$6:$L$29,"Đúc cấu kiện") -> 8275.1568 | E10: =SUMIFS('Quy doi vat tu'!$J$6:$J$29,'Quy doi vat tu'!$F$6:$F$29,$B10,'Quy doi vat tu'!$L$6:$L$29,"K2A đợt 1 (C16÷C2)") -> 0 | F10: =SUMIFS('Quy doi vat tu'!$J$6:$J$29,'Quy doi vat tu'!$F$6:$F$29,$B10,'Quy doi vat tu'!$L$6:$L$29,"K2A đợt 2 (đến +1,78)") -> 0 | G10: =SUMIFS('Quy doi vat tu'!$J$6:$J$29,'Quy doi vat tu'!$F$6:$F$29,$B10,'Quy doi vat tu'!$L$6:$L$29,"Ống địa kỹ thuật") -> 0 | H10: =SUM(D10:G10) -> 8275.1568
A11: 6 | B11: Thép tròn Fi ≤18mm | C11: kg | D11: =SUMIFS('Quy doi vat tu'!$J$6:$J$29,'Quy doi vat tu'!$F$6:$F$29,$B11,'Quy doi vat tu'!$L$6:$L$29,"Đúc cấu kiện") -> 14933.81 | E11: =SUMIFS('Quy doi vat tu'!$J$6:$J$29,'Quy doi vat tu'!$F$6:$F$29,$B11,'Quy doi vat tu'!$L$6:$L$29,"K2A đợt 1 (C16÷C2)") -> 0 | F11: =SUMIFS('Quy doi vat tu'!$J$6:$J$29,'Quy doi vat tu'!$F$6:$F$29,$B11,'Quy doi vat tu'!$L$6:$L$29,"K2A đợt 2 (đến +1,78)") -> 0 | G11: =SUMIFS('Quy doi vat tu'!$J$6:$J$29,'Quy doi vat tu'!$F$6:$F$29,$B11,'Quy doi vat tu'!$L$6:$L$29,"Ống địa kỹ thuật") -> 0 | H11: =SUM(D11:G11) -> 14933.81
A12: 7 | B12: Thép tấm | C12: kg | D12: =SUMIFS('Quy doi vat tu'!$J$6:$J$29,'Quy doi vat tu'!$F$6:$F$29,$B12,'Quy doi vat tu'!$L$6:$L$29,"Đúc cấu kiện") -> 4290.9607 | E12: =SUMIFS('Quy doi vat tu'!$J$6:$J$29,'Quy doi vat tu'!$F$6:$F$29,$B12,'Quy doi vat tu'!$L$6:$L$29,"K2A đợt 1 (C16÷C2)") -> 0 | F12: =SUMIFS('Quy doi vat tu'!$J$6:$J$29,'Quy doi vat tu'!$F$6:$F$29,$B12,'Quy doi vat tu'!$L$6:$L$29,"K2A đợt 2 (đến +1,78)") -> 0 | G12: =SUMIFS('Quy doi vat tu'!$J$6:$J$29,'Quy doi vat tu'!$F$6:$F$29,$B12,'Quy doi vat tu'!$L$6:$L$29,"Ống địa kỹ thuật") -> 0 | H12: =SUM(D12:G12) -> 4290.9607
A13: 8 | B13: Thép hình | C13: kg | D13: =SUMIFS('Quy doi vat tu'!$J$6:$J$29,'Quy doi vat tu'!$F$6:$F$29,$B13,'Quy doi vat tu'!$L$6:$L$29,"Đúc cấu kiện") -> 4044.982 | E13: =SUMIFS('Quy doi vat tu'!$J$6:$J$29,'Quy doi vat tu'!$F$6:$F$29,$B13,'Quy doi vat tu'!$L$6:$L$29,"K2A đợt 1 (C16÷C2)") -> 0 | F13: =SUMIFS('Quy doi vat tu'!$J$6:$J$29,'Quy doi vat tu'!$F$6:$F$29,$B13,'Quy doi vat tu'!$L$6:$L$29,"K2A đợt 2 (đến +1,78)") -> 0 | G13: =SUMIFS('Quy doi vat tu'!$J$6:$J$29,'Quy doi vat tu'!$F$6:$F$29,$B13,'Quy doi vat tu'!$L$6:$L$29,"Ống địa kỹ thuật") -> 0 | H13: =SUM(D13:G13) -> 4044.982
A14: 9 | B14: Que hàn | C14: kg | D14: =SUMIFS('Quy doi vat tu'!$J$6:$J$29,'Quy doi vat tu'!$F$6:$F$29,$B14,'Quy doi vat tu'!$L$6:$L$29,"Đúc cấu kiện") -> 542.64978 | E14: =SUMIFS('Quy doi vat tu'!$J$6:$J$29,'Quy doi vat tu'!$F$6:$F$29,$B14,'Quy doi vat tu'!$L$6:$L$29,"K2A đợt 1 (C16÷C2)") -> 0 | F14: =SUMIFS('Quy doi vat tu'!$J$6:$J$29,'Quy doi vat tu'!$F$6:$F$29,$B14,'Quy doi vat tu'!$L$6:$L$29,"K2A đợt 2 (đến +1,78)") -> 0 | G14: =SUMIFS('Quy doi vat tu'!$J$6:$J$29,'Quy doi vat tu'!$F$6:$F$29,$B14,'Quy doi vat tu'!$L$6:$L$29,"Ống địa kỹ thuật") -> 0 | H14: =SUM(D14:G14) -> 542.64978
A15: 10 | B15: Dây thép | C15: kg | D15: =SUMIFS('Quy doi vat tu'!$J$6:$J$29,'Quy doi vat tu'!$F$6:$F$29,$B15,'Quy doi vat tu'!$L$6:$L$29,"Đúc cấu kiện") -> 135.86839 | E15: =SUMIFS('Quy doi vat tu'!$J$6:$J$29,'Quy doi vat tu'!$F$6:$F$29,$B15,'Quy doi vat tu'!$L$6:$L$29,"K2A đợt 1 (C16÷C2)") -> 0 | F15: =SUMIFS('Quy doi vat tu'!$J$6:$J$29,'Quy doi vat tu'!$F$6:$F$29,$B15,'Quy doi vat tu'!$L$6:$L$29,"K2A đợt 2 (đến +1,78)") -> 0 | G15: =SUMIFS('Quy doi vat tu'!$J$6:$J$29,'Quy doi vat tu'!$F$6:$F$29,$B15,'Quy doi vat tu'!$L$6:$L$29,"Ống địa kỹ thuật") -> 0 | H15: =SUM(D15:G15) -> 135.86839
A16: 11 | B16: Cát đắp | C16: m3 | D16: =SUMIFS('Quy doi vat tu'!$J$6:$J$29,'Quy doi vat tu'!$F$6:$F$29,$B16,'Quy doi vat tu'!$L$6:$L$29,"Đúc cấu kiện") -> 0 | E16: =SUMIFS('Quy doi vat tu'!$J$6:$J$29,'Quy doi vat tu'!$F$6:$F$29,$B16,'Quy doi vat tu'!$L$6:$L$29,"K2A đợt 1 (C16÷C2)") -> 0 | F16: =SUMIFS('Quy doi vat tu'!$J$6:$J$29,'Quy doi vat tu'!$F$6:$F$29,$B16,'Quy doi vat tu'!$L$6:$L$29,"K2A đợt 2 (đến +1,78)") -> 14572.96 | G16: =SUMIFS('Quy doi vat tu'!$J$6:$J$29,'Quy doi vat tu'!$F$6:$F$29,$B16,'Quy doi vat tu'!$L$6:$L$29,"Ống địa kỹ thuật") -> 0 | H16: =SUM(D16:G16) -> 14572.96
A17: 12 | B17: Vải địa kỹ thuật | C17: m2 | D17: =SUMIFS('Quy doi vat tu'!$J$6:$J$29,'Quy doi vat tu'!$F$6:$F$29,$B17,'Quy doi vat tu'!$L$6:$L$29,"Đúc cấu kiện") -> 0 | E17: =SUMIFS('Quy doi vat tu'!$J$6:$J$29,'Quy doi vat tu'!$F$6:$F$29,$B17,'Quy doi vat tu'!$L$6:$L$29,"K2A đợt 1 (C16÷C2)") -> 2126.25 | F17: =SUMIFS('Quy doi vat tu'!$J$6:$J$29,'Quy doi vat tu'!$F$6:$F$29,$B17,'Quy doi vat tu'!$L$6:$L$29,"K2A đợt 2 (đến +1,78)") -> 21723.461 | G17: =SUMIFS('Quy doi vat tu'!$J$6:$J$29,'Quy doi vat tu'!$F$6:$F$29,$B17,'Quy doi vat tu'!$L$6:$L$29,"Ống địa kỹ thuật") -> 0 | H17: =SUM(D17:G17) -> 23849.711
... A22: 17 | B22: Cọc định vị | C22: kg | D22: =SUMIFS('Quy doi vat tu'!$J$6:$J$29,'Quy doi vat tu'!$F$6:$F$29,$B22,'Quy doi vat tu'!$L$6:$L$29,"Đúc cấu kiện") -> 0 | E22: =SUMIFS('Quy doi vat tu'!$J$6:$J$29,'Quy doi vat tu'!$F$6:$F$29,$B22,'Quy doi vat tu'!$L$6:$L$29,"K2A đợt 1 (C16÷C2)") -> 0 | F22: =SUMIFS('Quy doi vat tu'!$J$6:$J$29,'Quy doi vat tu'!$F$6:$F$29,$B22,'Quy doi vat tu'!$L$6:$L$29,"K2A đợt 2 (đến +1,78)") -> 0 | G22: =SUMIFS('Quy doi vat tu'!$J$6:$J$29,'Quy doi vat tu'!$F$6:$F$29,$B22,'Quy doi vat tu'!$L$6:$L$29,"Ống địa kỹ thuật") -> 338 | H22: =SUM(D22:G22) -> 338
B24: Ghi chú:
B25: 1. Vật tư = Khối lượng nghiệm thu × Định mức hao phí vật liệu trong dự toán (hạng mục Kè bờ tuyến 2A). Chi tiết từng công việc ở sheet 'Quy doi vat tu'.
B26: 2. Đúc cấu kiện: lấy các hồ sơ 'Theo dõi đổ bê tông M300'; hồ sơ trùng số/trùng đợt chỉ tính 1 lần (xem cột Ghi chú sheet 'Duc cau kien').
B27: 3. K2A đợt 1: tổng 14 đoạn C16÷C2 theo danh mục. Khối chặn chân lắp đặt (540 ck) đã được tính vật tư ở phần đúc cấu kiện nên không cộng lại.
B28: 4. K2A đợt 2: khối lượng thiết kế toàn đoạn (21 đoạn C1÷C22) như ghi trong danh mục; khối lát kè cũ tận dụng không phát sinh vật tư mới.
B29: 5. Ống địa kỹ thuật: 13.000 md theo số liệu người dùng cung cấp (danh mục hồ sơ không có công việc này).
B30: 6. Cát đắp: dự toán không có định mức vật liệu riêng cho cát đắp nên lấy bằng khối lượng nghiệm thu.

Sheet Duc cau kien
A1: KHỐI LƯỢNG ĐÚC CẤU KIỆN BÊ TÔNG M300 THEO HỒ SƠ (đã loại hồ sơ trùng)
A2: Dự án: Xử lý khẩn cấp kè biển khu du lịch Hải Tiến, xã Hoằng Tiến
A3: Nguồn: DANH_MUC_NGHIEM_THU_CAU_KIEN_DUC_SAN.xlsx – các hồ sơ 'Theo dõi đổ bê tông M300'
A5: Thông số 1 cấu kiện (suy ra từ danh mục, khớp 100% các dòng):
A6: Loại cấu kiện | B6: BT M300 (m³/ck) | C6: Ván khuôn (m²/ck) | D6: Thép móc cẩu (kg/ck)
A7: Khối bậc thang 2T | B7: 0.999 | C7: 5.515 | D7: 4.03
A8: Khối chặn chân 1,5x1,5x0,5m | B8: 1.044 | C8: 4.488 | D8: 0
A9: Khối vai kè loại 1 | B9: 0.909 | C9: 5.419 | D9: 0
A10: Khối vai kè loại 2 | B10: 0.882 | C10: 5.276 | D10: 0
A12: STT hồ sơ | B12: Số BBNT đổ BT | C12: Ngày | D12: Đợt bậc thang | E12: SL bậc thang (ck) | F12: Đợt chặn chân | G12: SL chặn chân (ck) | H12: Đợt vai kè | I12: SL vai kè 1 (ck) | J12: SL vai kè 2 (ck) | K12: BT M300 (m³) | L12: Ván khuôn (m²) | M12: Thép móc cẩu (kg) | N12: Ghi chú
A13: 4 | B13: 04/BBNT/BT M300, đá 2x4 | C13: 46243 | D13: 1 | E13: 68 | F13: 1 | G13: 12 | I13: 0 | J13: 0 | K13: =E13*$B$7+G13*$B$8+I13*$B$9+J13*$B$10 -> 80.46 | L13: =E13*$C$7+G13*$C$8+I13*$C$9+J13*$C$10 -> 428.876 | M13: =E13*$D$7 -> 274.04
A14: 8 | B14: 08/BBNT/BT M300, đá 2x4 | C14: 46244 | D14: 2 | E14: 68 | F14: 2 | G14: 12 | I14: 0 | J14: 0 | K14: =E14*$B$7+G14*$B$8+I14*$B$9+J14*$B$10 -> 80.46 | L14: =E14*$C$7+G14*$C$8+I14*$C$9+J14*$C$10 -> 428.876 | M14: =E14*$D$7 -> 274.04
A15: 12 | B15: 12/BBNT/BT M300, đá 2x4 | C15: 46245 | D15: 3 | E15: 54 | F15: 3 | G15: 7 | I15: 0 | J15: 0 | K15: =E15*$B$7+G15*$B$8+I15*$B$9+J15*$B$10 -> 61.254 | L15: =E15*$C$7+G15*$C$8+I15*$C$9+J15*$C$10 -> 329.226 | M15: =E15*$D$7 -> 217.62
A16: 16 | B16: 16/BBNT/BT M300, đá 2x4 | C16: 46246 | D16: 4 | E16: 71 | F16: 4 | G16: 12 | I16: 0 | J16: 0 | K16: =E16*$B$7+G16*$B$8+I16*$B$9+J16*$B$10 -> 83.457 | L16: =E16*$C$7+G16*$C$8+I16*$C$9+J16*$C$10 -> 445.421 | M16: =E16*$D$7 -> 286.13
A17: 20 | B17: 20/BBNT/BT M300, đá 2x4 | C17: 46247 | D17: 5 | E17: 73 | F17: 5 | G17: 8 | I17: 0 | J17: 0 | K17: =E17*$B$7+G17*$B$8+I17*$B$9+J17*$B$10 -> 81.279 | L17: =E17*$C$7+G17*$C$8+I17*$C$9+J17*$C$10 -> 438.499 | M17: =E17*$D$7 -> 294.19
A18: 24 | B18: 24/BBNT/BT M300, đá 2x4 | C18: 46248 | D18: 6 | E18: 45 | F18: 6 | G18: 8 | I18: 0 | J18: 0 | K18: =E18*$B$7+G18*$B$8+I18*$B$9+J18*$B$10 -> 53.307 | L18: =E18*$C$7+G18*$C$8+I18*$C$9+J18*$C$10 -> 284.079 | M18: =E18*$D$7 -> 181.35
A19: 28 | B19: 28/BBNT/BT M300, đá 2x4 | C19: 46249 | D19: 7 | E19: 78 | F19: 7 | G19: 16 | I19: 0 | J19: 0 | K19: =E19*$B$7+G19*$B$8+I19*$B$9+J19*$B$10 -> 94.626 | L19: =E19*$C$7+G19*$C$8+I19*$C$9+J19*$C$10 -> 501.978 | M19: =E19*$D$7 -> 314.34
A20: 32 | B20: 32/BBNT/BT M300, đá 2x4 | C20: 46250 | D20: 8 | E20: 70 | F20: 8 | G20: 16 | I20: 0 | J20: 0 | K20: =E20*$B$7+G20*$B$8+I20*$B$9+J20*$B$10 -> 86.634 | L20: =E20*$C$7+G20*$C$8+I20*$C$9+J20*$C$10 -> 457.858 | M20: =E20*$D$7 -> 282.1
A21: 36 | B21: 36/BBNT/BT M300, đá 2x4 | C21: 46251 | D21: 9 | E21: 78 | F21: 9 | G21: 16 | I21: 0 | J21: 0 | K21: =E21*$B$7+G21*$B$8+I21*$B$9+J21*$B$10 -> 94.626 | L21: =E21*$C$7+G21*$C$8+I21*$C$9+J21*$C$10 -> 501.978 | M21: =E21*$D$7 -> 314.34
A22: 40 | B22: 40/BBNT/BT M300, đá 2x4 | C22: 46252 | D22: 10 | E22: 72 | F22: 10 | G22: 11 | I22: 0 | J22: 0 | K22: =E22*$B$7+G22*$B$8+I22*$B$9+J22*$B$10 -> 83.412 | L22: =E22*$C$7+G22*$C$8+I22*$C$9+J22*$C$10 -> 446.448 | M22: =E22*$D$7 -> 290.16
A23: 44 | B23: 44/BBNT/BT M300, đá 2x4 | C23: 46253 | D23: 11 | E23: 35 | F23: 11 | G23: 4 | I23: 0 | J23: 0 | K23: =E23*$B$7+G23*$B$8+I23*$B$9+J23*$B$10 -> 39.141 | L23: =E23*$C$7+G23*$C$8+I23*$C$9+J23*$C$10 -> 210.977 | M23: =E23*$D$7 -> 141.05
A24: 48 | B24: 48/BBNT/BT M300, đá 2x4 | C24: 46254 | D24: 12 | E24: 35 | F24: 12 | G24: 8 | I24: 0 | J24: 0 | K24: =E24*$B$7+G24*$B$8+I24*$B$9+J24*$B$10 -> 43.317 | L24: =E24*$C$7+G24*$C$8+I24*$C$9+J24*$C$10 -> 228.929 | M24: =E24*$D$7 -> 141.05
... A32: 80 | B32: 80/BBNT/BT M300, đá 2x4 | C32: 46264 | D32: 20 | E32: 57 | F32: 20 | G32: 12 | I32: 0 | J32: 0 | K32: =E32*$B$7+G32*$B$8+I32*$B$9+J32*$B$10 -> 69.471 | L32: =E32*$C$7+G32*$C$8+I32*$C$9+J32*$C$10 -> 368.211 | M32: =E32*$D$7 -> 229.71
A33: 84 | B33: 80/BBNT/BT M300, đá 2x4 | C33: 46264 | D33: 20 | E33: 0 | F33: 20 | G33: 0 | I33: 0 | J33: 0 | K33: =E33*$B$7+G33*$B$8+I33*$B$9+J33*$B$10 -> 0 | L33: =E33*$C$7+G33*$C$8+I33*$C$9+J33*$C$10 -> 0 | M33: =E33*$D$7 -> 0 | N33: Bậc thang đợt 20 đã tính ở hồ sơ trước; Chặn chân đợt 20 đã tính ở hồ sơ trước
A34: 88 | B34: 88/BBNT/BT M300, đá 2x4 | C34: 46265 | D34: 21 | E34: 84 | F34: 21 | G34: 16 | I34: 0 | J34: 0 | K34: =E34*$B$7+G34*$B$8+I34*$B$9+J34*$B$10 -> 100.62 | L34: =E34*$C$7+G34*$C$8+I34*$C$9+J34*$C$10 -> 535.068 | M34: =E34*$D$7 -> 338.52
A35: 92 | B35: 96/BBNT/BT M300, đá 2x4 | C35: 46266 | D35: 22 | E35: 83 | F35: 22 | G35: 12 | I35: 0 | J35: 0 | K35: =E35*$B$7+G35*$B$8+I35*$B$9+J35*$B$10 -> 95.445 | L35: =E35*$C$7+G35*$C$8+I35*$C$9+J35*$C$10 -> 511.601 | M35: =E35*$D$7 -> 334.49
A36: 96 | B36: 96/BBNT/BT M300, đá 2x4 | C36: 46267 | D36: 23 | E36: 84 | F36: 23 | G36: 12 | I36: 0 | J36: 0 | K36: =E36*$B$7+G36*$B$8+I36*$B$9+J36*$B$10 -> 96.444 | L36: =E36*$C$7+G36*$C$8+I36*$C$9+J36*$C$10 -> 517.116 | M36: =E36*$D$7 -> 338.52
A37: 100 | B37: 100/BBNT/BT M300, đá 2x4 | C37: 46268 | D37: 24 | E37: 84 | F37: 24 | G37: 16 | I37: 0 | J37: 0 | K37: =E37*$B$7+G37*$B$8+I37*$B$9+J37*$B$10 -> 100.62 | L37: =E37*$C$7+G37*$C$8+I37*$C$9+J37*$C$10 -> 535.068 | M37: =E37*$D$7 -> 338.52
A38: 104 | B38: 104/BBNT/BT M300, đá 2x4 | C38: 46269 | D38: 25 | E38: 84 | F38: 25 | G38: 15 | I38: 0 | J38: 0 | K38: =E38*$B$7+G38*$B$8+I38*$B$9+J38*$B$10 -> 99.576 | L38: =E38*$C$7+G38*$C$8+I38*$C$9+J38*$C$10 -> 530.58 | M38: =E38*$D$7 -> 338.52
A39: 108 | B39: 108/BBNT/BT M300, đá 2x4 | C39: 46270 | D39: 26 | E39: 64 | F39: 26 | G39: 12 | I39: 0 | J39: 0 | K39: =E39*$B$7+G39*$B$8+I39*$B$9+J39*$B$10 -> 76.464 | L39: =E39*$C$7+G39*$C$8+I39*$C$9+J39*$C$10 -> 406.816 | M39: =E39*$D$7 -> 257.92
A40: 112 | B40: 112/BBNT/BT M300, đá 2x4 | C40: 46271 | D40: 27 | E40: 84 | F40: 27 | G40: 16 | I40: 0 | J40: 0 | K40: =E40*$B$7+G40*$B$8+I40*$B$9+J40*$B$10 -> 100.62 | L40: =E40*$C$7+G40*$C$8+I40*$C$9+J40*$C$10 -> 535.068 | M40: =E40*$D$7 -> 338.52
A41: 116 | B41: 116/BBNT/BT M300, đá 2x4 | C41: 46272 | D41: 28 | E41: 84 | F41: 28 | G41: 16 | I41: 0 | J41: 0 | K41: =E41*$B$7+G41*$B$8+I41*$B$9+J41*$B$10 -> 100.62 | L41: =E41*$C$7+G41*$C$8+I41*$C$9+J41*$C$10 -> 535.068 | M41: =E41*$D$7 -> 338.52
A42: 120 | B42: 120/BBNT/BT M300, đá 2x4 | C42: 46273 | D42: 29 | E42: 84 | F42: 29 | G42: 16 | I42: 0 | J42: 0 | K42: =E42*$B$7+G42*$B$8+I42*$B$9+J42*$B$10 -> 100.62 | L42: =E42*$C$7+G42*$C$8+I42*$C$9+J42*$C$10 -> 535.068 | M42: =E42*$D$7 -> 338.52
A43: 124 | B43: 124/BBNT/BT M300, đá 2x4 | C43: 46273 | D43: 29 | E43: 0 | F43: 29 | G43: 0 | I43: 0 | J43: 0 | K43: =E43*$B$7+G43*$B$8+I43*$B$9+J43*$B$10 -> 0 | L43: =E43*$C$7+G43*$C$8+I43*$C$9+J43*$C$10 -> 0 | M43: =E43*$D$7 -> 0 | N43: Bậc thang đợt 29 đã tính ở hồ sơ trước; Chặn chân đợt 29 đã tính ở hồ sơ trước
A44: 128 | B44: 128/BBNT/BT M300, đá 2x4 | C44: 46274 | D44: 30 | E44: 84 | F44: 30 | G44: 16 | I44: 0 | J44: 0 | K44: =E44*$B$7+G44*$B$8+I44*$B$9+J44*$B$10 -> 100.62 | L44: =E44*$C$7+G44*$C$8+I44*$C$9+J44*$C$10 -> 535.068 | M44: =E44*$D$7 -> 338.52
A45: 132 | B45: 128/BBNT/BT M300, đá 2x4 | C45: 46275 | D45: 30 | E45: 0 | F45: 30 | G45: 0 | I45: 0 | J45: 0 | K45: =E45*$B$7+G45*$B$8+I45*$B$9+J45*$B$10 -> 0 | L45: =E45*$C$7+G45*$C$8+I45*$C$9+J45*$C$10 -> 0 | M45: =E45*$D$7 -> 0 | N45: Bậc thang đợt 30 đã tính ở hồ sơ trước; Chặn chân đợt 30 đã tính ở hồ sơ trước
A46: 136 | B46: 136/BBNT/BT M300, đá 2x4 | C46: 46276 | D46: 31 | E46: 84 | F46: 31 | G46: 16 | I46: 0 | J46: 0 | K46: =E46*$B$7+G46*$B$8+I46*$B$9+J46*$B$10 -> 100.62 | L46: =E46*$C$7+G46*$C$8+I46*$C$9+J46*$C$10 -> 535.068 | M46: =E46*$D$7 -> 338.52
A47: 140 | B47: 140/BBNT/BT M300, đá 2x4 | C47: 46277 | D47: 32 | E47: 84 | F47: 32 | G47: 16 | I47: 0 | J47: 0 | K47: =E47*$B$7+G47*$B$8+I47*$B$9+J47*$B$10 -> 100.62 | L47: =E47*$C$7+G47*$C$8+I47*$C$9+J47*$C$10 -> 535.068 | M47: =E47*$D$7 -> 338.52
A48: 144 | B48: 144/BBNT/BT M300, đá 2x4 | C48: 46278 | D48: 33 | E48: 84 | F48: 33 | G48: 8 | I48: 0 | J48: 0 | K48: =E48*$B$7+G48*$B$8+I48*$B$9+J48*$B$10 -> 92.268 | L48: =E48*$C$7+G48*$C$8+I48*$C$9+J48*$C$10 -> 499.164 | M48: =E48*$D$7 -> 338.52
A49: 148 | B49: 148/BBNT/BT M300, đá 2x4 | C49: 46284 | D49: 34 | E49: 42 | F49: 34 | G49: 8 | H49: 1 | I49: 10 | J49: 10 | K49: =E49*$B$7+G49*$B$8+I49*$B$9+J49*$B$10 -> 68.22 | L49: =E49*$C$7+G49*$C$8+I49*$C$9+J49*$C$10 -> 374.484 | M49: =E49*$D$7 -> 169.26
...

Sheet Quy doi vat tu
A1: KHỐI LƯỢNG THI CÔNG THEO HỒ SƠ NGHIỆM THU VÀ QUY ĐỔI VẬT TƯ
A2: Dự án: Xử lý khẩn cấp kè biển khu du lịch Hải Tiến, xã Hoằng Tiến
A3: Định mức hao phí vật liệu lấy theo file Du_toan_Hoang_Tien_26.08.2026_TAC.xlsx – sheet 'Hao phí VT', hạng mục Kè bờ tuyến 2A
A5: Nguồn hồ sơ | B5: Công việc nghiệm thu | C5: Đơn vị | D5: Khối lượng nghiệm thu | E5: Mã định mức | F5: Vật tư | G5: Đơn vị VT | H5: Định mức | I5: Đơn vị ĐM tính trên | J5: Khối lượng vật tư | K5: Ghi chú
A6: Đúc cấu kiện | B6: Bê tông M300 đá 2x4 cấu kiện đúc sẵn (bậc thang, chặn chân, vai kè) | C6: m3 | D6: ='Duc cau kien'!K69 -> 4632.309 | E6: AG.11924 | F6: Xi măng PCB40 rời/bền sunfat type II | G6: kg | H6: 357.28 | I6: 1 | J6: =D6*H6/I6 -> 1655031.4 | K6: KL lấy từ sheet 'Duc cau kien' (đã loại trùng) | L6: Đúc cấu kiện
D7: =D6 -> 4632.309 | F7: Cát vàng | G7: m3 | H7: 0.510545 | I7: 1 | J7: =D7*H7/I7 -> 2365.0022 | L7: Đúc cấu kiện
D8: =D6 -> 4632.309 | F8: Đá 2x4 | G8: m3 | H8: 0.82824 | I8: 1 | J8: =D8*H8/I8 -> 3836.6636 | L8: Đúc cấu kiện
D9: =D6 -> 4632.309 | F9: Nước | G9: lít | H9: 151.54965 | I9: 1 | J9: =D9*H9/I9 -> 702024.81 | L9: Đúc cấu kiện
D10: =D6 -> 4632.309 | F10: Phụ gia R7 | G10: kg | H10: 1.7864 | I10: 1 | J10: =D10*H10/I10 -> 8275.1568 | L10: Đúc cấu kiện
A11: Đúc cấu kiện | B11: Ván khuôn cấu kiện đúc sẵn | C11: m2 | D11: ='Duc cau kien'!L69 -> 24846.327 | E11: AG.32211 | F11: Que hàn | G11: kg | H11: 1.9 | I11: 100 | J11: =D11*H11/I11 -> 472.08021 | K11: Định mức tính trên 100 m² | L11: Đúc cấu kiện
D12: =D11 -> 24846.327 | F12: Thép tấm | G12: kg | H12: 17.27 | I12: 100 | J12: =D12*H12/I12 -> 4290.9607 | L12: Đúc cấu kiện
D13: =D11 -> 24846.327 | F13: Thép hình | G13: kg | H13: 16.28 | I13: 100 | J13: =D13*H13/I13 -> 4044.982 | L13: Đúc cấu kiện
A14: Đúc cấu kiện | B14: Thép móc cẩu khối bậc thang | C14: kg | D14: ='Duc cau kien'!M69 -> 14640.99 | E14: AG.13720 | F14: Thép tròn Fi ≤18mm | G14: kg | H14: 1020 | I14: 1000 | J14: =D14*H14/I14 -> 14933.81 | K14: Định mức tính trên 1 tấn | L14: Đúc cấu kiện
D15: =D14 -> 14640.99 | F15: Que hàn | G15: kg | H15: 4.82 | I15: 1000 | J15: =D15*H15/I15 -> 70.569572 | L15: Đúc cấu kiện
D16: =D14 -> 14640.99 | F16: Dây thép | G16: kg | H16: 9.28 | I16: 1000 | J16: =D16*H16/I16 -> 135.86839 | L16: Đúc cấu kiện
A17: K2A đợt 1 (C16÷C2) | B17: Đào hố móng chân khay | C17: m3 | D17: 2419.2 | K17: Không phát sinh vật tư | L17: K2A đợt 1 (C16÷C2)
A18: K2A đợt 1 (C16÷C2) | B18: Trải vải địa kỹ thuật chân khay (rộng 7,5 m) | C18: m2 | D18: 2025 | E18: AL.16121 | F18: Vải địa kỹ thuật | G18: m2 | H18: 105 | I18: 100 | J18: =D18*H18/I18 -> 2126.25 | L18: K2A đợt 1 (C16÷C2)
A19: K2A đợt 1 (C16÷C2) | B19: Rải đá dăm 4x6 cm dày 20 cm chân khay | C19: m3 | D19: 405 | E19: TLB.21311 | F19: Đá 4x6 | G19: m3 | H19: 1.1 | I19: 1 | J19: =D19*H19/I19 -> 445.5 | L19: K2A đợt 1 (C16÷C2)
A20: K2A đợt 1 (C16÷C2) | B20: Đá hộc 100÷200 kg lớp dưới khối chặn chân | C20: m3 | D20: 243 | E20: AB.55313vd | F20: Đá hộc 100-200kg | G20: m3 | H20: 113 | I20: 100 | J20: =D20*H20/I20 -> 274.59 | L20: K2A đợt 1 (C16÷C2)
A21: K2A đợt 1 (C16÷C2) | B21: Đá hộc 100÷200 kg thềm chống xói | C21: m3 | D21: 567 | E21: AB.55313vd | F21: Đá hộc 100-200kg | G21: m3 | H21: 113 | I21: 100 | J21: =D21*H21/I21 -> 640.71 | L21: K2A đợt 1 (C16÷C2)
A22: K2A đợt 1 (C16÷C2) | B22: Lắp đặt khối bê tông chặn chân 1,5x1,5x0,5 m | C22: ck | D22: 540 | E22: AG.61110 | K22: Khối đã đúc – vật tư tính ở phần Đúc cấu kiện | L22: K2A đợt 1 (C16÷C2)
A23: K2A đợt 2 (đến +1,78) | B23: Đào thanh thải mái kè, ống buy, bậc lên xuống hiện trạng | C23: m3 | D23: 4134.64 | K23: Không phát sinh vật tư | L23: K2A đợt 2 (đến +1,78)
A24: K2A đợt 2 (đến +1,78) | B24: Đắp cát hố móng chân kè cũ đến cao trình +0,70 m | C24: m3 | D24: 14572.96 | E24: AB.24131 | F24: Cát đắp | G24: m3 | H24: 1 | I24: 1 | J24: =D24*H24/I24 -> 14572.96 | K24: Dự toán không có định mức vật liệu cho cát đắp – lấy bằng KL nghiệm thu | L24: K2A đợt 2 (đến +1,78)
A25: K2A đợt 2 (đến +1,78) | B25: Trải vải địa kỹ thuật không dệt trên mặt cát đắp | C25: m2 | D25: 20689.01 | E25: AL.16121 | F25: Vải địa kỹ thuật | G25: m2 | H25: 105 | I25: 100 | J25: =D25*H25/I25 -> 21723.461 | L25: K2A đợt 2 (đến +1,78)
A26: K2A đợt 2 (đến +1,78) | B26: Rải đá dăm 4x6 cm dày 20 cm | C26: m3 | D26: 3468.08 | E26: TLB.21311 | F26: Đá 4x6 | G26: m3 | H26: 1.1 | I26: 1 | J26: =D26*H26/I26 -> 3814.888 | L26: K2A đợt 2 (đến +1,78)
A27: K2A đợt 2 (đến +1,78) | B27: Đá hộc hỗn hợp (đá lõi) đến cao trình +1,78 m | C27: m3 | D27: 8795.58 | E27: AB.55311vd | F27: Đá hộc hỗn hợp | G27: m3 | H27: 113 | I27: 100 | J27: =D27*H27/I27 -> 9939.0054 | L27: K2A đợt 2 (đến +1,78)
A28: Ống địa kỹ thuật | B28: Cung cấp, thi công ống địa kỹ thuật (Geotube) | C28: m | D28: 13000 | E28: TT | F28: Ống địa kỹ thuật GREENTUBE H=3m | G28: m | H28: 1 | I28: 1 | J28: =D28*H28/I28 -> 13000 | K28: KL do người dùng cung cấp: thi công được 13.000 md | L28: Ống địa kỹ thuật
D29: =D28 -> 13000 | F29: Cọc định vị | G29: kg | H29: 0.026 | I29: 1 | J29: =D29*H29/I29 -> 338 | L29: Ống địa kỹ thuật
