Workbook

Sheet Chạy
A1: STT | B1: TC | C1: LT | D1: TL | E1: DT | F1: KCt 1 | G1: CDt 1 | H1: KCt 2 | I1: CDt 2 | J1: KC tim | K1: CD tim | L1: KCp 1 | M1: CDp 1 | N1: KCp 2 | O1: CDp 2 | P1: S bao | Q1: S le
A2: 1 | B2: 38 | C2: 672.28 | D2: 9 | E2: 7.31 | F2: -11.95 | G2: 1.94 | H2: -5.25 | I2: 1.94 | J2: 0 | K2: 2.06 | L2: 5.25 | M2: 1.94 | N2: 11.95 | O2: 1.94 | P2: 76.02 | Q2: 11.55
D3: 8 | E3: 7.39 | F3: -12.4 | G3: 1.64 | H3: -5.25 | I3: 1.64 | J3: 0 | K3: 1.76 | L3: 5.25 | M3: 1.64 | N3: 12.4 | O3: 1.64
D4: 7 | E4: 7.4 | F4: -11.74 | G4: 1.34 | H4: -5.25 | I4: 1.34 | J4: 0 | K4: 1.46 | L4: 5.25 | M4: 1.34 | N4: 12.85 | O4: 1.34
D5: 6 | E5: 7.44 | F5: -11.44 | G5: 1.04 | H5: -5.25 | I5: 1.04 | J5: 0 | K5: 1.16 | L5: 5.25 | M5: 1.04 | N5: 13.3 | O5: 1.04
D6: 5 | E6: 7.49 | F6: -11.14 | G6: 0.74 | H6: -5.25 | I6: 0.74 | J6: 0 | K6: 0.86 | L6: 5.25 | M6: 0.74 | N6: 13.75 | O6: 0.74
D7: 4 | E7: 7.53 | F7: -10.84 | G7: 0.44 | H7: -5.25 | I7: 0.44 | J7: 0 | K7: 0.56 | L7: 5.25 | M7: 0.44 | N7: 14.2 | O7: 0.44
D8: 3 | E8: 7.58 | F8: -10.54 | G8: 0.14 | H8: -5.25 | I8: 0.14 | J8: 0 | K8: 0.26 | L8: 5.25 | M8: 0.14 | N8: 14.65 | O8: 0.14
D9: 2 | E9: 7.62 | F9: -10.24 | G9: -0.16 | H9: -5.25 | I9: -0.16 | J9: 0 | K9: -0.04 | L9: 5.25 | M9: -0.16 | N9: 15.1 | O9: -0.16
D10: 1 | E10: 4.71 | F10: -9.94 | G10: -0.46 | H10: -5.25 | I10: -0.46 | J10: 0 | K10: -0.34 | L10: 5.25 | M10: -0.46 | N10: 15.55 | O10: -0.46
A11: 2 | B11: 39 | C11: 689.28 | D11: 9 | E11: 7.31 | F11: -11.95 | G11: 1.94 | H11: -5.25 | I11: 1.94 | J11: 0 | K11: 2.06 | L11: 5.25 | M11: 1.94 | N11: 11.95 | O11: 1.94 | P11: 69.55 | Q11: 11.55
D12: 8 | E12: 7.49 | F12: -12.4 | G12: 1.64 | H12: -5.25 | I12: 1.64 | J12: 0 | K12: 1.76 | L12: 5.25 | M12: 1.64 | N12: 12.4 | O12: 1.64
D13: 7 | E13: 7.55 | F13: -12.23 | G13: 1.34 | H13: -5.25 | I13: 1.34 | J13: 0 | K13: 1.46 | L13: 5.25 | M13: 1.34 | N13: 12.85 | O13: 1.34
D14: 6 | E14: 7.61 | F14: -11.97 | G14: 1.04 | H14: -5.25 | I14: 1.04 | J14: 0 | K14: 1.16 | L14: 5.25 | M14: 1.04 | N14: 13.3 | O14: 1.04
D15: 5 | E15: 7.54 | F15: -11.71 | G15: 0.74 | H15: -5.25 | I15: 0.74 | J15: 0 | K15: 0.86 | L15: 5.25 | M15: 0.74 | N15: 13.75 | O15: 0.74
D16: 4 | E16: 6.07 | F16: -11.46 | G16: 0.44 | H16: -5.25 | I16: 0.44 | J16: 0 | K16: 0.56 | L16: 5.25 | M16: 0.44 | N16: 9.34 | O16: 0.44
D17: 3 | E17: 5.56 | F17: -9.8 | G17: 0.14 | H17: -5.25 | I17: 0.14 | J17: 0 | K17: 0.26 | L17: 5.25 | M17: 0.14 | N17: 9.04 | O17: 0.14
D18: 2 | E18: 5.38 | F18: -9.5 | G18: -0.16 | H18: -5.25 | I18: -0.16 | J18: 0 | K18: -0.04 | L18: 5.25 | M18: -0.16 | N18: 8.74 | O18: -0.16
D19: 1 | E19: 3.49 | F19: -9.2 | G19: -0.46 | H19: -5.25 | I19: -0.46 | J19: 0 | K19: -0.34 | L19: 5.25 | M19: -0.46 | N19: 8.44 | O19: -0.46
A20: 3 | B20: F2 | C20: 701.03 | D20: 9 | E20: 3.42 | F20: -11.95 | G20: 1.94 | H20: -5.25 | I20: 1.94 | J20: 0 | K20: 2.06 | L20: 5.25 | M20: 1.94 | N20: -0.67 | O20: 2.05 | P20: 24.34 | Q20: 6.4
D21: 8 | E21: 3.36 | F21: -12.35 | G21: 1.64 | H21: -5.25 | I21: 1.64 | J21: 0 | K21: 1.76 | L21: 5.25 | M21: 1.64 | N21: -0.9 | O21: 1.74
D22: 7 | E22: 3.2 | F22: -12.07 | G22: 1.34 | H22: -5.25 | I22: 1.34 | J22: 0 | K22: 1.46 | L22: 5.25 | M22: 1.34 | N22: -1.14 | O22: 1.44
D23: 6 | E23: 3.05 | F23: -11.8 | G23: 1.04 | H23: -5.25 | I23: 1.04 | J23: 0 | K23: 1.16 | L23: 5.25 | M23: 1.04 | N23: -1.37 | O23: 1.13
D24: 5 | E24: 2.9 | F24: -11.52 | G24: 0.74 | H24: -5.25 | I24: 0.74 | J24: 0 | K24: 0.86 | L24: 5.25 | M24: 0.74 | N24: -1.61 | O24: 0.83
D25: 4 | E25: 2.01 | F25: -11.25 | G25: 0.44 | H25: -5.25 | I25: 0.44 | J25: 0 | K25: 0.56 | L25: 5.25 | M25: 0.44 | N25: -1.84 | O25: 0.52
D26: 3 | E26: 0
D27: 2 | E27: 0
D28: 1 | E28: 0
A29: 4 | B29: 40 | C29: 712.78 | D29: 9 | E29: 7.31 | F29: -11.95 | G29: 1.94 | H29: -5.25 | I29: 1.94 | J29: 0 | K29: 2.06 | L29: 5.25 | M29: 1.94 | N29: 11.95 | O29: 1.94 | P29: 69.54 | Q29: 11.55
D30: 8 | E30: 7.5 | F30: -12.4 | G30: 1.64 | H30: -5.25 | I30: 1.64 | J30: 0 | K30: 1.76 | L30: 5.25 | M30: 1.64 | N30: 12.4 | O30: 1.64
D31: 7 | E31: 7.56 | F31: -12.24 | G31: 1.34 | H31: -5.25 | I31: 1.34 | J31: 0 | K31: 1.46 | L31: 5.25 | M31: 1.34 | N31: 12.85 | O31: 1.34
D32: 6 | E32: 7.62 | F32: -11.99 | G32: 1.04 | H32: -5.25 | I32: 1.04 | J32: 0 | K32: 1.16 | L32: 5.25 | M32: 1.04 | N32: 13.3 | O32: 1.04
D33: 5 | E33: 7.44 | F33: -11.74 | G33: 0.74 | H33: -5.25 | I33: 0.74 | J33: 0 | K33: 0.86 | L33: 5.25 | M33: 0.74 | N33: 13.75 | O33: 0.74
D34: 4 | E34: 6.11 | F34: -11.49 | G34: 0.44 | H34: -5.25 | I34: 0.44 | J34: 0 | K34: 0.56 | L34: 5.25 | M34: 0.44 | N34: 9.2 | O34: 0.44
D35: 3 | E35: 5.56 | F35: -9.94 | G35: 0.14 | H35: -5.25 | I35: 0.14 | J35: 0 | K35: 0.26 | L35: 5.25 | M35: 0.14 | N35: 8.9 | O35: 0.14
D36: 2 | E36: 5.38 | F36: -9.64 | G36: -0.16 | H36: -5.25 | I36: -0.16 | J36: 0 | K36: -0.04 | L36: 5.25 | M36: -0.16 | N36: 8.6 | O36: -0.16
D37: 1 | E37: 3.52 | F37: -9.34 | G37: -0.46 | H37: -5.25 | I37: -0.46 | J37: 0 | K37: -0.34 | L37: 5.25 | M37: -0.46 | N37: 8.3 | O37: -0.46
A38: 5 | B38: 41 | C38: 729.78 | D38: 9 | E38: 6.18 | F38: -11.95 | G38: 1.94 | H38: -5.25 | I38: 1.94 | J38: 0 | K38: 2.06 | L38: 5.25 | M38: 1.94 | N38: 8.81 | O38: 1.94 | P38: 51.48 | Q38: 10.65
D39: 8 | E39: 5.59 | F39: -11.78 | G39: 1.64 | H39: -5.25 | I39: 1.64 | J39: 0 | K39: 1.76 | L39: 5.25 | M39: 1.64 | N39: 8.51 | O39: 1.64
D40: 7 | E40: 4.84 | F40: -8.21 | G40: 1.34 | H40: -5.25 | I40: 1.34 | J40: 0 | K40: 1.46 | L40: 5.25 | M40: 1.34 | N40: 8.21 | O40: 1.34
...

Sheet 1.KTHH L1
A1: PHỤ LỤC KIỂM TRA CAO ĐỘ, KÍCH THƯỚC HÌNH HỌC
A2: ="Kèm theo BBNT số: "&VLOOKUP(AZ2,'[1]Tuyến XD4'!$A$2:$G$60,7,0)&VLOOKUP(AZ2,'[1]Tuyến XD4'!$A$2:$G$60,4,0) -> Kèm theo BBNT số: 64.NĐXD4/CVXD ngày 16 tháng 09 năm 2026 | AZ2: 64
A3: Dự án: Xây dựng HTKT Khu tái định cư phục vụ di dân xã Hải Hà, thị xã Nghi Sơn, tỉnh Thanh Hóa.
A4: Gói thầu số 12: Xây dựng HTKT khu vực Hải Bình và Xuân Lâm (bao gồm cả bảo hiểm xây dựng công trình)
A5: Nhà thầu thi công: Công ty TNHH Hoàng Tuấn
A6: Hạng mục: Nền đường tuyến XD4
A7: - Đối tượng nghiệm thu: | G7: =VLOOKUP(AZ2,'[1]Tuyến XD4'!$A$2:$B$60,2,0) -> Đắp đất nền đường lớp 1 đoạn từ Km0+672,28 - Km0+746,82, độ chặt K>=0,95
A8: Sơ họa:
A19: TT | B19: Tên cọc | C19: Lý trình | D19: Bên trái (H1) | J19: Tim (H2) | M19: Bên phải (H3) | S19: Ghi chú
D20: KCTK | E20: KCTC | F20: Chênh KC (m) | G20: CDTK (m) | H20: CDTC (m) | I20: Chênh CD (m) | J20: CDTK (m) | K20: CDTC (m) | L20: Chênh CD (m) | M20: KCTK | N20: KCTC | O20: Chênh KC (m) | P20: CDTK (m) | Q20: CDTC (m) | R20: Chênh CD (m)
A21: 1 | B21: 38 | C21: 672.28 | D21: =+Chạy!F10 -> -9.94 | E21: =+D21+F21 -> -9.9294 | F21: =RANDBETWEEN(-105,115)/10000 -> 0.0106 | G21: =+Chạy!G10 -> -0.46 | H21: =G21+I21 -> -0.393 | I21: =RANDBETWEEN(-30,90)/1000 -> 0.067 | J21: =+Chạy!K10 -> -0.34 | K21: =J21+L21 -> -0.267 | L21: =RANDBETWEEN(-30,90)/1000 -> 0.073 | M21: =+Chạy!N10 -> 15.55 | N21: =+M21+O21 -> 15.5527 | O21: =RANDBETWEEN(-105,115)/10000 -> 0.0027 | P21: =+Chạy!O10 -> -0.46 | Q21: =P21+R21 -> -0.449 | R21: =RANDBETWEEN(-30,90)/1000 -> 0.011 | T21: 17
A22: 2 | B22: 39 | C22: =+C21+T21 -> 689.28 | D22: =+Chạy!F19 -> -9.2 | E22: =+D22+F22 -> -9.2055 | F22: =RANDBETWEEN(-105,115)/10000 -> -0.0055 | G22: =+Chạy!G19 -> -0.46 | H22: =G22+I22 -> -0.467 | I22: =RANDBETWEEN(-30,90)/1000 -> -0.007 | J22: =+Chạy!K19 -> -0.34 | K22: =J22+L22 -> -0.3 | L22: =RANDBETWEEN(-30,90)/1000 -> 0.04 | M22: =+Chạy!N19 -> 8.44 | N22: =+M22+O22 -> 8.4369 | O22: =RANDBETWEEN(-105,115)/10000 -> -0.0031 | P22: =+Chạy!O19 -> -0.46 | Q22: =P22+R22 -> -0.389 | R22: =RANDBETWEEN(-30,90)/1000 -> 0.071 | T22: 11.75
A23: 3 | B23: F2 | C23: =+C22+T22 -> 701.03 | T23: 11.75
A24: 4 | B24: 40 | C24: =+C23+T23 -> 712.78 | D24: =+Chạy!F37 -> -9.34 | E24: =+D24+F24 -> -9.3447 | F24: =RANDBETWEEN(-105,115)/10000 -> -0.0047 | G24: =+Chạy!G37 -> -0.46 | H24: =G24+I24 -> -0.428 | I24: =RANDBETWEEN(-30,90)/1000 -> 0.032 | J24: =+Chạy!K37 -> -0.34 | K24: =J24+L24 -> -0.259 | L24: =RANDBETWEEN(-30,90)/1000 -> 0.081 | M24: =+Chạy!N37 -> 8.3 | N24: =+M24+O24 -> 8.2952 | O24: =RANDBETWEEN(-105,115)/10000 -> -0.0048 | P24: =+Chạy!O37 -> -0.46 | Q24: =P24+R24 -> -0.389 | R24: =RANDBETWEEN(-30,90)/1000 -> 0.071 | T24: 17
A25: 5 | B25: 41 | C25: =+C24+T24 -> 729.78 | D25: =+Chạy!F46 -> -6.41 | E25: =+D25+F25 -> -6.4123 | F25: =RANDBETWEEN(-105,115)/10000 -> -0.0023 | G25: =+Chạy!G46 -> -0.46 | H25: =G25+I25 -> -0.403 | I25: =RANDBETWEEN(-30,90)/1000 -> 0.057 | J25: =+Chạy!K46 -> -0.34 | K25: =J25+L25 -> -0.265 | L25: =RANDBETWEEN(-30,90)/1000 -> 0.075 | M25: =+Chạy!N46 -> 6.41 | N25: =+M25+O25 -> 6.4179 | O25: =RANDBETWEEN(-105,115)/10000 -> 0.0079 | P25: =+Chạy!O46 -> -0.46 | Q25: =P25+R25 -> -0.391 | R25: =RANDBETWEEN(-30,90)/1000 -> 0.069 | T25: 17.04
A26: 6 | B26: 42 | C26: =+C25+T25 -> 746.82 | D26: =+Chạy!F55 -> -6.85 | E26: =+D26+F26 -> -6.8534 | F26: =RANDBETWEEN(-105,115)/10000 -> -0.0034 | G26: =+Chạy!G55 -> -0.46 | H26: =G26+I26 -> -0.423 | I26: =RANDBETWEEN(-30,90)/1000 -> 0.037 | J26: =+Chạy!K55 -> -0.34 | K26: =J26+L26 -> -0.364 | L26: =RANDBETWEEN(-30,90)/1000 -> -0.024 | M26: =+Chạy!N55 -> 8.01 | N26: =+M26+O26 -> 8.0184 | O26: =RANDBETWEEN(-105,115)/10000 -> 0.0084 | P26: =+Chạy!O55 -> -0.46 | Q26: =P26+R26 -> -0.453 | R26: =RANDBETWEEN(-30,90)/1000 -> 0.007
C62: NHÀ THẦU THI CÔNG | O62: TƯ VẤN GIÁM SÁT
C67: Nguyễn Xuân Hưng | O67: Trần Mạnh Tùng

Sheet 1.KL L1
A1: PHỤ LỤC KHỐI LƯỢNG
A2: ="Kèm theo BBNT số: "&VLOOKUP(AZ2,'[1]Tuyến XD4'!$A$2:$G$60,7,0)&VLOOKUP(AZ2,'[1]Tuyến XD4'!$A$2:$G$60,4,0) -> Kèm theo BBNT số: 64.NĐXD4/CVXD ngày 16 tháng 09 năm 2026 | AZ2: 64
A3: Dự án: Xây dựng HTKT Khu tái định cư phục vụ di dân xã Hải Hà, thị xã Nghi Sơn, tỉnh Thanh Hóa.
A4: Gói thầu số 12: Xây dựng HTKT khu vực Hải Bình và Xuân Lâm (bao gồm cả bảo hiểm xây dựng công trình)
A5: Nhà thầu thi công: Công ty TNHH Hoàng Tuấn
A6: Hạng mục: Nền đường tuyến XD4
A7: - Đối tượng nghiệm thu: | D7: =VLOOKUP(AZ2,'[1]Tuyến XD4'!$A$2:$B$60,2,0) -> Đắp đất nền đường lớp 1 đoạn từ Km0+672,28 - Km0+746,82, độ chặt K>=0,95
A9: STT | B9: Tên cọc | C9: Lý trình | D9: K/c lẻ | M9: Khối lượng đắp đất | AB9: Ghi chú
N10: Diện tích | O10: Diện tích (m2) | P10: Diện tích | Q10: Diện tích | U10: Khối lượng | V10: Khối lượng | W10: Khối lượng (m3) | X10: Khối lượng | Y10: Khối lượng
A11: 1 | B11: ='1.KTHH L1'!B21 -> 38 | C11: ='1.KTHH L1'!C21 -> 672.28 | D11: ='1.KTHH L1'!T21 -> 17 | O11: =Chạy!E10 -> 4.71 | W11: =(O11+O12)*D11/2 -> 69.7
A12: 2 | B12: ='1.KTHH L1'!B22 -> 39 | C12: ='1.KTHH L1'!C22 -> 689.28 | D12: ='1.KTHH L1'!T22 -> 11.75 | O12: =Chạy!E19 -> 3.49 | W12: =(O12+O13)*D12/2 -> 20.50375
A13: 3 | B13: ='1.KTHH L1'!B23 -> F2 | C13: ='1.KTHH L1'!C23 -> 701.03 | D13: ='1.KTHH L1'!T23 -> 11.75 | W13: =(O13+O14)*D13/2 -> 20.68
A14: 4 | B14: ='1.KTHH L1'!B24 -> 40 | C14: ='1.KTHH L1'!C24 -> 712.78 | D14: ='1.KTHH L1'!T24 -> 17 | O14: =Chạy!E37 -> 3.52 | W14: =(O14+O15)*D14/2 -> 53.21
A15: 5 | B15: ='1.KTHH L1'!B25 -> 41 | C15: ='1.KTHH L1'!C25 -> 729.78 | D15: ='1.KTHH L1'!T25 -> 17.04 | O15: =Chạy!E46 -> 2.74 | W15: =(O15+O16)*D15/2 -> 49.5012
A16: 6 | B16: ='1.KTHH L1'!B26 -> 42 | C16: ='1.KTHH L1'!C26 -> 746.82 | O16: =Chạy!E55 -> 3.07
A51: Tổng cộng (m3) | R51: =SUM(R11:R50) -> 0 | S51: =SUM(S11:S50) -> 0 | U51: =SUM(U11:U50) -> 0 | V51: =SUM(V11:V50) -> 0 | W51: =SUM(W11:W16) -> 213.59495 | X51: =SUM(X11:X50) -> 0 | Y51: =SUM(Y11:Y50) -> 0 | Z51: =SUM(Z11:Z50) -> 0 | AA51: =SUM(AA11:AA50) -> 0
A53: NHÀ THẦU THI CÔNG | E53: TƯ VẤN GIÁM SÁT
A59: Nguyễn Xuân Hưng | M59: Trần Mạnh Tùng

Sheet 2.KTHH L2
A1: PHỤ LỤC KIỂM TRA CAO ĐỘ, KÍCH THƯỚC HÌNH HỌC
A2: ="Kèm theo BBNT số: "&VLOOKUP(AZ2,'[1]Tuyến XD4'!$A$2:$G$60,7,0)&VLOOKUP(AZ2,'[1]Tuyến XD4'!$A$2:$G$60,4,0) -> Kèm theo BBNT số: 65.NĐXD4/CVXD ngày 17 tháng 09 năm 2026 | AZ2: 65
A3: ='1.KTHH L1'!A3 -> Dự án: Xây dựng HTKT Khu tái định cư phục vụ di dân xã Hải Hà, thị xã Nghi Sơn, tỉnh Thanh Hóa.
A4: ='1.KTHH L1'!A4 -> Gói thầu số 12: Xây dựng HTKT khu vực Hải Bình và Xuân Lâm (bao gồm cả bảo hiểm xây dựng công trình)
A5: ='1.KTHH L1'!A5 -> Nhà thầu thi công: Công ty TNHH Hoàng Tuấn
A6: Hạng mục: Nền đường tuyến XD4
A7: - Đối tượng nghiệm thu: | G7: =VLOOKUP(AZ2,'[1]Tuyến XD4'!$A$2:$B$60,2,0) -> Đắp đất nền đường lớp 2 đoạn từ Km0+672,28 - Km0+746,82, độ chặt K>=0,95
A8: Sơ họa:
A19: TT | B19: Tên cọc | C19: Lý trình | D19: Bên trái (H1) | J19: Tim (H2) | M19: Bên phải (H3) | S19: Ghi chú
D20: KCTK | E20: KCTC | F20: Chênh KC (m) | G20: CDTK (m) | H20: CDTC (m) | I20: Chênh CD (m) | J20: CDTK (m) | K20: CDTC (m) | L20: Chênh CD (m) | M20: KCTK | N20: KCTC | O20: Chênh KC (m) | P20: CDTK (m) | Q20: CDTC (m) | R20: Chênh CD (m)
A21: 1 | B21: 38 | C21: 672.28 | D21: =+Chạy!F9 -> -10.24 | E21: =+D21+F21 -> -10.2362 | F21: =RANDBETWEEN(-105,115)/10000 -> 0.0038 | G21: =+Chạy!G9 -> -0.16 | H21: =G21+I21 -> -0.142 | I21: =RANDBETWEEN(-30,90)/1000 -> 0.018 | J21: =+Chạy!K9 -> -0.04 | K21: =J21+L21 -> -0.035 | L21: =RANDBETWEEN(-30,90)/1000 -> 0.005 | M21: =+Chạy!N9 -> 15.1 | N21: =+M21+O21 -> 15.1092 | O21: =RANDBETWEEN(-105,115)/10000 -> 0.0092 | P21: =+Chạy!O9 -> -0.16 | Q21: =P21+R21 -> -0.073 | R21: =RANDBETWEEN(-30,90)/1000 -> 0.087 | T21: 17
A22: 2 | B22: 39 | C22: =+C21+T21 -> 689.28 | D22: =+Chạy!F18 -> -9.5 | E22: =+D22+F22 -> -9.5013 | F22: =RANDBETWEEN(-105,115)/10000 -> -0.0013 | G22: =+Chạy!G18 -> -0.16 | H22: =G22+I22 -> -0.114 | I22: =RANDBETWEEN(-30,90)/1000 -> 0.046 | J22: =+Chạy!K18 -> -0.04 | K22: =J22+L22 -> 0.007 | L22: =RANDBETWEEN(-30,90)/1000 -> 0.047 | M22: =+Chạy!N18 -> 8.74 | N22: =+M22+O22 -> 8.7424 | O22: =RANDBETWEEN(-105,115)/10000 -> 0.0024 | P22: =+Chạy!O18 -> -0.16 | Q22: =P22+R22 -> -0.19 | R22: =RANDBETWEEN(-30,90)/1000 -> -0.03 | T22: 11.75
A23: 3 | B23: F2 | C23: =+C22+T22 -> 701.03 | T23: 11.75
A24: 4 | B24: 40 | C24: =+C23+T23 -> 712.78 | D24: =+Chạy!F36 -> -9.64 | E24: =+D24+F24 -> -9.6411 | F24: =RANDBETWEEN(-105,115)/10000 -> -0.0011 | G24: =+Chạy!G36 -> -0.16 | H24: =G24+I24 -> -0.152 | I24: =RANDBETWEEN(-30,90)/1000 -> 0.008 | J24: =+Chạy!K36 -> -0.04 | K24: =J24+L24 -> -0.016 | L24: =RANDBETWEEN(-30,90)/1000 -> 0.024 | M24: =+Chạy!N36 -> 8.6 | N24: =+M24+O24 -> 8.606 | O24: =RANDBETWEEN(-105,115)/10000 -> 0.006 | P24: =+Chạy!O36 -> -0.16 | Q24: =P24+R24 -> -0.111 | R24: =RANDBETWEEN(-30,90)/1000 -> 0.049 | T24: 17
A25: 5 | B25: 41 | C25: =+C24+T24 -> 729.78 | D25: =+Chạy!F45 -> -6.71 | E25: =+D25+F25 -> -6.7085 | F25: =RANDBETWEEN(-105,115)/10000 -> 0.0015 | G25: =+Chạy!G45 -> -0.16 | H25: =G25+I25 -> -0.084 | I25: =RANDBETWEEN(-30,90)/1000 -> 0.076 | J25: =+Chạy!K45 -> -0.04 | K25: =J25+L25 -> 0.015 | L25: =RANDBETWEEN(-30,90)/1000 -> 0.055 | M25: =+Chạy!N45 -> 6.71 | N25: =+M25+O25 -> 6.7092 | O25: =RANDBETWEEN(-105,115)/10000 -> -0.0008 | P25: =+Chạy!O45 -> -0.16 | Q25: =P25+R25 -> -0.123 | R25: =RANDBETWEEN(-30,90)/1000 -> 0.037 | T25: 17.04
A26: 6 | B26: 42 | C26: =+C25+T25 -> 746.82 | D26: =+Chạy!F54 -> -7.15 | E26: =+D26+F26 -> -7.142 | F26: =RANDBETWEEN(-105,115)/10000 -> 0.008 | G26: =+Chạy!G54 -> -0.16 | H26: =G26+I26 -> -0.143 | I26: =RANDBETWEEN(-30,90)/1000 -> 0.017 | J26: =+Chạy!K54 -> -0.04 | K26: =J26+L26 -> 0.012 | L26: =RANDBETWEEN(-30,90)/1000 -> 0.052 | M26: =+Chạy!N54 -> 8.31 | N26: =+M26+O26 -> 8.3017 | O26: =RANDBETWEEN(-105,115)/10000 -> -0.0083 | P26: =+Chạy!O54 -> -0.16 | Q26: =P26+R26 -> -0.074 | R26: =RANDBETWEEN(-30,90)/1000 -> 0.086
C62: NHÀ THẦU THI CÔNG | O62: TƯ VẤN GIÁM SÁT
C67: Nguyễn Xuân Hưng | O67: Trần Mạnh Tùng

Sheet 2.KL L2
A1: PHỤ LỤC KHỐI LƯỢNG
A2: ="Kèm theo BBNT số: "&VLOOKUP(AZ2,'[1]Tuyến XD4'!$A$2:$G$60,7,0)&VLOOKUP(AZ2,'[1]Tuyến XD4'!$A$2:$G$60,4,0) -> Kèm theo BBNT số: 65.NĐXD4/CVXD ngày 17 tháng 09 năm 2026 | AZ2: 65
A3: ='1.KTHH L1'!A3 -> Dự án: Xây dựng HTKT Khu tái định cư phục vụ di dân xã Hải Hà, thị xã Nghi Sơn, tỉnh Thanh Hóa.
A4: ='1.KTHH L1'!A4 -> Gói thầu số 12: Xây dựng HTKT khu vực Hải Bình và Xuân Lâm (bao gồm cả bảo hiểm xây dựng công trình)
A5: ='1.KTHH L1'!A5 -> Nhà thầu thi công: Công ty TNHH Hoàng Tuấn
A6: Hạng mục: Nền đường tuyến XD4
A7: - Đối tượng nghiệm thu: | D7: =VLOOKUP(AZ2,'[1]Tuyến XD4'!$A$2:$B$60,2,0) -> Đắp đất nền đường lớp 2 đoạn từ Km0+672,28 - Km0+746,82, độ chặt K>=0,95
A9: STT | B9: Tên cọc | C9: Lý trình | D9: K/c lẻ | M9: Khối lượng đắp đất | AB9: Ghi chú
N10: Diện tích | O10: Diện tích (m2) | P10: Diện tích | Q10: Diện tích | U10: Khối lượng | V10: Khối lượng | W10: Khối lượng (m3) | X10: Khối lượng | Y10: Khối lượng
A11: 1 | B11: ='2.KTHH L2'!B21 -> 38 | C11: ='2.KTHH L2'!C21 -> 672.28 | D11: ='2.KTHH L2'!T21 -> 17 | O11: =Chạy!E9 -> 7.62 | W11: =(O11+O12)*D11/2 -> 110.5
A12: 2 | B12: ='2.KTHH L2'!B22 -> 39 | C12: ='2.KTHH L2'!C22 -> 689.28 | D12: ='2.KTHH L2'!T22 -> 11.75 | O12: =Chạy!E18 -> 5.38 | W12: =(O12+O13)*D12/2 -> 31.6075
A13: 3 | B13: ='2.KTHH L2'!B23 -> F2 | C13: ='2.KTHH L2'!C23 -> 701.03 | D13: ='2.KTHH L2'!T23 -> 11.75 | W13: =(O13+O14)*D13/2 -> 31.6075
A14: 4 | B14: ='2.KTHH L2'!B24 -> 40 | C14: ='2.KTHH L2'!C24 -> 712.78 | D14: ='2.KTHH L2'!T24 -> 17 | O14: =Chạy!E36 -> 5.38 | W14: =(O14+O15)*D14/2 -> 79.22
A15: 5 | B15: ='2.KTHH L2'!B25 -> 41 | C15: ='2.KTHH L2'!C25 -> 729.78 | D15: ='2.KTHH L2'!T25 -> 17.04 | O15: =Chạy!E45 -> 3.94 | W15: =(O15+O16)*D15/2 -> 72.3348
A16: 6 | B16: ='2.KTHH L2'!B26 -> 42 | C16: ='2.KTHH L2'!C26 -> 746.82 | O16: =Chạy!E54 -> 4.55
A51: Tổng cộng (m3) | R51: =SUM(R11:R50) -> 0 | S51: =SUM(S11:S50) -> 0 | U51: =SUM(U11:U50) -> 0 | V51: =SUM(V11:V50) -> 0 | W51: =SUM(W11:W16) -> 325.2698 | X51: =SUM(X11:X50) -> 0 | Y51: =SUM(Y11:Y50) -> 0 | Z51: =SUM(Z11:Z50) -> 0 | AA51: =SUM(AA11:AA50) -> 0
A53: NHÀ THẦU THI CÔNG | E53: TƯ VẤN GIÁM SÁT
A59: Nguyễn Xuân Hưng | M59: Trần Mạnh Tùng

Sheet 3.KTHH L3
A1: PHỤ LỤC KIỂM TRA CAO ĐỘ, KÍCH THƯỚC HÌNH HỌC
A2: ="Kèm theo BBNT số: "&VLOOKUP(AZ2,'[1]Tuyến XD4'!$A$2:$G$60,7,0)&VLOOKUP(AZ2,'[1]Tuyến XD4'!$A$2:$G$60,4,0) -> Kèm theo BBNT số: 66.NĐXD4/CVXD ngày 17 tháng 09 năm 2026 | AZ2: 66
A3: ='1.KTHH L1'!A3 -> Dự án: Xây dựng HTKT Khu tái định cư phục vụ di dân xã Hải Hà, thị xã Nghi Sơn, tỉnh Thanh Hóa.
A4: ='1.KTHH L1'!A4 -> Gói thầu số 12: Xây dựng HTKT khu vực Hải Bình và Xuân Lâm (bao gồm cả bảo hiểm xây dựng công trình)
A5: ='1.KTHH L1'!A5 -> Nhà thầu thi công: Công ty TNHH Hoàng Tuấn
A6: Hạng mục: Nền đường tuyến XD4
A7: - Đối tượng nghiệm thu: | G7: =VLOOKUP(AZ2,'[1]Tuyến XD4'!$A$2:$B$60,2,0) -> Đắp đất nền đường lớp 3 đoạn từ Km0+672,28 - Km0+746,82, độ chặt K>=0,95
A8: Sơ họa:
A20: TT | B20: Tên cọc | C20: Lý trình | D20: Bên trái (H1) | J20: Tim (H2) | M20: Bên phải (H3) | S20: Ghi chú
D21: KCTK | E21: KCTC | F21: Chênh KC (m) | G21: CDTK (m) | H21: CDTC (m) | I21: Chênh CD (m) | J21: CDTK (m) | K21: CDTC (m) | L21: Chênh CD (m) | M21: KCTK | N21: KCTC | O21: Chênh KC (m) | P21: CDTK (m) | Q21: CDTC (m) | R21: Chênh CD (m)
A22: 1 | B22: 38 | C22: 672.28 | D22: =+Chạy!F8 -> -10.54 | E22: =+D22+F22 -> -10.5288 | F22: =RANDBETWEEN(-105,115)/10000 -> 0.0112 | G22: =+Chạy!G8 -> 0.14 | H22: =G22+I22 -> 0.213 | I22: =RANDBETWEEN(-30,90)/1000 -> 0.073 | J22: =+Chạy!K8 -> 0.26 | K22: =J22+L22 -> 0.323 | L22: =RANDBETWEEN(-30,90)/1000 -> 0.063 | M22: =+Chạy!N8 -> 14.65 | N22: =+M22+O22 -> 14.6401 | O22: =RANDBETWEEN(-105,115)/10000 -> -0.0099 | P22: =+Chạy!O8 -> 0.14 | Q22: =P22+R22 -> 0.178 | R22: =RANDBETWEEN(-30,90)/1000 -> 0.038 | T22: 17
A23: 2 | B23: 39 | C23: =+C22+T22 -> 689.28 | D23: =+Chạy!F17 -> -9.8 | E23: =+D23+F23 -> -9.8081 | F23: =RANDBETWEEN(-105,115)/10000 -> -0.0081 | G23: =+Chạy!G17 -> 0.14 | H23: =G23+I23 -> 0.22 | I23: =RANDBETWEEN(-30,90)/1000 -> 0.08 | J23: =+Chạy!K17 -> 0.26 | K23: =J23+L23 -> 0.272 | L23: =RANDBETWEEN(-30,90)/1000 -> 0.012 | M23: =+Chạy!N17 -> 9.04 | N23: =+M23+O23 -> 9.0364 | O23: =RANDBETWEEN(-105,115)/10000 -> -0.0036 | P23: =+Chạy!O17 -> 0.14 | Q23: =P23+R23 -> 0.195 | R23: =RANDBETWEEN(-30,90)/1000 -> 0.055 | T23: 11.75
A24: 3 | B24: F2 | C24: =+C23+T23 -> 701.03 | T24: 11.75
A25: 4 | B25: 40 | C25: =+C24+T24 -> 712.78 | D25: =+Chạy!F35 -> -9.94 | E25: =+D25+F25 -> -9.9398 | F25: =RANDBETWEEN(-105,115)/10000 -> 0.0002 | G25: =+Chạy!G35 -> 0.14 | H25: =G25+I25 -> 0.2 | I25: =RANDBETWEEN(-30,90)/1000 -> 0.06 | J25: =+Chạy!K35 -> 0.26 | K25: =J25+L25 -> 0.231 | L25: =RANDBETWEEN(-30,90)/1000 -> -0.029 | M25: =+Chạy!N35 -> 8.9 | N25: =+M25+O25 -> 8.91 | O25: =RANDBETWEEN(-105,115)/10000 -> 0.01 | P25: =+Chạy!O35 -> 0.14 | Q25: =P25+R25 -> 0.164 | R25: =RANDBETWEEN(-30,90)/1000 -> 0.024 | T25: 17
A26: 5 | B26: 41 | C26: =+C25+T25 -> 729.78 | D26: =+Chạy!F44 -> -7.01 | E26: =+D26+F26 -> -7.0048 | F26: =RANDBETWEEN(-105,115)/10000 -> 0.0052 | G26: =+Chạy!G44 -> 0.14 | H26: =G26+I26 -> 0.158 | I26: =RANDBETWEEN(-30,90)/1000 -> 0.018 | J26: =+Chạy!K44 -> 0.26 | K26: =J26+L26 -> 0.329 | L26: =RANDBETWEEN(-30,90)/1000 -> 0.069 | M26: =+Chạy!N44 -> 7.01 | N26: =+M26+O26 -> 7.018 | O26: =RANDBETWEEN(-105,115)/10000 -> 0.008 | P26: =+Chạy!O44 -> 0.14 | Q26: =P26+R26 -> 0.21 | R26: =RANDBETWEEN(-30,90)/1000 -> 0.07 | T26: 17.04
A27: 6 | B27: 42 | C27: =+C26+T26 -> 746.82 | D27: =+Chạy!F53 -> -7.45 | E27: =+D27+F27 -> -7.4392 | F27: =RANDBETWEEN(-105,115)/10000 -> 0.0108 | G27: =+Chạy!G53 -> 0.14 | H27: =G27+I27 -> 0.146 | I27: =RANDBETWEEN(-30,90)/1000 -> 0.006 | J27: =+Chạy!K53 -> 0.26 | K27: =J27+L27 -> 0.33 | L27: =RANDBETWEEN(-30,90)/1000 -> 0.07 | M27: =+Chạy!N53 -> 8.61 | N27: =+M27+O27 -> 8.613 | O27: =RANDBETWEEN(-105,115)/10000 -> 0.003 | P27: =+Chạy!O53 -> 0.14 | Q27: =P27+R27 -> 0.184 | R27: =RANDBETWEEN(-30,90)/1000 -> 0.044
C63: NHÀ THẦU THI CÔNG | O63: TƯ VẤN GIÁM SÁT
C68: Nguyễn Xuân Hưng | O68: Trần Mạnh Tùng

Sheet 3.KL L3
A1: PHỤ LỤC KHỐI LƯỢNG
A2: ="Kèm theo BBNT số: "&VLOOKUP(AZ2,'[1]Tuyến XD4'!$A$2:$G$60,7,0)&VLOOKUP(AZ2,'[1]Tuyến XD4'!$A$2:$G$60,4,0) -> Kèm theo BBNT số: 66.NĐXD4/CVXD ngày 17 tháng 09 năm 2026 | AZ2: 66
A3: ='1.KTHH L1'!A3 -> Dự án: Xây dựng HTKT Khu tái định cư phục vụ di dân xã Hải Hà, thị xã Nghi Sơn, tỉnh Thanh Hóa.
A4: ='1.KTHH L1'!A4 -> Gói thầu số 12: Xây dựng HTKT khu vực Hải Bình và Xuân Lâm (bao gồm cả bảo hiểm xây dựng công trình)
A5: ='1.KTHH L1'!A5 -> Nhà thầu thi công: Công ty TNHH Hoàng Tuấn
A6: Hạng mục: Nền đường tuyến XD4
A7: - Đối tượng nghiệm thu: | D7: =VLOOKUP(AZ2,'[1]Tuyến XD4'!$A$2:$B$60,2,0) -> Đắp đất nền đường lớp 3 đoạn từ Km0+672,28 - Km0+746,82, độ chặt K>=0,95
A9: STT | B9: Tên cọc | C9: Lý trình | D9: K/c lẻ | M9: Khối lượng đắp đất | AB9: Ghi chú
N10: Diện tích | O10: Diện tích (m2) | P10: Diện tích | Q10: Diện tích | U10: Khối lượng | V10: Khối lượng | W10: Khối lượng (m3) | X10: Khối lượng | Y10: Khối lượng
A11: 1 | B11: ='3.KTHH L3'!B22 -> 38 | C11: ='3.KTHH L3'!C22 -> 672.28 | D11: ='3.KTHH L3'!T22 -> 17 | O11: =Chạy!E8 -> 7.58 | W11: =(O11+O12)*D11/2 -> 111.69
A12: 2 | B12: ='3.KTHH L3'!B23 -> 39 | C12: ='3.KTHH L3'!C23 -> 689.28 | D12: ='3.KTHH L3'!T23 -> 11.75 | O12: =Chạy!E17 -> 5.56 | W12: =(O12+O13)*D12/2 -> 32.665
A13: 3 | B13: ='3.KTHH L3'!B24 -> F2 | C13: ='3.KTHH L3'!C24 -> 701.03 | D13: ='3.KTHH L3'!T24 -> 11.75 | W13: =(O13+O14)*D13/2 -> 32.665
A14: 4 | B14: ='3.KTHH L3'!B25 -> 40 | C14: ='3.KTHH L3'!C25 -> 712.78 | D14: ='3.KTHH L3'!T25 -> 17 | O14: =Chạy!E35 -> 5.56 | W14: =(O14+O15)*D14/2 -> 82.28
A15: 5 | B15: ='3.KTHH L3'!B26 -> 41 | C15: ='3.KTHH L3'!C26 -> 729.78 | D15: ='3.KTHH L3'!T26 -> 17.04 | O15: =Chạy!E44 -> 4.12 | W15: =(O15+O16)*D15/2 -> 75.402
A16: 6 | B16: ='3.KTHH L3'!B27 -> 42 | C16: ='3.KTHH L3'!C27 -> 746.82 | O16: =Chạy!E53 -> 4.73
A51: Tổng cộng (m3) | R51: =SUM(R11:R50) -> 0 | S51: =SUM(S11:S50) -> 0 | U51: =SUM(U11:U50) -> 0 | V51: =SUM(V11:V50) -> 0 | W51: =SUM(W11:W16) -> 334.702 | X51: =SUM(X11:X50) -> 0 | Y51: =SUM(Y11:Y50) -> 0 | Z51: =SUM(Z11:Z50) -> 0 | AA51: =SUM(AA11:AA50) -> 0
A53: NHÀ THẦU THI CÔNG | E53: TƯ VẤN GIÁM SÁT
A59: Nguyễn Xuân Hưng | M59: Trần Mạnh Tùng

Sheet 4.KTHH L4
A1: PHỤ LỤC KIỂM TRA CAO ĐỘ, KÍCH THƯỚC HÌNH HỌC
A2: ="Kèm theo BBNT số: "&VLOOKUP(AZ2,'[1]Tuyến XD4'!$A$2:$G$60,7,0)&VLOOKUP(AZ2,'[1]Tuyến XD4'!$A$2:$G$60,4,0) -> Kèm theo BBNT số: 67.NĐXD4/CVXD ngày 18 tháng 09 năm 2026 | AZ2: 67
A3: ='1.KTHH L1'!A3 -> Dự án: Xây dựng HTKT Khu tái định cư phục vụ di dân xã Hải Hà, thị xã Nghi Sơn, tỉnh Thanh Hóa.
A4: ='1.KTHH L1'!A4 -> Gói thầu số 12: Xây dựng HTKT khu vực Hải Bình và Xuân Lâm (bao gồm cả bảo hiểm xây dựng công trình)
A5: ='1.KTHH L1'!A5 -> Nhà thầu thi công: Công ty TNHH Hoàng Tuấn
A6: Hạng mục: Nền đường tuyến XD4
A7: - Đối tượng nghiệm thu: | G7: =VLOOKUP(AZ2,'[1]Tuyến XD4'!$A$2:$B$60,2,0) -> Đắp đất nền đường lớp 4 đoạn từ Km0+672,28 - Km0+746,82, độ chặt K>=0,95
A8: Sơ họa:
A20: TT | B20: Tên cọc | C20: Lý trình | D20: Bên trái (H1) | J20: Tim (H2) | M20: Bên phải (H3) | S20: Ghi chú
D21: KCTK | E21: KCTC | F21: Chênh KC (m) | G21: CDTK (m) | H21: CDTC (m) | I21: Chênh CD (m) | J21: CDTK (m) | K21: CDTC (m) | L21: Chênh CD (m) | M21: KCTK | N21: KCTC | O21: Chênh KC (m) | P21: CDTK (m) | Q21: CDTC (m) | R21: Chênh CD (m)
A22: 1 | B22: 38 | C22: 672.28 | D22: =+Chạy!F7 -> -10.84 | E22: =+D22+F22 -> -10.8409 | F22: =RANDBETWEEN(-105,115)/10000 -> -0.0009 | G22: =+Chạy!G7 -> 0.44 | H22: =G22+I22 -> 0.44 | I22: =RANDBETWEEN(-30,90)/1000 -> 0 | J22: =+Chạy!K7 -> 0.56 | K22: =J22+L22 -> 0.562 | L22: =RANDBETWEEN(-30,90)/1000 -> 0.002 | M22: =+Chạy!N7 -> 14.2 | N22: =+M22+O22 -> 14.2016 | O22: =RANDBETWEEN(-105,115)/10000 -> 0.0016 | P22: =+Chạy!O7 -> 0.44 | Q22: =P22+R22 -> 0.478 | R22: =RANDBETWEEN(-30,90)/1000 -> 0.038 | T22: 17
A23: 2 | B23: 39 | C23: =+C22+T22 -> 689.28 | D23: =+Chạy!F16 -> -11.46 | E23: =+D23+F23 -> -11.4545 | F23: =RANDBETWEEN(-105,115)/10000 -> 0.0055 | G23: =+Chạy!G16 -> 0.44 | H23: =G23+I23 -> 0.415 | I23: =RANDBETWEEN(-30,90)/1000 -> -0.025 | J23: =+Chạy!K16 -> 0.56 | K23: =J23+L23 -> 0.536 | L23: =RANDBETWEEN(-30,90)/1000 -> -0.024 | M23: =+Chạy!N16 -> 9.34 | N23: =+M23+O23 -> 9.342 | O23: =RANDBETWEEN(-105,115)/10000 -> 0.002 | P23: =+Chạy!O16 -> 0.44 | Q23: =P23+R23 -> 0.459 | R23: =RANDBETWEEN(-30,90)/1000 -> 0.019 | T23: 11.75
A24: 3 | B24: F2 | C24: =+C23+T23 -> 701.03 | D24: =+Chạy!F25 -> -11.25 | E24: =+D24+F24 -> -11.2412 | F24: =RANDBETWEEN(-105,115)/10000 -> 0.0088 | G24: =+Chạy!G25 -> 0.44 | H24: =G24+I24 -> 0.417 | I24: =RANDBETWEEN(-30,90)/1000 -> -0.023 | J24: =+Chạy!K25 -> 0.56 | K24: =J24+L24 -> 0.65 | L24: =RANDBETWEEN(-30,90)/1000 -> 0.09 | M24: =+Chạy!N25 -> -1.84 | N24: =+M24+O24 -> -1.8388 | O24: =RANDBETWEEN(-105,115)/10000 -> 0.0012 | P24: =+Chạy!O25 -> 0.52 | Q24: =P24+R24 -> 0.537 | R24: =RANDBETWEEN(-30,90)/1000 -> 0.017 | T24: 11.75
A25: 4 | B25: 40 | C25: =+C24+T24 -> 712.78 | D25: =+Chạy!F34 -> -11.49 | E25: =+D25+F25 -> -11.4885 | F25: =RANDBETWEEN(-105,115)/10000 -> 0.0015 | G25: =+Chạy!G34 -> 0.44 | H25: =G25+I25 -> 0.52 | I25: =RANDBETWEEN(-30,90)/1000 -> 0.08 | J25: =+Chạy!K34 -> 0.56 | K25: =J25+L25 -> 0.636 | L25: =RANDBETWEEN(-30,90)/1000 -> 0.076 | M25: =+Chạy!N34 -> 9.2 | N25: =+M25+O25 -> 9.1945 | O25: =RANDBETWEEN(-105,115)/10000 -> -0.0055 | P25: =+Chạy!O34 -> 0.44 | Q25: =P25+R25 -> 0.429 | R25: =RANDBETWEEN(-30,90)/1000 -> -0.011 | T25: 17
A26: 5 | B26: 41 | C26: =+C25+T25 -> 729.78 | D26: =+Chạy!F43 -> -7.31 | E26: =+D26+F26 -> -7.3124 | F26: =RANDBETWEEN(-105,115)/10000 -> -0.0024 | G26: =+Chạy!G43 -> 0.44 | H26: =G26+I26 -> 0.5 | I26: =RANDBETWEEN(-30,90)/1000 -> 0.06 | J26: =+Chạy!K43 -> 0.56 | K26: =J26+L26 -> 0.623 | L26: =RANDBETWEEN(-30,90)/1000 -> 0.063 | M26: =+Chạy!N43 -> 7.31 | N26: =+M26+O26 -> 7.3016 | O26: =RANDBETWEEN(-105,115)/10000 -> -0.0084 | P26: =+Chạy!O43 -> 0.44 | Q26: =P26+R26 -> 0.476 | R26: =RANDBETWEEN(-30,90)/1000 -> 0.036 | T26: 17.04
A27: 6 | B27: 42 | C27: =+C26+T26 -> 746.82 | D27: =+Chạy!F52 -> -7.75 | E27: =+D27+F27 -> -7.7521 | F27: =RANDBETWEEN(-105,115)/10000 -> -0.0021 | G27: =+Chạy!G52 -> 0.44 | H27: =G27+I27 -> 0.484 | I27: =RANDBETWEEN(-30,90)/1000 -> 0.044 | J27: =+Chạy!K52 -> 0.56 | K27: =J27+L27 -> 0.614 | L27: =RANDBETWEEN(-30,90)/1000 -> 0.054 | M27: =+Chạy!N52 -> 8.91 | N27: =+M27+O27 -> 8.9125 | O27: =RANDBETWEEN(-105,115)/10000 -> 0.0025 | P27: =+Chạy!O52 -> 0.44 | Q27: =P27+R27 -> 0.464 | R27: =RANDBETWEEN(-30,90)/1000 -> 0.024
C63: NHÀ THẦU THI CÔNG | O63: TƯ VẤN GIÁM SÁT
C68: Nguyễn Xuân Hưng | O68: Trần Mạnh Tùng

Sheet 4.KL L4
A1: PHỤ LỤC KHỐI LƯỢNG
A2: ="Kèm theo BBNT số: "&VLOOKUP(AZ2,'[1]Tuyến XD4'!$A$2:$G$60,7,0)&VLOOKUP(AZ2,'[1]Tuyến XD4'!$A$2:$G$60,4,0) -> Kèm theo BBNT số: 67.NĐXD4/CVXD ngày 18 tháng 09 năm 2026 | AZ2: 67
A3: ='1.KTHH L1'!A3 -> Dự án: Xây dựng HTKT Khu tái định cư phục vụ di dân xã Hải Hà, thị xã Nghi Sơn, tỉnh Thanh Hóa.
A4: ='1.KTHH L1'!A4 -> Gói thầu số 12: Xây dựng HTKT khu vực Hải Bình và Xuân Lâm (bao gồm cả bảo hiểm xây dựng công trình)
A5: ='1.KTHH L1'!A5 -> Nhà thầu thi công: Công ty TNHH Hoàng Tuấn
A6: Hạng mục: Nền đường tuyến XD4
A7: - Đối tượng nghiệm thu: | D7: =VLOOKUP(AZ2,'[1]Tuyến XD4'!$A$2:$B$60,2,0) -> Đắp đất nền đường lớp 4 đoạn từ Km0+672,28 - Km0+746,82, độ chặt K>=0,95
A9: STT | B9: Tên cọc | C9: Lý trình | D9: K/c lẻ | M9: Khối lượng đắp đất | AB9: Ghi chú
N10: Diện tích | O10: Diện tích (m2) | P10: Diện tích | Q10: Diện tích | U10: Khối lượng | V10: Khối lượng | W10: Khối lượng (m3) | X10: Khối lượng | Y10: Khối lượng
A11: 1 | B11: ='4.KTHH L4'!B22 -> 38 | C11: ='4.KTHH L4'!C22 -> 672.28 | D11: ='4.KTHH L4'!T22 -> 17 | O11: =Chạy!E7 -> 7.53 | W11: =(O11+O12)*D11/2 -> 115.6
A12: 2 | B12: ='4.KTHH L4'!B23 -> 39 | C12: ='4.KTHH L4'!C23 -> 689.28 | D12: ='4.KTHH L4'!T23 -> 11.75 | O12: =Chạy!E16 -> 6.07 | W12: =(O12+O13)*D12/2 -> 47.47
A13: 3 | B13: ='4.KTHH L4'!B24 -> F2 | C13: ='4.KTHH L4'!C24 -> 701.03 | D13: ='4.KTHH L4'!T24 -> 11.75 | O13: =Chạy!E25 -> 2.01 | W13: =(O13+O14)*D13/2 -> 47.705
A14: 4 | B14: ='4.KTHH L4'!B25 -> 40 | C14: ='4.KTHH L4'!C25 -> 712.78 | D14: ='4.KTHH L4'!T25 -> 17 | O14: =Chạy!E34 -> 6.11 | W14: =(O14+O15)*D14/2 -> 88.485
A15: 5 | B15: ='4.KTHH L4'!B26 -> 41 | C15: ='4.KTHH L4'!C26 -> 729.78 | D15: ='4.KTHH L4'!T26 -> 17.04 | O15: =Chạy!E43 -> 4.3 | W15: =(O15+O16)*D15/2 -> 78.4692
A16: 6 | B16: ='4.KTHH L4'!B27 -> 42 | C16: ='4.KTHH L4'!C27 -> 746.82 | O16: =Chạy!E52 -> 4.91
A51: Tổng cộng (m3) | R51: =SUM(R11:R50) -> 0 | S51: =SUM(S11:S50) -> 0 | U51: =SUM(U11:U50) -> 0 | V51: =SUM(V11:V50) -> 0 | W51: =SUM(W11:W16) -> 377.7292 | X51: =SUM(X11:X50) -> 0 | Y51: =SUM(Y11:Y50) -> 0 | Z51: =SUM(Z11:Z50) -> 0 | AA51: =SUM(AA11:AA50) -> 0
A53: NHÀ THẦU THI CÔNG | E53: TƯ VẤN GIÁM SÁT
A59: Nguyễn Xuân Hưng | M59: Trần Mạnh Tùng

Sheet 5.KTHH L5
A1: PHỤ LỤC KIỂM TRA CAO ĐỘ, KÍCH THƯỚC HÌNH HỌC
A2: ="Kèm theo BBNT số: "&VLOOKUP(AZ2,'[1]Tuyến XD4'!$A$2:$G$60,7,0)&VLOOKUP(AZ2,'[1]Tuyến XD4'!$A$2:$G$60,4,0) -> Kèm theo BBNT số: 68.NĐXD4/CVXD ngày 18 tháng 09 năm 2026 | AZ2: 68
A3: ='1.KTHH L1'!A3 -> Dự án: Xây dựng HTKT Khu tái định cư phục vụ di dân xã Hải Hà, thị xã Nghi Sơn, tỉnh Thanh Hóa.
A4: ='1.KTHH L1'!A4 -> Gói thầu số 12: Xây dựng HTKT khu vực Hải Bình và Xuân Lâm (bao gồm cả bảo hiểm xây dựng công trình)
A5: ='1.KTHH L1'!A5 -> Nhà thầu thi công: Công ty TNHH Hoàng Tuấn
A6: Hạng mục: Nền đường tuyến XD4
A7: - Đối tượng nghiệm thu: | G7: =VLOOKUP(AZ2,'[1]Tuyến XD4'!$A$2:$B$60,2,0) -> Đắp đất nền đường lớp 5 đoạn từ Km0+672,28 - Km0+746,82, độ chặt K>=0,95
A8: Sơ họa:
A20: TT | B20: Tên cọc | C20: Lý trình | D20: Bên trái (H1) | J20: Tim (H2) | M20: Bên phải (H3) | S20: Ghi chú
D21: KCTK | E21: KCTC | F21: Chênh KC (m) | G21: CDTK (m) | H21: CDTC (m) | I21: Chênh CD (m) | J21: CDTK (m) | K21: CDTC (m) | L21: Chênh CD (m) | M21: KCTK | N21: KCTC | O21: Chênh KC (m) | P21: CDTK (m) | Q21: CDTC (m) | R21: Chênh CD (m)
A22: 1 | B22: 38 | C22: 672.28 | D22: =+Chạy!F6 -> -11.14 | E22: =+D22+F22 -> -11.1345 | F22: =RANDBETWEEN(-105,115)/10000 -> 0.0055 | G22: =+Chạy!G6 -> 0.74 | H22: =G22+I22 -> 0.77 | I22: =RANDBETWEEN(-30,90)/1000 -> 0.03 | J22: =+Chạy!K6 -> 0.86 | K22: =J22+L22 -> 0.866 | L22: =RANDBETWEEN(-30,90)/1000 -> 0.006 | M22: =+Chạy!N6 -> 13.75 | N22: =+M22+O22 -> 13.7489 | O22: =RANDBETWEEN(-105,115)/10000 -> -0.0011 | P22: =+Chạy!O6 -> 0.74 | Q22: =P22+R22 -> 0.711 | R22: =RANDBETWEEN(-30,90)/1000 -> -0.029 | T22: 17
A23: 2 | B23: 39 | C23: =+C22+T22 -> 689.28 | D23: =+Chạy!F15 -> -11.71 | E23: =+D23+F23 -> -11.7042 | F23: =RANDBETWEEN(-105,115)/10000 -> 0.0058 | G23: =+Chạy!G15 -> 0.74 | H23: =G23+I23 -> 0.746 | I23: =RANDBETWEEN(-30,90)/1000 -> 0.006 | J23: =+Chạy!K15 -> 0.86 | K23: =J23+L23 -> 0.861 | L23: =RANDBETWEEN(-30,90)/1000 -> 0.001 | M23: =+Chạy!N15 -> 13.75 | N23: =+M23+O23 -> 13.7597 | O23: =RANDBETWEEN(-105,115)/10000 -> 0.0097 | P23: =+Chạy!O15 -> 0.74 | Q23: =P23+R23 -> 0.717 | R23: =RANDBETWEEN(-30,90)/1000 -> -0.023 | T23: 11.75
A24: 3 | B24: F2 | C24: =+C23+T23 -> 701.03 | D24: =+Chạy!F24 -> -11.52 | E24: =+D24+F24 -> -11.5109 | F24: =RANDBETWEEN(-105,115)/10000 -> 0.0091 | G24: =+Chạy!G24 -> 0.74 | H24: =G24+I24 -> 0.723 | I24: =RANDBETWEEN(-30,90)/1000 -> -0.017 | J24: =+Chạy!K24 -> 0.86 | K24: =J24+L24 -> 0.927 | L24: =RANDBETWEEN(-30,90)/1000 -> 0.067 | M24: =+Chạy!N24 -> -1.61 | N24: =+M24+O24 -> -1.6183 | O24: =RANDBETWEEN(-105,115)/10000 -> -0.0083 | P24: =+Chạy!O24 -> 0.83 | Q24: =P24+R24 -> 0.872 | R24: =RANDBETWEEN(-30,90)/1000 -> 0.042 | T24: 11.75
A25: 4 | B25: 40 | C25: =+C24+T24 -> 712.78 | D25: =+Chạy!F33 -> -11.74 | E25: =+D25+F25 -> -11.7469 | F25: =RANDBETWEEN(-105,115)/10000 -> -0.0069 | G25: =+Chạy!G33 -> 0.74 | H25: =G25+I25 -> 0.819 | I25: =RANDBETWEEN(-30,90)/1000 -> 0.079 | J25: =+Chạy!K33 -> 0.86 | K25: =J25+L25 -> 0.891 | L25: =RANDBETWEEN(-30,90)/1000 -> 0.031 | M25: =+Chạy!N33 -> 13.75 | N25: =+M25+O25 -> 13.7593 | O25: =RANDBETWEEN(-105,115)/10000 -> 0.0093 | P25: =+Chạy!O33 -> 0.74 | Q25: =P25+R25 -> 0.827 | R25: =RANDBETWEEN(-30,90)/1000 -> 0.087 | T25: 17
A26: 5 | B26: 41 | C26: =+C25+T25 -> 729.78 | D26: =+Chạy!F42 -> -7.61 | E26: =+D26+F26 -> -7.5989 | F26: =RANDBETWEEN(-105,115)/10000 -> 0.0111 | G26: =+Chạy!G42 -> 0.74 | H26: =G26+I26 -> 0.782 | I26: =RANDBETWEEN(-30,90)/1000 -> 0.042 | J26: =+Chạy!K42 -> 0.86 | K26: =J26+L26 -> 0.853 | L26: =RANDBETWEEN(-30,90)/1000 -> -0.007 | M26: =+Chạy!N42 -> 7.61 | N26: =+M26+O26 -> 7.6017 | O26: =RANDBETWEEN(-105,115)/10000 -> -0.0083 | P26: =+Chạy!O42 -> 0.74 | Q26: =P26+R26 -> 0.807 | R26: =RANDBETWEEN(-30,90)/1000 -> 0.067 | T26: 17.04
A27: 6 | B27: 42 | C27: =+C26+T26 -> 746.82 | D27: =+Chạy!F51 -> -8.05 | E27: =+D27+F27 -> -8.0531 | F27: =RANDBETWEEN(-105,115)/10000 -> -0.0031 | G27: =+Chạy!G51 -> 0.74 | H27: =G27+I27 -> 0.721 | I27: =RANDBETWEEN(-30,90)/1000 -> -0.019 | J27: =+Chạy!K51 -> 0.86 | K27: =J27+L27 -> 0.914 | L27: =RANDBETWEEN(-30,90)/1000 -> 0.054 | M27: =+Chạy!N51 -> 13.75 | N27: =+M27+O27 -> 13.7437 | O27: =RANDBETWEEN(-105,115)/10000 -> -0.0063 | P27: =+Chạy!O51 -> 0.74 | Q27: =P27+R27 -> 0.773 | R27: =RANDBETWEEN(-30,90)/1000 -> 0.033
C63: NHÀ THẦU THI CÔNG | O63: TƯ VẤN GIÁM SÁT
C68: Nguyễn Xuân Hưng | O68: Trần Mạnh Tùng

Sheet 5.KL L5
A1: PHỤ LỤC KHỐI LƯỢNG
A2: ="Kèm theo BBNT số: "&VLOOKUP(AZ2,'[1]Tuyến XD4'!$A$2:$G$60,7,0)&VLOOKUP(AZ2,'[1]Tuyến XD4'!$A$2:$G$60,4,0) -> Kèm theo BBNT số: 68.NĐXD4/CVXD ngày 18 tháng 09 năm 2026 | AZ2: 68
A3: ='1.KTHH L1'!A3 -> Dự án: Xây dựng HTKT Khu tái định cư phục vụ di dân xã Hải Hà, thị xã Nghi Sơn, tỉnh Thanh Hóa.
A4: ='1.KTHH L1'!A4 -> Gói thầu số 12: Xây dựng HTKT khu vực Hải Bình và Xuân Lâm (bao gồm cả bảo hiểm xây dựng công trình)
A5: ='1.KTHH L1'!A5 -> Nhà thầu thi công: Công ty TNHH Hoàng Tuấn
A6: Hạng mục: Nền đường tuyến XD4
A7: - Đối tượng nghiệm thu: | D7: =VLOOKUP(AZ2,'[1]Tuyến XD4'!$A$2:$B$60,2,0) -> Đắp đất nền đường lớp 5 đoạn từ Km0+672,28 - Km0+746,82, độ chặt K>=0,95
A9: STT | B9: Tên cọc | C9: Lý trình | D9: K/c lẻ | M9: Khối lượng đắp đất | AB9: Ghi chú
N10: Diện tích | O10: Diện tích (m2) | P10: Diện tích | Q10: Diện tích | U10: Khối lượng | V10: Khối lượng | W10: Khối lượng (m3) | X10: Khối lượng | Y10: Khối lượng
A11: 1 | B11: ='5.KTHH L5'!B22 -> 38 | C11: ='5.KTHH L5'!C22 -> 672.28 | D11: ='5.KTHH L5'!T22 -> 17 | O11: =Chạy!E6 -> 7.49 | W11: =(O11+O12)*D11/2 -> 127.755
A12: 2 | B12: ='5.KTHH L5'!B23 -> 39 | C12: ='5.KTHH L5'!C23 -> 689.28 | D12: ='5.KTHH L5'!T23 -> 11.75 | O12: =Chạy!E15 -> 7.54 | W12: =(O12+O13)*D12/2 -> 61.335
A13: 3 | B13: ='5.KTHH L5'!B24 -> F2 | C13: ='5.KTHH L5'!C24 -> 701.03 | D13: ='5.KTHH L5'!T24 -> 11.75 | O13: =Chạy!E24 -> 2.9 | W13: =(O13+O14)*D13/2 -> 60.7475
A14: 4 | B14: ='5.KTHH L5'!B25 -> 40 | C14: ='5.KTHH L5'!C25 -> 712.78 | D14: ='5.KTHH L5'!T25 -> 17 | O14: =Chạy!E33 -> 7.44 | W14: =(O14+O15)*D14/2 -> 101.32
A15: 5 | B15: ='5.KTHH L5'!B26 -> 41 | C15: ='5.KTHH L5'!C26 -> 729.78 | D15: ='5.KTHH L5'!T26 -> 17.04 | O15: =Chạy!E42 -> 4.48 | W15: =(O15+O16)*D15/2 -> 87.5856
A16: 6 | B16: ='5.KTHH L5'!B27 -> 42 | C16: ='5.KTHH L5'!C27 -> 746.82 | O16: =Chạy!E51 -> 5.8
A51: Tổng cộng (m3) | R51: =SUM(R11:R50) -> 0 | S51: =SUM(S11:S50) -> 0 | U51: =SUM(U11:U50) -> 0 | V51: =SUM(V11:V50) -> 0 | W51: =SUM(W11:W16) -> 438.7431 | X51: =SUM(X11:X50) -> 0 | Y51: =SUM(Y11:Y50) -> 0 | Z51: =SUM(Z11:Z50) -> 0 | AA51: =SUM(AA11:AA50) -> 0
A53: NHÀ THẦU THI CÔNG | E53: TƯ VẤN GIÁM SÁT
A59: Nguyễn Xuân Hưng | M59: Trần Mạnh Tùng

Sheet 6.KTHH L6
A1: PHỤ LỤC KIỂM TRA CAO ĐỘ, KÍCH THƯỚC HÌNH HỌC
A2: ="Kèm theo BBNT số: "&VLOOKUP(AZ2,'[1]Tuyến XD4'!$A$2:$G$60,7,0)&VLOOKUP(AZ2,'[1]Tuyến XD4'!$A$2:$G$60,4,0) -> Kèm theo BBNT số: 69.NĐXD4/CVXD ngày 19 tháng 09 năm 2026 | AZ2: 69
A3: ='1.KTHH L1'!A3 -> Dự án: Xây dựng HTKT Khu tái định cư phục vụ di dân xã Hải Hà, thị xã Nghi Sơn, tỉnh Thanh Hóa.
A4: ='1.KTHH L1'!A4 -> Gói thầu số 12: Xây dựng HTKT khu vực Hải Bình và Xuân Lâm (bao gồm cả bảo hiểm xây dựng công trình)
A5: ='1.KTHH L1'!A5 -> Nhà thầu thi công: Công ty TNHH Hoàng Tuấn
A6: Hạng mục: Nền đường tuyến XD4
A7: - Đối tượng nghiệm thu: | G7: =VLOOKUP(AZ2,'[1]Tuyến XD4'!$A$2:$B$60,2,0) -> Đắp đất nền đường lớp 6 đoạn từ Km0+672,28 - Km0+746,82, độ chặt K>=0,95
A8: Sơ họa:
A20: TT | B20: Tên cọc | C20: Lý trình | D20: Bên trái (H1) | J20: Tim (H2) | M20: Bên phải (H3) | S20: Ghi chú
D21: KCTK | E21: KCTC | F21: Chênh KC (m) | G21: CDTK (m) | H21: CDTC (m) | I21: Chênh CD (m) | J21: CDTK (m) | K21: CDTC (m) | L21: Chênh CD (m) | M21: KCTK | N21: KCTC | O21: Chênh KC (m) | P21: CDTK (m) | Q21: CDTC (m) | R21: Chênh CD (m)
A22: 1 | B22: 38 | C22: 672.28 | D22: =+Chạy!F5 -> -11.44 | E22: =+D22+F22 -> -11.4303 | F22: =RANDBETWEEN(-105,115)/10000 -> 0.0097 | G22: =+Chạy!G5 -> 1.04 | H22: =G22+I22 -> 1.01 | I22: =RANDBETWEEN(-30,90)/1000 -> -0.03 | J22: =+Chạy!K5 -> 1.16 | K22: =J22+L22 -> 1.217 | L22: =RANDBETWEEN(-30,90)/1000 -> 0.057 | M22: =+Chạy!N5 -> 13.3 | N22: =+M22+O22 -> 13.2965 | O22: =RANDBETWEEN(-105,115)/10000 -> -0.0035 | P22: =+Chạy!O5 -> 1.04 | Q22: =P22+R22 -> 1.079 | R22: =RANDBETWEEN(-30,90)/1000 -> 0.039 | T22: 17
A23: 2 | B23: 39 | C23: =+C22+T22 -> 689.28 | D23: =+Chạy!F14 -> -11.97 | E23: =+D23+F23 -> -11.9758 | F23: =RANDBETWEEN(-105,115)/10000 -> -0.0058 | G23: =+Chạy!G14 -> 1.04 | H23: =G23+I23 -> 1.117 | I23: =RANDBETWEEN(-30,90)/1000 -> 0.077 | J23: =+Chạy!K14 -> 1.16 | K23: =J23+L23 -> 1.143 | L23: =RANDBETWEEN(-30,90)/1000 -> -0.017 | M23: =+Chạy!N14 -> 13.3 | N23: =+M23+O23 -> 13.3103 | O23: =RANDBETWEEN(-105,115)/10000 -> 0.0103 | P23: =+Chạy!O14 -> 1.04 | Q23: =P23+R23 -> 1.017 | R23: =RANDBETWEEN(-30,90)/1000 -> -0.023 | T23: 11.75
A24: 3 | B24: F2 | C24: =+C23+T23 -> 701.03 | D24: =+Chạy!F23 -> -11.8 | E24: =+D24+F24 -> -11.7887 | F24: =RANDBETWEEN(-105,115)/10000 -> 0.0113 | G24: =+Chạy!G23 -> 1.04 | H24: =G24+I24 -> 1.034 | I24: =RANDBETWEEN(-30,90)/1000 -> -0.006 | J24: =+Chạy!K23 -> 1.16 | K24: =J24+L24 -> 1.211 | L24: =RANDBETWEEN(-30,90)/1000 -> 0.051 | M24: =+Chạy!N23 -> -1.37 | N24: =+M24+O24 -> -1.3704 | O24: =RANDBETWEEN(-105,115)/10000 -> -0.0004 | P24: =+Chạy!O23 -> 1.13 | Q24: =P24+R24 -> 1.207 | R24: =RANDBETWEEN(-30,90)/1000 -> 0.077 | T24: 11.75
A25: 4 | B25: 40 | C25: =+C24+T24 -> 712.78 | D25: =+Chạy!F32 -> -11.99 | E25: =+D25+F25 -> -11.9907 | F25: =RANDBETWEEN(-105,115)/10000 -> -0.0007 | G25: =+Chạy!G32 -> 1.04 | H25: =G25+I25 -> 1.052 | I25: =RANDBETWEEN(-30,90)/1000 -> 0.012 | J25: =+Chạy!K32 -> 1.16 | K25: =J25+L25 -> 1.142 | L25: =RANDBETWEEN(-30,90)/1000 -> -0.018 | M25: =+Chạy!N32 -> 13.3 | N25: =+M25+O25 -> 13.305 | O25: =RANDBETWEEN(-105,115)/10000 -> 0.005 | P25: =+Chạy!O32 -> 1.04 | Q25: =P25+R25 -> 1.038 | R25: =RANDBETWEEN(-30,90)/1000 -> -0.002 | T25: 17
A26: 5 | B26: 41 | C26: =+C25+T25 -> 729.78 | D26: =+Chạy!F41 -> -7.91 | E26: =+D26+F26 -> -7.9101 | F26: =RANDBETWEEN(-105,115)/10000 -> -0.0001 | G26: =+Chạy!G41 -> 1.04 | H26: =G26+I26 -> 1.092 | I26: =RANDBETWEEN(-30,90)/1000 -> 0.052 | J26: =+Chạy!K41 -> 1.16 | K26: =J26+L26 -> 1.168 | L26: =RANDBETWEEN(-30,90)/1000 -> 0.008 | M26: =+Chạy!N41 -> 7.91 | N26: =+M26+O26 -> 7.9171 | O26: =RANDBETWEEN(-105,115)/10000 -> 0.0071 | P26: =+Chạy!O41 -> 1.04 | Q26: =P26+R26 -> 1.1 | R26: =RANDBETWEEN(-30,90)/1000 -> 0.06 | T26: 17.04
A27: 6 | B27: 42 | C27: =+C26+T26 -> 746.82 | D27: =+Chạy!F50 -> -8.35 | E27: =+D27+F27 -> -8.3442 | F27: =RANDBETWEEN(-105,115)/10000 -> 0.0058 | G27: =+Chạy!G50 -> 1.04 | H27: =G27+I27 -> 1.07 | I27: =RANDBETWEEN(-30,90)/1000 -> 0.03 | J27: =+Chạy!K50 -> 1.16 | K27: =J27+L27 -> 1.175 | L27: =RANDBETWEEN(-30,90)/1000 -> 0.015 | M27: =+Chạy!N50 -> 13.3 | N27: =+M27+O27 -> 13.3032 | O27: =RANDBETWEEN(-105,115)/10000 -> 0.0032 | P27: =+Chạy!O50 -> 1.04 | Q27: =P27+R27 -> 1.083 | R27: =RANDBETWEEN(-30,90)/1000 -> 0.043
C63: NHÀ THẦU THI CÔNG | O63: TƯ VẤN GIÁM SÁT
C68: Nguyễn Xuân Hưng | O68: Trần Mạnh Tùng

Sheet 6.KL L6
A1: PHỤ LỤC KHỐI LƯỢNG
A2: ="Kèm theo BBNT số: "&VLOOKUP(AZ2,'[1]Tuyến XD4'!$A$2:$G$60,7,0)&VLOOKUP(AZ2,'[1]Tuyến XD4'!$A$2:$G$60,4,0) -> Kèm theo BBNT số: 69.NĐXD4/CVXD ngày 19 tháng 09 năm 2026 | AZ2: 69
A3: ='1.KTHH L1'!A3 -> Dự án: Xây dựng HTKT Khu tái định cư phục vụ di dân xã Hải Hà, thị xã Nghi Sơn, tỉnh Thanh Hóa.
A4: ='1.KTHH L1'!A4 -> Gói thầu số 12: Xây dựng HTKT khu vực Hải Bình và Xuân Lâm (bao gồm cả bảo hiểm xây dựng công trình)
A5: ='1.KTHH L1'!A5 -> Nhà thầu thi công: Công ty TNHH Hoàng Tuấn
A6: Hạng mục: Nền đường tuyến XD4
A7: - Đối tượng nghiệm thu: | D7: =VLOOKUP(AZ2,'[1]Tuyến XD4'!$A$2:$B$60,2,0) -> Đắp đất nền đường lớp 6 đoạn từ Km0+672,28 - Km0+746,82, độ chặt K>=0,95
A9: STT | B9: Tên cọc | C9: Lý trình | D9: K/c lẻ | M9: Khối lượng đắp đất | AB9: Ghi chú
N10: Diện tích | O10: Diện tích (m2) | P10: Diện tích | Q10: Diện tích | U10: Khối lượng | V10: Khối lượng | W10: Khối lượng (m3) | X10: Khối lượng | Y10: Khối lượng
A11: 1 | B11: ='6.KTHH L6'!B22 -> 38 | C11: ='6.KTHH L6'!C22 -> 672.28 | D11: ='6.KTHH L6'!T22 -> 17 | O11: =Chạy!E5 -> 7.44 | W11: =(O11+O12)*D11/2 -> 127.925
A12: 2 | B12: ='6.KTHH L6'!B23 -> 39 | C12: ='6.KTHH L6'!C23 -> 689.28 | D12: ='6.KTHH L6'!T23 -> 11.75 | O12: =Chạy!E14 -> 7.61 | W12: =(O12+O13)*D12/2 -> 62.6275
A13: 3 | B13: ='6.KTHH L6'!B24 -> F2 | C13: ='6.KTHH L6'!C24 -> 701.03 | D13: ='6.KTHH L6'!T24 -> 11.75 | O13: =Chạy!E23 -> 3.05 | W13: =(O13+O14)*D13/2 -> 62.68625
A14: 4 | B14: ='6.KTHH L6'!B25 -> 40 | C14: ='6.KTHH L6'!C25 -> 712.78 | D14: ='6.KTHH L6'!T25 -> 17 | O14: =Chạy!E32 -> 7.62 | W14: =(O14+O15)*D14/2 -> 104.38
A15: 5 | B15: ='6.KTHH L6'!B26 -> 41 | C15: ='6.KTHH L6'!C26 -> 729.78 | D15: ='6.KTHH L6'!T26 -> 17.04 | O15: =Chạy!E41 -> 4.66 | W15: =(O15+O16)*D15/2 -> 95.2536
A16: 6 | B16: ='6.KTHH L6'!B27 -> 42 | C16: ='6.KTHH L6'!C27 -> 746.82 | O16: =Chạy!E50 -> 6.52
A51: Tổng cộng (m3) | R51: =SUM(R11:R50) -> 0 | S51: =SUM(S11:S50) -> 0 | U51: =SUM(U11:U50) -> 0 | V51: =SUM(V11:V50) -> 0 | W51: =SUM(W11:W16) -> 452.87235 | X51: =SUM(X11:X50) -> 0 | Y51: =SUM(Y11:Y50) -> 0 | Z51: =SUM(Z11:Z50) -> 0 | AA51: =SUM(AA11:AA50) -> 0
A53: NHÀ THẦU THI CÔNG | E53: TƯ VẤN GIÁM SÁT
A59: Nguyễn Xuân Hưng | M59: Trần Mạnh Tùng

Sheet 7.KTHH L7
A1: PHỤ LỤC KIỂM TRA CAO ĐỘ, KÍCH THƯỚC HÌNH HỌC
A2: ="Kèm theo BBNT số: "&VLOOKUP(AZ2,'[1]Tuyến XD4'!$A$2:$G$60,7,0)&VLOOKUP(AZ2,'[1]Tuyến XD4'!$A$2:$G$60,4,0) -> Kèm theo BBNT số: 70.NĐXD4/CVXD ngày 19 tháng 09 năm 2026 | AZ2: 70
A3: =+'1.KTHH L1'!A3 -> Dự án: Xây dựng HTKT Khu tái định cư phục vụ di dân xã Hải Hà, thị xã Nghi Sơn, tỉnh Thanh Hóa.
A4: =+'1.KTHH L1'!A4 -> Gói thầu số 12: Xây dựng HTKT khu vực Hải Bình và Xuân Lâm (bao gồm cả bảo hiểm xây dựng công trình)
A5: =+'1.KTHH L1'!A5 -> Nhà thầu thi công: Công ty TNHH Hoàng Tuấn
A6: Hạng mục: Nền đường tuyến XD4
A7: - Đối tượng nghiệm thu: | G7: =VLOOKUP(AZ2,'[1]Tuyến XD4'!$A$2:$B$60,2,0) -> Đắp đất nền đường lớp 7 đoạn từ Km0+672,28 - Km0+746,82, độ chặt K>=0,95
A8: Sơ họa:
A20: TT | B20: Tên cọc | C20: Lý trình | D20: Bên trái (H1) | J20: Tim (H2) | M20: Bên phải (H3) | S20: Ghi chú
D21: KCTK | E21: KCTC | F21: Chênh KC (m) | G21: CDTK (m) | H21: CDTC (m) | I21: Chênh CD (m) | J21: CDTK (m) | K21: CDTC (m) | L21: Chênh CD (m) | M21: KCTK | N21: KCTC | O21: Chênh KC (m) | P21: CDTK (m) | Q21: CDTC (m) | R21: Chênh CD (m)
A22: 1 | B22: 38 | C22: 672.28 | D22: =+Chạy!F4 -> -11.74 | E22: =+D22+F22 -> -11.7336 | F22: =RANDBETWEEN(-105,115)/10000 -> 0.0064 | G22: =+Chạy!G4 -> 1.34 | H22: =G22+I22 -> 1.378 | I22: =RANDBETWEEN(-30,90)/1000 -> 0.038 | J22: =+Chạy!K4 -> 1.46 | K22: =J22+L22 -> 1.543 | L22: =RANDBETWEEN(-30,90)/1000 -> 0.083 | M22: =+Chạy!N4 -> 12.85 | N22: =+M22+O22 -> 12.858 | O22: =RANDBETWEEN(-105,115)/10000 -> 0.008 | P22: =+Chạy!O4 -> 1.34 | Q22: =P22+R22 -> 1.421 | R22: =RANDBETWEEN(-30,90)/1000 -> 0.081 | T22: 17
A23: 2 | B23: 39 | C23: =+C22+T22 -> 689.28 | D23: =+Chạy!F13 -> -12.23 | E23: =+D23+F23 -> -12.2274 | F23: =RANDBETWEEN(-105,115)/10000 -> 0.0026 | G23: =+Chạy!G13 -> 1.34 | H23: =G23+I23 -> 1.353 | I23: =RANDBETWEEN(-30,90)/1000 -> 0.013 | J23: =+Chạy!K13 -> 1.46 | K23: =J23+L23 -> 1.446 | L23: =RANDBETWEEN(-30,90)/1000 -> -0.014 | M23: =+Chạy!N13 -> 12.85 | N23: =+M23+O23 -> 12.8526 | O23: =RANDBETWEEN(-105,115)/10000 -> 0.0026 | P23: =+Chạy!O13 -> 1.34 | Q23: =P23+R23 -> 1.318 | R23: =RANDBETWEEN(-30,90)/1000 -> -0.022 | T23: 11.75
A24: 3 | B24: F2 | C24: =+C23+T23 -> 701.03 | D24: =+Chạy!F22 -> -12.07 | E24: =+D24+F24 -> -12.0793 | F24: =RANDBETWEEN(-105,115)/10000 -> -0.0093 | G24: =+Chạy!G22 -> 1.34 | H24: =G24+I24 -> 1.31 | I24: =RANDBETWEEN(-30,90)/1000 -> -0.03 | J24: =+Chạy!K22 -> 1.46 | K24: =J24+L24 -> 1.437 | L24: =RANDBETWEEN(-30,90)/1000 -> -0.023 | M24: =+Chạy!N22 -> -1.14 | N24: =+M24+O24 -> -1.1361 | O24: =RANDBETWEEN(-105,115)/10000 -> 0.0039 | P24: =+Chạy!O22 -> 1.44 | Q24: =P24+R24 -> 1.421 | R24: =RANDBETWEEN(-30,90)/1000 -> -0.019 | T24: 11.75
A25: 4 | B25: 40 | C25: =+C24+T24 -> 712.78 | D25: =+Chạy!F31 -> -12.24 | E25: =+D25+F25 -> -12.2416 | F25: =RANDBETWEEN(-105,115)/10000 -> -0.0016 | G25: =+Chạy!G31 -> 1.34 | H25: =G25+I25 -> 1.389 | I25: =RANDBETWEEN(-30,90)/1000 -> 0.049 | J25: =+Chạy!K31 -> 1.46 | K25: =J25+L25 -> 1.498 | L25: =RANDBETWEEN(-30,90)/1000 -> 0.038 | M25: =+Chạy!N31 -> 12.85 | N25: =+M25+O25 -> 12.8519 | O25: =RANDBETWEEN(-105,115)/10000 -> 0.0019 | P25: =+Chạy!O31 -> 1.34 | Q25: =P25+R25 -> 1.357 | R25: =RANDBETWEEN(-30,90)/1000 -> 0.017 | T25: 17
A26: 5 | B26: 41 | C26: =+C25+T25 -> 729.78 | D26: =+Chạy!F40 -> -8.21 | E26: =+D26+F26 -> -8.2165 | F26: =RANDBETWEEN(-105,115)/10000 -> -0.0065 | G26: =+Chạy!G40 -> 1.34 | H26: =G26+I26 -> 1.346 | I26: =RANDBETWEEN(-30,90)/1000 -> 0.006 | J26: =+Chạy!K40 -> 1.46 | K26: =J26+L26 -> 1.471 | L26: =RANDBETWEEN(-30,90)/1000 -> 0.011 | M26: =+Chạy!N40 -> 8.21 | N26: =+M26+O26 -> 8.2016 | O26: =RANDBETWEEN(-105,115)/10000 -> -0.0084 | P26: =+Chạy!O40 -> 1.34 | Q26: =P26+R26 -> 1.313 | R26: =RANDBETWEEN(-30,90)/1000 -> -0.027 | T26: 17.04
A27: 6 | B27: 42 | C27: =+C26+T26 -> 746.82 | D27: =+Chạy!F49 -> -8.65 | E27: =+D27+F27 -> -8.6597 | F27: =RANDBETWEEN(-105,115)/10000 -> -0.0097 | G27: =+Chạy!G49 -> 1.34 | H27: =G27+I27 -> 1.344 | I27: =RANDBETWEEN(-30,90)/1000 -> 0.004 | J27: =+Chạy!K49 -> 1.46 | K27: =J27+L27 -> 1.53 | L27: =RANDBETWEEN(-30,90)/1000 -> 0.07 | M27: =+Chạy!N49 -> 12.85 | N27: =+M27+O27 -> 12.8545 | O27: =RANDBETWEEN(-105,115)/10000 -> 0.0045 | P27: =+Chạy!O49 -> 1.34 | Q27: =P27+R27 -> 1.406 | R27: =RANDBETWEEN(-30,90)/1000 -> 0.066
C63: NHÀ THẦU THI CÔNG | O63: TƯ VẤN GIÁM SÁT
C68: Nguyễn Xuân Hưng | O68: Trần Mạnh Tùng

Sheet 7.KL L7
A1: PHỤ LỤC KHỐI LƯỢNG
A2: ="Kèm theo BBNT số: "&VLOOKUP(AZ2,'[1]Tuyến XD4'!$A$2:$G$60,7,0)&VLOOKUP(AZ2,'[1]Tuyến XD4'!$A$2:$G$60,4,0) -> Kèm theo BBNT số: 70.NĐXD4/CVXD ngày 19 tháng 09 năm 2026 | AZ2: 70
A3: =+'1.KTHH L1'!A3 -> Dự án: Xây dựng HTKT Khu tái định cư phục vụ di dân xã Hải Hà, thị xã Nghi Sơn, tỉnh Thanh Hóa.
A4: =+'1.KTHH L1'!A4 -> Gói thầu số 12: Xây dựng HTKT khu vực Hải Bình và Xuân Lâm (bao gồm cả bảo hiểm xây dựng công trình)
A5: =+'1.KTHH L1'!A5 -> Nhà thầu thi công: Công ty TNHH Hoàng Tuấn
A6: Hạng mục: Nền đường tuyến XD4
A7: - Đối tượng nghiệm thu: | D7: =VLOOKUP(AZ2,'[1]Tuyến XD4'!$A$2:$B$60,2,0) -> Đắp đất nền đường lớp 7 đoạn từ Km0+672,28 - Km0+746,82, độ chặt K>=0,95
A9: STT | B9: Tên cọc | C9: Lý trình | D9: K/c lẻ | M9: Khối lượng đắp đất | AB9: Ghi chú
N10: Diện tích | O10: Diện tích (m2) | P10: Diện tích | Q10: Diện tích | U10: Khối lượng | V10: Khối lượng | W10: Khối lượng (m3) | X10: Khối lượng | Y10: Khối lượng
A11: 1 | B11: ='7.KTHH L7'!B22 -> 38 | C11: ='7.KTHH L7'!C22 -> 672.28 | D11: ='7.KTHH L7'!T22 -> 17 | O11: =Chạy!E4 -> 7.4 | W11: =(O11+O12)*D11/2 -> 127.075
A12: 2 | B12: ='7.KTHH L7'!B23 -> 39 | C12: ='7.KTHH L7'!C23 -> 689.28 | D12: ='7.KTHH L7'!T23 -> 11.75 | O12: =Chạy!E13 -> 7.55 | W12: =(O12+O13)*D12/2 -> 63.15625
A13: 3 | B13: ='7.KTHH L7'!B24 -> F2 | C13: ='7.KTHH L7'!C24 -> 701.03 | D13: ='7.KTHH L7'!T24 -> 11.75 | O13: =Chạy!E22 -> 3.2 | W13: =(O13+O14)*D13/2 -> 63.215
A14: 4 | B14: ='7.KTHH L7'!B25 -> 40 | C14: ='7.KTHH L7'!C25 -> 712.78 | D14: ='7.KTHH L7'!T25 -> 17 | O14: =Chạy!E31 -> 7.56 | W14: =(O14+O15)*D14/2 -> 105.4
A15: 5 | B15: ='7.KTHH L7'!B26 -> 41 | C15: ='7.KTHH L7'!C26 -> 729.78 | D15: ='7.KTHH L7'!T26 -> 17.04 | O15: =Chạy!E40 -> 4.84 | W15: =(O15+O16)*D15/2 -> 96.3612
A16: 6 | B16: ='7.KTHH L7'!B27 -> 42 | C16: ='7.KTHH L7'!C27 -> 746.82 | O16: =Chạy!E49 -> 6.47
A51: Tổng cộng (m3) | R51: =SUM(R11:R50) -> 0 | S51: =SUM(S11:S50) -> 0 | U51: =SUM(U11:U50) -> 0 | V51: =SUM(V11:V50) -> 0 | W51: =SUM(W11:W16) -> 455.20745 | X51: =SUM(X11:X50) -> 0 | Y51: =SUM(Y11:Y50) -> 0 | Z51: =SUM(Z11:Z50) -> 0 | AA51: =SUM(AA11:AA50) -> 0
A53: NHÀ THẦU THI CÔNG | E53: TƯ VẤN GIÁM SÁT
A59: Nguyễn Xuân Hưng | M59: Trần Mạnh Tùng

Sheet 8.KTHH L8
A1: PHỤ LỤC KIỂM TRA CAO ĐỘ, KÍCH THƯỚC HÌNH HỌC
A2: ="Kèm theo BBNT số: "&VLOOKUP(AZ2,'[1]Tuyến XD4'!$A$2:$G$60,7,0)&VLOOKUP(AZ2,'[1]Tuyến XD4'!$A$2:$G$60,4,0) -> Kèm theo BBNT số: 71.NĐXD4/CVXD ngày 20 tháng 09 năm 2026 | AZ2: 71
A3: =+'1.KTHH L1'!A3 -> Dự án: Xây dựng HTKT Khu tái định cư phục vụ di dân xã Hải Hà, thị xã Nghi Sơn, tỉnh Thanh Hóa.
A4: =+'1.KTHH L1'!A4 -> Gói thầu số 12: Xây dựng HTKT khu vực Hải Bình và Xuân Lâm (bao gồm cả bảo hiểm xây dựng công trình)
A5: =+'1.KTHH L1'!A5 -> Nhà thầu thi công: Công ty TNHH Hoàng Tuấn
A6: Hạng mục: Nền đường tuyến XD4
A7: - Đối tượng nghiệm thu: | G7: =VLOOKUP(AZ2,'[1]Tuyến XD4'!$A$2:$B$60,2,0) -> Đắp đất nền đường lớp 8 đoạn từ Km0+672,28 - Km0+746,82, độ chặt K>=0,95
A8: Sơ họa:
A20: TT | B20: Tên cọc | C20: Lý trình | D20: Bên trái (H1) | J20: Tim (H2) | M20: Bên phải (H3) | S20: Ghi chú
D21: KCTK | E21: KCTC | F21: Chênh KC (m) | G21: CDTK (m) | H21: CDTC (m) | I21: Chênh CD (m) | J21: CDTK (m) | K21: CDTC (m) | L21: Chênh CD (m) | M21: KCTK | N21: KCTC | O21: Chênh KC (m) | P21: CDTK (m) | Q21: CDTC (m) | R21: Chênh CD (m)
A22: 1 | B22: 38 | C22: 672.28 | D22: =+Chạy!F3 -> -12.4 | E22: =+D22+F22 -> -12.3916 | F22: =RANDBETWEEN(-105,115)/10000 -> 0.0084 | G22: =+Chạy!G3 -> 1.64 | H22: =G22+I22 -> 1.62 | I22: =RANDBETWEEN(-30,90)/1000 -> -0.02 | J22: =+Chạy!K3 -> 1.76 | K22: =J22+L22 -> 1.764 | L22: =RANDBETWEEN(-30,90)/1000 -> 0.004 | M22: =+Chạy!N3 -> 12.4 | N22: =+M22+O22 -> 12.3948 | O22: =RANDBETWEEN(-105,115)/10000 -> -0.0052 | P22: =+Chạy!O3 -> 1.64 | Q22: =P22+R22 -> 1.671 | R22: =RANDBETWEEN(-30,90)/1000 -> 0.031 | T22: 17
A23: 2 | B23: 39 | C23: =+C22+T22 -> 689.28 | D23: =+Chạy!F12 -> -12.4 | E23: =+D23+F23 -> -12.3972 | F23: =RANDBETWEEN(-105,115)/10000 -> 0.0028 | G23: =+Chạy!G12 -> 1.64 | H23: =G23+I23 -> 1.677 | I23: =RANDBETWEEN(-30,90)/1000 -> 0.037 | J23: =+Chạy!K12 -> 1.76 | K23: =J23+L23 -> 1.751 | L23: =RANDBETWEEN(-30,90)/1000 -> -0.009 | M23: =+Chạy!N12 -> 12.4 | N23: =+M23+O23 -> 12.3983 | O23: =RANDBETWEEN(-105,115)/10000 -> -0.0017 | P23: =+Chạy!O12 -> 1.64 | Q23: =P23+R23 -> 1.65 | R23: =RANDBETWEEN(-30,90)/1000 -> 0.01 | T23: 11.75
A24: 3 | B24: F2 | C24: =+C23+T23 -> 701.03 | D24: =+Chạy!F21 -> -12.35 | E24: =+D24+F24 -> -12.3563 | F24: =RANDBETWEEN(-105,115)/10000 -> -0.0063 | G24: =+Chạy!G21 -> 1.64 | H24: =G24+I24 -> 1.714 | I24: =RANDBETWEEN(-30,90)/1000 -> 0.074 | J24: =+Chạy!K21 -> 1.76 | K24: =J24+L24 -> 1.848 | L24: =RANDBETWEEN(-30,90)/1000 -> 0.088 | M24: =+Chạy!N21 -> -0.9 | N24: =+M24+O24 -> -0.9055 | O24: =RANDBETWEEN(-105,115)/10000 -> -0.0055 | P24: =+Chạy!O21 -> 1.74 | Q24: =P24+R24 -> 1.765 | R24: =RANDBETWEEN(-30,90)/1000 -> 0.025 | T24: 11.75
A25: 4 | B25: 40 | C25: =+C24+T24 -> 712.78 | D25: =+Chạy!F30 -> -12.4 | E25: =+D25+F25 -> -12.3999 | F25: =RANDBETWEEN(-105,115)/10000 -> 0.0001 | G25: =+Chạy!G30 -> 1.64 | H25: =G25+I25 -> 1.714 | I25: =RANDBETWEEN(-30,90)/1000 -> 0.074 | J25: =+Chạy!K30 -> 1.76 | K25: =J25+L25 -> 1.759 | L25: =RANDBETWEEN(-30,90)/1000 -> -0.001 | M25: =+Chạy!N30 -> 12.4 | N25: =+M25+O25 -> 12.4055 | O25: =RANDBETWEEN(-105,115)/10000 -> 0.0055 | P25: =+Chạy!O30 -> 1.64 | Q25: =P25+R25 -> 1.687 | R25: =RANDBETWEEN(-30,90)/1000 -> 0.047 | T25: 17
A26: 5 | B26: 41 | C26: =+C25+T25 -> 729.78 | D26: =+Chạy!F39 -> -11.78 | E26: =+D26+F26 -> -11.784 | F26: =RANDBETWEEN(-105,115)/10000 -> -0.004 | G26: =+Chạy!G39 -> 1.64 | H26: =G26+I26 -> 1.68 | I26: =RANDBETWEEN(-30,90)/1000 -> 0.04 | J26: =+Chạy!K39 -> 1.76 | K26: =J26+L26 -> 1.735 | L26: =RANDBETWEEN(-30,90)/1000 -> -0.025 | M26: =+Chạy!N39 -> 8.51 | N26: =+M26+O26 -> 8.5004 | O26: =RANDBETWEEN(-105,115)/10000 -> -0.0096 | P26: =+Chạy!O39 -> 1.64 | Q26: =P26+R26 -> 1.713 | R26: =RANDBETWEEN(-30,90)/1000 -> 0.073 | T26: 17.04
A27: 6 | B27: 42 | C27: =+C26+T26 -> 746.82 | D27: =+Chạy!F48 -> -12.4 | E27: =+D27+F27 -> -12.3963 | F27: =RANDBETWEEN(-105,115)/10000 -> 0.0037 | G27: =+Chạy!G48 -> 1.64 | H27: =G27+I27 -> 1.669 | I27: =RANDBETWEEN(-30,90)/1000 -> 0.029 | J27: =+Chạy!K48 -> 1.76 | K27: =J27+L27 -> 1.821 | L27: =RANDBETWEEN(-30,90)/1000 -> 0.061 | M27: =+Chạy!N48 -> 12.4 | N27: =+M27+O27 -> 12.4032 | O27: =RANDBETWEEN(-105,115)/10000 -> 0.0032 | P27: =+Chạy!O48 -> 1.64 | Q27: =P27+R27 -> 1.644 | R27: =RANDBETWEEN(-30,90)/1000 -> 0.004
C63: NHÀ THẦU THI CÔNG | O63: TƯ VẤN GIÁM SÁT
C68: Nguyễn Xuân Hưng | O68: =+'1.KTHH L1'!O67:R67 -> Trần Mạnh Tùng

Sheet 8.KL L8
A1: PHỤ LỤC KHỐI LƯỢNG
A2: ="Kèm theo BBNT số: "&VLOOKUP(AZ2,'[1]Tuyến XD4'!$A$2:$G$60,7,0)&VLOOKUP(AZ2,'[1]Tuyến XD4'!$A$2:$G$60,4,0) -> Kèm theo BBNT số: 71.NĐXD4/CVXD ngày 20 tháng 09 năm 2026 | AZ2: 71
A3: =+'1.KTHH L1'!A3 -> Dự án: Xây dựng HTKT Khu tái định cư phục vụ di dân xã Hải Hà, thị xã Nghi Sơn, tỉnh Thanh Hóa.
A4: =+'1.KTHH L1'!A4 -> Gói thầu số 12: Xây dựng HTKT khu vực Hải Bình và Xuân Lâm (bao gồm cả bảo hiểm xây dựng công trình)
A5: =+'1.KTHH L1'!A5 -> Nhà thầu thi công: Công ty TNHH Hoàng Tuấn
A6: Hạng mục: Nền đường tuyến XD4
A7: - Đối tượng nghiệm thu: | D7: =VLOOKUP(AZ2,'[1]Tuyến XD4'!$A$2:$B$60,2,0) -> Đắp đất nền đường lớp 8 đoạn từ Km0+672,28 - Km0+746,82, độ chặt K>=0,95
A9: STT | B9: Tên cọc | C9: Lý trình | D9: K/c lẻ | M9: Khối lượng đắp đất | AB9: Ghi chú
N10: Diện tích | O10: Diện tích (m2) | P10: Diện tích | Q10: Diện tích | U10: Khối lượng | V10: Khối lượng | W10: Khối lượng (m3) | X10: Khối lượng | Y10: Khối lượng
A11: 1 | B11: ='8.KTHH L8'!B22 -> 38 | C11: ='8.KTHH L8'!C22 -> 672.28 | D11: ='8.KTHH L8'!T22 -> 17 | O11: =Chạy!E3 -> 7.39 | W11: =(O11+O12)*D11/2 -> 126.48
A12: 2 | B12: ='8.KTHH L8'!B23 -> 39 | C12: ='8.KTHH L8'!C23 -> 689.28 | D12: ='8.KTHH L8'!T23 -> 11.75 | O12: =Chạy!E12 -> 7.49 | W12: =(O12+O13)*D12/2 -> 63.74375
A13: 3 | B13: ='8.KTHH L8'!B24 -> F2 | C13: ='8.KTHH L8'!C24 -> 701.03 | D13: ='8.KTHH L8'!T24 -> 11.75 | O13: =Chạy!E21 -> 3.36 | W13: =(O13+O14)*D13/2 -> 63.8025
A14: 4 | B14: ='8.KTHH L8'!B25 -> 40 | C14: ='8.KTHH L8'!C25 -> 712.78 | D14: ='8.KTHH L8'!T25 -> 17 | O14: =Chạy!E30 -> 7.5 | W14: =(O14+O15)*D14/2 -> 111.265
A15: 5 | B15: ='8.KTHH L8'!B26 -> 41 | C15: ='8.KTHH L8'!C26 -> 729.78 | D15: ='8.KTHH L8'!T26 -> 17.04 | O15: =Chạy!E39 -> 5.59 | W15: =(O15+O16)*D15/2 -> 103.1772
A16: 6 | B16: ='8.KTHH L8'!B27 -> 42 | C16: ='8.KTHH L8'!C27 -> 746.82 | O16: =Chạy!E48 -> 6.52
A51: Tổng cộng (m3) | R51: =SUM(R11:R50) -> 0 | S51: =SUM(S11:S50) -> 0 | U51: =SUM(U11:U50) -> 0 | V51: =SUM(V11:V50) -> 0 | W51: =SUM(W11:W16) -> 468.46845 | X51: =SUM(X11:X50) -> 0 | Y51: =SUM(Y11:Y50) -> 0 | Z51: =SUM(Z11:Z50) -> 0 | AA51: =SUM(AA11:AA50) -> 0
A53: NHÀ THẦU THI CÔNG | E53: TƯ VẤN GIÁM SÁT
A59: Nguyễn Xuân Hưng | M59: Trần Mạnh Tùng

Sheet 9.KTHH L9
A1: PHỤ LỤC KIỂM TRA CAO ĐỘ, KÍCH THƯỚC HÌNH HỌC
A2: ="Kèm theo BBNT số: "&VLOOKUP(AZ2,'[1]Tuyến XD4'!$A$2:$G$60,7,0)&VLOOKUP(AZ2,'[1]Tuyến XD4'!$A$2:$G$60,4,0) -> Kèm theo BBNT số: 72.NĐXD4/CVXD ngày 20 tháng 09 năm 2026 | AZ2: 72
A3: =+'1.KTHH L1'!A3 -> Dự án: Xây dựng HTKT Khu tái định cư phục vụ di dân xã Hải Hà, thị xã Nghi Sơn, tỉnh Thanh Hóa.
A4: =+'1.KTHH L1'!A4 -> Gói thầu số 12: Xây dựng HTKT khu vực Hải Bình và Xuân Lâm (bao gồm cả bảo hiểm xây dựng công trình)
A5: =+'1.KTHH L1'!A5 -> Nhà thầu thi công: Công ty TNHH Hoàng Tuấn
A6: Hạng mục: Nền đường tuyến XD4
A7: - Đối tượng nghiệm thu: | G7: =VLOOKUP(AZ2,'[1]Tuyến XD4'!$A$2:$B$60,2,0) -> Đắp đất nền đường lớp 9 đoạn từ Km0+672,28 - Km0+746,82, độ chặt K>=0,95
A8: Sơ họa:
A20: TT | B20: Tên cọc | C20: Lý trình | D20: Bên trái (H1) | J20: Tim (H2) | M20: Bên phải (H3) | S20: Ghi chú
D21: KCTK | E21: KCTC | F21: Chênh KC (m) | G21: CDTK (m) | H21: CDTC (m) | I21: Chênh CD (m) | J21: CDTK (m) | K21: CDTC (m) | L21: Chênh CD (m) | M21: KCTK | N21: KCTC | O21: Chênh KC (m) | P21: CDTK (m) | Q21: CDTC (m) | R21: Chênh CD (m)
A22: 1 | B22: 38 | C22: 672.28 | D22: =+Chạy!F2 -> -11.95 | E22: =+D22+F22 -> -11.9583 | F22: =RANDBETWEEN(-105,115)/10000 -> -0.0083 | G22: =+Chạy!G2 -> 1.94 | H22: =G22+I22 -> 1.997 | I22: =RANDBETWEEN(-30,90)/1000 -> 0.057 | J22: =+Chạy!K2 -> 2.06 | K22: =J22+L22 -> 2.043 | L22: =RANDBETWEEN(-30,90)/1000 -> -0.017 | M22: =+Chạy!N2 -> 11.95 | N22: =+M22+O22 -> 11.9489 | O22: =RANDBETWEEN(-105,115)/10000 -> -0.0011 | P22: =+Chạy!O2 -> 1.94 | Q22: =P22+R22 -> 1.942 | R22: =RANDBETWEEN(-30,90)/1000 -> 0.002 | T22: 17
A23: 2 | B23: 39 | C23: =+C22+T22 -> 689.28 | D23: =+Chạy!F11 -> -11.95 | E23: =+D23+F23 -> -11.9489 | F23: =RANDBETWEEN(-105,115)/10000 -> 0.0011 | G23: =+Chạy!G11 -> 1.94 | H23: =G23+I23 -> 1.963 | I23: =RANDBETWEEN(-30,90)/1000 -> 0.023 | J23: =+Chạy!K11 -> 2.06 | K23: =J23+L23 -> 2.064 | L23: =RANDBETWEEN(-30,90)/1000 -> 0.004 | M23: =+Chạy!N11 -> 11.95 | N23: =+M23+O23 -> 11.9596 | O23: =RANDBETWEEN(-105,115)/10000 -> 0.0096 | P23: =+Chạy!O11 -> 1.94 | Q23: =P23+R23 -> 1.935 | R23: =RANDBETWEEN(-30,90)/1000 -> -0.005 | T23: 11.75
A24: 3 | B24: F2 | C24: =+C23+T23 -> 701.03 | D24: =+Chạy!F20 -> -11.95 | E24: =+D24+F24 -> -11.9443 | F24: =RANDBETWEEN(-105,115)/10000 -> 0.0057 | G24: =+Chạy!G20 -> 1.94 | H24: =G24+I24 -> 2.019 | I24: =RANDBETWEEN(-30,90)/1000 -> 0.079 | J24: =+Chạy!K20 -> 2.06 | K24: =J24+L24 -> 2.118 | L24: =RANDBETWEEN(-30,90)/1000 -> 0.058 | M24: =+Chạy!N20 -> -0.67 | N24: =+M24+O24 -> -0.6744 | O24: =RANDBETWEEN(-105,115)/10000 -> -0.0044 | P24: =+Chạy!O20 -> 2.05 | Q24: =P24+R24 -> 2.14 | R24: =RANDBETWEEN(-30,90)/1000 -> 0.09 | T24: 11.75
