Workbook

Sheet Chạy
A1: STT | B1: TC | C1: LT | D1: TL | E1: DT | F1: KCt 1 | G1: CDt 1 | H1: KCt 2 | I1: CDt 2 | J1: KC tim | K1: CD tim | L1: KCp 1 | M1: CDp 1 | N1: KCp 2 | O1: CDp 2 | P1: S bao | Q1: S le
A2: 1 | B2: 24 | C2: 441.84 | D2: 4 | E2: 1.56 | F2: -10.12 | G2: 3.02 | H2: -5.51 | I2: 2.74 | J2: - | K2: - | L2: - | M2: - | N2: - | O2: - | P2: 5.77 | Q2: 0
D3: 3 | E3: 1.05 | F3: -10.93 | G3: 2.68 | H3: -5.25 | I3: 2.68 | J3: - | K3: - | L3: - | M3: - | N3: - | O3: -
D4: 2 | E4: 1.53 | F4: -11.2 | G4: 2.5 | H4: -5.25 | I4: 2.5 | J4: - | K4: - | L4: - | M4: - | N4: - | O4: -
D5: 1 | E5: 1.63 | F5: -11.58 | G5: 2.25 | H5: -5.25 | I5: 2.25 | J5: - | K5: - | L5: - | M5: - | N5: - | O5: -
A6: 1 | B6: 24 | C6: 441.84 | D6: 4 | E6: 1.56 | F6: - | G6: - | H6: - | I6: - | J6: - | K6: - | L6: 5.51 | M6: 2.93 | N6: 10.12 | O6: 2.92 | P6: 5.77 | Q6: 0
D7: 3 | E7: 1.05 | F7: - | G7: - | H7: - | I7: - | J7: - | K7: - | L7: 5.25 | M7: 2.68 | N7: 10.93 | O7: 2.68
D8: 2 | E8: 1.53 | F8: - | G8: - | H8: - | I8: - | J8: - | K8: - | L8: 5.25 | M8: 2.5 | N8: 11.2 | O8: 2.5
D9: 1 | E9: 1.63 | F9: - | G9: - | H9: - | I9: - | J9: - | K9: - | L9: 5.25 | M9: 2.25 | N9: 11.58 | O9: 2.25
A10: 2 | B10: 25 | C10: 454.34 | D10: 4 | E10: 1.56 | F10: -10.12 | G10: 3.01 | H10: -5.51 | I10: 2.73 | J10: - | K10: - | L10: - | M10: - | N10: - | O10: - | P10: 5.77 | Q10: 0
D11: 3 | E11: 1.05 | F11: -10.93 | G11: 2.67 | H11: -5.25 | I11: 2.67 | J11: - | K11: - | L11: - | M11: - | N11: - | O11: -
D12: 2 | E12: 1.53 | F12: -11.2 | G12: 2.49 | H12: -5.25 | I12: 2.49 | J12: - | K12: - | L12: - | M12: - | N12: - | O12: -
D13: 1 | E13: 1.63 | F13: -11.58 | G13: 2.24 | H13: -5.25 | I13: 2.24 | J13: - | K13: - | L13: - | M13: - | N13: - | O13: -
A14: 2 | B14: 25 | C14: 454.34 | D14: 4 | E14: 1.56 | F14: - | G14: - | H14: - | I14: - | J14: - | K14: - | L14: 5.51 | M14: 2.92 | N14: 10.12 | O14: 2.91 | P14: 5.77 | Q14: 0
D15: 3 | E15: 1.05 | F15: - | G15: - | H15: - | I15: - | J15: - | K15: - | L15: 5.25 | M15: 2.67 | N15: 10.93 | O15: 2.67
D16: 2 | E16: 1.53 | F16: - | G16: - | H16: - | I16: - | J16: - | K16: - | L16: 5.25 | M16: 2.49 | N16: 11.2 | O16: 2.49
D17: 1 | E17: 1.63 | F17: - | G17: - | H17: - | I17: - | J17: - | K17: - | L17: 5.25 | M17: 2.24 | N17: 11.58 | O17: 2.24
A18: 3 | B18: 26 | C18: 466.84 | D18: 4 | E18: 1.56 | F18: -10.12 | G18: 3.01 | H18: -5.51 | I18: 2.72 | J18: - | K18: - | L18: - | M18: - | N18: - | O18: - | P18: 5.77 | Q18: 0
D19: 3 | E19: 1.05 | F19: -10.93 | G19: 2.66 | H19: -5.25 | I19: 2.66 | J19: - | K19: - | L19: - | M19: - | N19: - | O19: -
D20: 2 | E20: 1.53 | F20: -11.2 | G20: 2.48 | H20: -5.25 | I20: 2.48 | J20: - | K20: - | L20: - | M20: - | N20: - | O20: -
D21: 1 | E21: 1.63 | F21: -11.58 | G21: 2.23 | H21: -5.25 | I21: 2.23 | J21: - | K21: - | L21: - | M21: - | N21: - | O21: -
A22: 3 | B22: 26 | C22: 466.84 | D22: 4 | E22: 1.56 | F22: - | G22: - | H22: - | I22: - | J22: - | K22: - | L22: 5.51 | M22: 2.91 | N22: 10.12 | O22: 2.91 | P22: 5.77 | Q22: 0
D23: 3 | E23: 1.05 | F23: - | G23: - | H23: - | I23: - | J23: - | K23: - | L23: 5.25 | M23: 2.66 | N23: 10.93 | O23: 2.66
D24: 2 | E24: 1.53 | F24: - | G24: - | H24: - | I24: - | J24: - | K24: - | L24: 5.25 | M24: 2.48 | N24: 11.2 | O24: 2.48
D25: 1 | E25: 1.63 | F25: - | G25: - | H25: - | I25: - | J25: - | K25: - | L25: 5.25 | M25: 2.23 | N25: 11.58 | O25: 2.23
A26: 4 | B26: 27 | C26: 474.34 | D26: 4 | E26: 1.56 | F26: -10.12 | G26: 3 | H26: -5.51 | I26: 2.72 | J26: - | K26: - | L26: - | M26: - | N26: - | O26: - | P26: 5.77 | Q26: 0
D27: 3 | E27: 1.05 | F27: -10.93 | G27: 2.66 | H27: -5.25 | I27: 2.66 | J27: - | K27: - | L27: - | M27: - | N27: - | O27: -
D28: 2 | E28: 1.53 | F28: -11.2 | G28: 2.48 | H28: -5.25 | I28: 2.48 | J28: - | K28: - | L28: - | M28: - | N28: - | O28: -
D29: 1 | E29: 1.63 | F29: -11.58 | G29: 2.23 | H29: -5.25 | I29: 2.23 | J29: - | K29: - | L29: - | M29: - | N29: - | O29: -
A30: 4 | B30: 27 | C30: 474.34 | D30: 4 | E30: 1.56 | F30: - | G30: - | H30: - | I30: - | J30: - | K30: - | L30: 5.51 | M30: 2.91 | N30: 10.12 | O30: 2.9 | P30: 5.77 | Q30: 0
D31: 3 | E31: 1.05 | F31: - | G31: - | H31: - | I31: - | J31: - | K31: - | L31: 5.25 | M31: 2.66 | N31: 10.93 | O31: 2.66
D32: 2 | E32: 1.53 | F32: - | G32: - | H32: - | I32: - | J32: - | K32: - | L32: 5.25 | M32: 2.48 | N32: 11.2 | O32: 2.48
D33: 1 | E33: 1.63 | F33: - | G33: - | H33: - | I33: - | J33: - | K33: - | L33: 5.25 | M33: 2.23 | N33: 11.58 | O33: 2.23
A34: 5 | B34: 28 | C34: 494.34 | D34: 4 | E34: 1.56 | F34: -10.12 | G34: 2.99 | H34: -5.51 | I34: 2.71 | J34: - | K34: - | L34: - | M34: - | N34: - | O34: - | P34: 5.77 | Q34: 0
D35: 3 | E35: 1.05 | F35: -10.93 | G35: 2.65 | H35: -5.25 | I35: 2.65 | J35: - | K35: - | L35: - | M35: - | N35: - | O35: -
D36: 2 | E36: 1.53 | F36: -11.2 | G36: 2.47 | H36: -5.25 | I36: 2.47 | J36: - | K36: - | L36: - | M36: - | N36: - | O36: -
D37: 1 | E37: 1.63 | F37: -11.58 | G37: 2.22 | H37: -5.25 | I37: 2.22 | J37: - | K37: - | L37: - | M37: - | N37: - | O37: -
A38: 5 | B38: 28 | C38: 494.34 | D38: 4 | E38: 1.56 | F38: - | G38: - | H38: - | I38: - | J38: - | K38: - | L38: 5.51 | M38: 2.9 | N38: 10.12 | O38: 2.89 | P38: 5.77 | Q38: 0
D39: 3 | E39: 1.05 | F39: - | G39: - | H39: - | I39: - | J39: - | K39: - | L39: 5.25 | M39: 2.65 | N39: 10.93 | O39: 2.65
D40: 2 | E40: 1.53 | F40: - | G40: - | H40: - | I40: - | J40: - | K40: - | L40: 5.25 | M40: 2.47 | N40: 11.2 | O40: 2.47
...

Sheet 1. KTHH L1
A1: PHỤ LỤC KIỂM TRA CAO ĐỘ, KÍCH THƯỚC HÌNH HỌC
A2: ="Kèm theo BBNT số: "&VLOOKUP(AZ2,'[1]Tuyến XD4'!$A$2:$G$60,7,0)&VLOOKUP(AZ2,'[1]Tuyến XD4'!$A$2:$G$60,4,0) -> Kèm theo BBNT số: 18.NĐXD4/CVXD ngày 24 tháng 08 năm 2026 | AZ2: 18
A3: Dự án: Xây dựng HTKT Khu tái định cư phục vụ di dân xã Hải Hà, thị xã Nghi Sơn, tỉnh Thanh Hóa.
A4: Gói thầu số 12: Xây dựng HTKT khu vực Hải Bình và Xuân Lâm (bao gồm cả bảo hiểm xây dựng công trình)
A5: Nhà thầu thi công: Công ty TNHH Hoàng Tuấn
A6: Hạng mục: Nền đường tuyến XD4
A7: - Đối tượng nghiệm thu: | D7: =VLOOKUP(AZ2,'[1]Tuyến XD4'!$A$2:$B$60,2,0) -> Đắp đất lề đường lớp 1, độ chặt K>=0,95 đoạn từ Km0+441,84 - Km0+554,08
A8: Sơ họa:
A19: TT | B19: Tên cọc | C19: Lý trình | D19: Lề trái (H1) | G19: Lề trái (H2) | J19: Lề phải (H3) | M19: Lề phải (H4) | P19: Ghi chú
D20: CDTK (m) | E20: CDTC (m) | F20: Chênh CD (m) | G20: CDTK (m) | H20: CDTC (m) | I20: Chênh CD (m) | J20: CDTK (m) | K20: CDTC (m) | L20: Chênh CD (m) | M20: CDTK (m) | N20: CDTC (m) | O20: Chênh CD (m)
A21: 1 | B21: 24 | C21: 441.84 | D21: =Chạy!G5 -> 2.25 | E21: =D21+F21 -> 2.337 | F21: =RANDBETWEEN(-30,100)/1000 -> 0.087 | G21: =Chạy!I5 -> 2.25 | H21: =G21+I21 -> 2.242 | I21: =RANDBETWEEN(-30,100)/1000 -> -0.008 | J21: =Chạy!M9 -> 2.25 | K21: =J21+L21 -> 2.304 | L21: =RANDBETWEEN(-30,100)/1000 -> 0.054 | M21: =Chạy!O9 -> 2.25 | N21: =M21+O21 -> 2.235 | O21: =RANDBETWEEN(-30,100)/1000 -> -0.015 | Q21: 12.5
A22: 2 | B22: 25 | C22: =C21+Q21 -> 454.34 | D22: =Chạy!G13 -> 2.24 | E22: =D22+F22 -> 2.323 | F22: =RANDBETWEEN(-30,100)/1000 -> 0.083 | G22: =Chạy!I13 -> 2.24 | H22: =G22+I22 -> 2.284 | I22: =RANDBETWEEN(-30,100)/1000 -> 0.044 | J22: =Chạy!M17 -> 2.24 | K22: =J22+L22 -> 2.331 | L22: =RANDBETWEEN(-30,100)/1000 -> 0.091 | M22: =Chạy!O17 -> 2.24 | N22: =M22+O22 -> 2.252 | O22: =RANDBETWEEN(-30,100)/1000 -> 0.012 | Q22: 12.5
A23: 3 | B23: 26 | C23: =C22+Q22 -> 466.84 | D23: =Chạy!G21 -> 2.23 | E23: =D23+F23 -> 2.282 | F23: =RANDBETWEEN(-30,100)/1000 -> 0.052 | G23: =Chạy!I21 -> 2.23 | H23: =G23+I23 -> 2.208 | I23: =RANDBETWEEN(-30,100)/1000 -> -0.022 | J23: =Chạy!M25 -> 2.23 | K23: =J23+L23 -> 2.254 | L23: =RANDBETWEEN(-30,100)/1000 -> 0.024 | M23: =Chạy!O25 -> 2.23 | N23: =M23+O23 -> 2.232 | O23: =RANDBETWEEN(-30,100)/1000 -> 0.002 | Q23: 7.5
A24: 4 | B24: 27 | C24: =C23+Q23 -> 474.34 | D24: =Chạy!G29 -> 2.23 | E24: =D24+F24 -> 2.263 | F24: =RANDBETWEEN(-30,100)/1000 -> 0.033 | G24: =Chạy!I29 -> 2.23 | H24: =G24+I24 -> 2.216 | I24: =RANDBETWEEN(-30,100)/1000 -> -0.014 | J24: =Chạy!M33 -> 2.23 | K24: =J24+L24 -> 2.293 | L24: =RANDBETWEEN(-30,100)/1000 -> 0.063 | M24: =Chạy!O33 -> 2.23 | N24: =M24+O24 -> 2.323 | O24: =RANDBETWEEN(-30,100)/1000 -> 0.093 | Q24: 20
A25: 5 | B25: 28 | C25: =C24+Q24 -> 494.34 | D25: =Chạy!G37 -> 2.22 | E25: =D25+F25 -> 2.249 | F25: =RANDBETWEEN(-30,100)/1000 -> 0.029 | G25: =Chạy!I37 -> 2.22 | H25: =G25+I25 -> 2.317 | I25: =RANDBETWEEN(-30,100)/1000 -> 0.097 | J25: =Chạy!M41 -> 2.22 | K25: =J25+L25 -> 2.218 | L25: =RANDBETWEEN(-30,100)/1000 -> -0.002 | M25: =Chạy!O41 -> 2.22 | N25: =M25+O25 -> 2.222 | O25: =RANDBETWEEN(-30,100)/1000 -> 0.002 | Q25: 17.14
A26: 6 | B26: 29 | C26: =C25+Q25 -> 511.48 | D26: =Chạy!G45 -> 2.21 | E26: =D26+F26 -> 2.252 | F26: =RANDBETWEEN(-30,100)/1000 -> 0.042 | G26: =Chạy!I45 -> 2.21 | H26: =G26+I26 -> 2.203 | I26: =RANDBETWEEN(-30,100)/1000 -> -0.007 | J26: =Chạy!M49 -> 2.21 | K26: =J26+L26 -> 2.285 | L26: =RANDBETWEEN(-30,100)/1000 -> 0.075 | M26: =Chạy!O49 -> 2.21 | N26: =M26+O26 -> 2.188 | O26: =RANDBETWEEN(-30,100)/1000 -> -0.022 | Q26: 3.12
A27: 7 | B27: 30 | C27: =C26+Q26 -> 514.6 | D27: =Chạy!G53 -> 2.21 | E27: =D27+F27 -> 2.183 | F27: =RANDBETWEEN(-30,100)/1000 -> -0.027 | G27: =Chạy!I53 -> 2.21 | H27: =G27+I27 -> 2.196 | I27: =RANDBETWEEN(-30,100)/1000 -> -0.014 | J27: =Chạy!M57 -> 2.21 | K27: =J27+L27 -> 2.25 | L27: =RANDBETWEEN(-30,100)/1000 -> 0.04 | M27: =Chạy!O57 -> 2.21 | N27: =M27+O27 -> 2.245 | O27: =RANDBETWEEN(-30,100)/1000 -> 0.035 | Q27: 10.48
A28: 8 | B28: D | C28: =C27+Q27 -> 525.08 | D28: =Chạy!G61 -> 2.2 | E28: =D28+F28 -> 2.216 | F28: =RANDBETWEEN(-30,100)/1000 -> 0.016 | G28: =Chạy!I61 -> 2.2 | H28: =G28+I28 -> 2.244 | I28: =RANDBETWEEN(-30,100)/1000 -> 0.044 | J28: =Chạy!M65 -> 2.2 | K28: =J28+L28 -> 2.255 | L28: =RANDBETWEEN(-30,100)/1000 -> 0.055 | M28: =Chạy!O65 -> 2.2 | N28: =M28+O28 -> 2.27 | O28: =RANDBETWEEN(-30,100)/1000 -> 0.07 | Q28: 13.6
A29: 9 | B29: 31 | C29: =C28+Q28 -> 538.68 | D29: =Chạy!G69 -> 2.2 | E29: =D29+F29 -> 2.282 | F29: =RANDBETWEEN(-30,100)/1000 -> 0.082 | G29: =Chạy!I69 -> 2.2 | H29: =G29+I29 -> 2.295 | I29: =RANDBETWEEN(-30,100)/1000 -> 0.095 | J29: =Chạy!M73 -> 2.2 | K29: =J29+L29 -> 2.234 | L29: =RANDBETWEEN(-30,100)/1000 -> 0.034 | M29: =Chạy!O73 -> 2.2 | N29: =M29+O29 -> 2.196 | O29: =RANDBETWEEN(-30,100)/1000 -> -0.004 | Q29: 15.4
A30: 10 | B30: 32 | C30: =C29+Q29 -> 554.08 | D30: =Chạy!G77 -> 2.19 | E30: =D30+F30 -> 2.266 | F30: =RANDBETWEEN(-30,100)/1000 -> 0.076 | G30: =Chạy!I77 -> 2.19 | H30: =G30+I30 -> 2.176 | I30: =RANDBETWEEN(-30,100)/1000 -> -0.014 | J30: =Chạy!M81 -> 2.19 | K30: =J30+L30 -> 2.245 | L30: =RANDBETWEEN(-30,100)/1000 -> 0.055 | M30: =Chạy!O81 -> 2.19 | N30: =M30+O30 -> 2.201 | O30: =RANDBETWEEN(-30,100)/1000 -> 0.011
C60: NHÀ THẦU THI CÔNG | K60: TƯ VẤN GIÁM SÁT
C65: Nguyễn Xuân Hưng | K65: Trần Mạnh Tùng

Sheet KL L1
A1: PHỤ LỤC KHỐI LƯỢNG
A2: ="Kèm theo BBNT số: "&VLOOKUP(AZ2,'[1]Tuyến XD4'!$A$2:$G$60,7,0)&VLOOKUP(AZ2,'[1]Tuyến XD4'!$A$2:$G$60,4,0) -> Kèm theo BBNT số: 18.NĐXD4/CVXD ngày 24 tháng 08 năm 2026 | AZ2: 18
A3: Dự án: Xây dựng HTKT Khu tái định cư phục vụ di dân xã Hải Hà, thị xã Nghi Sơn, tỉnh Thanh Hóa.
A4: Gói thầu số 12: Xây dựng HTKT khu vực Hải Bình và Xuân Lâm (bao gồm cả bảo hiểm xây dựng công trình)
A5: Nhà thầu thi công: Công ty TNHH Hoàng Tuấn
A6: Hạng mục: Nền đường tuyến XD4
A7: - Đối tượng nghiệm thu: | D7: =VLOOKUP(AZ2,'[1]Tuyến XD4'!$A$2:$B$60,2,0) -> Đắp đất lề đường lớp 1, độ chặt K>=0,95 đoạn từ Km0+441,84 - Km0+554,08
A9: STT | B9: Tên cọc | C9: Lý trình | D9: K/c lẻ | G9: Ghi chú
E10: Diện tích | F10: Khối lượng
A11: 1 | B11: ='1. KTHH L1'!B21 -> 24 | C11: ='1. KTHH L1'!C21 -> 441.84 | D11: ='1. KTHH L1'!Q21 -> 12.5 | E11: =Chạy!E5+Chạy!E9 -> 3.26 | F11: =(E11+E12)*D11/2 -> 40.75
A12: 2 | B12: ='1. KTHH L1'!B22 -> 25 | C12: ='1. KTHH L1'!C22 -> 454.34 | D12: ='1. KTHH L1'!Q22 -> 12.5 | E12: =Chạy!E13+Chạy!E17 -> 3.26 | F12: =(E12+E13)*D12/2 -> 40.75
A13: 3 | B13: ='1. KTHH L1'!B23 -> 26 | C13: ='1. KTHH L1'!C23 -> 466.84 | D13: ='1. KTHH L1'!Q23 -> 7.5 | E13: =Chạy!E21+Chạy!E25 -> 3.26 | F13: =(E13+E14)*D13/2 -> 24.45
A14: 4 | B14: ='1. KTHH L1'!B24 -> 27 | C14: ='1. KTHH L1'!C24 -> 474.34 | D14: ='1. KTHH L1'!Q24 -> 20 | E14: =Chạy!E29+Chạy!E33 -> 3.26 | F14: =(E14+E15)*D14/2 -> 65.2
A15: 5 | B15: ='1. KTHH L1'!B25 -> 28 | C15: ='1. KTHH L1'!C25 -> 494.34 | D15: ='1. KTHH L1'!Q25 -> 17.14 | E15: =Chạy!E37+Chạy!E41 -> 3.26 | F15: =(E15+E16)*D15/2 -> 55.8764
A16: 6 | B16: ='1. KTHH L1'!B26 -> 29 | C16: ='1. KTHH L1'!C26 -> 511.48 | D16: ='1. KTHH L1'!Q26 -> 3.12 | E16: =Chạy!E45+Chạy!E49 -> 3.26 | F16: =(E16+E17)*D16/2 -> 10.1712
A17: 7 | B17: ='1. KTHH L1'!B27 -> 30 | C17: ='1. KTHH L1'!C27 -> 514.6 | D17: ='1. KTHH L1'!Q27 -> 10.48 | E17: =Chạy!E53+Chạy!E57 -> 3.26 | F17: =(E17+E18)*D17/2 -> 34.1648
A18: 8 | B18: ='1. KTHH L1'!B28 -> D | C18: ='1. KTHH L1'!C28 -> 525.08 | D18: ='1. KTHH L1'!Q28 -> 13.6 | E18: =Chạy!E61+Chạy!E65 -> 3.26 | F18: =(E18+E19)*D18/2 -> 44.336
A19: 9 | B19: ='1. KTHH L1'!B29 -> 31 | C19: ='1. KTHH L1'!C29 -> 538.68 | D19: ='1. KTHH L1'!Q29 -> 15.4 | E19: =Chạy!E69+Chạy!E73 -> 3.26 | F19: =(E19+E20)*D19/2 -> 50.204
A20: 10 | B20: ='1. KTHH L1'!B30 -> 32 | C20: ='1. KTHH L1'!C30 -> 554.08 | E20: =Chạy!E77+Chạy!E81 -> 3.26
A49: Tổng cộng (m3) | F49: =SUM(F11:F20) -> 365.9024
A51: NHÀ THẦU THI CÔNG | E51: TƯ VẤN GIÁM SÁT
A57: Nguyễn Xuân Hưng | E57: Trần Mạnh Tùng

Sheet 1. KTHH L2
A1: PHỤ LỤC KIỂM TRA CAO ĐỘ, KÍCH THƯỚC HÌNH HỌC
A2: ="Kèm theo BBNT số: "&VLOOKUP(AZ2,'[1]Tuyến XD4'!$A$2:$G$60,7,0)&VLOOKUP(AZ2,'[1]Tuyến XD4'!$A$2:$G$60,4,0) -> Kèm theo BBNT số: 20.NĐXD4/CVXD ngày 25 tháng 08 năm 2026 | AZ2: 20
A3: Dự án: Xây dựng HTKT Khu tái định cư phục vụ di dân xã Hải Hà, thị xã Nghi Sơn, tỉnh Thanh Hóa.
A4: Gói thầu số 12: Xây dựng HTKT khu vực Hải Bình và Xuân Lâm (bao gồm cả bảo hiểm xây dựng công trình)
A5: Nhà thầu thi công: Công ty TNHH Hoàng Tuấn
A6: Hạng mục: Nền đường tuyến XD4
A7: - Đối tượng nghiệm thu: | D7: =VLOOKUP(AZ2,'[1]Tuyến XD4'!$A$2:$B$60,2,0) -> Đắp đất lề đường lớp 2, độ chặt K>=0,95 đoạn từ Km0+441,84 - Km0+554,08
A8: Sơ họa:
A19: TT | B19: Tên cọc | C19: Lý trình | D19: Lề trái (H1) | G19: Lề trái (H2) | J19: Lề phải (H3) | M19: Lề phải (H4) | P19: Ghi chú
D20: CDTK (m) | E20: CDTC (m) | F20: Chênh CD (m) | G20: CDTK (m) | H20: CDTC (m) | I20: Chênh CD (m) | J20: CDTK (m) | K20: CDTC (m) | L20: Chênh CD (m) | M20: CDTK (m) | N20: CDTC (m) | O20: Chênh CD (m)
A21: 1 | B21: 24 | C21: 441.84 | D21: =Chạy!G4 -> 2.5 | E21: =D21+F21 -> 2.51 | F21: =RANDBETWEEN(-30,100)/1000 -> 0.01 | G21: =Chạy!I4 -> 2.5 | H21: =G21+I21 -> 2.517 | I21: =RANDBETWEEN(-30,100)/1000 -> 0.017 | J21: =Chạy!M8 -> 2.5 | K21: =J21+L21 -> 2.522 | L21: =RANDBETWEEN(-30,100)/1000 -> 0.022 | M21: =Chạy!O8 -> 2.5 | N21: =M21+O21 -> 2.551 | O21: =RANDBETWEEN(-30,100)/1000 -> 0.051 | Q21: 12.5
A22: 2 | B22: 25 | C22: =C21+Q21 -> 454.34 | D22: =Chạy!G12 -> 2.49 | E22: =D22+F22 -> 2.574 | F22: =RANDBETWEEN(-30,100)/1000 -> 0.084 | G22: =Chạy!I12 -> 2.49 | H22: =G22+I22 -> 2.557 | I22: =RANDBETWEEN(-30,100)/1000 -> 0.067 | J22: =Chạy!M16 -> 2.49 | K22: =J22+L22 -> 2.545 | L22: =RANDBETWEEN(-30,100)/1000 -> 0.055 | M22: =Chạy!O16 -> 2.49 | N22: =M22+O22 -> 2.519 | O22: =RANDBETWEEN(-30,100)/1000 -> 0.029 | Q22: 12.5
A23: 3 | B23: 26 | C23: =C22+Q22 -> 466.84 | D23: =Chạy!G20 -> 2.48 | E23: =D23+F23 -> 2.535 | F23: =RANDBETWEEN(-30,100)/1000 -> 0.055 | G23: =Chạy!I20 -> 2.48 | H23: =G23+I23 -> 2.572 | I23: =RANDBETWEEN(-30,100)/1000 -> 0.092 | J23: =Chạy!M24 -> 2.48 | K23: =J23+L23 -> 2.534 | L23: =RANDBETWEEN(-30,100)/1000 -> 0.054 | M23: =Chạy!O24 -> 2.48 | N23: =M23+O23 -> 2.533 | O23: =RANDBETWEEN(-30,100)/1000 -> 0.053 | Q23: 7.5
A24: 4 | B24: 27 | C24: =C23+Q23 -> 474.34 | D24: =Chạy!G28 -> 2.48 | E24: =D24+F24 -> 2.467 | F24: =RANDBETWEEN(-30,100)/1000 -> -0.013 | G24: =Chạy!I28 -> 2.48 | H24: =G24+I24 -> 2.564 | I24: =RANDBETWEEN(-30,100)/1000 -> 0.084 | J24: =Chạy!M32 -> 2.48 | K24: =J24+L24 -> 2.551 | L24: =RANDBETWEEN(-30,100)/1000 -> 0.071 | M24: =Chạy!O32 -> 2.48 | N24: =M24+O24 -> 2.46 | O24: =RANDBETWEEN(-30,100)/1000 -> -0.02 | Q24: 20
A25: 5 | B25: 28 | C25: =C24+Q24 -> 494.34 | D25: =Chạy!G36 -> 2.47 | E25: =D25+F25 -> 2.445 | F25: =RANDBETWEEN(-30,100)/1000 -> -0.025 | G25: =Chạy!I36 -> 2.47 | H25: =G25+I25 -> 2.569 | I25: =RANDBETWEEN(-30,100)/1000 -> 0.099 | J25: =Chạy!M40 -> 2.47 | K25: =J25+L25 -> 2.478 | L25: =RANDBETWEEN(-30,100)/1000 -> 0.008 | M25: =Chạy!O40 -> 2.47 | N25: =M25+O25 -> 2.529 | O25: =RANDBETWEEN(-30,100)/1000 -> 0.059 | Q25: 17.14
A26: 6 | B26: 29 | C26: =C25+Q25 -> 511.48 | D26: =Chạy!G44 -> 2.46 | E26: =D26+F26 -> 2.536 | F26: =RANDBETWEEN(-30,100)/1000 -> 0.076 | G26: =Chạy!I44 -> 2.46 | H26: =G26+I26 -> 2.434 | I26: =RANDBETWEEN(-30,100)/1000 -> -0.026 | J26: =Chạy!M48 -> 2.46 | K26: =J26+L26 -> 2.434 | L26: =RANDBETWEEN(-30,100)/1000 -> -0.026 | M26: =Chạy!O48 -> 2.46 | N26: =M26+O26 -> 2.45 | O26: =RANDBETWEEN(-30,100)/1000 -> -0.01 | Q26: 3.12
A27: 7 | B27: 30 | C27: =C26+Q26 -> 514.6 | D27: =Chạy!G52 -> 2.46 | E27: =D27+F27 -> 2.52 | F27: =RANDBETWEEN(-30,100)/1000 -> 0.06 | G27: =Chạy!I52 -> 2.46 | H27: =G27+I27 -> 2.43 | I27: =RANDBETWEEN(-30,100)/1000 -> -0.03 | J27: =Chạy!M56 -> 2.46 | K27: =J27+L27 -> 2.55 | L27: =RANDBETWEEN(-30,100)/1000 -> 0.09 | M27: =Chạy!O56 -> 2.46 | N27: =M27+O27 -> 2.537 | O27: =RANDBETWEEN(-30,100)/1000 -> 0.077 | Q27: 10.48
A28: 8 | B28: D | C28: =C27+Q27 -> 525.08 | D28: =Chạy!G60 -> 2.45 | E28: =D28+F28 -> 2.46 | F28: =RANDBETWEEN(-30,100)/1000 -> 0.01 | G28: =Chạy!I60 -> 2.45 | H28: =G28+I28 -> 2.468 | I28: =RANDBETWEEN(-30,100)/1000 -> 0.018 | J28: =Chạy!M64 -> 2.45 | K28: =J28+L28 -> 2.457 | L28: =RANDBETWEEN(-30,100)/1000 -> 0.007 | M28: =Chạy!O64 -> 2.45 | N28: =M28+O28 -> 2.43 | O28: =RANDBETWEEN(-30,100)/1000 -> -0.02 | Q28: 13.6
A29: 9 | B29: 31 | C29: =C28+Q28 -> 538.68 | D29: =Chạy!G68 -> 2.45 | E29: =D29+F29 -> 2.42 | F29: =RANDBETWEEN(-30,100)/1000 -> -0.03 | G29: =Chạy!I68 -> 2.45 | H29: =G29+I29 -> 2.421 | I29: =RANDBETWEEN(-30,100)/1000 -> -0.029 | J29: =Chạy!M72 -> 2.45 | K29: =J29+L29 -> 2.535 | L29: =RANDBETWEEN(-30,100)/1000 -> 0.085 | M29: =Chạy!O72 -> 2.45 | N29: =M29+O29 -> 2.491 | O29: =RANDBETWEEN(-30,100)/1000 -> 0.041 | Q29: 15.4
A30: 10 | B30: 32 | C30: =C29+Q29 -> 554.08 | D30: =Chạy!G76 -> 2.44 | E30: =D30+F30 -> 2.495 | F30: =RANDBETWEEN(-30,100)/1000 -> 0.055 | G30: =Chạy!I76 -> 2.44 | H30: =G30+I30 -> 2.426 | I30: =RANDBETWEEN(-30,100)/1000 -> -0.014 | J30: =Chạy!M80 -> 2.44 | K30: =J30+L30 -> 2.508 | L30: =RANDBETWEEN(-30,100)/1000 -> 0.068 | M30: =Chạy!O80 -> 2.44 | N30: =M30+O30 -> 2.517 | O30: =RANDBETWEEN(-30,100)/1000 -> 0.077
C60: NHÀ THẦU THI CÔNG | K60: TƯ VẤN GIÁM SÁT
C65: Nguyễn Xuân Hưng | K65: Trần Mạnh Tùng

Sheet KL L2
A1: PHỤ LỤC KHỐI LƯỢNG
A2: ="Kèm theo BBNT số: "&VLOOKUP(AZ2,'[1]Tuyến XD4'!$A$2:$G$60,7,0)&VLOOKUP(AZ2,'[1]Tuyến XD4'!$A$2:$G$60,4,0) -> Kèm theo BBNT số: 20.NĐXD4/CVXD ngày 25 tháng 08 năm 2026 | AZ2: 20
A3: Dự án: Xây dựng HTKT Khu tái định cư phục vụ di dân xã Hải Hà, thị xã Nghi Sơn, tỉnh Thanh Hóa.
A4: Gói thầu số 12: Xây dựng HTKT khu vực Hải Bình và Xuân Lâm (bao gồm cả bảo hiểm xây dựng công trình)
A5: Nhà thầu thi công: Công ty TNHH Hoàng Tuấn
A6: Hạng mục: Nền đường tuyến XD4
A7: - Đối tượng nghiệm thu: | D7: =VLOOKUP(AZ2,'[1]Tuyến XD4'!$A$2:$B$60,2,0) -> Đắp đất lề đường lớp 2, độ chặt K>=0,95 đoạn từ Km0+441,84 - Km0+554,08
A9: STT | B9: Tên cọc | C9: Lý trình | D9: K/c lẻ | G9: Ghi chú
E10: Diện tích | F10: Khối lượng
A11: 1 | B11: ='1. KTHH L2'!B21 -> 24 | C11: ='1. KTHH L2'!C21 -> 441.84 | D11: ='1. KTHH L2'!Q21 -> 12.5 | E11: =Chạy!E4+Chạy!E8 -> 3.06 | F11: =(E11+E12)*D11/2 -> 38.25
A12: 2 | B12: ='1. KTHH L2'!B22 -> 25 | C12: ='1. KTHH L2'!C22 -> 454.34 | D12: ='1. KTHH L2'!Q22 -> 12.5 | E12: =Chạy!E12+Chạy!E16 -> 3.06 | F12: =(E12+E13)*D12/2 -> 38.25
A13: 3 | B13: ='1. KTHH L2'!B23 -> 26 | C13: ='1. KTHH L2'!C23 -> 466.84 | D13: ='1. KTHH L2'!Q23 -> 7.5 | E13: =Chạy!E20+Chạy!E24 -> 3.06 | F13: =(E13+E14)*D13/2 -> 22.95
A14: 4 | B14: ='1. KTHH L2'!B24 -> 27 | C14: ='1. KTHH L2'!C24 -> 474.34 | D14: ='1. KTHH L2'!Q24 -> 20 | E14: =Chạy!E28+Chạy!E32 -> 3.06 | F14: =(E14+E15)*D14/2 -> 61.2
A15: 5 | B15: ='1. KTHH L2'!B25 -> 28 | C15: ='1. KTHH L2'!C25 -> 494.34 | D15: ='1. KTHH L2'!Q25 -> 17.14 | E15: =Chạy!E36+Chạy!E40 -> 3.06 | F15: =(E15+E16)*D15/2 -> 52.4484
A16: 6 | B16: ='1. KTHH L2'!B26 -> 29 | C16: ='1. KTHH L2'!C26 -> 511.48 | D16: ='1. KTHH L2'!Q26 -> 3.12 | E16: =Chạy!E44+Chạy!E48 -> 3.06 | F16: =(E16+E17)*D16/2 -> 9.5472
A17: 7 | B17: ='1. KTHH L2'!B27 -> 30 | C17: ='1. KTHH L2'!C27 -> 514.6 | D17: ='1. KTHH L2'!Q27 -> 10.48 | E17: =Chạy!E52+Chạy!E56 -> 3.06 | F17: =(E17+E18)*D17/2 -> 32.0688
A18: 8 | B18: ='1. KTHH L2'!B28 -> D | C18: ='1. KTHH L2'!C28 -> 525.08 | D18: ='1. KTHH L2'!Q28 -> 13.6 | E18: =Chạy!E60+Chạy!E64 -> 3.06 | F18: =(E18+E19)*D18/2 -> 41.616
A19: 9 | B19: ='1. KTHH L2'!B29 -> 31 | C19: ='1. KTHH L2'!C29 -> 538.68 | D19: ='1. KTHH L2'!Q29 -> 15.4 | E19: =Chạy!E68+Chạy!E72 -> 3.06 | F19: =(E19+E20)*D19/2 -> 47.124
A20: 10 | B20: ='1. KTHH L2'!B30 -> 32 | C20: ='1. KTHH L2'!C30 -> 554.08 | E20: =Chạy!E76+Chạy!E80 -> 3.06
A49: Tổng cộng (m3) | F49: =SUM(F11:F20) -> 343.4544
A51: NHÀ THẦU THI CÔNG | E51: TƯ VẤN GIÁM SÁT
A57: Nguyễn Xuân Hưng | E57: Trần Mạnh Tùng

Sheet 1. KTHH L3
A1: PHỤ LỤC KIỂM TRA CAO ĐỘ, KÍCH THƯỚC HÌNH HỌC
A2: ="Kèm theo BBNT số: "&VLOOKUP(AZ2,'[1]Tuyến XD4'!$A$2:$G$60,7,0)&VLOOKUP(AZ2,'[1]Tuyến XD4'!$A$2:$G$60,4,0) -> Kèm theo BBNT số: 22.NĐXD4/CVXD ngày 26 tháng 08 năm 2026 | AZ2: 22
A3: Dự án: Xây dựng HTKT Khu tái định cư phục vụ di dân xã Hải Hà, thị xã Nghi Sơn, tỉnh Thanh Hóa.
A4: Gói thầu số 12: Xây dựng HTKT khu vực Hải Bình và Xuân Lâm (bao gồm cả bảo hiểm xây dựng công trình)
A5: Nhà thầu thi công: Công ty TNHH Hoàng Tuấn
A6: Hạng mục: Nền đường tuyến XD4
A7: - Đối tượng nghiệm thu: | D7: =VLOOKUP(AZ2,'[1]Tuyến XD4'!$A$2:$B$60,2,0) -> Đắp đất lề đường lớp 3, độ chặt K>=0,95 đoạn từ Km0+441,84 - Km0+554,08
A8: Sơ họa:
A19: TT | B19: Tên cọc | C19: Lý trình | D19: Lề trái (H1) | G19: Lề trái (H2) | J19: Lề phải (H3) | M19: Lề phải (H4) | P19: Ghi chú
D20: CDTK (m) | E20: CDTC (m) | F20: Chênh CD (m) | G20: CDTK (m) | H20: CDTC (m) | I20: Chênh CD (m) | J20: CDTK (m) | K20: CDTC (m) | L20: Chênh CD (m) | M20: CDTK (m) | N20: CDTC (m) | O20: Chênh CD (m)
A21: 1 | B21: 24 | C21: 441.84 | D21: =Chạy!G3 -> 2.68 | E21: =D21+F21 -> 2.677 | F21: =RANDBETWEEN(-30,100)/1000 -> -0.003 | G21: =Chạy!I3 -> 2.68 | H21: =G21+I21 -> 2.717 | I21: =RANDBETWEEN(-30,100)/1000 -> 0.037 | J21: =Chạy!M7 -> 2.68 | K21: =J21+L21 -> 2.78 | L21: =RANDBETWEEN(-30,100)/1000 -> 0.1 | M21: =Chạy!O7 -> 2.68 | N21: =M21+O21 -> 2.715 | O21: =RANDBETWEEN(-30,100)/1000 -> 0.035 | Q21: 12.5
A22: 2 | B22: 25 | C22: =C21+Q21 -> 454.34 | D22: =Chạy!G11 -> 2.67 | E22: =D22+F22 -> 2.661 | F22: =RANDBETWEEN(-30,100)/1000 -> -0.009 | G22: =Chạy!I11 -> 2.67 | H22: =G22+I22 -> 2.673 | I22: =RANDBETWEEN(-30,100)/1000 -> 0.003 | J22: =Chạy!M15 -> 2.67 | K22: =J22+L22 -> 2.685 | L22: =RANDBETWEEN(-30,100)/1000 -> 0.015 | M22: =Chạy!O15 -> 2.67 | N22: =M22+O22 -> 2.675 | O22: =RANDBETWEEN(-30,100)/1000 -> 0.005 | Q22: 12.5
A23: 3 | B23: 26 | C23: =C22+Q22 -> 466.84 | D23: =Chạy!G19 -> 2.66 | E23: =D23+F23 -> 2.722 | F23: =RANDBETWEEN(-30,100)/1000 -> 0.062 | G23: =Chạy!I19 -> 2.66 | H23: =G23+I23 -> 2.651 | I23: =RANDBETWEEN(-30,100)/1000 -> -0.009 | J23: =Chạy!M23 -> 2.66 | K23: =J23+L23 -> 2.678 | L23: =RANDBETWEEN(-30,100)/1000 -> 0.018 | M23: =Chạy!O23 -> 2.66 | N23: =M23+O23 -> 2.686 | O23: =RANDBETWEEN(-30,100)/1000 -> 0.026 | Q23: 7.5
A24: 4 | B24: 27 | C24: =C23+Q23 -> 474.34 | D24: =Chạy!G27 -> 2.66 | E24: =D24+F24 -> 2.715 | F24: =RANDBETWEEN(-30,100)/1000 -> 0.055 | G24: =Chạy!I27 -> 2.66 | H24: =G24+I24 -> 2.666 | I24: =RANDBETWEEN(-30,100)/1000 -> 0.006 | J24: =Chạy!M31 -> 2.66 | K24: =J24+L24 -> 2.665 | L24: =RANDBETWEEN(-30,100)/1000 -> 0.005 | M24: =Chạy!O31 -> 2.66 | N24: =M24+O24 -> 2.735 | O24: =RANDBETWEEN(-30,100)/1000 -> 0.075 | Q24: 20
A25: 5 | B25: 28 | C25: =C24+Q24 -> 494.34 | D25: =Chạy!G35 -> 2.65 | E25: =D25+F25 -> 2.648 | F25: =RANDBETWEEN(-30,100)/1000 -> -0.002 | G25: =Chạy!I35 -> 2.65 | H25: =G25+I25 -> 2.715 | I25: =RANDBETWEEN(-30,100)/1000 -> 0.065 | J25: =Chạy!M39 -> 2.65 | K25: =J25+L25 -> 2.644 | L25: =RANDBETWEEN(-30,100)/1000 -> -0.006 | M25: =Chạy!O39 -> 2.65 | N25: =M25+O25 -> 2.682 | O25: =RANDBETWEEN(-30,100)/1000 -> 0.032 | Q25: 17.14
A26: 6 | B26: 29 | C26: =C25+Q25 -> 511.48 | D26: =Chạy!G43 -> 2.64 | E26: =D26+F26 -> 2.651 | F26: =RANDBETWEEN(-30,100)/1000 -> 0.011 | G26: =Chạy!I43 -> 2.64 | H26: =G26+I26 -> 2.686 | I26: =RANDBETWEEN(-30,100)/1000 -> 0.046 | J26: =Chạy!M47 -> 2.64 | K26: =J26+L26 -> 2.705 | L26: =RANDBETWEEN(-30,100)/1000 -> 0.065 | M26: =Chạy!O47 -> 2.64 | N26: =M26+O26 -> 2.688 | O26: =RANDBETWEEN(-30,100)/1000 -> 0.048 | Q26: 3.12
A27: 7 | B27: 30 | C27: =C26+Q26 -> 514.6 | D27: =Chạy!G51 -> 2.64 | E27: =D27+F27 -> 2.623 | F27: =RANDBETWEEN(-30,100)/1000 -> -0.017 | G27: =Chạy!I51 -> 2.64 | H27: =G27+I27 -> 2.719 | I27: =RANDBETWEEN(-30,100)/1000 -> 0.079 | J27: =Chạy!M55 -> 2.64 | K27: =J27+L27 -> 2.625 | L27: =RANDBETWEEN(-30,100)/1000 -> -0.015 | M27: =Chạy!O55 -> 2.64 | N27: =M27+O27 -> 2.64 | O27: =RANDBETWEEN(-30,100)/1000 -> 0 | Q27: 10.48
A28: 8 | B28: D | C28: =C27+Q27 -> 525.08 | D28: =Chạy!G59 -> 2.63 | E28: =D28+F28 -> 2.656 | F28: =RANDBETWEEN(-30,100)/1000 -> 0.026 | G28: =Chạy!I59 -> 2.63 | H28: =G28+I28 -> 2.601 | I28: =RANDBETWEEN(-30,100)/1000 -> -0.029 | J28: =Chạy!M63 -> 2.63 | K28: =J28+L28 -> 2.673 | L28: =RANDBETWEEN(-30,100)/1000 -> 0.043 | M28: =Chạy!O63 -> 2.63 | N28: =M28+O28 -> 2.611 | O28: =RANDBETWEEN(-30,100)/1000 -> -0.019 | Q28: 13.6
A29: 9 | B29: 31 | C29: =C28+Q28 -> 538.68 | D29: =Chạy!G67 -> 2.63 | E29: =D29+F29 -> 2.725 | F29: =RANDBETWEEN(-30,100)/1000 -> 0.095 | G29: =Chạy!I67 -> 2.63 | H29: =G29+I29 -> 2.666 | I29: =RANDBETWEEN(-30,100)/1000 -> 0.036 | J29: =Chạy!M71 -> 2.63 | K29: =J29+L29 -> 2.621 | L29: =RANDBETWEEN(-30,100)/1000 -> -0.009 | M29: =Chạy!O71 -> 2.63 | N29: =M29+O29 -> 2.683 | O29: =RANDBETWEEN(-30,100)/1000 -> 0.053 | Q29: 15.4
A30: 10 | B30: 32 | C30: =C29+Q29 -> 554.08 | D30: =Chạy!G75 -> 2.62 | E30: =D30+F30 -> 2.698 | F30: =RANDBETWEEN(-30,100)/1000 -> 0.078 | G30: =Chạy!I75 -> 2.62 | H30: =G30+I30 -> 2.703 | I30: =RANDBETWEEN(-30,100)/1000 -> 0.083 | J30: =Chạy!M79 -> 2.62 | K30: =J30+L30 -> 2.604 | L30: =RANDBETWEEN(-30,100)/1000 -> -0.016 | M30: =Chạy!O79 -> 2.62 | N30: =M30+O30 -> 2.685 | O30: =RANDBETWEEN(-30,100)/1000 -> 0.065
C60: NHÀ THẦU THI CÔNG | K60: TƯ VẤN GIÁM SÁT
C65: Nguyễn Xuân Hưng | K65: Trần Mạnh Tùng

Sheet KL L3
A1: PHỤ LỤC KHỐI LƯỢNG
A2: ="Kèm theo BBNT số: "&VLOOKUP(AZ2,'[1]Tuyến XD4'!$A$2:$G$60,7,0)&VLOOKUP(AZ2,'[1]Tuyến XD4'!$A$2:$G$60,4,0) -> Kèm theo BBNT số: 22.NĐXD4/CVXD ngày 26 tháng 08 năm 2026 | AZ2: 22
A3: Dự án: Xây dựng HTKT Khu tái định cư phục vụ di dân xã Hải Hà, thị xã Nghi Sơn, tỉnh Thanh Hóa.
A4: Gói thầu số 12: Xây dựng HTKT khu vực Hải Bình và Xuân Lâm (bao gồm cả bảo hiểm xây dựng công trình)
A5: Nhà thầu thi công: Công ty TNHH Hoàng Tuấn
A6: Hạng mục: Nền đường tuyến XD4
A7: - Đối tượng nghiệm thu: | D7: =VLOOKUP(AZ2,'[1]Tuyến XD4'!$A$2:$B$60,2,0) -> Đắp đất lề đường lớp 3, độ chặt K>=0,95 đoạn từ Km0+441,84 - Km0+554,08
A9: STT | B9: Tên cọc | C9: Lý trình | D9: K/c lẻ | G9: Ghi chú
E10: Diện tích | F10: Khối lượng
A11: 1 | B11: ='1. KTHH L3'!B21 -> 24 | C11: ='1. KTHH L3'!C21 -> 441.84 | D11: ='1. KTHH L3'!Q21 -> 12.5 | E11: =Chạy!E3+Chạy!E7 -> 2.1 | F11: =(E11+E12)*D11/2 -> 26.25
A12: 2 | B12: ='1. KTHH L3'!B22 -> 25 | C12: ='1. KTHH L3'!C22 -> 454.34 | D12: ='1. KTHH L3'!Q22 -> 12.5 | E12: =Chạy!E11+Chạy!E15 -> 2.1 | F12: =(E12+E13)*D12/2 -> 26.25
A13: 3 | B13: ='1. KTHH L3'!B23 -> 26 | C13: ='1. KTHH L3'!C23 -> 466.84 | D13: ='1. KTHH L3'!Q23 -> 7.5 | E13: =Chạy!E19+Chạy!E23 -> 2.1 | F13: =(E13+E14)*D13/2 -> 15.75
A14: 4 | B14: ='1. KTHH L3'!B24 -> 27 | C14: ='1. KTHH L3'!C24 -> 474.34 | D14: ='1. KTHH L3'!Q24 -> 20 | E14: =Chạy!E27+Chạy!E31 -> 2.1 | F14: =(E14+E15)*D14/2 -> 42
A15: 5 | B15: ='1. KTHH L3'!B25 -> 28 | C15: ='1. KTHH L3'!C25 -> 494.34 | D15: ='1. KTHH L3'!Q25 -> 17.14 | E15: =Chạy!E35+Chạy!E39 -> 2.1 | F15: =(E15+E16)*D15/2 -> 35.994
A16: 6 | B16: ='1. KTHH L3'!B26 -> 29 | C16: ='1. KTHH L3'!C26 -> 511.48 | D16: ='1. KTHH L3'!Q26 -> 3.12 | E16: =Chạy!E43+Chạy!E47 -> 2.1 | F16: =(E16+E17)*D16/2 -> 6.552
A17: 7 | B17: ='1. KTHH L3'!B27 -> 30 | C17: ='1. KTHH L3'!C27 -> 514.6 | D17: ='1. KTHH L3'!Q27 -> 10.48 | E17: =Chạy!E51+Chạy!E55 -> 2.1 | F17: =(E17+E18)*D17/2 -> 22.008
A18: 8 | B18: ='1. KTHH L3'!B28 -> D | C18: ='1. KTHH L3'!C28 -> 525.08 | D18: ='1. KTHH L3'!Q28 -> 13.6 | E18: =Chạy!E59+Chạy!E63 -> 2.1 | F18: =(E18+E19)*D18/2 -> 28.56
A19: 9 | B19: ='1. KTHH L3'!B29 -> 31 | C19: ='1. KTHH L3'!C29 -> 538.68 | D19: ='1. KTHH L3'!Q29 -> 15.4 | E19: =Chạy!E67+Chạy!E71 -> 2.1 | F19: =(E19+E20)*D19/2 -> 32.34
A20: 10 | B20: ='1. KTHH L3'!B30 -> 32 | C20: ='1. KTHH L3'!C30 -> 554.08 | E20: =Chạy!E75+Chạy!E79 -> 2.1
A49: Tổng cộng (m3) | F49: =SUM(F11:F20) -> 235.704
A51: NHÀ THẦU THI CÔNG | E51: TƯ VẤN GIÁM SÁT
A57: Nguyễn Xuân Hưng | E57: Trần Mạnh Tùng

Sheet 1. KTHH L4
A1: PHỤ LỤC KIỂM TRA CAO ĐỘ, KÍCH THƯỚC HÌNH HỌC
A2: ="Kèm theo BBNT số: "&VLOOKUP(AZ2,'[1]Tuyến XD4'!$A$2:$G$60,7,0)&VLOOKUP(AZ2,'[1]Tuyến XD4'!$A$2:$G$60,4,0) -> Kèm theo BBNT số: 23.NĐXD4/CVXD ngày 27 tháng 08 năm 2026 | AZ2: 23
A3: Dự án: Xây dựng HTKT Khu tái định cư phục vụ di dân xã Hải Hà, thị xã Nghi Sơn, tỉnh Thanh Hóa.
A4: Gói thầu số 12: Xây dựng HTKT khu vực Hải Bình và Xuân Lâm (bao gồm cả bảo hiểm xây dựng công trình)
A5: Nhà thầu thi công: Công ty TNHH Hoàng Tuấn
A6: Hạng mục: Nền đường tuyến XD4
A7: - Đối tượng nghiệm thu: | D7: =VLOOKUP(AZ2,'[1]Tuyến XD4'!$A$2:$B$60,2,0) -> Đắp đất lề đường lớp 4, độ chặt K>=0,95 đoạn từ Km0+441,84 - Km0+554,08
A8: Sơ họa:
A18: TT | B18: Tên cọc | C18: Lý trình | D18: Lề trái (H1) | G18: Lề trái (H2) | J18: Lề phải (H3) | M18: Lề phải (H4) | P18: Ghi chú
D19: CDTK (m) | E19: CDTC (m) | F19: Chênh CD (m) | G19: CDTK (m) | H19: CDTC (m) | I19: Chênh CD (m) | J19: CDTK (m) | K19: CDTC (m) | L19: Chênh CD (m) | M19: CDTK (m) | N19: CDTC (m) | O19: Chênh CD (m)
A20: 1 | B20: 24 | C20: 441.84 | D20: =Chạy!G2 -> 3.02 | E20: =D20+F20 -> 3.03 | F20: =RANDBETWEEN(-30,100)/1000 -> 0.01 | G20: =Chạy!I2 -> 2.74 | H20: =G20+I20 -> 2.715 | I20: =RANDBETWEEN(-30,100)/1000 -> -0.025 | J20: =Chạy!M6 -> 2.93 | K20: =J20+L20 -> 2.924 | L20: =RANDBETWEEN(-30,100)/1000 -> -0.006 | M20: =Chạy!O6 -> 2.92 | N20: =M20+O20 -> 2.911 | O20: =RANDBETWEEN(-30,100)/1000 -> -0.009 | Q20: 12.5
A21: 2 | B21: 25 | C21: =C20+Q20 -> 454.34 | D21: =Chạy!G10 -> 3.01 | E21: =D21+F21 -> 3.025 | F21: =RANDBETWEEN(-30,100)/1000 -> 0.015 | G21: =Chạy!I10 -> 2.73 | H21: =G21+I21 -> 2.783 | I21: =RANDBETWEEN(-30,100)/1000 -> 0.053 | J21: =Chạy!M14 -> 2.92 | K21: =J21+L21 -> 2.963 | L21: =RANDBETWEEN(-30,100)/1000 -> 0.043 | M21: =Chạy!O14 -> 2.91 | N21: =M21+O21 -> 2.95 | O21: =RANDBETWEEN(-30,100)/1000 -> 0.04 | Q21: 12.5
A22: 3 | B22: 26 | C22: =C21+Q21 -> 466.84 | D22: =Chạy!G18 -> 3.01 | E22: =D22+F22 -> 3.086 | F22: =RANDBETWEEN(-30,100)/1000 -> 0.076 | G22: =Chạy!I18 -> 2.72 | H22: =G22+I22 -> 2.786 | I22: =RANDBETWEEN(-30,100)/1000 -> 0.066 | J22: =Chạy!M22 -> 2.91 | K22: =J22+L22 -> 2.899 | L22: =RANDBETWEEN(-30,100)/1000 -> -0.011 | M22: =Chạy!O22 -> 2.91 | N22: =M22+O22 -> 2.901 | O22: =RANDBETWEEN(-30,100)/1000 -> -0.009 | Q22: 7.5
A23: 4 | B23: 27 | C23: =C22+Q22 -> 474.34 | D23: =Chạy!G26 -> 3 | E23: =D23+F23 -> 3.033 | F23: =RANDBETWEEN(-30,100)/1000 -> 0.033 | G23: =Chạy!I26 -> 2.72 | H23: =G23+I23 -> 2.738 | I23: =RANDBETWEEN(-30,100)/1000 -> 0.018 | J23: =Chạy!M30 -> 2.91 | K23: =J23+L23 -> 2.929 | L23: =RANDBETWEEN(-30,100)/1000 -> 0.019 | M23: =Chạy!O30 -> 2.9 | N23: =M23+O23 -> 2.901 | O23: =RANDBETWEEN(-30,100)/1000 -> 0.001 | Q23: 20
A24: 5 | B24: 28 | C24: =C23+Q23 -> 494.34 | D24: =Chạy!G34 -> 2.99 | E24: =D24+F24 -> 2.977 | F24: =RANDBETWEEN(-30,100)/1000 -> -0.013 | G24: =Chạy!I34 -> 2.71 | H24: =G24+I24 -> 2.681 | I24: =RANDBETWEEN(-30,100)/1000 -> -0.029 | J24: =Chạy!M38 -> 2.9 | K24: =J24+L24 -> 2.992 | L24: =RANDBETWEEN(-30,100)/1000 -> 0.092 | M24: =Chạy!O38 -> 2.89 | N24: =M24+O24 -> 2.87 | O24: =RANDBETWEEN(-30,100)/1000 -> -0.02 | Q24: 17.14
A25: 6 | B25: 29 | C25: =C24+Q24 -> 511.48 | D25: =Chạy!G42 -> 2.98 | E25: =D25+F25 -> 3.047 | F25: =RANDBETWEEN(-30,100)/1000 -> 0.067 | G25: =Chạy!I42 -> 2.7 | H25: =G25+I25 -> 2.708 | I25: =RANDBETWEEN(-30,100)/1000 -> 0.008 | J25: =Chạy!M46 -> 2.89 | K25: =J25+L25 -> 2.941 | L25: =RANDBETWEEN(-30,100)/1000 -> 0.051 | M25: =Chạy!O46 -> 2.88 | N25: =M25+O25 -> 2.915 | O25: =RANDBETWEEN(-30,100)/1000 -> 0.035 | Q25: 3.12
A26: 7 | B26: 30 | C26: =C25+Q25 -> 514.6 | D26: =Chạy!G50 -> 2.98 | E26: =D26+F26 -> 3.073 | F26: =RANDBETWEEN(-30,100)/1000 -> 0.093 | G26: =Chạy!I50 -> 2.7 | H26: =G26+I26 -> 2.795 | I26: =RANDBETWEEN(-30,100)/1000 -> 0.095 | J26: =Chạy!M54 -> 2.89 | K26: =J26+L26 -> 2.952 | L26: =RANDBETWEEN(-30,100)/1000 -> 0.062 | M26: =Chạy!O54 -> 2.88 | N26: =M26+O26 -> 2.883 | O26: =RANDBETWEEN(-30,100)/1000 -> 0.003 | Q26: 10.48
A27: 8 | B27: D | C27: =C26+Q26 -> 525.08 | D27: =Chạy!G58 -> 2.97 | E27: =D27+F27 -> 3.024 | F27: =RANDBETWEEN(-30,100)/1000 -> 0.054 | G27: =Chạy!I58 -> 2.69 | H27: =G27+I27 -> 2.762 | I27: =RANDBETWEEN(-30,100)/1000 -> 0.072 | J27: =Chạy!M62 -> 2.88 | K27: =J27+L27 -> 2.946 | L27: =RANDBETWEEN(-30,100)/1000 -> 0.066 | M27: =Chạy!O62 -> 2.88 | N27: =M27+O27 -> 2.908 | O27: =RANDBETWEEN(-30,100)/1000 -> 0.028 | Q27: 13.6
A28: 9 | B28: 31 | C28: =C27+Q27 -> 538.68 | D28: =Chạy!G66 -> 2.97 | E28: =D28+F28 -> 2.962 | F28: =RANDBETWEEN(-30,100)/1000 -> -0.008 | G28: =Chạy!I66 -> 2.69 | H28: =G28+I28 -> 2.756 | I28: =RANDBETWEEN(-30,100)/1000 -> 0.066 | J28: =Chạy!M70 -> 2.88 | K28: =J28+L28 -> 2.934 | L28: =RANDBETWEEN(-30,100)/1000 -> 0.054 | M28: =Chạy!O70 -> 2.87 | N28: =M28+O28 -> 2.91 | O28: =RANDBETWEEN(-30,100)/1000 -> 0.04 | Q28: 15.4
A29: 10 | B29: 32 | C29: =C28+Q28 -> 554.08 | D29: =Chạy!G74 -> 2.96 | E29: =D29+F29 -> 3.025 | F29: =RANDBETWEEN(-30,100)/1000 -> 0.065 | G29: =Chạy!I74 -> 2.68 | H29: =G29+I29 -> 2.704 | I29: =RANDBETWEEN(-30,100)/1000 -> 0.024 | J29: =Chạy!M78 -> 2.87 | K29: =J29+L29 -> 2.926 | L29: =RANDBETWEEN(-30,100)/1000 -> 0.056 | M29: =Chạy!O78 -> 2.86 | N29: =M29+O29 -> 2.906 | O29: =RANDBETWEEN(-30,100)/1000 -> 0.046
C59: NHÀ THẦU THI CÔNG | K59: TƯ VẤN GIÁM SÁT
C64: Nguyễn Xuân Hưng | K64: Lê Minh Hải

Sheet KL L4
A1: PHỤ LỤC KHỐI LƯỢNG
A2: ="Kèm theo BBNT số: "&VLOOKUP(AZ2,'[1]Tuyến XD4'!$A$2:$G$60,7,0)&VLOOKUP(AZ2,'[1]Tuyến XD4'!$A$2:$G$60,4,0) -> Kèm theo BBNT số: 23.NĐXD4/CVXD ngày 27 tháng 08 năm 2026 | AZ2: 23
A3: Dự án: Xây dựng HTKT Khu tái định cư phục vụ di dân xã Hải Hà, thị xã Nghi Sơn, tỉnh Thanh Hóa.
A4: Gói thầu số 12: Xây dựng HTKT khu vực Hải Bình và Xuân Lâm (bao gồm cả bảo hiểm xây dựng công trình)
A5: Nhà thầu thi công: Công ty TNHH Hoàng Tuấn
A6: Hạng mục: Nền đường tuyến XD4
A7: - Đối tượng nghiệm thu: | D7: =VLOOKUP(AZ2,'[1]Tuyến XD4'!$A$2:$B$60,2,0) -> Đắp đất lề đường lớp 4, độ chặt K>=0,95 đoạn từ Km0+441,84 - Km0+554,08
A9: STT | B9: Tên cọc | C9: Lý trình | D9: K/c lẻ | G9: Ghi chú
E10: Diện tích | F10: Khối lượng
A11: 1 | B11: ='1. KTHH L4'!B20 -> 24 | C11: ='1. KTHH L4'!C20 -> 441.84 | D11: ='1. KTHH L4'!Q20 -> 12.5 | E11: =Chạy!E2+Chạy!E6 -> 3.12 | F11: =(E11+E12)*D11/2 -> 39
A12: 2 | B12: ='1. KTHH L4'!B21 -> 25 | C12: ='1. KTHH L4'!C21 -> 454.34 | D12: ='1. KTHH L4'!Q21 -> 12.5 | E12: =Chạy!E10+Chạy!E14 -> 3.12 | F12: =(E12+E13)*D12/2 -> 39
A13: 3 | B13: ='1. KTHH L4'!B22 -> 26 | C13: ='1. KTHH L4'!C22 -> 466.84 | D13: ='1. KTHH L4'!Q22 -> 7.5 | E13: =Chạy!E18+Chạy!E22 -> 3.12 | F13: =(E13+E14)*D13/2 -> 23.4
A14: 4 | B14: ='1. KTHH L4'!B23 -> 27 | C14: ='1. KTHH L4'!C23 -> 474.34 | D14: ='1. KTHH L4'!Q23 -> 20 | E14: =Chạy!E26+Chạy!E30 -> 3.12 | F14: =(E14+E15)*D14/2 -> 62.4
A15: 5 | B15: ='1. KTHH L4'!B24 -> 28 | C15: ='1. KTHH L4'!C24 -> 494.34 | D15: ='1. KTHH L4'!Q24 -> 17.14 | E15: =Chạy!E34+Chạy!E38 -> 3.12 | F15: =(E15+E16)*D15/2 -> 53.4768
A16: 6 | B16: ='1. KTHH L4'!B25 -> 29 | C16: ='1. KTHH L4'!C25 -> 511.48 | D16: ='1. KTHH L4'!Q25 -> 3.12 | E16: =Chạy!E42+Chạy!E46 -> 3.12 | F16: =(E16+E17)*D16/2 -> 9.7344
A17: 7 | B17: ='1. KTHH L4'!B26 -> 30 | C17: ='1. KTHH L4'!C26 -> 514.6 | D17: ='1. KTHH L4'!Q26 -> 10.48 | E17: =Chạy!E50+Chạy!E54 -> 3.12 | F17: =(E17+E18)*D17/2 -> 32.6976
A18: 8 | B18: ='1. KTHH L4'!B27 -> D | C18: ='1. KTHH L4'!C27 -> 525.08 | D18: ='1. KTHH L4'!Q27 -> 13.6 | E18: =Chạy!E58+Chạy!E62 -> 3.12 | F18: =(E18+E19)*D18/2 -> 42.432
A19: 9 | B19: ='1. KTHH L4'!B28 -> 31 | C19: ='1. KTHH L4'!C28 -> 538.68 | D19: ='1. KTHH L4'!Q28 -> 15.4 | E19: =Chạy!E66+Chạy!E70 -> 3.12 | F19: =(E19+E20)*D19/2 -> 48.048
A20: 10 | B20: ='1. KTHH L4'!B29 -> 32 | C20: ='1. KTHH L4'!C29 -> 554.08 | E20: =Chạy!E74+Chạy!E78 -> 3.12
A49: Tổng cộng (m3) | F49: =SUM(F11:F20) -> 350.1888
A51: NHÀ THẦU THI CÔNG | E51: TƯ VẤN GIÁM SÁT
A57: Nguyễn Xuân Hưng | E57: ='1. KTHH L4'!K64 -> Lê Minh Hải
