Workbook

Sheet IN
A1: DANH MỤC NGHIỆM THU
A2: Dự án: Xây dựng hạ tầng kỹ thuật Khu tái định cư phục vụ di dân xã Hải Hà, thị xã Nghi Sơn, tỉnh Thanh Hóa
A3: Gói thầu số 12: Xây dựng hạ tầng kỹ thuật khu vực Hải Bình và Xuân Lâm (bao gồm cả bảo hiểm xây dựng công trình)
A4: Nhà thầu thi công : Công ty TNHH Hoàng Tuấn
A5: Hạng mục: Nền đường tuyến XD4 đoạn từ Km0+554,08-:-Km0+672,28
A7: STT | B7: Nội dung nghiệm thu | C7: Thời gian nghiệm thu | D7: Thời gian bắt đầu | F7: Thời gian kết thúc
D8: ='Tuyến XD4'!H2 -> 0 | E8: ='Tuyến XD4'!I2 -> 0 | F8: ='Tuyến XD4'!K2 -> 0 | G8: ='Tuyến XD4'!L2 -> 0
A9: ='Tuyến XD4'!A3 -> 29 | B9: ='Tuyến XD4'!B3 -> Kiểm tra cao độ đường đen đoạn từ Km0+554,08 -:- Km0+672,28 | C9: ='Tuyến XD4'!C3 -> 46263 | D9: ='Tuyến XD4'!H3 -> 9 | E9: ='Tuyến XD4'!I3 -> 00 | F9: ='Tuyến XD4'!K3 -> 9 | G9: ='Tuyến XD4'!L3 -> 30
A10: ='Tuyến XD4'!A4 -> 30 | B10: ='Tuyến XD4'!B4 -> Đào đất xử lý nền đường đoạn từ Km0+554,08 - Km0+672,28 | C10: ='Tuyến XD4'!C4 -> 46264 | D10: ='Tuyến XD4'!H4 -> 11 | E10: ='Tuyến XD4'!I4 -> 00 | F10: ='Tuyến XD4'!K4 -> 11 | G10: ='Tuyến XD4'!L4 -> 30
A11: ='Tuyến XD4'!A5 -> 31 | B11: ='Tuyến XD4'!B5 -> Rải vải địa kỹ thuật đoạn từ Km0+554,08 - Km0+672,28 | C11: ='Tuyến XD4'!C5 -> 46265 | D11: ='Tuyến XD4'!H5 -> 14 | E11: ='Tuyến XD4'!I5 -> 00 | F11: ='Tuyến XD4'!K5 -> 14 | G11: ='Tuyến XD4'!L5 -> 30
A12: ='Tuyến XD4'!A6 -> 32 | B12: ='Tuyến XD4'!B6 -> Đắp cát nền đường lớp 1 đoạn từ Km0+554,08 - Km0+672,28, độ chặt K>=0,95 | C12: ='Tuyến XD4'!C6 -> 46265 | D12: ='Tuyến XD4'!H6 -> 17 | E12: ='Tuyến XD4'!I6 -> 00 | F12: ='Tuyến XD4'!K6 -> 17 | G12: ='Tuyến XD4'!L6 -> 30
A13: ='Tuyến XD4'!A7 -> 33 | B13: ='Tuyến XD4'!B7 -> Đắp cát nền đường lớp 2 đoạn từ Km0+554,08 - Km0+672,28, độ chặt K>=0,95 | C13: ='Tuyến XD4'!C7 -> 46268 | D13: ='Tuyến XD4'!H7 -> 9 | E13: ='Tuyến XD4'!I7 -> 00 | F13: ='Tuyến XD4'!K7 -> 9 | G13: ='Tuyến XD4'!L7 -> 30
A14: ='Tuyến XD4'!A8 -> 34 | B14: ='Tuyến XD4'!B8 -> Đắp cát nền đường lớp 3 đoạn từ Km0+554,08 - Km0+672,28, độ chặt K>=0,95 | C14: ='Tuyến XD4'!C8 -> 46268 | D14: ='Tuyến XD4'!H8 -> 15 | E14: ='Tuyến XD4'!I8 -> 00 | F14: ='Tuyến XD4'!K8 -> 15 | G14: ='Tuyến XD4'!L8 -> 30
A15: ='Tuyến XD4'!A9 -> 35 | B15: ='Tuyến XD4'!B9 -> Đắp cát nền đường lớp 4 đoạn từ Km0+554,08 - Km0+672,28, độ chặt K>=0,95 | C15: ='Tuyến XD4'!C9 -> 46268 | D15: ='Tuyến XD4'!H9 -> 9 | E15: ='Tuyến XD4'!I9 -> 00 | F15: ='Tuyến XD4'!K9 -> 9 | G15: ='Tuyến XD4'!L9 -> 30
A16: ='Tuyến XD4'!A10 -> 36 | B16: ='Tuyến XD4'!B10 -> Đắp đất nền đường lớp 1 đoạn từ Km0+554,08 - Km0+672,28, độ chặt K>=0,95 | C16: ='Tuyến XD4'!C10 -> 46268 | D16: ='Tuyến XD4'!H10 -> 15 | E16: ='Tuyến XD4'!I10 -> 00 | F16: ='Tuyến XD4'!K10 -> 15 | G16: ='Tuyến XD4'!L10 -> 30
A17: ='Tuyến XD4'!A11 -> 37 | B17: ='Tuyến XD4'!B11 -> Đắp đất nền đường lớp 2 đoạn từ Km0+554,08 - Km0+672,28, độ chặt K>=0,95 | C17: ='Tuyến XD4'!C11 -> 46268 | D17: ='Tuyến XD4'!H11 -> 9 | E17: ='Tuyến XD4'!I11 -> 00 | F17: ='Tuyến XD4'!K11 -> 9 | G17: ='Tuyến XD4'!L11 -> 30
A18: ='Tuyến XD4'!A12 -> 38 | B18: ='Tuyến XD4'!B12 -> Đắp đất nền đường lớp 3 đoạn từ Km0+554,08 - Km0+672,28, độ chặt K>=0,95 | C18: ='Tuyến XD4'!C12 -> 46268 | D18: ='Tuyến XD4'!H12 -> 15 | E18: ='Tuyến XD4'!I12 -> 00 | F18: ='Tuyến XD4'!K12 -> 15 | G18: ='Tuyến XD4'!L12 -> 30
A19: ='Tuyến XD4'!A13 -> 39 | B19: ='Tuyến XD4'!B13 -> Đắp đất nền đường lớp 4 đoạn từ Km0+554,08 - Km0+672,28, độ chặt K>=0,95 | C19: ='Tuyến XD4'!C13 -> 46269 | D19: ='Tuyến XD4'!H13 -> 9 | E19: ='Tuyến XD4'!I13 -> 00 | F19: ='Tuyến XD4'!K13 -> 9 | G19: ='Tuyến XD4'!L13 -> 30
A20: ='Tuyến XD4'!A14 -> 40 | B20: ='Tuyến XD4'!B14 -> Đắp đất nền đường lớp 5 đoạn từ Km0+554,08 - Km0+672,28, độ chặt K>=0,95 | C20: ='Tuyến XD4'!C14 -> 46269 | D20: ='Tuyến XD4'!H14 -> 15 | E20: ='Tuyến XD4'!I14 -> 00 | F20: ='Tuyến XD4'!K14 -> 15 | G20: ='Tuyến XD4'!L14 -> 30
... A36: ='Tuyến XD4'!A30 -> 56 | B36: ='Tuyến XD4'!B30 -> Bê tông nhựa C16 - Chiều dày mặt đường đã lèn ép 6cm | C36: ='Tuyến XD4'!C30 -> 46284 | D36: ='Tuyến XD4'!H30 -> 16 | E36: ='Tuyến XD4'!I30 -> 00 | F36: ='Tuyến XD4'!K30 -> 16 | G36: ='Tuyến XD4'!L30 -> 30

Sheet Tuyến XD4
A1: STT | B1: Nội dung nghiệm thu | C1: Thời gian nghiệm thu | D1: Thời gian bằng chữ | E1: Bản vẽ | F1: Số PYC | G1: Số BBNT | H1: Giờ bắt đầu | I1: Phút bắt đầu | J1: Tiêu chuẩn | K1: Giờ kết thúc | L1: Phút kết thúc | M1: Ngày | N1: Tháng | O1: Năm | P1: Kỹ thuật TC | Q1: Giám sát | R1: Số BBNT vật liệu, thiết bị | S1: Thời gian nghiệm thu vật liệu
A3: 29 | B3: Kiểm tra cao độ đường đen đoạn từ Km0+554,08 -:- Km0+672,28 | C3: 46263 | D3: =CONCATENATE("ngày ",TEXT(C3,"dd")," tháng ",TEXT(C3,"mm")," năm ",TEXT(C3,"yyyy")) -> ngày 29 tháng 08 năm 2026 | E3: Tuyến XD4 | F3: =TEXT(A3,"00") & ".NĐ/YCNT" -> 29.NĐ/YCNT | G3: =TEXT(A3,"00") & ".NĐXD4/CVXD " -> 29.NĐXD4/CVXD | H3: 9 | I3: 00 | K3: =+H3 -> 9 | L3: 30 | M3: =CONCATENATE(TEXT(C3,"dd")) -> 29 | N3: =CONCATENATE(TEXT(C3,"mm")) -> 08 | O3: =CONCATENATE(TEXT(C3,"yyyy")) -> 2026 | P3: Nguyễn Xuân Hưng | Q3: Trần Mạnh Tùng
A4: =+A3+1 -> 30 | B4: Đào đất xử lý nền đường đoạn từ Km0+554,08 - Km0+672,28 | C4: 46264 | D4: =CONCATENATE("ngày ",TEXT(C4,"dd")," tháng ",TEXT(C4,"mm")," năm ",TEXT(C4,"yyyy")) -> ngày 30 tháng 08 năm 2026 | E4: Tuyến XD4 | F4: =TEXT(A4,"00") & ".NĐ/YCNT" -> 30.NĐ/YCNT | G4: =TEXT(A4,"00") & ".NĐXD4/CVXD " -> 30.NĐXD4/CVXD | H4: 11 | I4: 00 | J4: TCVN 4447-2012: Công tác đất. Thi công và nghiệm thu. | K4: =+H4 -> 11 | L4: 30 | M4: =CONCATENATE(TEXT(C4,"dd")) -> 30 | N4: =CONCATENATE(TEXT(C4,"mm")) -> 08 | O4: =CONCATENATE(TEXT(C4,"yyyy")) -> 2026 | P4: Nguyễn Xuân Hưng | Q4: Trần Mạnh Tùng
A5: =+A4+1 -> 31 | B5: Rải vải địa kỹ thuật đoạn từ Km0+554,08 - Km0+672,28 | C5: 46265 | D5: =CONCATENATE("ngày ",TEXT(C5,"dd")," tháng ",TEXT(C5,"mm")," năm ",TEXT(C5,"yyyy")) -> ngày 31 tháng 08 năm 2026 | E5: Tuyến XD4 | F5: =TEXT(A5,"00") & ".NĐ/YCNT" -> 31.NĐ/YCNT | G5: =TEXT(A5,"00") & ".NĐXD4/CVXD " -> 31.NĐXD4/CVXD | H5: 14 | I5: 00 | J5: TCVN 9844 : 2013 Vải địa kỹ thuật trong xây dựng nền đắp trên đất yếu - Tiêu chuẩn thiết kế, thi công và nghiệm thu | K5: =+H5 -> 14 | L5: 30 | M5: =CONCATENATE(TEXT(C5,"dd")) -> 31 | N5: =CONCATENATE(TEXT(C5,"mm")) -> 08 | O5: =CONCATENATE(TEXT(C5,"yyyy")) -> 2026 | P5: Nguyễn Xuân Hưng | Q5: Trần Mạnh Tùng
A6: =+A5+1 -> 32 | B6: Đắp cát nền đường lớp 1 đoạn từ Km0+554,08 - Km0+672,28, độ chặt K>=0,95 | C6: 46265 | D6: =CONCATENATE("ngày ",TEXT(C6,"dd")," tháng ",TEXT(C6,"mm")," năm ",TEXT(C6,"yyyy")) -> ngày 31 tháng 08 năm 2026 | E6: Tuyến XD4 | F6: =TEXT(A6,"00") & ".NĐ/YCNT" -> 32.NĐ/YCNT | G6: =TEXT(A6,"00") & ".NĐXD4/CVXD " -> 32.NĐXD4/CVXD | H6: 17 | I6: 00 | J6: TCVN 4447-2012: Công tác đất. Thi công và nghiệm thu. | K6: =+H6 -> 17 | L6: 30 | M6: =CONCATENATE(TEXT(C6,"dd")) -> 31 | N6: =CONCATENATE(TEXT(C6,"mm")) -> 08 | O6: =CONCATENATE(TEXT(C6,"yyyy")) -> 2026 | P6: Nguyễn Xuân Hưng | Q6: Trần Mạnh Tùng
A7: =+A6+1 -> 33 | B7: Đắp cát nền đường lớp 2 đoạn từ Km0+554,08 - Km0+672,28, độ chặt K>=0,95 | C7: 46268 | D7: =CONCATENATE("ngày ",TEXT(C7,"dd")," tháng ",TEXT(C7,"mm")," năm ",TEXT(C7,"yyyy")) -> ngày 03 tháng 09 năm 2026 | E7: Tuyến XD4 | F7: =TEXT(A7,"00") & ".NĐ/YCNT" -> 33.NĐ/YCNT | G7: =TEXT(A7,"00") & ".NĐXD4/CVXD " -> 33.NĐXD4/CVXD | H7: 9 | I7: 00 | J7: TCVN 4447-2012: Công tác đất. Thi công và nghiệm thu. | K7: =+H7 -> 9 | L7: 30 | M7: =CONCATENATE(TEXT(C7,"dd")) -> 03 | N7: =CONCATENATE(TEXT(C7,"mm")) -> 09 | O7: =CONCATENATE(TEXT(C7,"yyyy")) -> 2026 | P7: Nguyễn Xuân Hưng | Q7: Trần Mạnh Tùng
A8: =+A7+1 -> 34 | B8: Đắp cát nền đường lớp 3 đoạn từ Km0+554,08 - Km0+672,28, độ chặt K>=0,95 | C8: 46268 | D8: =CONCATENATE("ngày ",TEXT(C8,"dd")," tháng ",TEXT(C8,"mm")," năm ",TEXT(C8,"yyyy")) -> ngày 03 tháng 09 năm 2026 | E8: Tuyến XD4 | F8: =TEXT(A8,"00") & ".NĐ/YCNT" -> 34.NĐ/YCNT | G8: =TEXT(A8,"00") & ".NĐXD4/CVXD " -> 34.NĐXD4/CVXD | H8: 15 | I8: 00 | J8: TCVN 4447-2012: Công tác đất. Thi công và nghiệm thu. | K8: =+H8 -> 15 | L8: 30 | M8: =CONCATENATE(TEXT(C8,"dd")) -> 03 | N8: =CONCATENATE(TEXT(C8,"mm")) -> 09 | O8: =CONCATENATE(TEXT(C8,"yyyy")) -> 2026 | P8: Nguyễn Xuân Hưng | Q8: Trần Mạnh Tùng
A9: =+A8+1 -> 35 | B9: Đắp cát nền đường lớp 4 đoạn từ Km0+554,08 - Km0+672,28, độ chặt K>=0,95 | C9: 46268 | D9: =CONCATENATE("ngày ",TEXT(C9,"dd")," tháng ",TEXT(C9,"mm")," năm ",TEXT(C9,"yyyy")) -> ngày 03 tháng 09 năm 2026 | E9: Tuyến XD4 | F9: =TEXT(A9,"00") & ".NĐ/YCNT" -> 35.NĐ/YCNT | G9: =TEXT(A9,"00") & ".NĐXD4/CVXD " -> 35.NĐXD4/CVXD | H9: 9 | I9: 00 | J9: TCVN 4447-2012: Công tác đất. Thi công và nghiệm thu. | K9: =+H9 -> 9 | L9: 30 | M9: =CONCATENATE(TEXT(C9,"dd")) -> 03 | N9: =CONCATENATE(TEXT(C9,"mm")) -> 09 | O9: =CONCATENATE(TEXT(C9,"yyyy")) -> 2026 | P9: Nguyễn Xuân Hưng | Q9: Trần Mạnh Tùng
A10: =+A9+1 -> 36 | B10: Đắp đất nền đường lớp 1 đoạn từ Km0+554,08 - Km0+672,28, độ chặt K>=0,95 | C10: 46268 | D10: =CONCATENATE("ngày ",TEXT(C10,"dd")," tháng ",TEXT(C10,"mm")," năm ",TEXT(C10,"yyyy")) -> ngày 03 tháng 09 năm 2026 | E10: Tuyến XD4 | F10: =TEXT(A10,"00") & ".NĐ/YCNT" -> 36.NĐ/YCNT | G10: =TEXT(A10,"00") & ".NĐXD4/CVXD " -> 36.NĐXD4/CVXD | H10: 15 | I10: 00 | J10: TCVN 4447-2012: Công tác đất. Thi công và nghiệm thu. | K10: =+H10 -> 15 | L10: 30 | M10: =CONCATENATE(TEXT(C10,"dd")) -> 03 | N10: =CONCATENATE(TEXT(C10,"mm")) -> 09 | O10: =CONCATENATE(TEXT(C10,"yyyy")) -> 2026 | P10: Nguyễn Xuân Hưng | Q10: Trần Mạnh Tùng
A11: =+A10+1 -> 37 | B11: Đắp đất nền đường lớp 2 đoạn từ Km0+554,08 - Km0+672,28, độ chặt K>=0,95 | C11: 46268 | D11: =CONCATENATE("ngày ",TEXT(C11,"dd")," tháng ",TEXT(C11,"mm")," năm ",TEXT(C11,"yyyy")) -> ngày 03 tháng 09 năm 2026 | E11: Tuyến XD4 | F11: =TEXT(A11,"00") & ".NĐ/YCNT" -> 37.NĐ/YCNT | G11: =TEXT(A11,"00") & ".NĐXD4/CVXD " -> 37.NĐXD4/CVXD | H11: 9 | I11: 00 | J11: TCVN 4447-2012: Công tác đất. Thi công và nghiệm thu. | K11: =+H11 -> 9 | L11: 30 | M11: =CONCATENATE(TEXT(C11,"dd")) -> 03 | N11: =CONCATENATE(TEXT(C11,"mm")) -> 09 | O11: =CONCATENATE(TEXT(C11,"yyyy")) -> 2026 | P11: Nguyễn Xuân Hưng | Q11: Trần Mạnh Tùng
A12: =+A11+1 -> 38 | B12: Đắp đất nền đường lớp 3 đoạn từ Km0+554,08 - Km0+672,28, độ chặt K>=0,95 | C12: 46268 | D12: =CONCATENATE("ngày ",TEXT(C12,"dd")," tháng ",TEXT(C12,"mm")," năm ",TEXT(C12,"yyyy")) -> ngày 03 tháng 09 năm 2026 | E12: Tuyến XD4 | F12: =TEXT(A12,"00") & ".NĐ/YCNT" -> 38.NĐ/YCNT | G12: =TEXT(A12,"00") & ".NĐXD4/CVXD " -> 38.NĐXD4/CVXD | H12: 15 | I12: 00 | J12: TCVN 4447-2012: Công tác đất. Thi công và nghiệm thu. | K12: =+H12 -> 15 | L12: 30 | M12: =CONCATENATE(TEXT(C12,"dd")) -> 03 | N12: =CONCATENATE(TEXT(C12,"mm")) -> 09 | O12: =CONCATENATE(TEXT(C12,"yyyy")) -> 2026 | P12: Nguyễn Xuân Hưng | Q12: Trần Mạnh Tùng
A13: =+A12+1 -> 39 | B13: Đắp đất nền đường lớp 4 đoạn từ Km0+554,08 - Km0+672,28, độ chặt K>=0,95 | C13: 46269 | D13: =CONCATENATE("ngày ",TEXT(C13,"dd")," tháng ",TEXT(C13,"mm")," năm ",TEXT(C13,"yyyy")) -> ngày 04 tháng 09 năm 2026 | E13: Tuyến XD4 | F13: =TEXT(A13,"00") & ".NĐ/YCNT" -> 39.NĐ/YCNT | G13: =TEXT(A13,"00") & ".NĐXD4/CVXD " -> 39.NĐXD4/CVXD | H13: 9 | I13: 00 | J13: TCVN 4447-2012: Công tác đất. Thi công và nghiệm thu. | K13: =+H13 -> 9 | L13: 30 | M13: =CONCATENATE(TEXT(C13,"dd")) -> 04 | N13: =CONCATENATE(TEXT(C13,"mm")) -> 09 | O13: =CONCATENATE(TEXT(C13,"yyyy")) -> 2026 | P13: Nguyễn Xuân Hưng | Q13: Trần Mạnh Tùng
A14: =+A13+1 -> 40 | B14: Đắp đất nền đường lớp 5 đoạn từ Km0+554,08 - Km0+672,28, độ chặt K>=0,95 | C14: 46269 | D14: =CONCATENATE("ngày ",TEXT(C14,"dd")," tháng ",TEXT(C14,"mm")," năm ",TEXT(C14,"yyyy")) -> ngày 04 tháng 09 năm 2026 | E14: Tuyến XD4 | F14: =TEXT(A14,"00") & ".NĐ/YCNT" -> 40.NĐ/YCNT | G14: =TEXT(A14,"00") & ".NĐXD4/CVXD " -> 40.NĐXD4/CVXD | H14: 15 | I14: 00 | J14: TCVN 4447-2012: Công tác đất. Thi công và nghiệm thu. | K14: =+H14 -> 15 | L14: 30 | M14: =CONCATENATE(TEXT(C14,"dd")) -> 04 | N14: =CONCATENATE(TEXT(C14,"mm")) -> 09 | O14: =CONCATENATE(TEXT(C14,"yyyy")) -> 2026 | P14: Nguyễn Xuân Hưng | Q14: Trần Mạnh Tùng
A15: =+A14+1 -> 41 | B15: Đắp đất nền đường lớp 6 đoạn từ Km0+554,08 - Km0+672,28, độ chặt K>=0,95 | C15: 46270 | D15: =CONCATENATE("ngày ",TEXT(C15,"dd")," tháng ",TEXT(C15,"mm")," năm ",TEXT(C15,"yyyy")) -> ngày 05 tháng 09 năm 2026 | E15: Tuyến XD4 | F15: =TEXT(A15,"00") & ".NĐ/YCNT" -> 41.NĐ/YCNT | G15: =TEXT(A15,"00") & ".NĐXD4/CVXD " -> 41.NĐXD4/CVXD | H15: 9 | I15: 00 | J15: TCVN 4447-2012: Công tác đất. Thi công và nghiệm thu. | K15: =+H15 -> 9 | L15: 30 | M15: =CONCATENATE(TEXT(C15,"dd")) -> 05 | N15: =CONCATENATE(TEXT(C15,"mm")) -> 09 | O15: =CONCATENATE(TEXT(C15,"yyyy")) -> 2026 | P15: Nguyễn Xuân Hưng | Q15: Trần Mạnh Tùng
... A26: =+A25+1 -> 52 | B26: Đắp cấp phối đá dăm loại 1 đoạn từ Km0+554,08 - Km0+672,28 | C26: 46275 | D26: =CONCATENATE("ngày ",TEXT(C26,"dd")," tháng ",TEXT(C26,"mm")," năm ",TEXT(C26,"yyyy")) -> ngày 10 tháng 09 năm 2026 | E26: Tuyến XD4 | F26: =TEXT(A26,"00") & ".NĐ/YCNT" -> 52.NĐ/YCNT | G26: =TEXT(A26,"00") & ".NĐXD4/CVXD " -> 52.NĐXD4/CVXD | H26: 15 | I26: 00 | J26: TCVN 8859:2023 Lớp móng cấp phối đá dăm trong kết cấu áo đường | K26: =+H26 -> 15 | L26: 30 | M26: =CONCATENATE(TEXT(C26,"dd")) -> 10 | N26: =CONCATENATE(TEXT(C26,"mm")) -> 09 | O26: =CONCATENATE(TEXT(C26,"yyyy")) -> 2026 | P26: Nguyễn Xuân Hưng | Q26: Trần Mạnh Tùng
A27: =+A26+1 -> 53 | B27: Vệ sinh, thổi bụi mặt đường | C27: 46277 | D27: =CONCATENATE("ngày ",TEXT(C27,"dd")," tháng ",TEXT(C27,"mm")," năm ",TEXT(C27,"yyyy")) -> ngày 12 tháng 09 năm 2026 | E27: Tuyến XD4 | F27: =TEXT(A27,"00") & ".NĐ/YCNT" -> 53.NĐ/YCNT | G27: =TEXT(A27,"00") & ".NĐXD4/CVXD " -> 53.NĐXD4/CVXD | H27: 16 | I27: 00 | K27: =+H27 -> 16 | L27: 30 | M27: =CONCATENATE(TEXT(C27,"dd")) -> 12 | N27: =CONCATENATE(TEXT(C27,"mm")) -> 09 | O27: =CONCATENATE(TEXT(C27,"yyyy")) -> 2026 | P27: Nguyễn Xuân Hưng | Q27: Trần Mạnh Tùng
A28: =+A27+1 -> 54 | B28: Tưới lớp thấm bám mặt đường, nhựa MC70, lượng nhựa 1kg/m2 | C28: 46279 | D28: =CONCATENATE("ngày ",TEXT(C28,"dd")," tháng ",TEXT(C28,"mm")," năm ",TEXT(C28,"yyyy")) -> ngày 14 tháng 09 năm 2026 | E28: Tuyến XD4 | F28: =TEXT(A28,"00") & ".NĐ/YCNT" -> 54.NĐ/YCNT | G28: =TEXT(A28,"00") & ".NĐXD4/CVXD " -> 54.NĐXD4/CVXD | H28: 16 | I28: 00 | J28: + TCVN 13567-1: 2022. Lớp mặt đường bằng hỗn hợp nhựa nóng. Thi công và nghiệm thu. | K28: =+H28 -> 16 | L28: 30 | M28: =CONCATENATE(TEXT(C28,"dd")) -> 14 | N28: =CONCATENATE(TEXT(C28,"mm")) -> 09 | O28: =CONCATENATE(TEXT(C28,"yyyy")) -> 2026 | P28: Nguyễn Xuân Hưng | Q28: Trần Mạnh Tùng
A29: =+A28+1 -> 55 | B29: Rải thảm mặt đường bê tông nhựa C16 - Chiều dày mặt đường đã lèn ép 6cm | C29: 46282 | D29: =CONCATENATE("ngày ",TEXT(C29,"dd")," tháng ",TEXT(C29,"mm")," năm ",TEXT(C29,"yyyy")) -> ngày 17 tháng 09 năm 2026 | E29: Tuyến XD4 | F29: =TEXT(A29,"00") & ".NĐ/YCNT" -> 55.NĐ/YCNT | G29: =TEXT(A29,"00") & ".NĐXD4/CVXD " -> 55.NĐXD4/CVXD | H29: 16 | I29: 00 | J29: + TCVN 13567-1: 2022. Lớp mặt đường bằng hỗn hợp nhựa nóng. Thi công và nghiệm thu. | K29: =+H29 -> 16 | L29: 30 | M29: =CONCATENATE(TEXT(C29,"dd")) -> 17 | N29: =CONCATENATE(TEXT(C29,"mm")) -> 09 | O29: =CONCATENATE(TEXT(C29,"yyyy")) -> 2026 | P29: Nguyễn Xuân Hưng | Q29: Trần Mạnh Tùng
A30: =+A29+1 -> 56 | B30: Bê tông nhựa C16 - Chiều dày mặt đường đã lèn ép 6cm | C30: 46284 | D30: =CONCATENATE("ngày ",TEXT(C30,"dd")," tháng ",TEXT(C30,"mm")," năm ",TEXT(C30,"yyyy")) -> ngày 19 tháng 09 năm 2026 | E30: Tuyến XD4 | F30: =TEXT(A30,"00") & ".NĐ/YCNT" -> 56.NĐ/YCNT | G30: =TEXT(A30,"00") & ".NĐXD4/CVXD " -> 56.NĐXD4/CVXD | H30: 16 | I30: 00 | J30: + TCVN 13567-1: 2022. Lớp mặt đường bằng hỗn hợp nhựa nóng. Thi công và nghiệm thu. | K30: =+H30 -> 16 | L30: 30 | M30: =CONCATENATE(TEXT(C30,"dd")) -> 19 | N30: =CONCATENATE(TEXT(C30,"mm")) -> 09 | O30: =CONCATENATE(TEXT(C30,"yyyy")) -> 2026 | P30: Nguyễn Xuân Hưng | Q30: Trần Mạnh Tùng

Sheet 1. PL đường đen
A1: PHỤ LỤC KIỂM TRA CAO ĐỘ ĐƯỜNG ĐEN
A2: ="Kèm theo BBNT số: "&VLOOKUP(T2,'Tuyến XD4'!$A$2:$G$60,7,0)&VLOOKUP(T2,'Tuyến XD4'!$A$2:$G$60,4,0) -> Kèm theo BBNT số: 29.NĐXD4/CVXD ngày 29 tháng 08 năm 2026 | T2: 29
A3: Dự án: Xây dựng HTKT Khu tái định cư phục vụ di dân xã Hải Hà, thị xã Nghi Sơn, tỉnh Thanh Hóa.
A4: Gói thầu số 12: Xây dựng HTKT khu vực Hải Bình và Xuân Lâm (bao gồm cả bảo hiểm xây dựng công trình)
A5: Nhà thầu thi công: Công ty TNHH Hoàng Tuấn
A6: Hạng mục: Nền đường tuyến XD4
A7: - Đối tượng nghiệm thu: | D7: =VLOOKUP(T2,'Tuyến XD4'!$A$2:$B$60,2,0) -> Kiểm tra cao độ đường đen đoạn từ Km0+554,08 -:- Km0+672,28
A8: Sơ họa:
A10: TT | B10: Tên cọc | C10: Lý trình | D10: Bên trái (H1) | G10: Bên trái (H2) | J10: Tim (H3) | M10: Bên phải (H4) | P10: Bên phải (H5) | S10: Ghi chú
D11: CDTK | E11: CDTC | F11: Chênh CD | G11: CDTK | H11: CDTC | I11: Chênh CD | J11: CDTK | K11: CDTC | L11: Chênh CD | M11: CDTK | N11: CDTC | O11: Chênh CD | P11: CDTK | Q11: CDTC | R11: Chênh CD
A12: 1 | B12: 32 | C12: 554.08 | D12: 1.24 | E12: =D12+F12 -> 1.186 | F12: =RANDBETWEEN(-105,125)/1000 -> -0.054 | G12: 1.04 | H12: =G12+I12 -> 1.047 | I12: =RANDBETWEEN(-105,125)/1000 -> 0.007 | J12: -0.15 | K12: =J12+L12 -> -0.079 | L12: =RANDBETWEEN(-105,125)/1000 -> 0.071 | M12: -0.08 | N12: =M12+O12 -> -0.177 | O12: =RANDBETWEEN(-105,125)/1000 -> -0.097 | P12: -0.02 | Q12: =P12+R12 -> 0.078 | R12: =RANDBETWEEN(-105,125)/1000 -> 0.098 | T12: 15.4
A13: 2 | B13: 33 | C13: =C12+T12 -> 569.48 | D13: -0.14 | E13: =D13+F13 -> -0.143 | F13: =RANDBETWEEN(-105,125)/1000 -> -0.003 | G13: -0.19 | H13: =G13+I13 -> -0.214 | I13: =RANDBETWEEN(-105,125)/1000 -> -0.024 | J13: -0.25 | K13: =J13+L13 -> -0.254 | L13: =RANDBETWEEN(-105,125)/1000 -> -0.004 | M13: -0.26 | N13: =M13+O13 -> -0.291 | O13: =RANDBETWEEN(-105,125)/1000 -> -0.031 | P13: -0.27 | Q13: =P13+R13 -> -0.265 | R13: =RANDBETWEEN(-105,125)/1000 -> 0.005 | T13: 3.64
A14: 3 | B14: TD | C14: =C13+T13 -> 573.12 | D14: 1.21 | E14: =D14+F14 -> 1.27 | F14: =RANDBETWEEN(-105,125)/1000 -> 0.06 | G14: 1.52 | H14: =G14+I14 -> 1.475 | I14: =RANDBETWEEN(-105,125)/1000 -> -0.045 | J14: 1.41 | K14: =J14+L14 -> 1.467 | L14: =RANDBETWEEN(-105,125)/1000 -> 0.057 | M14: 1.48 | N14: =M14+O14 -> 1.512 | O14: =RANDBETWEEN(-105,125)/1000 -> 0.032 | P14: 1.55 | Q14: =P14+R14 -> 1.671 | R14: =RANDBETWEEN(-105,125)/1000 -> 0.121 | T14: 6.56
A15: 4 | B15: P | C15: =C14+T14 -> 579.68 | D15: 1.62 | E15: =D15+F15 -> 1.693 | F15: =RANDBETWEEN(-105,125)/1000 -> 0.073 | G15: 1.6 | H15: =G15+I15 -> 1.656 | I15: =RANDBETWEEN(-105,125)/1000 -> 0.056 | J15: -0.28 | K15: =J15+L15 -> -0.316 | L15: =RANDBETWEEN(-105,125)/1000 -> -0.036 | M15: -0.33 | N15: =M15+O15 -> -0.292 | O15: =RANDBETWEEN(-105,125)/1000 -> 0.038 | P15: -0.38 | Q15: =P15+R15 -> -0.411 | R15: =RANDBETWEEN(-105,125)/1000 -> -0.031 | T15: 4.84
A16: 5 | B16: E2 | C16: =C15+T15 -> 584.52 | D16: 1.39 | E16: =D16+F16 -> 1.33 | F16: =RANDBETWEEN(-105,125)/1000 -> -0.06 | G16: 1.3 | H16: =G16+I16 -> 1.401 | I16: =RANDBETWEEN(-105,125)/1000 -> 0.101 | J16: -0.29 | K16: =J16+L16 -> -0.318 | L16: =RANDBETWEEN(-105,125)/1000 -> -0.028 | M16: -0.33 | N16: =M16+O16 -> -0.288 | O16: =RANDBETWEEN(-105,125)/1000 -> 0.042 | P16: -0.37 | Q16: =P16+R16 -> -0.387 | R16: =RANDBETWEEN(-105,125)/1000 -> -0.017 | T16: 1.71
A17: 6 | B17: TC | C17: =C16+T16 -> 586.23 | D17: 1.39 | E17: =D17+F17 -> 1.342 | F17: =RANDBETWEEN(-105,125)/1000 -> -0.048 | G17: 1.35 | H17: =G17+I17 -> 1.256 | I17: =RANDBETWEEN(-105,125)/1000 -> -0.094 | J17: -0.28 | K17: =J17+L17 -> -0.268 | L17: =RANDBETWEEN(-105,125)/1000 -> 0.012 | M17: -0.31 | N17: =M17+O17 -> -0.24 | O17: =RANDBETWEEN(-105,125)/1000 -> 0.07 | P17: -0.35 | Q17: =P17+R17 -> -0.386 | R17: =RANDBETWEEN(-105,125)/1000 -> -0.036 | T17: 11.55
A18: 7 | B18: 34 | C18: =C17+T17 -> 597.78 | D18: 1.61 | E18: =D18+F18 -> 1.544 | F18: =RANDBETWEEN(-105,125)/1000 -> -0.066 | G18: -0.05 | H18: =G18+I18 -> 0.031 | I18: =RANDBETWEEN(-105,125)/1000 -> 0.081 | J18: -0.45 | K18: =J18+L18 -> -0.42 | L18: =RANDBETWEEN(-105,125)/1000 -> 0.03 | M18: -0.36 | N18: =M18+O18 -> -0.294 | O18: =RANDBETWEEN(-105,125)/1000 -> 0.066 | P18: -0.27 | Q18: =P18+R18 -> -0.301 | R18: =RANDBETWEEN(-105,125)/1000 -> -0.031 | T18: 17
A19: 8 | B19: 35 | C19: =C18+T18 -> 614.78 | D19: 1.55 | E19: =D19+F19 -> 1.634 | F19: =RANDBETWEEN(-105,125)/1000 -> 0.084 | G19: 0.16 | H19: =G19+I19 -> 0.093 | I19: =RANDBETWEEN(-105,125)/1000 -> -0.067 | J19: -0.15 | K19: =J19+L19 -> -0.166 | L19: =RANDBETWEEN(-105,125)/1000 -> -0.016 | M19: -0.11 | N19: =M19+O19 -> -0.204 | O19: =RANDBETWEEN(-105,125)/1000 -> -0.094 | P19: -0.07 | Q19: =P19+R19 -> -0.111 | R19: =RANDBETWEEN(-105,125)/1000 -> -0.041 | T19: 17.05
A20: 9 | B20: 36 | C20: =C19+T19 -> 631.83 | D20: 0.15 | E20: =D20+F20 -> 0.13 | F20: =RANDBETWEEN(-105,125)/1000 -> -0.02 | G20: 0.02 | H20: =G20+I20 -> 0.093 | I20: =RANDBETWEEN(-105,125)/1000 -> 0.073 | J20: -0.12 | K20: =J20+L20 -> -0.138 | L20: =RANDBETWEEN(-105,125)/1000 -> -0.018 | M20: -0.06 | N20: =M20+O20 -> -0.105 | O20: =RANDBETWEEN(-105,125)/1000 -> -0.045 | P20: -0.01 | Q20: =P20+R20 -> -0.094 | R20: =RANDBETWEEN(-105,125)/1000 -> -0.084 | T20: 11.7
A21: 10 | B21: E9 | C21: =C20+T20 -> 643.53 | D21: 0.28 | E21: =D21+F21 -> 0.369 | F21: =RANDBETWEEN(-105,125)/1000 -> 0.089 | G21: 0.15 | H21: =G21+I21 -> 0.258 | I21: =RANDBETWEEN(-105,125)/1000 -> 0.108 | J21: 0.01 | K21: =J21+L21 -> 0.018 | L21: =RANDBETWEEN(-105,125)/1000 -> 0.008 | M21: -0.05 | N21: =M21+O21 -> -0.097 | O21: =RANDBETWEEN(-105,125)/1000 -> -0.047 | P21: -0.1 | Q21: =P21+R21 -> 0.01 | R21: =RANDBETWEEN(-105,125)/1000 -> 0.11 | T21: 11.75
A22: 11 | B22: 37 | C22: =C21+T21 -> 655.28 | D22: 0.3 | E22: =D22+F22 -> 0.292 | F22: =RANDBETWEEN(-105,125)/1000 -> -0.008 | G22: 0.03 | H22: =G22+I22 -> 0.155 | I22: =RANDBETWEEN(-105,125)/1000 -> 0.125 | J22: -0.25 | K22: =J22+L22 -> -0.239 | L22: =RANDBETWEEN(-105,125)/1000 -> 0.011 | M22: -0.28 | N22: =M22+O22 -> -0.155 | O22: =RANDBETWEEN(-105,125)/1000 -> 0.125 | P22: -0.3 | Q22: =P22+R22 -> -0.196 | R22: =RANDBETWEEN(-105,125)/1000 -> 0.104 | T22: 17
A23: 12 | B23: 38 | C23: =C22+T22 -> 672.28 | D23: 0.39 | E23: =D23+F23 -> 0.356 | F23: =RANDBETWEEN(-105,125)/1000 -> -0.034 | G23: -1.46 | H23: =G23+I23 -> -1.372 | I23: =RANDBETWEEN(-105,125)/1000 -> 0.088 | J23: -1.62 | K23: =J23+L23 -> -1.694 | L23: =RANDBETWEEN(-105,125)/1000 -> -0.074 | M23: -1.68 | N23: =M23+O23 -> -1.725 | O23: =RANDBETWEEN(-105,125)/1000 -> -0.045 | P23: -1.73 | Q23: =P23+R23 -> -1.72 | R23: =RANDBETWEEN(-105,125)/1000 -> 0.01
A53: NHÀ THẦU THI CÔNG | K53: TƯ VẤN GIÁM SÁT
A57: Nguyễn Xuân Hưng | K57: ='Tuyến XD4'!Q3 -> Trần Mạnh Tùng

Sheet 2. Cao độ đào nền
A1: PHỤ LỤC KIỂM TRA CAO ĐỘ ĐÀO NỀN ĐƯỜNG
A2: ="Kèm theo BBNT số: "&VLOOKUP(W2,'Tuyến XD4'!$A$2:$G$60,7,0)&VLOOKUP(W2,'Tuyến XD4'!$A$2:$G$60,4,0) -> Kèm theo BBNT số: 30.NĐXD4/CVXD ngày 30 tháng 08 năm 2026 | W2: 30
A3: Dự án: Xây dựng HTKT Khu tái định cư phục vụ di dân xã Hải Hà, thị xã Nghi Sơn, tỉnh Thanh Hóa.
A4: Gói thầu số 12: Xây dựng HTKT khu vực Hải Bình và Xuân Lâm (bao gồm cả bảo hiểm xây dựng công trình)
A5: Nhà thầu thi công: Công ty TNHH Hoàng Tuấn
A6: Hạng mục: Nền đường tuyến XD4
A7: - Đối tượng nghiệm thu: | E7: =VLOOKUP(W2,'Tuyến XD4'!$A$2:$B$60,2,0) -> Đào đất xử lý nền đường đoạn từ Km0+554,08 - Km0+672,28
A8: Sơ họa:
A20: TT | B20: Tên cọc | C20: Lý trình | D20: Bên trái (H1) | J20: Tim (H2) | M20: Bên phải (H3) | S20: Chiều rộng đáy đào | V20: Ghi chú
D21: KCTK | E21: KCTC | F21: Chênh KC (m) | G21: CDTK (m) | H21: CDTC (m) | I21: Chênh CD (m) | J21: CDTK (m) | K21: CDTC (m) | L21: Chênh CD (m) | M21: KCTK | N21: KCTC | O21: Chênh KC (m) | P21: CDTK (m) | Q21: CDTC (m) | R21: Chênh CD (m) | S21: CRTK (m) | T21: CRTC (m) | U21: Chênh CR (m)
A24: =+'1. PL đường đen'!A12 -> 1 | B24: =+'1. PL đường đen'!B12 -> 32 | C24: =+'1. PL đường đen'!C12 -> 554.08 | D24: -5.42 | E24: =D24+F24 -> -5.408 | F24: =RANDBETWEEN(-105,115)/1000 -> 0.012 | G24: -1.61 | H24: =G24+I24 -> -1.561 | I24: =RANDBETWEEN(-105,115)/1000 -> 0.049 | J24: -1.61 | K24: =J24+L24 -> -1.614 | L24: =RANDBETWEEN(-105,115)/1000 -> -0.004 | M24: 8.66 | N24: =M24+O24 -> 8.584 | O24: =RANDBETWEEN(-105,115)/1000 -> -0.076 | P24: -1.61 | Q24: =P24+R24 -> -1.689 | R24: =RANDBETWEEN(-105,115)/1000 -> -0.079 | S24: =ABS(D24)+ABS(M24) -> 14.08 | T24: =S24+U24 -> 14.051 | U24: =RANDBETWEEN(-105,135)/1000 -> -0.029
A25: =+'1. PL đường đen'!A13 -> 2 | B25: =+'1. PL đường đen'!B13 -> 33 | C25: =+'1. PL đường đen'!C13 -> 569.48 | D25: -8.97 | E25: =D25+F25 -> -8.947 | F25: =RANDBETWEEN(-105,115)/1000 -> 0.023 | G25: -1.61 | H25: =G25+I25 -> -1.541 | I25: =RANDBETWEEN(-105,115)/1000 -> 0.069 | J25: -1.61 | K25: =J25+L25 -> -1.637 | L25: =RANDBETWEEN(-105,115)/1000 -> -0.027 | M25: 9.34 | N25: =M25+O25 -> 9.355 | O25: =RANDBETWEEN(-105,115)/1000 -> 0.015 | P25: -1.61 | Q25: =P25+R25 -> -1.691 | R25: =RANDBETWEEN(-105,115)/1000 -> -0.081 | S25: =ABS(D25)+ABS(M25) -> 18.31 | T25: =S25+U25 -> 18.343 | U25: =RANDBETWEEN(-105,135)/1000 -> 0.033
A26: =+'1. PL đường đen'!A14 -> 3 | B26: =+'1. PL đường đen'!B14 -> TD | C26: =+'1. PL đường đen'!C14 -> 573.12 | D26: -10.66 | E26: =D26+F26 -> -10.761 | F26: =RANDBETWEEN(-105,115)/1000 -> -0.101 | G26: -1.61 | H26: =G26+I26 -> -1.524 | I26: =RANDBETWEEN(-105,115)/1000 -> 0.086 | J26: -1.61 | K26: =J26+L26 -> -1.672 | L26: =RANDBETWEEN(-105,115)/1000 -> -0.062 | M26: 9.31 | N26: =M26+O26 -> 9.35 | O26: =RANDBETWEEN(-105,115)/1000 -> 0.04 | P26: -1.61 | Q26: =P26+R26 -> -1.68 | R26: =RANDBETWEEN(-105,115)/1000 -> -0.07 | S26: =ABS(D26)+ABS(M26) -> 19.97 | T26: =S26+U26 -> 19.95 | U26: =RANDBETWEEN(-105,135)/1000 -> -0.02
A27: =+'1. PL đường đen'!A15 -> 4 | B27: =+'1. PL đường đen'!B15 -> P | C27: =+'1. PL đường đen'!C15 -> 579.68 | D27: -9.58 | E27: =D27+F27 -> -9.501 | F27: =RANDBETWEEN(-105,115)/1000 -> 0.079 | G27: -1.61 | H27: =G27+I27 -> -1.653 | I27: =RANDBETWEEN(-105,115)/1000 -> -0.043 | J27: -1.61 | K27: =J27+L27 -> -1.574 | L27: =RANDBETWEEN(-105,115)/1000 -> 0.036 | M27: 14.26 | N27: =M27+O27 -> 14.299 | O27: =RANDBETWEEN(-105,115)/1000 -> 0.039 | P27: -1.61 | Q27: =P27+R27 -> -1.659 | R27: =RANDBETWEEN(-105,115)/1000 -> -0.049 | S27: =ABS(D27)+ABS(M27) -> 23.84 | T27: =S27+U27 -> 23.964 | U27: =RANDBETWEEN(-105,135)/1000 -> 0.124
A28: =+'1. PL đường đen'!A16 -> 5 | B28: =+'1. PL đường đen'!B16 -> E2 | C28: =+'1. PL đường đen'!C16 -> 584.52 | D28: -9.91 | E28: =D28+F28 -> -10.013 | F28: =RANDBETWEEN(-105,115)/1000 -> -0.103 | G28: -1.61 | H28: =G28+I28 -> -1.529 | I28: =RANDBETWEEN(-105,115)/1000 -> 0.081 | J28: -1.61 | K28: =J28+L28 -> -1.676 | L28: =RANDBETWEEN(-105,115)/1000 -> -0.066 | M28: 14.28 | N28: =M28+O28 -> 14.234 | O28: =RANDBETWEEN(-105,115)/1000 -> -0.046 | P28: -1.61 | Q28: =P28+R28 -> -1.654 | R28: =RANDBETWEEN(-105,115)/1000 -> -0.044 | S28: =ABS(D28)+ABS(M28) -> 24.19 | T28: =S28+U28 -> 24.1 | U28: =RANDBETWEEN(-105,135)/1000 -> -0.09
A29: =+'1. PL đường đen'!A17 -> 6 | B29: =+'1. PL đường đen'!B17 -> TC | C29: =+'1. PL đường đen'!C17 -> 586.23 | D29: -9.91 | E29: =D29+F29 -> -9.907 | F29: =RANDBETWEEN(-105,115)/1000 -> 0.003 | G29: -1.61 | H29: =G29+I29 -> -1.508 | I29: =RANDBETWEEN(-105,115)/1000 -> 0.102 | J29: -1.61 | K29: =J29+L29 -> -1.56 | L29: =RANDBETWEEN(-105,115)/1000 -> 0.05 | M29: 14.2 | N29: =M29+O29 -> 14.149 | O29: =RANDBETWEEN(-105,115)/1000 -> -0.051 | P29: -1.61 | Q29: =P29+R29 -> -1.684 | R29: =RANDBETWEEN(-105,115)/1000 -> -0.074 | S29: =ABS(D29)+ABS(M29) -> 24.11 | T29: =S29+U29 -> 24.218 | U29: =RANDBETWEEN(-105,135)/1000 -> 0.108
A30: =+'1. PL đường đen'!A18 -> 7 | B30: =+'1. PL đường đen'!B18 -> 34 | C30: =+'1. PL đường đen'!C18 -> 597.78 | D30: -5.5 | E30: =D30+F30 -> -5.558 | F30: =RANDBETWEEN(-105,115)/1000 -> -0.058 | G30: -1.61 | H30: =G30+I30 -> -1.63 | I30: =RANDBETWEEN(-105,115)/1000 -> -0.02 | J30: -0.62 | K30: =J30+L30 -> -0.649 | L30: =RANDBETWEEN(-105,115)/1000 -> -0.029 | M30: 9.3 | N30: =M30+O30 -> 9.356 | O30: =RANDBETWEEN(-105,115)/1000 -> 0.056 | P30: -1.61 | Q30: =P30+R30 -> -1.621 | R30: =RANDBETWEEN(-105,115)/1000 -> -0.011 | S30: =ABS(D30)+ABS(M30) -> 14.8 | T30: =S30+U30 -> 14.92 | U30: =RANDBETWEEN(-105,135)/1000 -> 0.12
A31: =+'1. PL đường đen'!A19 -> 8 | B31: =+'1. PL đường đen'!B19 -> 35 | C31: =+'1. PL đường đen'!C19 -> 614.78 | D31: -6 | E31: =D31+F31 -> -6.036 | F31: =RANDBETWEEN(-105,115)/1000 -> -0.036 | G31: -1.61 | H31: =G31+I31 -> -1.6 | I31: =RANDBETWEEN(-105,115)/1000 -> 0.01 | J31: -0.54 | K31: =J31+L31 -> -0.546 | L31: =RANDBETWEEN(-105,115)/1000 -> -0.006 | M31: 8.78 | N31: =M31+O31 -> 8.84 | O31: =RANDBETWEEN(-105,115)/1000 -> 0.06 | P31: -1.61 | Q31: =P31+R31 -> -1.497 | R31: =RANDBETWEEN(-105,115)/1000 -> 0.113 | S31: =ABS(D31)+ABS(M31) -> 14.78 | T31: =S31+U31 -> 14.693 | U31: =RANDBETWEEN(-105,135)/1000 -> -0.087
A32: =+'1. PL đường đen'!A20 -> 9 | B32: =+'1. PL đường đen'!B20 -> 36 | C32: =+'1. PL đường đen'!C20 -> 631.83 | D32: -8.19 | E32: =D32+F32 -> -8.148 | F32: =RANDBETWEEN(-105,115)/1000 -> 0.042 | G32: -1.62 | H32: =G32+I32 -> -1.626 | I32: =RANDBETWEEN(-105,115)/1000 -> -0.006 | J32: -1.62 | K32: =J32+L32 -> -1.534 | L32: =RANDBETWEEN(-105,115)/1000 -> 0.086 | M32: 8.61 | N32: =M32+O32 -> 8.642 | O32: =RANDBETWEEN(-105,115)/1000 -> 0.032 | P32: -1.62 | Q32: =P32+R32 -> -1.722 | R32: =RANDBETWEEN(-105,115)/1000 -> -0.102 | S32: =ABS(D32)+ABS(M32) -> 16.8 | T32: =S32+U32 -> 16.908 | U32: =RANDBETWEEN(-105,135)/1000 -> 0.108
A33: =+'1. PL đường đen'!A21 -> 10 | B33: =+'1. PL đường đen'!B21 -> E9 | C33: =+'1. PL đường đen'!C21 -> 643.53 | D33: -9.26 | E33: =D33+F33 -> -9.264 | F33: =RANDBETWEEN(-105,115)/1000 -> -0.004 | G33: -1.62 | H33: =G33+I33 -> -1.667 | I33: =RANDBETWEEN(-105,115)/1000 -> -0.047 | J33: -1.62 | K33: =J33+L33 -> -1.714 | L33: =RANDBETWEEN(-105,115)/1000 -> -0.094 | M33: 13.66 | N33: =M33+O33 -> 13.703 | O33: =RANDBETWEEN(-105,115)/1000 -> 0.043 | P33: -1.62 | Q33: =P33+R33 -> -1.72 | R33: =RANDBETWEEN(-105,115)/1000 -> -0.1 | S33: =ABS(D33)+ABS(M33) -> 22.92 | T33: =S33+U33 -> 22.851 | U33: =RANDBETWEEN(-105,135)/1000 -> -0.069
A34: =+'1. PL đường đen'!A22 -> 11 | B34: =+'1. PL đường đen'!B22 -> 37 | C34: =+'1. PL đường đen'!C22 -> 655.28 | D34: -7.85 | E34: =D34+F34 -> -7.871 | F34: =RANDBETWEEN(-105,115)/1000 -> -0.021 | G34: -1.62 | H34: =G34+I34 -> -1.527 | I34: =RANDBETWEEN(-105,115)/1000 -> 0.093 | J34: -1.62 | K34: =J34+L34 -> -1.623 | L34: =RANDBETWEEN(-105,115)/1000 -> -0.003 | M34: 9.44 | N34: =M34+O34 -> 9.507 | O34: =RANDBETWEEN(-105,115)/1000 -> 0.067 | P34: -1.62 | Q34: =P34+R34 -> -1.702 | R34: =RANDBETWEEN(-105,115)/1000 -> -0.082 | S34: =ABS(D34)+ABS(M34) -> 17.29 | T34: =S34+U34 -> 17.334 | U34: =RANDBETWEEN(-105,135)/1000 -> 0.044
A35: =+'1. PL đường đen'!A23 -> 12 | B35: =+'1. PL đường đen'!B23 -> 38 | C35: =+'1. PL đường đen'!C23 -> 672.28 | D35: -8.62 | E35: =D35+F35 -> -8.551 | F35: =RANDBETWEEN(-105,115)/1000 -> 0.069 | G35: -1.78 | H35: =G35+I35 -> -1.806 | I35: =RANDBETWEEN(-105,115)/1000 -> -0.026 | J35: -1.77 | K35: =J35+L35 -> -1.674 | L35: =RANDBETWEEN(-105,115)/1000 -> 0.096 | M35: 13.3 | N35: =M35+O35 -> 13.292 | O35: =RANDBETWEEN(-105,115)/1000 -> -0.008 | P35: -1.76 | Q35: =P35+R35 -> -1.813 | R35: =RANDBETWEEN(-105,115)/1000 -> -0.053 | S35: =ABS(D35)+ABS(M35) -> 21.92 | T35: =S35+U35 -> 22.015 | U35: =RANDBETWEEN(-105,135)/1000 -> 0.095
E63: NHÀ THẦU THI CÔNG | O63: TƯ VẤN GIÁM SÁT
E68: Nguyễn Xuân Hưng | O68: ='1. PL đường đen'!K57 -> Trần Mạnh Tùng

Sheet 2. KL đào nền
A1: PHỤ LỤC KHỐI LƯỢNG
A2: ="Kèm theo BBNT số: "&VLOOKUP(N2,'Tuyến XD4'!$A$2:$G$60,7,0)&VLOOKUP(N2,'Tuyến XD4'!$A$2:$G$60,4,0) -> Kèm theo BBNT số: 30.NĐXD4/CVXD ngày 30 tháng 08 năm 2026 | N2: 30
A3: ='2. Cao độ đào nền'!A3 -> Dự án: Xây dựng HTKT Khu tái định cư phục vụ di dân xã Hải Hà, thị xã Nghi Sơn, tỉnh Thanh Hóa.
A4: ='2. Cao độ đào nền'!A4 -> Gói thầu số 12: Xây dựng HTKT khu vực Hải Bình và Xuân Lâm (bao gồm cả bảo hiểm xây dựng công trình)
A5: Nhà thầu thi công: Công ty TNHH Hoàng Tuấn
A6: ='2. Cao độ đào nền'!A6 -> Hạng mục: Nền đường tuyến XD4
A7: - Đối tượng nghiệm thu: | D7: =VLOOKUP(N2,'Tuyến XD4'!$A$2:$B$60,2,0) -> Đào đất xử lý nền đường đoạn từ Km0+554,08 - Km0+672,28
A9: STT | B9: Tên cọc | C9: Lý trình | D9: K/c lẻ | F9: Đào xử lý nền đường | G9: Diện tích (m2) | J9: Khối lượng (m3) | M9: Ghi chú
F10: Diện tích | G10: Đào xử lý nền | H10: Đào đánh cấp | I10: Đào khuôn | J10: Đào xử lý nền | K10: Đào đánh cấp | L10: Đào khuôn
A11: 1 | B11: ='1. PL đường đen'!B12 -> 32 | C11: ='1. PL đường đen'!C12 -> 554.08 | D11: ='1. PL đường đen'!T12 -> 15.4 | E11: =RANDBETWEEN(1,7)/100 -> 0.01 | F11: 27.56 | G11: =+F11+E11 -> 27.57 | J11: =(G11+G12)*D11/2 -> 422.422
A12: 2 | B12: ='1. PL đường đen'!B13 -> 33 | C12: ='1. PL đường đen'!C13 -> 569.48 | D12: ='1. PL đường đen'!T13 -> 3.64 | E12: =RANDBETWEEN(1,7)/100 -> 0.06 | F12: 27.23 | G12: =+F12+E12 -> 27.29 | J12: =(G12+G13)*D12/2 -> 176.8858
A13: 3 | B13: ='1. PL đường đen'!B14 -> TD | C13: ='1. PL đường đen'!C14 -> 573.12 | D13: ='1. PL đường đen'!T14 -> 6.56 | E13: =RANDBETWEEN(1,7)/100 -> 0.07 | F13: 69.83 | G13: =+F13+E13 -> 69.9 | J13: =(G13+G14)*D13/2 -> 384.908
A14: 4 | B14: ='1. PL đường đen'!B15 -> P | C14: ='1. PL đường đen'!C15 -> 579.68 | D14: ='1. PL đường đen'!T15 -> 4.84 | E14: =RANDBETWEEN(1,7)/100 -> 0.07 | F14: 47.38 | G14: =+F14+E14 -> 47.45 | J14: =(G14+G15)*D14/2 -> 227.8188
A15: 5 | B15: ='1. PL đường đen'!B16 -> E2 | C15: ='1. PL đường đen'!C16 -> 584.52 | D15: ='1. PL đường đen'!T16 -> 1.71 | E15: =RANDBETWEEN(1,7)/100 -> 0.05 | F15: 46.64 | G15: =+F15+E15 -> 46.69 | J15: =(G15+G16)*D15/2 -> 80.17335
A16: 6 | B16: ='1. PL đường đen'!B17 -> TC | C16: ='1. PL đường đen'!C17 -> 586.23 | D16: ='1. PL đường đen'!T17 -> 11.55 | E16: =RANDBETWEEN(1,7)/100 -> 0.03 | F16: 47.05 | G16: =+F16+E16 -> 47.08 | J16: =(G16+G17)*D16/2 -> 387.90675
A17: 7 | B17: ='1. PL đường đen'!B18 -> 34 | C17: ='1. PL đường đen'!C18 -> 597.78 | D17: ='1. PL đường đen'!T18 -> 17 | E17: =RANDBETWEEN(1,7)/100 -> 0.06 | F17: 20.03 | G17: =+F17+E17 -> 20.09 | J17: =(G17+G18)*D17/2 -> 376.805
A18: 8 | B18: ='1. PL đường đen'!B19 -> 35 | C18: ='1. PL đường đen'!C19 -> 614.78 | D18: ='1. PL đường đen'!T19 -> 17.05 | E18: =RANDBETWEEN(1,7)/100 -> 0.07 | F18: 24.17 | G18: =+F18+E18 -> 24.24 | J18: =(G18+G19)*D18/2 -> 456.258
A19: 9 | B19: ='1. PL đường đen'!B20 -> 36 | C19: ='1. PL đường đen'!C20 -> 631.83 | D19: ='1. PL đường đen'!T20 -> 11.7 | E19: =RANDBETWEEN(1,7)/100 -> 0.05 | F19: 29.23 | G19: =+F19+E19 -> 29.28 | J19: =(G19+G20)*D19/2 -> 409.3245
A20: 10 | B20: ='1. PL đường đen'!B21 -> E9 | C20: ='1. PL đường đen'!C21 -> 643.53 | D20: ='1. PL đường đen'!T21 -> 11.75 | E20: =RANDBETWEEN(1,7)/100 -> 0.01 | F20: 40.68 | G20: =+F20+E20 -> 40.69 | J20: =(G20+G21)*D20/2 -> 401.79125
A21: 11 | B21: ='1. PL đường đen'!B22 -> 37 | C21: ='1. PL đường đen'!C22 -> 655.28 | D21: ='1. PL đường đen'!T22 -> 17 | E21: =RANDBETWEEN(1,7)/100 -> 0.07 | F21: 27.63 | G21: =+F21+E21 -> 27.7 | J21: =(G21+G22)*D21/2 -> 277.1
A22: 12 | B22: ='1. PL đường đen'!B23 -> 38 | C22: ='1. PL đường đen'!C23 -> 672.28 | E22: =RANDBETWEEN(1,7)/100 -> 0.05 | F22: 4.85 | G22: =+F22+E22 -> 4.9
A51: Tổng cộng (m3) | J51: =SUM(J11:J22) -> 3601.3935
A53: NHÀ THẦU THI CÔNG | E53: TƯ VẤN GIÁM SÁT
A58: ='2. Cao độ đào nền'!E68 -> Nguyễn Xuân Hưng | E58: =+'2. Cao độ đào nền'!O68 -> Trần Mạnh Tùng

Sheet 3. KTHH vải lọc
A1: PHỤ LỤC KIỂM TRA KÍCH THƯỚC HÌNH HỌC
A2: ="Kèm theo BBNT số: "&VLOOKUP(W2,'Tuyến XD4'!$A$2:$G$60,7,0)&VLOOKUP(W2,'Tuyến XD4'!$A$2:$G$60,4,0) -> Kèm theo BBNT số: 31.NĐXD4/CVXD ngày 31 tháng 08 năm 2026 | W2: 31
A3: Dự án: Xây dựng HTKT Khu tái định cư phục vụ di dân xã Hải Hà, thị xã Nghi Sơn, tỉnh Thanh Hóa.
A4: Gói thầu số 12: Xây dựng HTKT khu vực Hải Bình và Xuân Lâm (bao gồm cả bảo hiểm xây dựng công trình)
A5: Nhà thầu thi công: Công ty TNHH Hoàng Tuấn
A6: Hạng mục: Nền đường tuyến XD4
A7: - Đối tượng nghiệm thu: | E7: =VLOOKUP(W2,'Tuyến XD4'!$A$2:$B$60,2,0) -> Rải vải địa kỹ thuật đoạn từ Km0+554,08 - Km0+672,28
A8: Sơ họa:
A20: TT | B20: Tên cọc | C20: Lý trình | D20: L1 (m) | G20: L2 (m) | J20: L3 (m) | M20: L4 (m) | P20: L5 (m) | S20: L6 (m) | V20: Ghi chú
D21: Thiết kế (m) | E21: Thi công (m) | F21: Chênh lệch (m) | G21: Thiết kế (m) | H21: Thi công (m) | I21: Chênh lệch (m) | J21: Thiết kế (m) | K21: Thi công (m) | L21: Chênh lệch (m) | M21: Thiết kế (m) | N21: Thi công (m) | O21: Chênh lệch (m) | P21: Thiết kế (m) | Q21: Thi công (m) | R21: Chênh lệch (m) | S21: Thiết kế (m) | T21: Thi công (m) | U21: Chênh lệch (m)
A24: =+'1. PL đường đen'!A12 -> 1 | B24: =+'1. PL đường đen'!B12 -> 32 | C24: =+'1. PL đường đen'!C12 -> 554.08 | D24: 2 | E24: =+D24+F24 -> 2.06 | F24: =RANDBETWEEN(5,10)/100 -> 0.06 | G24: 1.41 | H24: =+G24+I24 -> 1.51 | I24: =RANDBETWEEN(5,10)/100 -> 0.1 | J24: 5.42 | K24: =+J24+L24 -> 5.52 | L24: =RANDBETWEEN(5,10)/100 -> 0.1 | M24: 8.66 | N24: =+M24+O24 -> 8.71 | O24: =RANDBETWEEN(5,10)/100 -> 0.05 | P24: 1.41 | Q24: =+P24+R24 -> 1.51 | R24: =RANDBETWEEN(5,10)/100 -> 0.1 | S24: 2 | T24: =+S24+U24 -> 2.08 | U24: =RANDBETWEEN(5,10)/100 -> 0.08
A25: =+'1. PL đường đen'!A13 -> 2 | B25: =+'1. PL đường đen'!B13 -> 33 | C25: =+'1. PL đường đen'!C13 -> 569.48 | D25: 2 | E25: =+D25+F25 -> 2.05 | F25: =RANDBETWEEN(5,10)/100 -> 0.05 | G25: 1.42 | H25: =+G25+I25 -> 1.49 | I25: =RANDBETWEEN(5,10)/100 -> 0.07 | J25: 8.97 | K25: =+J25+L25 -> 9.03 | L25: =RANDBETWEEN(5,10)/100 -> 0.06 | M25: 9.34 | N25: =+M25+O25 -> 9.4 | O25: =RANDBETWEEN(5,10)/100 -> 0.06 | P25: 1.42 | Q25: =+P25+R25 -> 1.52 | R25: =RANDBETWEEN(5,10)/100 -> 0.1 | S25: 2 | T25: =+S25+U25 -> 2.06 | U25: =RANDBETWEEN(5,10)/100 -> 0.06
A26: =+'1. PL đường đen'!A14 -> 3 | B26: =+'1. PL đường đen'!B14 -> TD | C26: =+'1. PL đường đen'!C14 -> 573.12 | D26: 2 | E26: =+D26+F26 -> 2.09 | F26: =RANDBETWEEN(5,10)/100 -> 0.09 | G26: 1.41 | H26: =+G26+I26 -> 1.46 | I26: =RANDBETWEEN(5,10)/100 -> 0.05 | J26: 10.66 | K26: =+J26+L26 -> 10.73 | L26: =RANDBETWEEN(5,10)/100 -> 0.07 | M26: 9.31 | N26: =+M26+O26 -> 9.36 | O26: =RANDBETWEEN(5,10)/100 -> 0.05 | P26: 1.41 | Q26: =+P26+R26 -> 1.48 | R26: =RANDBETWEEN(5,10)/100 -> 0.07 | S26: 2 | T26: =+S26+U26 -> 2.06 | U26: =RANDBETWEEN(5,10)/100 -> 0.06
A27: =+'1. PL đường đen'!A15 -> 4 | B27: =+'1. PL đường đen'!B15 -> P | C27: =+'1. PL đường đen'!C15 -> 579.68 | D27: 2 | E27: =+D27+F27 -> 2.06 | F27: =RANDBETWEEN(5,10)/100 -> 0.06 | G27: 1.41 | H27: =+G27+I27 -> 1.48 | I27: =RANDBETWEEN(5,10)/100 -> 0.07 | J27: 9.58 | K27: =+J27+L27 -> 9.63 | L27: =RANDBETWEEN(5,10)/100 -> 0.05 | M27: 14.26 | N27: =+M27+O27 -> 14.34 | O27: =RANDBETWEEN(5,10)/100 -> 0.08 | P27: 1.41 | Q27: =+P27+R27 -> 1.47 | R27: =RANDBETWEEN(5,10)/100 -> 0.06 | S27: 2 | T27: =+S27+U27 -> 2.08 | U27: =RANDBETWEEN(5,10)/100 -> 0.08
A28: =+'1. PL đường đen'!A16 -> 5 | B28: =+'1. PL đường đen'!B16 -> E2 | C28: =+'1. PL đường đen'!C16 -> 584.52 | D28: 2 | E28: =+D28+F28 -> 2.05 | F28: =RANDBETWEEN(5,10)/100 -> 0.05 | G28: 1.41 | H28: =+G28+I28 -> 1.46 | I28: =RANDBETWEEN(5,10)/100 -> 0.05 | J28: 9.91 | K28: =+J28+L28 -> 10 | L28: =RANDBETWEEN(5,10)/100 -> 0.09 | M28: 14.28 | N28: =+M28+O28 -> 14.33 | O28: =RANDBETWEEN(5,10)/100 -> 0.05 | P28: 1.41 | Q28: =+P28+R28 -> 1.49 | R28: =RANDBETWEEN(5,10)/100 -> 0.08 | S28: 2 | T28: =+S28+U28 -> 2.05 | U28: =RANDBETWEEN(5,10)/100 -> 0.05
A29: =+'1. PL đường đen'!A17 -> 6 | B29: =+'1. PL đường đen'!B17 -> TC | C29: =+'1. PL đường đen'!C17 -> 586.23 | D29: 2 | E29: =+D29+F29 -> 2.08 | F29: =RANDBETWEEN(5,10)/100 -> 0.08 | G29: 1.41 | H29: =+G29+I29 -> 1.51 | I29: =RANDBETWEEN(5,10)/100 -> 0.1 | J29: 9.91 | K29: =+J29+L29 -> 9.99 | L29: =RANDBETWEEN(5,10)/100 -> 0.08 | M29: 14.2 | N29: =+M29+O29 -> 14.28 | O29: =RANDBETWEEN(5,10)/100 -> 0.08 | P29: 1.41 | Q29: =+P29+R29 -> 1.48 | R29: =RANDBETWEEN(5,10)/100 -> 0.07 | S29: 2 | T29: =+S29+U29 -> 2.08 | U29: =RANDBETWEEN(5,10)/100 -> 0.08
A30: =+'1. PL đường đen'!A18 -> 7 | B30: =+'1. PL đường đen'!B18 -> 34 | C30: =+'1. PL đường đen'!C18 -> 597.78 | D30: 2 | E30: =+D30+F30 -> 2.08 | F30: =RANDBETWEEN(5,10)/100 -> 0.08 | G30: 1 | H30: =+G30+I30 -> 1.08 | I30: =RANDBETWEEN(5,10)/100 -> 0.08 | J30: 5.5 | K30: =+J30+L30 -> 5.56 | L30: =RANDBETWEEN(5,10)/100 -> 0.06 | M30: 9.3 | N30: =+M30+O30 -> 9.4 | O30: =RANDBETWEEN(5,10)/100 -> 0.1 | P30: 1.41 | Q30: =+P30+R30 -> 1.46 | R30: =RANDBETWEEN(5,10)/100 -> 0.05 | S30: 2 | T30: =+S30+U30 -> 2.06 | U30: =RANDBETWEEN(5,10)/100 -> 0.06
A31: =+'1. PL đường đen'!A19 -> 8 | B31: =+'1. PL đường đen'!B19 -> 35 | C31: =+'1. PL đường đen'!C19 -> 614.78 | D31: 2 | E31: =+D31+F31 -> 2.07 | F31: =RANDBETWEEN(5,10)/100 -> 0.07 | G31: 1 | H31: =+G31+I31 -> 1.06 | I31: =RANDBETWEEN(5,10)/100 -> 0.06 | J31: 6 | K31: =+J31+L31 -> 6.06 | L31: =RANDBETWEEN(5,10)/100 -> 0.06 | M31: 8.78 | N31: =+M31+O31 -> 8.84 | O31: =RANDBETWEEN(5,10)/100 -> 0.06 | P31: 1.41 | Q31: =+P31+R31 -> 1.5 | R31: =RANDBETWEEN(5,10)/100 -> 0.09 | S31: 2 | T31: =+S31+U31 -> 2.06 | U31: =RANDBETWEEN(5,10)/100 -> 0.06
A32: =+'1. PL đường đen'!A20 -> 9 | B32: =+'1. PL đường đen'!B20 -> 36 | C32: =+'1. PL đường đen'!C20 -> 631.83 | D32: 2 | E32: =+D32+F32 -> 2.08 | F32: =RANDBETWEEN(5,10)/100 -> 0.08 | G32: 1.41 | H32: =+G32+I32 -> 1.5 | I32: =RANDBETWEEN(5,10)/100 -> 0.09 | J32: 8.19 | K32: =+J32+L32 -> 8.27 | L32: =RANDBETWEEN(5,10)/100 -> 0.08 | M32: 8.61 | N32: =+M32+O32 -> 8.68 | O32: =RANDBETWEEN(5,10)/100 -> 0.07 | P32: 1.41 | Q32: =+P32+R32 -> 1.46 | R32: =RANDBETWEEN(5,10)/100 -> 0.05 | S32: 2 | T32: =+S32+U32 -> 2.09 | U32: =RANDBETWEEN(5,10)/100 -> 0.09
A33: =+'1. PL đường đen'!A21 -> 10 | B33: =+'1. PL đường đen'!B21 -> E9 | C33: =+'1. PL đường đen'!C21 -> 643.53 | D33: 2 | E33: =+D33+F33 -> 2.05 | F33: =RANDBETWEEN(5,10)/100 -> 0.05 | G33: 1.41 | H33: =+G33+I33 -> 1.46 | I33: =RANDBETWEEN(5,10)/100 -> 0.05 | J33: 9.26 | K33: =+J33+L33 -> 9.33 | L33: =RANDBETWEEN(5,10)/100 -> 0.07 | M33: 13.66 | N33: =+M33+O33 -> 13.75 | O33: =RANDBETWEEN(5,10)/100 -> 0.09 | P33: 1.41 | Q33: =+P33+R33 -> 1.46 | R33: =RANDBETWEEN(5,10)/100 -> 0.05 | S33: 2 | T33: =+S33+U33 -> 2.07 | U33: =RANDBETWEEN(5,10)/100 -> 0.07
A34: =+'1. PL đường đen'!A22 -> 11 | B34: =+'1. PL đường đen'!B22 -> 37 | C34: =+'1. PL đường đen'!C22 -> 655.28 | D34: 2 | E34: =+D34+F34 -> 2.05 | F34: =RANDBETWEEN(5,10)/100 -> 0.05 | G34: 1.41 | H34: =+G34+I34 -> 1.46 | I34: =RANDBETWEEN(5,10)/100 -> 0.05 | J34: 7.85 | K34: =+J34+L34 -> 7.93 | L34: =RANDBETWEEN(5,10)/100 -> 0.08 | M34: 9.44 | N34: =+M34+O34 -> 9.53 | O34: =RANDBETWEEN(5,10)/100 -> 0.09 | P34: 1.41 | Q34: =+P34+R34 -> 1.5 | R34: =RANDBETWEEN(5,10)/100 -> 0.09 | S34: 2 | T34: =+S34+U34 -> 2.08 | U34: =RANDBETWEEN(5,10)/100 -> 0.08
A35: =+'1. PL đường đen'!A23 -> 12 | B35: =+'1. PL đường đen'!B23 -> 38 | C35: =+'1. PL đường đen'!C23 -> 672.28 | D35: 2 | E35: =+D35+F35 -> 2.06 | F35: =RANDBETWEEN(5,10)/100 -> 0.06 | G35: 1.49 | H35: =+G35+I35 -> 1.56 | I35: =RANDBETWEEN(5,10)/100 -> 0.07 | J35: 8.62 | K35: =+J35+L35 -> 8.67 | L35: =RANDBETWEEN(5,10)/100 -> 0.05 | M35: 13.3 | N35: =+M35+O35 -> 13.38 | O35: =RANDBETWEEN(5,10)/100 -> 0.08 | P35: 2.3 | Q35: =+P35+R35 -> 2.39 | R35: =RANDBETWEEN(5,10)/100 -> 0.09 | S35: 2 | T35: =+S35+U35 -> 2.06 | U35: =RANDBETWEEN(5,10)/100 -> 0.06
E63: NHÀ THẦU THI CÔNG | O63: TƯ VẤN GIÁM SÁT
E68: Nguyễn Xuân Hưng | O68: Trần Mạnh Tùng

Sheet 3. KL vải lọc
A1: PHỤ LỤC KHỐI LƯỢNG
A2: ="Kèm theo BBNT số: "&VLOOKUP(O2,'Tuyến XD4'!$A$2:$G$60,7,0)&VLOOKUP(O2,'Tuyến XD4'!$A$2:$G$60,4,0) -> Kèm theo BBNT số: 31.NĐXD4/CVXD ngày 31 tháng 08 năm 2026 | O2: 31
A3: ='2. Cao độ đào nền'!A3 -> Dự án: Xây dựng HTKT Khu tái định cư phục vụ di dân xã Hải Hà, thị xã Nghi Sơn, tỉnh Thanh Hóa.
A4: ='2. Cao độ đào nền'!A4 -> Gói thầu số 12: Xây dựng HTKT khu vực Hải Bình và Xuân Lâm (bao gồm cả bảo hiểm xây dựng công trình)
A5: Nhà thầu thi công: Công ty TNHH Hoàng Tuấn
A6: ='2. Cao độ đào nền'!A6 -> Hạng mục: Nền đường tuyến XD4
A7: - Đối tượng nghiệm thu: | D7: =VLOOKUP(O2,'Tuyến XD4'!$A$2:$B$60,2,0) -> Rải vải địa kỹ thuật đoạn từ Km0+554,08 - Km0+672,28
A9: STT | B9: Tên cọc | C9: Lý trình | D9: K/c lẻ | K9: Khối lượng vải địa kỹ thuật | M9: Ghi chú
E10: Khối lượng thi công | K10: Chiều dài (m) | L10: Diện tích (m2)
A11: 1 | B11: ='1. PL đường đen'!B12 -> 32 | C11: ='1. PL đường đen'!C12 -> 554.08 | D11: ='1. PL đường đen'!T12 -> 15.4 | E11: ='3. KTHH vải lọc'!E24 -> 2.06 | F11: ='3. KTHH vải lọc'!H24 -> 1.51 | G11: ='3. KTHH vải lọc'!K24 -> 5.52 | H11: ='3. KTHH vải lọc'!N24 -> 8.71 | I11: ='3. KTHH vải lọc'!Q24 -> 1.51 | J11: ='3. KTHH vải lọc'!T24 -> 2.08 | K11: =SUM(E11:J11) -> 21.39 | L11: =(K11+K12)*D11/2 -> 361.438
A12: 2 | B12: ='1. PL đường đen'!B13 -> 33 | C12: ='1. PL đường đen'!C13 -> 569.48 | D12: ='1. PL đường đen'!T13 -> 3.64 | E12: ='3. KTHH vải lọc'!E25 -> 2.05 | F12: ='3. KTHH vải lọc'!H25 -> 1.49 | G12: ='3. KTHH vải lọc'!K25 -> 9.03 | H12: ='3. KTHH vải lọc'!N25 -> 9.4 | I12: ='3. KTHH vải lọc'!Q25 -> 1.52 | J12: ='3. KTHH vải lọc'!T25 -> 2.06 | K12: =SUM(E12:J12) -> 25.55 | L12: =(K12+K13)*D12/2 -> 95.9686
A13: 3 | B13: ='1. PL đường đen'!B14 -> TD | C13: ='1. PL đường đen'!C14 -> 573.12 | D13: ='1. PL đường đen'!T14 -> 6.56 | E13: ='3. KTHH vải lọc'!E26 -> 2.09 | F13: ='3. KTHH vải lọc'!H26 -> 1.46 | G13: ='3. KTHH vải lọc'!K26 -> 10.73 | H13: ='3. KTHH vải lọc'!N26 -> 9.36 | I13: ='3. KTHH vải lọc'!Q26 -> 1.48 | J13: ='3. KTHH vải lọc'!T26 -> 2.06 | K13: =SUM(E13:J13) -> 27.18 | L13: =(K13+K14)*D13/2 -> 191.0272
A14: 4 | B14: ='1. PL đường đen'!B15 -> P | C14: ='1. PL đường đen'!C15 -> 579.68 | D14: ='1. PL đường đen'!T15 -> 4.84 | E14: ='3. KTHH vải lọc'!E27 -> 2.06 | F14: ='3. KTHH vải lọc'!H27 -> 1.48 | G14: ='3. KTHH vải lọc'!K27 -> 9.63 | H14: ='3. KTHH vải lọc'!N27 -> 14.34 | I14: ='3. KTHH vải lọc'!Q27 -> 1.47 | J14: ='3. KTHH vải lọc'!T27 -> 2.08 | K14: =SUM(E14:J14) -> 31.06 | L14: =(K14+K15)*D14/2 -> 151.1048
A15: 5 | B15: ='1. PL đường đen'!B16 -> E2 | C15: ='1. PL đường đen'!C16 -> 584.52 | D15: ='1. PL đường đen'!T16 -> 1.71 | E15: ='3. KTHH vải lọc'!E28 -> 2.05 | F15: ='3. KTHH vải lọc'!H28 -> 1.46 | G15: ='3. KTHH vải lọc'!K28 -> 10 | H15: ='3. KTHH vải lọc'!N28 -> 14.33 | I15: ='3. KTHH vải lọc'!Q28 -> 1.49 | J15: ='3. KTHH vải lọc'!T28 -> 2.05 | K15: =SUM(E15:J15) -> 31.38 | L15: =(K15+K16)*D15/2 -> 53.694
A16: 6 | B16: ='1. PL đường đen'!B17 -> TC | C16: ='1. PL đường đen'!C17 -> 586.23 | D16: ='1. PL đường đen'!T17 -> 11.55 | E16: ='3. KTHH vải lọc'!E29 -> 2.08 | F16: ='3. KTHH vải lọc'!H29 -> 1.51 | G16: ='3. KTHH vải lọc'!K29 -> 9.99 | H16: ='3. KTHH vải lọc'!N29 -> 14.28 | I16: ='3. KTHH vải lọc'!Q29 -> 1.48 | J16: ='3. KTHH vải lọc'!T29 -> 2.08 | K16: =SUM(E16:J16) -> 31.42 | L16: =(K16+K17)*D16/2 -> 306.4215
A17: 7 | B17: ='1. PL đường đen'!B18 -> 34 | C17: ='1. PL đường đen'!C18 -> 597.78 | D17: ='1. PL đường đen'!T18 -> 17 | E17: ='3. KTHH vải lọc'!E30 -> 2.08 | F17: ='3. KTHH vải lọc'!H30 -> 1.08 | G17: ='3. KTHH vải lọc'!K30 -> 5.56 | H17: ='3. KTHH vải lọc'!N30 -> 9.4 | I17: ='3. KTHH vải lọc'!Q30 -> 1.46 | J17: ='3. KTHH vải lọc'!T30 -> 2.06 | K17: =SUM(E17:J17) -> 21.64 | L17: =(K17+K18)*D17/2 -> 367.455
A18: 8 | B18: ='1. PL đường đen'!B19 -> 35 | C18: ='1. PL đường đen'!C19 -> 614.78 | D18: ='1. PL đường đen'!T19 -> 17.05 | E18: ='3. KTHH vải lọc'!E31 -> 2.07 | F18: ='3. KTHH vải lọc'!H31 -> 1.06 | G18: ='3. KTHH vải lọc'!K31 -> 6.06 | H18: ='3. KTHH vải lọc'!N31 -> 8.84 | I18: ='3. KTHH vải lọc'!Q31 -> 1.5 | J18: ='3. KTHH vải lọc'!T31 -> 2.06 | K18: =SUM(E18:J18) -> 21.59 | L18: =(K18+K19)*D18/2 -> 389.33675
A19: 9 | B19: ='1. PL đường đen'!B20 -> 36 | C19: ='1. PL đường đen'!C20 -> 631.83 | D19: ='1. PL đường đen'!T20 -> 11.7 | E19: ='3. KTHH vải lọc'!E32 -> 2.08 | F19: ='3. KTHH vải lọc'!H32 -> 1.5 | G19: ='3. KTHH vải lọc'!K32 -> 8.27 | H19: ='3. KTHH vải lọc'!N32 -> 8.68 | I19: ='3. KTHH vải lọc'!Q32 -> 1.46 | J19: ='3. KTHH vải lọc'!T32 -> 2.09 | K19: =SUM(E19:J19) -> 24.08 | L19: =(K19+K20)*D19/2 -> 317.07
A20: 10 | B20: ='1. PL đường đen'!B21 -> E9 | C20: ='1. PL đường đen'!C21 -> 643.53 | D20: ='1. PL đường đen'!T21 -> 11.75 | E20: ='3. KTHH vải lọc'!E33 -> 2.05 | F20: ='3. KTHH vải lọc'!H33 -> 1.46 | G20: ='3. KTHH vải lọc'!K33 -> 9.33 | H20: ='3. KTHH vải lọc'!N33 -> 13.75 | I20: ='3. KTHH vải lọc'!Q33 -> 1.46 | J20: ='3. KTHH vải lọc'!T33 -> 2.07 | K20: =SUM(E20:J20) -> 30.12 | L20: =(K20+K21)*D20/2 -> 321.18625
A21: 11 | B21: ='1. PL đường đen'!B22 -> 37 | C21: ='1. PL đường đen'!C22 -> 655.28 | D21: ='1. PL đường đen'!T22 -> 17 | E21: ='3. KTHH vải lọc'!E34 -> 2.05 | F21: ='3. KTHH vải lọc'!H34 -> 1.46 | G21: ='3. KTHH vải lọc'!K34 -> 7.93 | H21: ='3. KTHH vải lọc'!N34 -> 9.53 | I21: ='3. KTHH vải lọc'!Q34 -> 1.5 | J21: ='3. KTHH vải lọc'!T34 -> 2.08 | K21: =SUM(E21:J21) -> 24.55 | L21: =(K21+K22)*D21/2 -> 464.695
A22: 12 | B22: ='1. PL đường đen'!B23 -> 38 | C22: ='1. PL đường đen'!C23 -> 672.28 | E22: ='3. KTHH vải lọc'!E35 -> 2.06 | F22: ='3. KTHH vải lọc'!H35 -> 1.56 | G22: ='3. KTHH vải lọc'!K35 -> 8.67 | H22: ='3. KTHH vải lọc'!N35 -> 13.38 | I22: ='3. KTHH vải lọc'!Q35 -> 2.39 | J22: ='3. KTHH vải lọc'!T35 -> 2.06 | K22: =SUM(E22:J22) -> 30.12
A51: Tổng cộng (m3) | L51: =SUM(L11:L22) -> 3019.3971
A53: NHÀ THẦU THI CÔNG | E53: TƯ VẤN GIÁM SÁT
A60: ='2. Cao độ đào nền'!E68 -> Nguyễn Xuân Hưng | K60: Trần Mạnh Tùng

Sheet chạy VL
A1: STT | B1: Tên cọc | C1: Lý trình | D1: Tên lớp | E1: Phần | F1: B trái | G1: B phải
A2: 1 | B2: 32 | C2: 554.08 | D2: 1 | E2: gập | F2: 2 | G2: 2
D3: 1 | E3: taluy | F3: 1.41 | G3: 1.41
D4: 1 | E4: đáy | F4: 5.42 | G4: 8.66
A5: 2 | B5: 33 | C5: 569.48 | D5: 1 | E5: gập | F5: 2 | G5: 2
D6: 1 | E6: taluy | F6: 1.42 | G6: 1.42
D7: 1 | E7: đáy | F7: 8.97 | G7: 9.34
A8: 3 | B8: TD | C8: 573.12 | D8: 1 | E8: gập | F8: 2 | G8: 2
D9: 1 | E9: taluy | F9: 1.41 | G9: 1.41
D10: 1 | E10: đáy | F10: 10.66 | G10: 9.31
A11: 4 | B11: P | C11: 579.68 | D11: 1 | E11: gập | F11: 2 | G11: 2
D12: 1 | E12: taluy | F12: 1.41 | G12: 1.41
D13: 1 | E13: đáy | F13: 9.58 | G13: 14.26
A14: 5 | B14: E2 | C14: 584.52 | D14: 1 | E14: gập | F14: 2 | G14: 2
D15: 1 | E15: taluy | F15: 1.41 | G15: 1.41
D16: 1 | E16: đáy | F16: 9.91 | G16: 14.28
A17: 6 | B17: TC | C17: 586.23 | D17: 1 | E17: gập | F17: 2 | G17: 2
D18: 1 | E18: taluy | F18: 1.41 | G18: 1.41
D19: 1 | E19: đáy | F19: 9.91 | G19: 14.2
A20: 7 | B20: 34 | C20: 597.78 | D20: 1 | E20: gập | F20: 2 | G20: 2
D21: 1 | E21: taluy | F21: 1 | G21: 1.41
D22: 1 | E22: đáy | F22: 5.5 | G22: 9.3
A23: 8 | B23: 35 | C23: 614.78 | D23: 1 | E23: gập | F23: 2 | G23: 2
D24: 1 | E24: taluy | F24: 1 | G24: 1.41
D25: 1 | E25: đáy | F25: 6 | G25: 8.78
A26: 9 | B26: 36 | C26: 631.83 | D26: 1 | E26: gập | F26: 2 | G26: 2
D27: 1 | E27: taluy | F27: 1.41 | G27: 1.41
D28: 1 | E28: đáy | F28: 8.19 | G28: 8.61
A29: 10 | B29: E9 | C29: 643.53 | D29: 1 | E29: gập | F29: 2 | G29: 2
D30: 1 | E30: taluy | F30: 1.41 | G30: 1.41
D31: 1 | E31: đáy | F31: 9.26 | G31: 13.66
A32: 11 | B32: 37 | C32: 655.28 | D32: 1 | E32: gập | F32: 2 | G32: 2
D33: 1 | E33: taluy | F33: 1.41 | G33: 1.41
D34: 1 | E34: đáy | F34: 7.85 | G34: 9.44
A35: 12 | B35: 38 | C35: 672.28 | D35: 1 | E35: gập | F35: 2 | G35: 2
D36: 1 | E36: taluy | F36: 1.49 | G36: 2.3
D37: 1 | E37: đáy | F37: 8.62 | G37: 13.3

Sheet KL tưới nhựa
A1: PHỤ LỤC KHỐI LƯỢNG TƯỚI NHỰA
A2: ="Kèm theo BBNT số: "&VLOOKUP(L2,'Tuyến XD4'!$A$2:$G$60,7,0)&VLOOKUP(L2,'Tuyến XD4'!$A$2:$G$60,4,0) -> Kèm theo BBNT số: 54.NĐXD4/CVXD ngày 14 tháng 09 năm 2026 | L2: 54
A3: Dự án: Xây dựng HTKT Khu tái định cư phục vụ di dân xã Hải Hà, thị xã Nghi Sơn, tỉnh Thanh Hóa.
A4: Gói thầu số 12: Xây dựng HTKT khu vực Hải Bình và Xuân Lâm (bao gồm cả bảo hiểm xây dựng công trình)
A5: Nhà thầu thi công: Công ty TNHH Hoàng Tuấn
A6: Hạng mục: Nền đường tuyến XD4
A7: - Đối tượng nghiệm thu: | E7: =VLOOKUP(L2,'Tuyến XD4'!$A$2:$B$60,2,0) -> Tưới lớp thấm bám mặt đường, nhựa MC70, lượng nhựa 1kg/m2
A9: STT | B9: Tên cọc | C9: Lý trình | D9: K/c lẻ | E9: Bề rộng tưới nhựa | H9: Diện tích tưới nhựa | K9: Ghi chú
E10: Thiết kế | F10: Thực tế | G10: Chênh lệch | H10: Thiết kế | I10: Thực tế | J10: Chênh lệch
A11: 1 | B11: ='1. PL đường đen'!B12 -> 32 | C11: 554.08 | D11: ='1. PL đường đen'!T12 -> 15.4 | E11: 10.5 | F11: =+E11+G11 -> 10.566 | G11: =RANDBETWEEN(-30,110)/1000 -> 0.066 | H11: =+(E11+E12)/2*D11 -> 161.7 | I11: =+(F11+F12)/2*D11 -> 162.239 | J11: =+I11-H11 -> 0.539
A12: 2 | B12: ='1. PL đường đen'!B13 -> 33 | C12: =C11+D11 -> 569.48 | D12: ='1. PL đường đen'!T13 -> 3.64 | E12: 10.5 | F12: =+E12+G12 -> 10.504 | G12: =RANDBETWEEN(-30,110)/1000 -> 0.004 | H12: =+(E12+E13)/2*D12 -> 38.22 | I12: =+(F12+F13)/2*D12 -> 38.19452 | J12: =+I12-H12 -> -0.02548
A13: 3 | B13: ='1. PL đường đen'!B14 -> TD | C13: =C12+D12 -> 573.12 | D13: ='1. PL đường đen'!T14 -> 6.56 | E13: 10.5 | F13: =+E13+G13 -> 10.482 | G13: =RANDBETWEEN(-30,110)/1000 -> -0.018 | H13: =+(E13+E14)/2*D13 -> 68.88 | I13: =+(F13+F14)/2*D13 -> 69.0604 | J13: =+I13-H13 -> 0.1804
A14: 4 | B14: ='1. PL đường đen'!B15 -> P | C14: =C13+D13 -> 579.68 | D14: ='1. PL đường đen'!T15 -> 4.84 | E14: 10.5 | F14: =+E14+G14 -> 10.573 | G14: =RANDBETWEEN(-30,110)/1000 -> 0.073 | H14: =+(E14+E15)/2*D14 -> 50.82 | I14: =+(F14+F15)/2*D14 -> 51.06442 | J14: =+I14-H14 -> 0.24442
A15: 5 | B15: ='1. PL đường đen'!B16 -> E2 | C15: =C14+D14 -> 584.52 | D15: ='1. PL đường đen'!T16 -> 1.71 | E15: 10.5 | F15: =+E15+G15 -> 10.528 | G15: =RANDBETWEEN(-30,110)/1000 -> 0.028 | H15: =+(E15+E16)/2*D15 -> 17.955 | I15: =+(F15+F16)/2*D15 -> 17.991765 | J15: =+I15-H15 -> 0.036765
A16: 6 | B16: ='1. PL đường đen'!B17 -> TC | C16: =C15+D15 -> 586.23 | D16: ='1. PL đường đen'!T17 -> 11.55 | E16: 10.5 | F16: =+E16+G16 -> 10.515 | G16: =RANDBETWEEN(-30,110)/1000 -> 0.015 | H16: =+(E16+E17)/2*D16 -> 121.275 | I16: =+(F16+F17)/2*D16 -> 121.6908 | J16: =+I16-H16 -> 0.4158
A17: 7 | B17: ='1. PL đường đen'!B18 -> 34 | C17: =C16+D16 -> 597.78 | D17: ='1. PL đường đen'!T18 -> 17 | E17: 10.5 | F17: =+E17+G17 -> 10.557 | G17: =RANDBETWEEN(-30,110)/1000 -> 0.057 | H17: =+(E17+E18)/2*D17 -> 178.5 | I17: =+(F17+F18)/2*D17 -> 179.724 | J17: =+I17-H17 -> 1.224
A18: 8 | B18: ='1. PL đường đen'!B19 -> 35 | C18: =C17+D17 -> 614.78 | D18: ='1. PL đường đen'!T19 -> 17.05 | E18: 10.5 | F18: =+E18+G18 -> 10.587 | G18: =RANDBETWEEN(-30,110)/1000 -> 0.087 | H18: =+(E18+E19)/2*D18 -> 179.025 | I18: =+(F18+F19)/2*D18 -> 179.99685 | J18: =+I18-H18 -> 0.97185
A19: 9 | B19: ='1. PL đường đen'!B20 -> 36 | C19: =C18+D18 -> 631.83 | D19: ='1. PL đường đen'!T20 -> 11.7 | E19: 10.5 | F19: =+E19+G19 -> 10.527 | G19: =RANDBETWEEN(-30,110)/1000 -> 0.027 | H19: =+(E19+E20)/2*D19 -> 122.85 | I19: =+(F19+F20)/2*D19 -> 123.61635 | J19: =+I19-H19 -> 0.76635
A20: 10 | B20: ='1. PL đường đen'!B21 -> E9 | C20: =C19+D19 -> 643.53 | D20: ='1. PL đường đen'!T21 -> 11.75 | E20: 10.5 | F20: =+E20+G20 -> 10.604 | G20: =RANDBETWEEN(-30,110)/1000 -> 0.104 | H20: =+(E20+E21)/2*D20 -> 123.375 | I20: =+(F20+F21)/2*D20 -> 124.23862 | J20: =+I20-H20 -> 0.863625
A21: 11 | B21: ='1. PL đường đen'!B22 -> 37 | C21: =C20+D20 -> 655.28 | D21: ='1. PL đường đen'!T22 -> 17 | E21: 10.5 | F21: =+E21+G21 -> 10.543 | G21: =RANDBETWEEN(-30,110)/1000 -> 0.043 | H21: =+(E21+E22)/2*D21 -> 178.5 | I21: =+(F21+F22)/2*D21 -> 179.1375 | J21: =+I21-H21 -> 0.6375
A22: 12 | B22: ='1. PL đường đen'!B23 -> 38 | C22: =C21+D21 -> 672.28 | E22: 10.5 | F22: =+E22+G22 -> 10.532 | G22: =RANDBETWEEN(-30,110)/1000 -> 0.032
A49: Tổng cộng (m3) | H49: =SUM(H11:H22) -> 1241.1 | I49: =SUM(I11:I22) -> 1246.9542 | J49: =+I49-H49 -> 5.85423
A51: NHÀ THẦU THI CÔNG | G51: TƯ VẤN GIÁM SÁT
A56: Nguyễn Xuân Hưng | G56: Lê Minh Hải

Sheet CĐ mặt đường
A1: PHỤ LỤC KIỂM TRA CAO ĐỘ MẶT ĐƯỜNG
A2: ="Kèm theo BBNT số: "&VLOOKUP(T2,'Tuyến XD4'!$A$2:$G$60,7,0)&VLOOKUP(T2,'Tuyến XD4'!$A$2:$G$60,4,0) -> Kèm theo BBNT số: 55.NĐXD4/CVXD ngày 17 tháng 09 năm 2026 | T2: 55
A3: Dự án: Xây dựng HTKT Khu tái định cư phục vụ di dân xã Hải Hà, thị xã Nghi Sơn, tỉnh Thanh Hóa.
A4: Gói thầu số 12: Xây dựng HTKT khu vực Hải Bình và Xuân Lâm (bao gồm cả bảo hiểm xây dựng công trình)
A5: Nhà thầu thi công: Công ty TNHH Hoàng Tuấn
A6: Hạng mục: Nền đường tuyến XD4
A7: - Đối tượng nghiệm thu: | D7: =VLOOKUP(T2,'Tuyến XD4'!$A$2:$B$60,2,0) -> Rải thảm mặt đường bê tông nhựa C16 - Chiều dày mặt đường đã lèn ép 6cm
A8: Sơ hoạ:
A20: TT | B20: Tên cọc | C20: Lý trình | D20: Bên trái (H1) | J20: Tim (H2) | M20: Bên phải (H3) | S20: Ghi chú
D21: KCTK | E21: KCTC | F21: Chênh KC (m) | G21: CDTK (m) | H21: CDTC (m) | I21: Chênh CD (m) | J21: CDTK (m) | K21: CDTC (m) | L21: Chênh CD (m) | M21: KCTK | N21: KCTC | O21: Chênh KC (m) | P21: CDTK (m) | Q21: CDTC (m) | R21: Chênh CD (m)
A22: ='1. PL đường đen'!A12 -> 1 | B22: ='1. PL đường đen'!B12 -> 32 | C22: ='1. PL đường đen'!C12 -> 554.08 | D22: 5.25 | E22: =+D22+F22 -> 5.259 | F22: =RANDBETWEEN(-20,20)/1000 -> 0.009 | G22: =+J22-4.95*2%-(D22-4.95)*6% -> 2.828 | H22: =G22+I22 -> 2.846 | I22: =RANDBETWEEN(-30,70)/1000 -> 0.018 | J22: 2.945 | K22: =J22+L22 -> 2.937 | L22: =RANDBETWEEN(-30,70)/1000 -> -0.008 | M22: =D22 -> 5.25 | N22: =+M22+O22 -> 5.265 | O22: =RANDBETWEEN(-20,20)/1000 -> 0.015 | P22: =+J22-4.95*2%-(M22-4.95)*6% -> 2.828 | Q22: =P22+R22 -> 2.843 | R22: =RANDBETWEEN(-20,20)/1000 -> 0.015
A23: ='1. PL đường đen'!A13 -> 2 | B23: ='1. PL đường đen'!B13 -> 33 | C23: ='1. PL đường đen'!C13 -> 569.48 | D23: =+D22 -> 5.25 | E23: =+D23+F23 -> 5.267 | F23: =RANDBETWEEN(-20,20)/1000 -> 0.017 | G23: =+J23-4.95*2%-(D23-4.95)*6% -> 2.821 | H23: =G23+I23 -> 2.817 | I23: =RANDBETWEEN(-30,70)/1000 -> -0.004 | J23: 2.938 | K23: =J23+L23 -> 2.943 | L23: =RANDBETWEEN(-30,70)/1000 -> 0.005 | M23: =D23 -> 5.25 | N23: =+M23+O23 -> 5.24 | O23: =RANDBETWEEN(-20,20)/1000 -> -0.01 | P23: =+J23-4.95*2%-(M23-4.95)*6% -> 2.821 | Q23: =P23+R23 -> 2.824 | R23: =RANDBETWEEN(-20,20)/1000 -> 0.003
A24: ='1. PL đường đen'!A14 -> 3 | B24: ='1. PL đường đen'!B14 -> TD | C24: ='1. PL đường đen'!C14 -> 573.12 | D24: =+D23 -> 5.25 | E24: =+D24+F24 -> 5.247 | F24: =RANDBETWEEN(-20,20)/1000 -> -0.003 | G24: =+J24-4.95*2%-(D24-4.95)*6% -> 2.82 | H24: =G24+I24 -> 2.851 | I24: =RANDBETWEEN(-30,70)/1000 -> 0.031 | J24: 2.937 | K24: =J24+L24 -> 2.993 | L24: =RANDBETWEEN(-30,70)/1000 -> 0.056 | M24: =D24 -> 5.25 | N24: =+M24+O24 -> 5.251 | O24: =RANDBETWEEN(-20,20)/1000 -> 0.001 | P24: =+J24-4.95*2%-(M24-4.95)*6% -> 2.82 | Q24: =P24+R24 -> 2.838 | R24: =RANDBETWEEN(-20,20)/1000 -> 0.018
A25: ='1. PL đường đen'!A15 -> 4 | B25: ='1. PL đường đen'!B15 -> P | C25: ='1. PL đường đen'!C15 -> 579.68 | D25: =+D24 -> 5.25 | E25: =+D25+F25 -> 5.245 | F25: =RANDBETWEEN(-20,20)/1000 -> -0.005 | G25: =+J25-4.95*2%-(D25-4.95)*6% -> 2.819 | H25: =G25+I25 -> 2.873 | I25: =RANDBETWEEN(-30,70)/1000 -> 0.054 | J25: 2.936 | K25: =J25+L25 -> 2.939 | L25: =RANDBETWEEN(-30,70)/1000 -> 0.003 | M25: =D25 -> 5.25 | N25: =+M25+O25 -> 5.257 | O25: =RANDBETWEEN(-20,20)/1000 -> 0.007 | P25: =+J25-4.95*2%-(M25-4.95)*6% -> 2.819 | Q25: =P25+R25 -> 2.82 | R25: =RANDBETWEEN(-20,20)/1000 -> 0.001
A26: ='1. PL đường đen'!A16 -> 5 | B26: ='1. PL đường đen'!B16 -> E2 | C26: ='1. PL đường đen'!C16 -> 584.52 | D26: =+D25 -> 5.25 | E26: =+D26+F26 -> 5.262 | F26: =RANDBETWEEN(-20,20)/1000 -> 0.012 | G26: =+J26-4.95*2%-(D26-4.95)*6% -> 2.818 | H26: =G26+I26 -> 2.798 | I26: =RANDBETWEEN(-30,70)/1000 -> -0.02 | J26: 2.935 | K26: =J26+L26 -> 2.918 | L26: =RANDBETWEEN(-30,70)/1000 -> -0.017 | M26: =D26 -> 5.25 | N26: =+M26+O26 -> 5.243 | O26: =RANDBETWEEN(-20,20)/1000 -> -0.007 | P26: =+J26-4.95*2%-(M26-4.95)*6% -> 2.818 | Q26: =P26+R26 -> 2.834 | R26: =RANDBETWEEN(-20,20)/1000 -> 0.016
A27: ='1. PL đường đen'!A17 -> 6 | B27: ='1. PL đường đen'!B17 -> TC | C27: ='1. PL đường đen'!C17 -> 586.23 | D27: =+D26 -> 5.25 | E27: =+D27+F27 -> 5.247 | F27: =RANDBETWEEN(-20,20)/1000 -> -0.003 | G27: =+J27-4.95*2%-(D27-4.95)*6% -> 2.817 | H27: =G27+I27 -> 2.862 | I27: =RANDBETWEEN(-30,70)/1000 -> 0.045 | J27: 2.934 | K27: =J27+L27 -> 3.002 | L27: =RANDBETWEEN(-30,70)/1000 -> 0.068 | M27: =D27 -> 5.25 | N27: =+M27+O27 -> 5.253 | O27: =RANDBETWEEN(-20,20)/1000 -> 0.003 | P27: =+J27-4.95*2%-(M27-4.95)*6% -> 2.817 | Q27: =P27+R27 -> 2.803 | R27: =RANDBETWEEN(-20,20)/1000 -> -0.014
