Workbook

Sheet Chạy
A1: STT | B1: TC | C1: LT | D1: TL | E1: DT | F1: KCt 1 | G1: CDt 1 | H1: KCt 2 | I1: CDt 2 | J1: KC tim | K1: CD tim | L1: KCp 1 | M1: CDp 1 | N1: KCp 2 | O1: CDp 2 | P1: S bao | Q1: S le
A2: 1 | B2: 31 | C2: 609.11 | D2: 8 | E2: 7.31 | F2: -11.95 | G2: 1.84 | H2: -5.25 | I2: 1.84 | J2: 0 | K2: 1.96 | L2: 5.25 | M2: 1.84 | N2: 11.95 | O2: 1.84 | P2: 68.14 | Q2: 11.55
D3: 7 | E3: 7.58 | F3: -12.4 | G3: 1.54 | H3: -5.25 | I3: 1.54 | J3: 0 | K3: 1.66 | L3: 5.25 | M3: 1.54 | N3: 12.4 | O3: 1.54
D4: 6 | E4: 7.85 | F4: -12.85 | G4: 1.24 | H4: -5.25 | I4: 1.24 | J4: 0 | K4: 1.36 | L4: 5.25 | M4: 1.24 | N4: 12.85 | O4: 1.24
D5: 5 | E5: 8.12 | F5: -13.3 | G5: 0.94 | H5: -5.25 | I5: 0.94 | J5: 0 | K5: 1.06 | L5: 5.25 | M5: 0.94 | N5: 13.3 | O5: 0.94
D6: 4 | E6: 8.39 | F6: -13.75 | G6: 0.64 | H6: -5.25 | I6: 0.64 | J6: 0 | K6: 0.76 | L6: 5.25 | M6: 0.64 | N6: 13.75 | O6: 0.64
D7: 3 | E7: 7.42 | F7: -14.2 | G7: 0.34 | H7: -5.25 | I7: 0.34 | J7: 0 | K7: 0.46 | L7: 5.25 | M7: 0.34 | N7: 14.2 | O7: 0.34
D8: 2 | E8: 5.72 | F8: -9.76 | G8: 0.04 | H8: -5.25 | I8: 0.04 | J8: 0 | K8: 0.16 | L8: 5.25 | M8: 0.04 | N8: 9.62 | O8: 0.04
D9: 1 | E9: 4.22 | F9: -9.46 | G9: -0.26 | H9: -5.25 | I9: -0.26 | J9: 0 | K9: -0.14 | L9: 5.25 | M9: -0.26 | N9: 9.32 | O9: -0.26
A10: 2 | B10: E10 | C10: 620.86 | D10: 8 | E10: 7.31 | F10: -11.95 | G10: 1.84 | H10: -5.25 | I10: 1.84 | J10: 0 | K10: 1.96 | L10: 5.25 | M10: 1.84 | N10: 11.95 | O10: 1.84 | P10: 66.71 | Q10: 11.55
D11: 7 | E11: 7.58 | F11: -12.4 | G11: 1.54 | H11: -5.25 | I11: 1.54 | J11: 0 | K11: 1.66 | L11: 5.25 | M11: 1.54 | N11: 12.4 | O11: 1.54
D12: 6 | E12: 7.85 | F12: -12.85 | G12: 1.24 | H12: -5.25 | I12: 1.24 | J12: 0 | K12: 1.36 | L12: 5.25 | M12: 1.24 | N12: 12.85 | O12: 1.24
D13: 5 | E13: 8.12 | F13: -13.3 | G13: 0.94 | H13: -5.25 | I13: 0.94 | J13: 0 | K13: 1.06 | L13: 5.25 | M13: 0.94 | N13: 13.3 | O13: 0.94
D14: 4 | E14: 8.34 | F14: -13.75 | G14: 0.64 | H14: -5.25 | I14: 0.64 | J14: 0 | K14: 0.76 | L14: 5.25 | M14: 0.64 | N14: 13.75 | O14: 0.64
D15: 3 | E15: 6.08 | F15: -10.01 | G15: 0.34 | H15: -5.25 | I15: 0.34 | J15: 0 | K15: 0.46 | L15: 5.25 | M15: 0.34 | N15: 14.2 | O15: 0.34
D16: 2 | E16: 5.68 | F16: -9.54 | G16: 0.04 | H16: -5.25 | I16: 0.04 | J16: 0 | K16: 0.16 | L16: 5.25 | M16: 0.04 | N16: 9.68 | O16: 0.04
D17: 1 | E17: 4.22 | F17: -9.24 | G17: -0.26 | H17: -5.25 | I17: -0.26 | J17: 0 | K17: -0.14 | L17: 5.25 | M17: -0.26 | N17: 9.38 | O17: -0.26
A18: 3 | B18: 32 | C18: 632.61 | D18: 8 | E18: 7.31 | F18: -11.95 | G18: 1.84 | H18: -5.25 | I18: 1.84 | J18: 0 | K18: 1.96 | L18: 5.25 | M18: 1.84 | N18: 11.95 | O18: 1.84 | P18: 70.95 | Q18: 11.55
D19: 7 | E19: 7.58 | F19: -12.4 | G19: 1.54 | H19: -5.25 | I19: 1.54 | J19: 0 | K19: 1.66 | L19: 5.25 | M19: 1.54 | N19: 12.4 | O19: 1.54
D20: 6 | E20: 7.85 | F20: -12.85 | G20: 1.24 | H20: -5.25 | I20: 1.24 | J20: 0 | K20: 1.36 | L20: 5.25 | M20: 1.24 | N20: 12.85 | O20: 1.24
D21: 5 | E21: 8.12 | F21: -13.3 | G21: 0.94 | H21: -5.25 | I21: 0.94 | J21: 0 | K21: 1.06 | L21: 5.25 | M21: 0.94 | N21: 13.3 | O21: 0.94
D22: 4 | E22: 8.39 | F22: -13.75 | G22: 0.64 | H22: -5.25 | I22: 0.64 | J22: 0 | K22: 0.76 | L22: 5.25 | M22: 0.64 | N22: 13.75 | O22: 0.64
D23: 3 | E23: 8.66 | F23: -14.2 | G23: 0.34 | H23: -5.25 | I23: 0.34 | J23: 0 | K23: 0.46 | L23: 5.25 | M23: 0.34 | N23: 14.2 | O23: 0.34
D24: 2 | E24: 6.98 | F24: -14.65 | G24: 0.04 | H24: -5.25 | I24: 0.04 | J24: 0 | K24: 0.16 | L24: 5.25 | M24: 0.04 | N24: 14.65 | O24: 0.04
D25: 1 | E25: 4.53 | F25: -9.97 | G25: -0.26 | H25: -5.25 | I25: -0.26 | J25: 0 | K25: -0.14 | L25: 5.25 | M25: -0.26 | N25: 10.13 | O25: -0.26
A26: 4 | B26: 33 | C26: 652.61 | D26: 8 | E26: 7.31 | F26: -11.95 | G26: 1.85 | H26: -5.25 | I26: 1.85 | J26: 0 | K26: 1.96 | L26: 5.25 | M26: 1.85 | N26: 11.95 | O26: 1.85 | P26: 73.81 | Q26: 11.55
D27: 7 | E27: 7.58 | F27: -12.4 | G27: 1.55 | H27: -5.25 | I27: 1.55 | J27: 0 | K27: 1.66 | L27: 5.25 | M27: 1.55 | N27: 12.4 | O27: 1.55
D28: 6 | E28: 7.85 | F28: -12.85 | G28: 1.25 | H28: -5.25 | I28: 1.25 | J28: 0 | K28: 1.36 | L28: 5.25 | M28: 1.25 | N28: 12.85 | O28: 1.25
D29: 5 | E29: 8.12 | F29: -13.3 | G29: 0.95 | H29: -5.25 | I29: 0.95 | J29: 0 | K29: 1.06 | L29: 5.25 | M29: 0.95 | N29: 13.3 | O29: 0.95
D30: 4 | E30: 8.39 | F30: -13.75 | G30: 0.65 | H30: -5.25 | I30: 0.65 | J30: 0 | K30: 0.76 | L30: 5.25 | M30: 0.65 | N30: 13.75 | O30: 0.65
D31: 3 | E31: 8.66 | F31: -14.2 | G31: 0.35 | H31: -5.25 | I31: 0.35 | J31: 0 | K31: 0.46 | L31: 5.25 | M31: 0.35 | N31: 14.2 | O31: 0.35
D32: 2 | E32: 8.93 | F32: -14.65 | G32: 0.05 | H32: -5.25 | I32: 0.05 | J32: 0 | K32: 0.16 | L32: 5.25 | M32: 0.05 | N32: 14.65 | O32: 0.05
D33: 1 | E33: 5.44 | F33: -15.1 | G33: -0.25 | H33: -5.25 | I33: -0.25 | J33: 0 | K33: -0.14 | L33: 5.25 | M33: -0.25 | N33: 15.1 | O33: -0.25
A34: 5 | B34: 34 | C34: 672.61 | D34: 8 | E34: 7.31 | F34: -11.95 | G34: 1.85 | H34: -5.25 | I34: 1.85 | J34: 0 | K34: 1.96 | L34: 5.25 | M34: 1.85 | N34: 11.95 | O34: 1.85 | P34: 70.29 | Q34: 11.55
D35: 7 | E35: 7.58 | F35: -12.4 | G35: 1.55 | H35: -5.25 | I35: 1.55 | J35: 0 | K35: 1.66 | L35: 5.25 | M35: 1.55 | N35: 12.4 | O35: 1.55
D36: 6 | E36: 7.85 | F36: -12.85 | G36: 1.25 | H36: -5.25 | I36: 1.25 | J36: 0 | K36: 1.36 | L36: 5.25 | M36: 1.25 | N36: 12.85 | O36: 1.25
D37: 5 | E37: 8.12 | F37: -13.3 | G37: 0.95 | H37: -5.25 | I37: 0.95 | J37: 0 | K37: 1.06 | L37: 5.25 | M37: 0.95 | N37: 13.3 | O37: 0.95
D38: 4 | E38: 8.39 | F38: -13.75 | G38: 0.65 | H38: -5.25 | I38: 0.65 | J38: 0 | K38: 0.76 | L38: 5.25 | M38: 0.65 | N38: 13.75 | O38: 0.65
D39: 3 | E39: 8.66 | F39: -14.2 | G39: 0.35 | H39: -5.25 | I39: 0.35 | J39: 0 | K39: 0.46 | L39: 5.25 | M39: 0.35 | N39: 14.2 | O39: 0.35
D40: 2 | E40: 6.34 | F40: -14.65 | G40: 0.05 | H40: -5.25 | I40: 0.05 | J40: 0 | K40: 0.16 | L40: 5.25 | M40: 0.05 | N40: 14.65 | O40: 0.05
...

Sheet 1.KTHH L1
A1: PHỤ LỤC KIỂM TRA CAO ĐỘ, KÍCH THƯỚC HÌNH HỌC
A2: ="Kèm theo BBNT số: "&VLOOKUP(AZ2,'[1]Tuyến XD8'!$A$2:$G$60,7,0)&VLOOKUP(AZ2,'[1]Tuyến XD8'!$A$2:$G$60,4,0) -> Kèm theo BBNT số: 91.NĐXD8/CVXD ngày 30 tháng 09 năm 2026 | AZ2: 91
A3: Dự án: Xây dựng HTKT Khu tái định cư phục vụ di dân xã Hải Hà, thị xã Nghi Sơn, tỉnh Thanh Hóa.
A4: Gói thầu số 12: Xây dựng HTKT khu vực Hải Bình và Xuân Lâm (bao gồm cả bảo hiểm xây dựng công trình)
A5: Nhà thầu thi công: Công ty TNHH Hoàng Tuấn
A6: Hạng mục: Nền đường tuyến XD8
A7: - Đối tượng nghiệm thu: | G7: =VLOOKUP(AZ2,'[1]Tuyến XD8'!$A$2:$B$60,2,0) -> Đắp đất nền đường lớp 1 đoạn từ Km0+609,11 - Km0+724,11, độ chặt K>=0,95
A8: Sơ họa:
A19: TT | B19: Tên cọc | C19: Lý trình | D19: Bên trái (H1) | J19: Tim (H2) | M19: Bên phải (H3) | S19: Ghi chú
D20: KCTK | E20: KCTC | F20: Chênh KC (m) | G20: CDTK (m) | H20: CDTC (m) | I20: Chênh CD (m) | J20: CDTK (m) | K20: CDTC (m) | L20: Chênh CD (m) | M20: KCTK | N20: KCTC | O20: Chênh KC (m) | P20: CDTK (m) | Q20: CDTC (m) | R20: Chênh CD (m)
A21: 1 | B21: 31 | C21: 609.11 | D21: =+Chạy!F9 -> -9.46 | E21: =+D21+F21 -> -9.4524 | F21: =RANDBETWEEN(-105,115)/10000 -> 0.0076 | G21: =+Chạy!G9 -> -0.26 | H21: =G21+I21 -> -0.283 | I21: =RANDBETWEEN(-30,90)/1000 -> -0.023 | J21: =+Chạy!K9 -> -0.14 | K21: =J21+L21 -> -0.163 | L21: =RANDBETWEEN(-30,90)/1000 -> -0.023 | M21: =+Chạy!N9 -> 9.32 | N21: =+M21+O21 -> 9.3262 | O21: =RANDBETWEEN(-105,115)/10000 -> 0.0062 | P21: =+Chạy!O9 -> -0.26 | Q21: =P21+R21 -> -0.269 | R21: =RANDBETWEEN(-30,90)/1000 -> -0.009 | T21: 11.75
A22: 2 | B22: E10 | C22: =+C21+T21 -> 620.86 | D22: =+Chạy!F17 -> -9.24 | E22: =+D22+F22 -> -9.2444 | F22: =RANDBETWEEN(-105,115)/10000 -> -0.0044 | G22: =+Chạy!G17 -> -0.26 | H22: =G22+I22 -> -0.253 | I22: =RANDBETWEEN(-30,90)/1000 -> 0.007 | J22: =+Chạy!K17 -> -0.14 | K22: =J22+L22 -> -0.16 | L22: =RANDBETWEEN(-30,90)/1000 -> -0.02 | M22: =+Chạy!N17 -> 9.38 | N22: =+M22+O22 -> 9.373 | O22: =RANDBETWEEN(-105,115)/10000 -> -0.007 | P22: =+Chạy!O17 -> -0.26 | Q22: =P22+R22 -> -0.226 | R22: =RANDBETWEEN(-30,90)/1000 -> 0.034 | T22: 11.75
A23: 3 | B23: 32 | C23: =+C22+T22 -> 632.61 | D23: =+Chạy!F25 -> -9.97 | E23: =+D23+F23 -> -9.9662 | F23: =RANDBETWEEN(-105,115)/10000 -> 0.0038 | G23: =+Chạy!G25 -> -0.26 | H23: =G23+I23 -> -0.279 | I23: =RANDBETWEEN(-30,90)/1000 -> -0.019 | J23: =+Chạy!K25 -> -0.14 | K23: =J23+L23 -> -0.116 | L23: =RANDBETWEEN(-30,90)/1000 -> 0.024 | M23: =+Chạy!N25 -> 10.13 | N23: =+M23+O23 -> 10.1296 | O23: =RANDBETWEEN(-105,115)/10000 -> -0.0004 | P23: =+Chạy!O25 -> -0.26 | Q23: =P23+R23 -> -0.209 | R23: =RANDBETWEEN(-30,90)/1000 -> 0.051 | T23: 20
A24: 4 | B24: 33 | C24: =+C23+T23 -> 652.61 | D24: =+Chạy!F33 -> -15.1 | E24: =+D24+F24 -> -15.1037 | F24: =RANDBETWEEN(-105,115)/10000 -> -0.0037 | G24: =+Chạy!G33 -> -0.25 | H24: =G24+I24 -> -0.161 | I24: =RANDBETWEEN(-30,90)/1000 -> 0.089 | J24: =+Chạy!K33 -> -0.14 | K24: =J24+L24 -> -0.121 | L24: =RANDBETWEEN(-30,90)/1000 -> 0.019 | M24: =+Chạy!N33 -> 15.1 | N24: =+M24+O24 -> 15.1024 | O24: =RANDBETWEEN(-105,115)/10000 -> 0.0024 | P24: =+Chạy!O33 -> -0.25 | Q24: =P24+R24 -> -0.191 | R24: =RANDBETWEEN(-30,90)/1000 -> 0.059 | T24: 20
A25: 5 | B25: 34 | C25: =+C24+T24 -> 672.61 | D25: =+Chạy!F41 -> -9.83 | E25: =+D25+F25 -> -9.8247 | F25: =RANDBETWEEN(-105,115)/10000 -> 0.0053 | G25: =+Chạy!G41 -> -0.25 | H25: =G25+I25 -> -0.232 | I25: =RANDBETWEEN(-30,90)/1000 -> 0.018 | J25: =+Chạy!K41 -> -0.14 | K25: =J25+L25 -> -0.132 | L25: =RANDBETWEEN(-30,90)/1000 -> 0.008 | M25: =+Chạy!N41 -> 9.87 | N25: =+M25+O25 -> 9.8677 | O25: =RANDBETWEEN(-105,115)/10000 -> -0.0023 | P25: =+Chạy!O41 -> -0.25 | Q25: =P25+R25 -> -0.271 | R25: =RANDBETWEEN(-30,90)/1000 -> -0.021 | T25: 20
A26: 6 | B26: 35 | C26: =+C25+T25 -> 692.61 | D26: =+Chạy!F49 -> -15.1 | E26: =+D26+F26 -> -15.091 | F26: =RANDBETWEEN(-105,115)/10000 -> 0.009 | G26: =+Chạy!G49 -> -0.25 | H26: =G26+I26 -> -0.173 | I26: =RANDBETWEEN(-30,90)/1000 -> 0.077 | J26: =+Chạy!K49 -> -0.13 | K26: =J26+L26 -> -0.076 | L26: =RANDBETWEEN(-30,90)/1000 -> 0.054 | M26: =+Chạy!N49 -> 15.1 | N26: =+M26+O26 -> 15.108 | O26: =RANDBETWEEN(-105,115)/10000 -> 0.008 | P26: =+Chạy!O49 -> -0.25 | Q26: =P26+R26 -> -0.175 | R26: =RANDBETWEEN(-30,90)/1000 -> 0.075 | T26: 20
A27: 7 | B27: 36 | C27: =+C26+T26 -> 712.61 | D27: =+Chạy!F57 -> -6.45 | E27: =+D27+F27 -> -6.4466 | F27: =RANDBETWEEN(-105,115)/10000 -> 0.0034 | G27: =+Chạy!G57 -> -0.25 | H27: =G27+I27 -> -0.225 | I27: =RANDBETWEEN(-30,90)/1000 -> 0.025 | J27: =+Chạy!K57 -> -0.13 | K27: =J27+L27 -> -0.086 | L27: =RANDBETWEEN(-30,90)/1000 -> 0.044 | M27: =+Chạy!N57 -> 15.1 | N27: =+M27+O27 -> 15.0949 | O27: =RANDBETWEEN(-105,115)/10000 -> -0.0051 | P27: =+Chạy!O57 -> -0.25 | Q27: =P27+R27 -> -0.232 | R27: =RANDBETWEEN(-30,90)/1000 -> 0.018 | T27: 11.5
A28: 8 | B28: 37 | C28: =+C27+T27 -> 724.11 | D28: =+Chạy!F65 -> -15.1 | E28: =+D28+F28 -> -15.0892 | F28: =RANDBETWEEN(-105,115)/10000 -> 0.0108 | G28: =+Chạy!G65 -> -0.25 | H28: =G28+I28 -> -0.209 | I28: =RANDBETWEEN(-30,90)/1000 -> 0.041 | J28: =+Chạy!K65 -> -0.13 | K28: =J28+L28 -> -0.056 | L28: =RANDBETWEEN(-30,90)/1000 -> 0.074 | M28: =+Chạy!N65 -> 9.44 | N28: =+M28+O28 -> 9.4492 | O28: =RANDBETWEEN(-105,115)/10000 -> 0.0092 | P28: =+Chạy!O65 -> -0.25 | Q28: =P28+R28 -> -0.26 | R28: =RANDBETWEEN(-30,90)/1000 -> -0.01
C62: NHÀ THẦU THI CÔNG | O62: TƯ VẤN GIÁM SÁT
C67: Nguyễn Xuân Hưng | O67: Lê Quốc Huy

Sheet 1.KL L1
A1: PHỤ LỤC KHỐI LƯỢNG
A2: ="Kèm theo BBNT số: "&VLOOKUP(AZ2,'[1]Tuyến XD8'!$A$2:$G$60,7,0)&VLOOKUP(AZ2,'[1]Tuyến XD8'!$A$2:$G$60,4,0) -> Kèm theo BBNT số: 91.NĐXD8/CVXD ngày 30 tháng 09 năm 2026 | AZ2: 91
A3: Dự án: Xây dựng HTKT Khu tái định cư phục vụ di dân xã Hải Hà, thị xã Nghi Sơn, tỉnh Thanh Hóa.
A4: Gói thầu số 12: Xây dựng HTKT khu vực Hải Bình và Xuân Lâm (bao gồm cả bảo hiểm xây dựng công trình)
A5: Nhà thầu thi công: Công ty TNHH Hoàng Tuấn
A6: Hạng mục: Nền đường tuyến XD8
A7: - Đối tượng nghiệm thu: | D7: =VLOOKUP(AZ2,'[1]Tuyến XD8'!$A$2:$B$60,2,0) -> Đắp đất nền đường lớp 1 đoạn từ Km0+609,11 - Km0+724,11, độ chặt K>=0,95
A9: STT | B9: Tên cọc | C9: Lý trình | D9: K/c lẻ | M9: Khối lượng đắp đất | AB9: Ghi chú
N10: Diện tích | O10: Diện tích (m2) | P10: Diện tích | Q10: Diện tích | U10: Khối lượng | V10: Khối lượng | W10: Khối lượng (m3) | X10: Khối lượng | Y10: Khối lượng
A11: 1 | B11: ='1.KTHH L1'!B21 -> 31 | C11: ='1.KTHH L1'!C21 -> 609.11 | D11: ='1.KTHH L1'!T21 -> 11.75 | O11: =Chạy!E9 -> 4.22 | W11: =(O11+O12)*D11/2 -> 49.585
A12: 2 | B12: ='1.KTHH L1'!B22 -> E10 | C12: ='1.KTHH L1'!C22 -> 620.86 | D12: ='1.KTHH L1'!T22 -> 11.75 | O12: =Chạy!E17 -> 4.22 | W12: =(O12+O13)*D12/2 -> 51.40625
A13: 3 | B13: ='1.KTHH L1'!B23 -> 32 | C13: ='1.KTHH L1'!C23 -> 632.61 | D13: ='1.KTHH L1'!T23 -> 20 | O13: =Chạy!E25 -> 4.53 | W13: =(O13+O14)*D13/2 -> 99.7
A14: 4 | B14: ='1.KTHH L1'!B24 -> 33 | C14: ='1.KTHH L1'!C24 -> 652.61 | D14: ='1.KTHH L1'!T24 -> 20 | O14: =Chạy!E33 -> 5.44 | W14: =(O14+O15)*D14/2 -> 99.5
A15: 5 | B15: ='1.KTHH L1'!B25 -> 34 | C15: ='1.KTHH L1'!C25 -> 672.61 | D15: ='1.KTHH L1'!T25 -> 20 | O15: =Chạy!E41 -> 4.51 | W15: =(O15+O16)*D15/2 -> 101.2
A16: 6 | B16: ='1.KTHH L1'!B26 -> 35 | C16: ='1.KTHH L1'!C26 -> 692.61 | D16: ='1.KTHH L1'!T26 -> 20 | O16: =Chạy!E49 -> 5.61 | W16: =(O16+O17)*D16/2 -> 97.8
A17: 7 | B17: ='1.KTHH L1'!B27 -> 36 | C17: ='1.KTHH L1'!C27 -> 712.61 | D17: ='1.KTHH L1'!T27 -> 11.5 | O17: =Chạy!E57 -> 4.17 | W17: =(O17+O18)*D17/2 -> 56.2925
A18: 8 | B18: ='1.KTHH L1'!B28 -> 37 | C18: ='1.KTHH L1'!C28 -> 724.11 | O18: =Chạy!E65 -> 5.62
A51: Tổng cộng (m3) | R51: =SUM(R11:R50) -> 0 | S51: =SUM(S11:S50) -> 0 | U51: =SUM(U11:U50) -> 0 | V51: =SUM(V11:V50) -> 0 | W51: =SUM(W11:W18) -> 555.48375 | X51: =SUM(X11:X50) -> 0 | Y51: =SUM(Y11:Y50) -> 0 | Z51: =SUM(Z11:Z50) -> 0 | AA51: =SUM(AA11:AA50) -> 0
A53: NHÀ THẦU THI CÔNG | E53: TƯ VẤN GIÁM SÁT
A59: Nguyễn Xuân Hưng | M59: Lê Quốc Huy

Sheet 2.KTHH L2
A1: PHỤ LỤC KIỂM TRA CAO ĐỘ, KÍCH THƯỚC HÌNH HỌC
A2: ="Kèm theo BBNT số: "&VLOOKUP(AZ2,'[1]Tuyến XD8'!$A$2:$G$60,7,0)&VLOOKUP(AZ2,'[1]Tuyến XD8'!$A$2:$G$60,4,0) -> Kèm theo BBNT số: 92.NĐXD8/CVXD ngày 01 tháng 10 năm 2026 | AZ2: 92
A3: ='1.KTHH L1'!A3 -> Dự án: Xây dựng HTKT Khu tái định cư phục vụ di dân xã Hải Hà, thị xã Nghi Sơn, tỉnh Thanh Hóa.
A4: ='1.KTHH L1'!A4 -> Gói thầu số 12: Xây dựng HTKT khu vực Hải Bình và Xuân Lâm (bao gồm cả bảo hiểm xây dựng công trình)
A5: ='1.KTHH L1'!A5 -> Nhà thầu thi công: Công ty TNHH Hoàng Tuấn
A6: Hạng mục: Nền đường tuyến XD8
A7: - Đối tượng nghiệm thu: | G7: =VLOOKUP(AZ2,'[1]Tuyến XD8'!$A$2:$B$60,2,0) -> Đắp đất nền đường lớp 2 đoạn từ Km0+609,11 - Km0+724,11, độ chặt K>=0,95
A8: Sơ họa:
A19: TT | B19: Tên cọc | C19: Lý trình | D19: Bên trái (H1) | J19: Tim (H2) | M19: Bên phải (H3) | S19: Ghi chú
D20: KCTK | E20: KCTC | F20: Chênh KC (m) | G20: CDTK (m) | H20: CDTC (m) | I20: Chênh CD (m) | J20: CDTK (m) | K20: CDTC (m) | L20: Chênh CD (m) | M20: KCTK | N20: KCTC | O20: Chênh KC (m) | P20: CDTK (m) | Q20: CDTC (m) | R20: Chênh CD (m)
A21: 1 | B21: 31 | C21: 609.11 | D21: =+Chạy!F8 -> -9.76 | E21: =+D21+F21 -> -9.7663 | F21: =RANDBETWEEN(-105,115)/10000 -> -0.0063 | G21: =+Chạy!G8 -> 0.04 | H21: =G21+I21 -> 0.018 | I21: =RANDBETWEEN(-30,90)/1000 -> -0.022 | J21: =+Chạy!K8 -> 0.16 | K21: =J21+L21 -> 0.135 | L21: =RANDBETWEEN(-30,90)/1000 -> -0.025 | M21: =+Chạy!N8 -> 9.62 | N21: =+M21+O21 -> 9.6213 | O21: =RANDBETWEEN(-105,115)/10000 -> 0.0013 | P21: =+Chạy!O8 -> 0.04 | Q21: =P21+R21 -> 0.112 | R21: =RANDBETWEEN(-30,90)/1000 -> 0.072 | T21: 11.75
A22: 2 | B22: E10 | C22: =+C21+T21 -> 620.86 | D22: =+Chạy!F16 -> -9.54 | E22: =+D22+F22 -> -9.5388 | F22: =RANDBETWEEN(-105,115)/10000 -> 0.0012 | G22: =+Chạy!G16 -> 0.04 | H22: =G22+I22 -> 0.019 | I22: =RANDBETWEEN(-30,90)/1000 -> -0.021 | J22: =+Chạy!K16 -> 0.16 | K22: =J22+L22 -> 0.173 | L22: =RANDBETWEEN(-30,90)/1000 -> 0.013 | M22: =+Chạy!N16 -> 9.68 | N22: =+M22+O22 -> 9.6783 | O22: =RANDBETWEEN(-105,115)/10000 -> -0.0017 | P22: =+Chạy!O16 -> 0.04 | Q22: =P22+R22 -> 0.058 | R22: =RANDBETWEEN(-30,90)/1000 -> 0.018 | T22: 11.75
A23: 3 | B23: 32 | C23: =+C22+T22 -> 632.61 | D23: =+Chạy!F24 -> -14.65 | E23: =+D23+F23 -> -14.6467 | F23: =RANDBETWEEN(-105,115)/10000 -> 0.0033 | G23: =+Chạy!G24 -> 0.04 | H23: =G23+I23 -> 0.028 | I23: =RANDBETWEEN(-30,90)/1000 -> -0.012 | J23: =+Chạy!K24 -> 0.16 | K23: =J23+L23 -> 0.197 | L23: =RANDBETWEEN(-30,90)/1000 -> 0.037 | M23: =+Chạy!N24 -> 14.65 | N23: =+M23+O23 -> 14.6454 | O23: =RANDBETWEEN(-105,115)/10000 -> -0.0046 | P23: =+Chạy!O24 -> 0.04 | Q23: =P23+R23 -> 0.076 | R23: =RANDBETWEEN(-30,90)/1000 -> 0.036 | T23: 20
A24: 4 | B24: 33 | C24: =+C23+T23 -> 652.61 | D24: =+Chạy!F32 -> -14.65 | E24: =+D24+F24 -> -14.6497 | F24: =RANDBETWEEN(-105,115)/10000 -> 0.0003 | G24: =+Chạy!G32 -> 0.05 | H24: =G24+I24 -> 0.024 | I24: =RANDBETWEEN(-30,90)/1000 -> -0.026 | J24: =+Chạy!K32 -> 0.16 | K24: =J24+L24 -> 0.162 | L24: =RANDBETWEEN(-30,90)/1000 -> 0.002 | M24: =+Chạy!N32 -> 14.65 | N24: =+M24+O24 -> 14.6424 | O24: =RANDBETWEEN(-105,115)/10000 -> -0.0076 | P24: =+Chạy!O32 -> 0.05 | Q24: =P24+R24 -> 0.048 | R24: =RANDBETWEEN(-30,90)/1000 -> -0.002 | T24: 20
A25: 5 | B25: 34 | C25: =+C24+T24 -> 672.61 | D25: =+Chạy!F40 -> -14.65 | E25: =+D25+F25 -> -14.6599 | F25: =RANDBETWEEN(-105,115)/10000 -> -0.0099 | G25: =+Chạy!G40 -> 0.05 | H25: =G25+I25 -> 0.107 | I25: =RANDBETWEEN(-30,90)/1000 -> 0.057 | J25: =+Chạy!K40 -> 0.16 | K25: =J25+L25 -> 0.17 | L25: =RANDBETWEEN(-30,90)/1000 -> 0.01 | M25: =+Chạy!N40 -> 14.65 | N25: =+M25+O25 -> 14.6506 | O25: =RANDBETWEEN(-105,115)/10000 -> 0.0006 | P25: =+Chạy!O40 -> 0.05 | Q25: =P25+R25 -> 0.077 | R25: =RANDBETWEEN(-30,90)/1000 -> 0.027 | T25: 20
A26: 6 | B26: 35 | C26: =+C25+T25 -> 692.61 | D26: =+Chạy!F48 -> -14.65 | E26: =+D26+F26 -> -14.6432 | F26: =RANDBETWEEN(-105,115)/10000 -> 0.0068 | G26: =+Chạy!G48 -> 0.05 | H26: =G26+I26 -> 0.044 | I26: =RANDBETWEEN(-30,90)/1000 -> -0.006 | J26: =+Chạy!K48 -> 0.17 | K26: =J26+L26 -> 0.147 | L26: =RANDBETWEEN(-30,90)/1000 -> -0.023 | M26: =+Chạy!N48 -> 14.65 | N26: =+M26+O26 -> 14.642 | O26: =RANDBETWEEN(-105,115)/10000 -> -0.008 | P26: =+Chạy!O48 -> 0.05 | Q26: =P26+R26 -> 0.036 | R26: =RANDBETWEEN(-30,90)/1000 -> -0.014 | T26: 20
A27: 7 | B27: 36 | C27: =+C26+T26 -> 712.61 | D27: =+Chạy!F56 -> -6.75 | E27: =+D27+F27 -> -6.7507 | F27: =RANDBETWEEN(-105,115)/10000 -> -0.0007 | G27: =+Chạy!G56 -> 0.05 | H27: =G27+I27 -> 0.092 | I27: =RANDBETWEEN(-30,90)/1000 -> 0.042 | J27: =+Chạy!K56 -> 0.17 | K27: =J27+L27 -> 0.2 | L27: =RANDBETWEEN(-30,90)/1000 -> 0.03 | M27: =+Chạy!N56 -> 14.65 | N27: =+M27+O27 -> 14.6447 | O27: =RANDBETWEEN(-105,115)/10000 -> -0.0053 | P27: =+Chạy!O56 -> 0.05 | Q27: =P27+R27 -> 0.099 | R27: =RANDBETWEEN(-30,90)/1000 -> 0.049 | T27: 11.5
A28: 8 | B28: 37 | C28: =+C27+T27 -> 724.11 | D28: =+Chạy!F64 -> -14.65 | E28: =+D28+F28 -> -14.6581 | F28: =RANDBETWEEN(-105,115)/10000 -> -0.0081 | G28: =+Chạy!G64 -> 0.05 | H28: =G28+I28 -> 0.129 | I28: =RANDBETWEEN(-30,90)/1000 -> 0.079 | J28: =+Chạy!K64 -> 0.17 | K28: =J28+L28 -> 0.186 | L28: =RANDBETWEEN(-30,90)/1000 -> 0.016 | M28: =+Chạy!N64 -> 9.74 | N28: =+M28+O28 -> 9.7319 | O28: =RANDBETWEEN(-105,115)/10000 -> -0.0081 | P28: =+Chạy!O64 -> 0.05 | Q28: =P28+R28 -> 0.115 | R28: =RANDBETWEEN(-30,90)/1000 -> 0.065
C62: NHÀ THẦU THI CÔNG | O62: TƯ VẤN GIÁM SÁT
C67: Nguyễn Xuân Hưng | O67: Lê Quốc Huy

Sheet 2.KL L2
A1: PHỤ LỤC KHỐI LƯỢNG
A2: ="Kèm theo BBNT số: "&VLOOKUP(AZ2,'[1]Tuyến XD8'!$A$2:$G$60,7,0)&VLOOKUP(AZ2,'[1]Tuyến XD8'!$A$2:$G$60,4,0) -> Kèm theo BBNT số: 92.NĐXD8/CVXD ngày 01 tháng 10 năm 2026 | AZ2: 92
A3: ='1.KTHH L1'!A3 -> Dự án: Xây dựng HTKT Khu tái định cư phục vụ di dân xã Hải Hà, thị xã Nghi Sơn, tỉnh Thanh Hóa.
A4: ='1.KTHH L1'!A4 -> Gói thầu số 12: Xây dựng HTKT khu vực Hải Bình và Xuân Lâm (bao gồm cả bảo hiểm xây dựng công trình)
A5: ='1.KTHH L1'!A5 -> Nhà thầu thi công: Công ty TNHH Hoàng Tuấn
A6: Hạng mục: Nền đường tuyến XD8
A7: - Đối tượng nghiệm thu: | D7: =VLOOKUP(AZ2,'[1]Tuyến XD8'!$A$2:$B$60,2,0) -> Đắp đất nền đường lớp 2 đoạn từ Km0+609,11 - Km0+724,11, độ chặt K>=0,95
A9: STT | B9: Tên cọc | C9: Lý trình | D9: K/c lẻ | M9: Khối lượng đắp đất | AB9: Ghi chú
N10: Diện tích | O10: Diện tích (m2) | P10: Diện tích | Q10: Diện tích | U10: Khối lượng | V10: Khối lượng | W10: Khối lượng (m3) | X10: Khối lượng | Y10: Khối lượng
A11: 1 | B11: ='2.KTHH L2'!B21 -> 31 | C11: ='2.KTHH L2'!C21 -> 609.11 | D11: ='2.KTHH L2'!T21 -> 11.75 | O11: =Chạy!E8 -> 5.72 | W11: =(O11+O12)*D11/2 -> 66.975
A12: 2 | B12: ='2.KTHH L2'!B22 -> E10 | C12: ='2.KTHH L2'!C22 -> 620.86 | D12: ='2.KTHH L2'!T22 -> 11.75 | O12: =Chạy!E16 -> 5.68 | W12: =(O12+O13)*D12/2 -> 74.3775
A13: 3 | B13: ='2.KTHH L2'!B23 -> 32 | C13: ='2.KTHH L2'!C23 -> 632.61 | D13: ='2.KTHH L2'!T23 -> 20 | O13: =Chạy!E24 -> 6.98 | W13: =(O13+O14)*D13/2 -> 159.1
A14: 4 | B14: ='2.KTHH L2'!B24 -> 33 | C14: ='2.KTHH L2'!C24 -> 652.61 | D14: ='2.KTHH L2'!T24 -> 20 | O14: =Chạy!E32 -> 8.93 | W14: =(O14+O15)*D14/2 -> 152.7
A15: 5 | B15: ='2.KTHH L2'!B25 -> 34 | C15: ='2.KTHH L2'!C25 -> 672.61 | D15: ='2.KTHH L2'!T25 -> 20 | O15: =Chạy!E40 -> 6.34 | W15: =(O15+O16)*D15/2 -> 152.7
A16: 6 | B16: ='2.KTHH L2'!B26 -> 35 | C16: ='2.KTHH L2'!C26 -> 692.61 | D16: ='2.KTHH L2'!T26 -> 20 | O16: =Chạy!E48 -> 8.93 | W16: =(O16+O17)*D16/2 -> 152.2
A17: 7 | B17: ='2.KTHH L2'!B27 -> 36 | C17: ='2.KTHH L2'!C27 -> 712.61 | D17: ='2.KTHH L2'!T27 -> 11.5 | O17: =Chạy!E56 -> 6.29 | W17: =(O17+O18)*D17/2 -> 78.3725
A18: 8 | B18: ='2.KTHH L2'!B28 -> 37 | C18: ='2.KTHH L2'!C28 -> 724.11 | O18: =Chạy!E64 -> 7.34
A51: Tổng cộng (m3) | R51: =SUM(R11:R50) -> 0 | S51: =SUM(S11:S50) -> 0 | U51: =SUM(U11:U50) -> 0 | V51: =SUM(V11:V50) -> 0 | W51: =SUM(W11:W18) -> 836.425 | X51: =SUM(X11:X50) -> 0 | Y51: =SUM(Y11:Y50) -> 0 | Z51: =SUM(Z11:Z50) -> 0 | AA51: =SUM(AA11:AA50) -> 0
A53: NHÀ THẦU THI CÔNG | E53: TƯ VẤN GIÁM SÁT
A59: Nguyễn Xuân Hưng | M59: Lê Quốc Huy

Sheet 3.KTHH L3
A1: PHỤ LỤC KIỂM TRA CAO ĐỘ, KÍCH THƯỚC HÌNH HỌC
A2: ="Kèm theo BBNT số: "&VLOOKUP(AZ2,'[1]Tuyến XD8'!$A$2:$G$60,7,0)&VLOOKUP(AZ2,'[1]Tuyến XD8'!$A$2:$G$60,4,0) -> Kèm theo BBNT số: 93.NĐXD8/CVXD ngày 01 tháng 10 năm 2026 | AZ2: 93
A3: ='1.KTHH L1'!A3 -> Dự án: Xây dựng HTKT Khu tái định cư phục vụ di dân xã Hải Hà, thị xã Nghi Sơn, tỉnh Thanh Hóa.
A4: ='1.KTHH L1'!A4 -> Gói thầu số 12: Xây dựng HTKT khu vực Hải Bình và Xuân Lâm (bao gồm cả bảo hiểm xây dựng công trình)
A5: ='1.KTHH L1'!A5 -> Nhà thầu thi công: Công ty TNHH Hoàng Tuấn
A6: Hạng mục: Nền đường tuyến XD8
A7: - Đối tượng nghiệm thu: | G7: =VLOOKUP(AZ2,'[1]Tuyến XD8'!$A$2:$B$60,2,0) -> Đắp đất nền đường lớp 3 đoạn từ Km0+609,11 - Km0+724,11, độ chặt K>=0,95
A8: Sơ họa:
A20: TT | B20: Tên cọc | C20: Lý trình | D20: Bên trái (H1) | J20: Tim (H2) | M20: Bên phải (H3) | S20: Ghi chú
D21: KCTK | E21: KCTC | F21: Chênh KC (m) | G21: CDTK (m) | H21: CDTC (m) | I21: Chênh CD (m) | J21: CDTK (m) | K21: CDTC (m) | L21: Chênh CD (m) | M21: KCTK | N21: KCTC | O21: Chênh KC (m) | P21: CDTK (m) | Q21: CDTC (m) | R21: Chênh CD (m)
A22: 1 | B22: 31 | C22: 609.11 | D22: =+Chạy!F7 -> -14.2 | E22: =+D22+F22 -> -14.2087 | F22: =RANDBETWEEN(-105,115)/10000 -> -0.0087 | G22: =+Chạy!G7 -> 0.34 | H22: =G22+I22 -> 0.394 | I22: =RANDBETWEEN(-30,90)/1000 -> 0.054 | J22: =+Chạy!K7 -> 0.46 | K22: =J22+L22 -> 0.54 | L22: =RANDBETWEEN(-30,90)/1000 -> 0.08 | M22: =+Chạy!N7 -> 14.2 | N22: =+M22+O22 -> 14.2042 | O22: =RANDBETWEEN(-105,115)/10000 -> 0.0042 | P22: =+Chạy!O7 -> 0.34 | Q22: =P22+R22 -> 0.366 | R22: =RANDBETWEEN(-30,90)/1000 -> 0.026 | T22: 11.75
A23: 2 | B23: E10 | C23: =+C22+T22 -> 620.86 | D23: =+Chạy!F15 -> -10.01 | E23: =+D23+F23 -> -10.012 | F23: =RANDBETWEEN(-105,115)/10000 -> -0.002 | G23: =+Chạy!G15 -> 0.34 | H23: =G23+I23 -> 0.424 | I23: =RANDBETWEEN(-30,90)/1000 -> 0.084 | J23: =+Chạy!K15 -> 0.46 | K23: =J23+L23 -> 0.514 | L23: =RANDBETWEEN(-30,90)/1000 -> 0.054 | M23: =+Chạy!N15 -> 14.2 | N23: =+M23+O23 -> 14.208 | O23: =RANDBETWEEN(-105,115)/10000 -> 0.008 | P23: =+Chạy!O15 -> 0.34 | Q23: =P23+R23 -> 0.315 | R23: =RANDBETWEEN(-30,90)/1000 -> -0.025 | T23: 11.75
A24: 3 | B24: 32 | C24: =+C23+T23 -> 632.61 | D24: =+Chạy!F23 -> -14.2 | E24: =+D24+F24 -> -14.1996 | F24: =RANDBETWEEN(-105,115)/10000 -> 0.0004 | G24: =+Chạy!G23 -> 0.34 | H24: =G24+I24 -> 0.416 | I24: =RANDBETWEEN(-30,90)/1000 -> 0.076 | J24: =+Chạy!K23 -> 0.46 | K24: =J24+L24 -> 0.512 | L24: =RANDBETWEEN(-30,90)/1000 -> 0.052 | M24: =+Chạy!N23 -> 14.2 | N24: =+M24+O24 -> 14.2031 | O24: =RANDBETWEEN(-105,115)/10000 -> 0.0031 | P24: =+Chạy!O23 -> 0.34 | Q24: =P24+R24 -> 0.425 | R24: =RANDBETWEEN(-30,90)/1000 -> 0.085 | T24: 20
A25: 4 | B25: 33 | C25: =+C24+T24 -> 652.61 | D25: =+Chạy!F31 -> -14.2 | E25: =+D25+F25 -> -14.2088 | F25: =RANDBETWEEN(-105,115)/10000 -> -0.0088 | G25: =+Chạy!G31 -> 0.35 | H25: =G25+I25 -> 0.32 | I25: =RANDBETWEEN(-30,90)/1000 -> -0.03 | J25: =+Chạy!K31 -> 0.46 | K25: =J25+L25 -> 0.534 | L25: =RANDBETWEEN(-30,90)/1000 -> 0.074 | M25: =+Chạy!N31 -> 14.2 | N25: =+M25+O25 -> 14.1951 | O25: =RANDBETWEEN(-105,115)/10000 -> -0.0049 | P25: =+Chạy!O31 -> 0.35 | Q25: =P25+R25 -> 0.435 | R25: =RANDBETWEEN(-30,90)/1000 -> 0.085 | T25: 20
A26: 5 | B26: 34 | C26: =+C25+T25 -> 672.61 | D26: =+Chạy!F39 -> -14.2 | E26: =+D26+F26 -> -14.2092 | F26: =RANDBETWEEN(-105,115)/10000 -> -0.0092 | G26: =+Chạy!G39 -> 0.35 | H26: =G26+I26 -> 0.37 | I26: =RANDBETWEEN(-30,90)/1000 -> 0.02 | J26: =+Chạy!K39 -> 0.46 | K26: =J26+L26 -> 0.549 | L26: =RANDBETWEEN(-30,90)/1000 -> 0.089 | M26: =+Chạy!N39 -> 14.2 | N26: =+M26+O26 -> 14.1953 | O26: =RANDBETWEEN(-105,115)/10000 -> -0.0047 | P26: =+Chạy!O39 -> 0.35 | Q26: =P26+R26 -> 0.34 | R26: =RANDBETWEEN(-30,90)/1000 -> -0.01 | T26: 20
A27: 6 | B27: 35 | C27: =+C26+T26 -> 692.61 | D27: =+Chạy!F47 -> -14.2 | E27: =+D27+F27 -> -14.1966 | F27: =RANDBETWEEN(-105,115)/10000 -> 0.0034 | G27: =+Chạy!G47 -> 0.35 | H27: =G27+I27 -> 0.351 | I27: =RANDBETWEEN(-30,90)/1000 -> 0.001 | J27: =+Chạy!K47 -> 0.47 | K27: =J27+L27 -> 0.49 | L27: =RANDBETWEEN(-30,90)/1000 -> 0.02 | M27: =+Chạy!N47 -> 14.2 | N27: =+M27+O27 -> 14.199 | O27: =RANDBETWEEN(-105,115)/10000 -> -0.001 | P27: =+Chạy!O47 -> 0.35 | Q27: =P27+R27 -> 0.33 | R27: =RANDBETWEEN(-30,90)/1000 -> -0.02 | T27: 20
A28: 7 | B28: 36 | C28: =+C27+T27 -> 712.61 | D28: =+Chạy!F55 -> -7.05 | E28: =+D28+F28 -> -7.054 | F28: =RANDBETWEEN(-105,115)/10000 -> -0.004 | G28: =+Chạy!G55 -> 0.35 | H28: =G28+I28 -> 0.358 | I28: =RANDBETWEEN(-30,90)/1000 -> 0.008 | J28: =+Chạy!K55 -> 0.47 | K28: =J28+L28 -> 0.474 | L28: =RANDBETWEEN(-30,90)/1000 -> 0.004 | M28: =+Chạy!N55 -> 14.2 | N28: =+M28+O28 -> 14.1948 | O28: =RANDBETWEEN(-105,115)/10000 -> -0.0052 | P28: =+Chạy!O55 -> 0.35 | Q28: =P28+R28 -> 0.36 | R28: =RANDBETWEEN(-30,90)/1000 -> 0.01 | T28: 11.5
A29: 8 | B29: 37 | C29: =+C28+T28 -> 724.11 | D29: =+Chạy!F63 -> -14.2 | E29: =+D29+F29 -> -14.2075 | F29: =RANDBETWEEN(-105,115)/10000 -> -0.0075 | G29: =+Chạy!G63 -> 0.35 | H29: =G29+I29 -> 0.347 | I29: =RANDBETWEEN(-30,90)/1000 -> -0.003 | J29: =+Chạy!K63 -> 0.47 | K29: =J29+L29 -> 0.462 | L29: =RANDBETWEEN(-30,90)/1000 -> -0.008 | M29: =+Chạy!N63 -> 13.04 | N29: =+M29+O29 -> 13.0463 | O29: =RANDBETWEEN(-105,115)/10000 -> 0.0063 | P29: =+Chạy!O63 -> 0.35 | Q29: =P29+R29 -> 0.347 | R29: =RANDBETWEEN(-30,90)/1000 -> -0.003
C63: NHÀ THẦU THI CÔNG | O63: TƯ VẤN GIÁM SÁT
C68: Nguyễn Xuân Hưng | O68: Lê Quốc Huy

Sheet 3.KL L3
A1: PHỤ LỤC KHỐI LƯỢNG
A2: ="Kèm theo BBNT số: "&VLOOKUP(AZ2,'[1]Tuyến XD8'!$A$2:$G$60,7,0)&VLOOKUP(AZ2,'[1]Tuyến XD8'!$A$2:$G$60,4,0) -> Kèm theo BBNT số: 93.NĐXD8/CVXD ngày 01 tháng 10 năm 2026 | AZ2: 93
A3: ='1.KTHH L1'!A3 -> Dự án: Xây dựng HTKT Khu tái định cư phục vụ di dân xã Hải Hà, thị xã Nghi Sơn, tỉnh Thanh Hóa.
A4: ='1.KTHH L1'!A4 -> Gói thầu số 12: Xây dựng HTKT khu vực Hải Bình và Xuân Lâm (bao gồm cả bảo hiểm xây dựng công trình)
A5: ='1.KTHH L1'!A5 -> Nhà thầu thi công: Công ty TNHH Hoàng Tuấn
A6: Hạng mục: Nền đường tuyến XD8
A7: - Đối tượng nghiệm thu: | D7: =VLOOKUP(AZ2,'[1]Tuyến XD8'!$A$2:$B$60,2,0) -> Đắp đất nền đường lớp 3 đoạn từ Km0+609,11 - Km0+724,11, độ chặt K>=0,95
A9: STT | B9: Tên cọc | C9: Lý trình | D9: K/c lẻ | M9: Khối lượng đắp đất | AB9: Ghi chú
N10: Diện tích | O10: Diện tích (m2) | P10: Diện tích | Q10: Diện tích | U10: Khối lượng | V10: Khối lượng | W10: Khối lượng (m3) | X10: Khối lượng | Y10: Khối lượng
A11: 1 | B11: ='3.KTHH L3'!B22 -> 31 | C11: ='3.KTHH L3'!C22 -> 609.11 | D11: ='3.KTHH L3'!T22 -> 11.75 | O11: =Chạy!E7 -> 7.42 | W11: =(O11+O12)*D11/2 -> 79.3125
A12: 2 | B12: ='3.KTHH L3'!B23 -> E10 | C12: ='3.KTHH L3'!C23 -> 620.86 | D12: ='3.KTHH L3'!T23 -> 11.75 | O12: =Chạy!E15 -> 6.08 | W12: =(O12+O13)*D12/2 -> 86.5975
A13: 3 | B13: ='3.KTHH L3'!B24 -> 32 | C13: ='3.KTHH L3'!C24 -> 632.61 | D13: ='3.KTHH L3'!T24 -> 20 | O13: =Chạy!E23 -> 8.66 | W13: =(O13+O14)*D13/2 -> 173.2
A14: 4 | B14: ='3.KTHH L3'!B25 -> 33 | C14: ='3.KTHH L3'!C25 -> 652.61 | D14: ='3.KTHH L3'!T25 -> 20 | O14: =Chạy!E31 -> 8.66 | W14: =(O14+O15)*D14/2 -> 173.2
A15: 5 | B15: ='3.KTHH L3'!B26 -> 34 | C15: ='3.KTHH L3'!C26 -> 672.61 | D15: ='3.KTHH L3'!T26 -> 20 | O15: =Chạy!E39 -> 8.66 | W15: =(O15+O16)*D15/2 -> 173.2
A16: 6 | B16: ='3.KTHH L3'!B27 -> 35 | C16: ='3.KTHH L3'!C27 -> 692.61 | D16: ='3.KTHH L3'!T27 -> 20 | O16: =Chạy!E47 -> 8.66 | W16: =(O16+O17)*D16/2 -> 150.6
A17: 7 | B17: ='3.KTHH L3'!B28 -> 36 | C17: ='3.KTHH L3'!C28 -> 712.61 | D17: ='3.KTHH L3'!T28 -> 11.5 | O17: =Chạy!E55 -> 6.4 | W17: =(O17+O18)*D17/2 -> 80.615
A18: 8 | B18: ='3.KTHH L3'!B29 -> 37 | C18: ='3.KTHH L3'!C29 -> 724.11 | O18: =Chạy!E63 -> 7.62
A51: Tổng cộng (m3) | R51: =SUM(R11:R50) -> 0 | S51: =SUM(S11:S50) -> 0 | U51: =SUM(U11:U50) -> 0 | V51: =SUM(V11:V50) -> 0 | W51: =SUM(W11:W18) -> 916.725 | X51: =SUM(X11:X50) -> 0 | Y51: =SUM(Y11:Y50) -> 0 | Z51: =SUM(Z11:Z50) -> 0 | AA51: =SUM(AA11:AA50) -> 0
A53: NHÀ THẦU THI CÔNG | E53: TƯ VẤN GIÁM SÁT
A59: Nguyễn Xuân Hưng | M59: Lê Quốc Huy

Sheet 4.KTHH L4
A1: PHỤ LỤC KIỂM TRA CAO ĐỘ, KÍCH THƯỚC HÌNH HỌC
A2: ="Kèm theo BBNT số: "&VLOOKUP(AZ2,'[1]Tuyến XD8'!$A$2:$G$60,7,0)&VLOOKUP(AZ2,'[1]Tuyến XD8'!$A$2:$G$60,4,0) -> Kèm theo BBNT số: 94.NĐXD8/CVXD ngày 02 tháng 10 năm 2026 | AZ2: 94
A3: ='1.KTHH L1'!A3 -> Dự án: Xây dựng HTKT Khu tái định cư phục vụ di dân xã Hải Hà, thị xã Nghi Sơn, tỉnh Thanh Hóa.
A4: ='1.KTHH L1'!A4 -> Gói thầu số 12: Xây dựng HTKT khu vực Hải Bình và Xuân Lâm (bao gồm cả bảo hiểm xây dựng công trình)
A5: ='1.KTHH L1'!A5 -> Nhà thầu thi công: Công ty TNHH Hoàng Tuấn
A6: Hạng mục: Nền đường tuyến XD8
A7: - Đối tượng nghiệm thu: | G7: =VLOOKUP(AZ2,'[1]Tuyến XD8'!$A$2:$B$60,2,0) -> Đắp đất nền đường lớp 4 đoạn từ Km0+609,11 - Km0+724,11, độ chặt K>=0,95
A8: Sơ họa:
A20: TT | B20: Tên cọc | C20: Lý trình | D20: Bên trái (H1) | J20: Tim (H2) | M20: Bên phải (H3) | S20: Ghi chú
D21: KCTK | E21: KCTC | F21: Chênh KC (m) | G21: CDTK (m) | H21: CDTC (m) | I21: Chênh CD (m) | J21: CDTK (m) | K21: CDTC (m) | L21: Chênh CD (m) | M21: KCTK | N21: KCTC | O21: Chênh KC (m) | P21: CDTK (m) | Q21: CDTC (m) | R21: Chênh CD (m)
A22: 1 | B22: 31 | C22: 609.11 | D22: =+Chạy!F6 -> -13.75 | E22: =+D22+F22 -> -13.7526 | F22: =RANDBETWEEN(-105,115)/10000 -> -0.0026 | G22: =+Chạy!G6 -> 0.64 | H22: =G22+I22 -> 0.662 | I22: =RANDBETWEEN(-30,90)/1000 -> 0.022 | J22: =+Chạy!K6 -> 0.76 | K22: =J22+L22 -> 0.779 | L22: =RANDBETWEEN(-30,90)/1000 -> 0.019 | M22: =+Chạy!N6 -> 13.75 | N22: =+M22+O22 -> 13.7547 | O22: =RANDBETWEEN(-105,115)/10000 -> 0.0047 | P22: =+Chạy!O6 -> 0.64 | Q22: =P22+R22 -> 0.661 | R22: =RANDBETWEEN(-30,90)/1000 -> 0.021 | T22: 11.75
A23: 2 | B23: E10 | C23: =+C22+T22 -> 620.86 | D23: =+Chạy!F14 -> -13.75 | E23: =+D23+F23 -> -13.7545 | F23: =RANDBETWEEN(-105,115)/10000 -> -0.0045 | G23: =+Chạy!G14 -> 0.64 | H23: =G23+I23 -> 0.628 | I23: =RANDBETWEEN(-30,90)/1000 -> -0.012 | J23: =+Chạy!K14 -> 0.76 | K23: =J23+L23 -> 0.82 | L23: =RANDBETWEEN(-30,90)/1000 -> 0.06 | M23: =+Chạy!N14 -> 13.75 | N23: =+M23+O23 -> 13.7473 | O23: =RANDBETWEEN(-105,115)/10000 -> -0.0027 | P23: =+Chạy!O14 -> 0.64 | Q23: =P23+R23 -> 0.66 | R23: =RANDBETWEEN(-30,90)/1000 -> 0.02 | T23: 11.75
A24: 3 | B24: 32 | C24: =+C23+T23 -> 632.61 | D24: =+Chạy!F22 -> -13.75 | E24: =+D24+F24 -> -13.7504 | F24: =RANDBETWEEN(-105,115)/10000 -> -0.0004 | G24: =+Chạy!G22 -> 0.64 | H24: =G24+I24 -> 0.63 | I24: =RANDBETWEEN(-30,90)/1000 -> -0.01 | J24: =+Chạy!K22 -> 0.76 | K24: =J24+L24 -> 0.792 | L24: =RANDBETWEEN(-30,90)/1000 -> 0.032 | M24: =+Chạy!N22 -> 13.75 | N24: =+M24+O24 -> 13.7545 | O24: =RANDBETWEEN(-105,115)/10000 -> 0.0045 | P24: =+Chạy!O22 -> 0.64 | Q24: =P24+R24 -> 0.633 | R24: =RANDBETWEEN(-30,90)/1000 -> -0.007 | T24: 20
A25: 4 | B25: 33 | C25: =+C24+T24 -> 652.61 | D25: =+Chạy!F30 -> -13.75 | E25: =+D25+F25 -> -13.7491 | F25: =RANDBETWEEN(-105,115)/10000 -> 0.0009 | G25: =+Chạy!G30 -> 0.65 | H25: =G25+I25 -> 0.655 | I25: =RANDBETWEEN(-30,90)/1000 -> 0.005 | J25: =+Chạy!K30 -> 0.76 | K25: =J25+L25 -> 0.797 | L25: =RANDBETWEEN(-30,90)/1000 -> 0.037 | M25: =+Chạy!N30 -> 13.75 | N25: =+M25+O25 -> 13.7527 | O25: =RANDBETWEEN(-105,115)/10000 -> 0.0027 | P25: =+Chạy!O30 -> 0.65 | Q25: =P25+R25 -> 0.729 | R25: =RANDBETWEEN(-30,90)/1000 -> 0.079 | T25: 20
A26: 5 | B26: 34 | C26: =+C25+T25 -> 672.61 | D26: =+Chạy!F38 -> -13.75 | E26: =+D26+F26 -> -13.7498 | F26: =RANDBETWEEN(-105,115)/10000 -> 0.0002 | G26: =+Chạy!G38 -> 0.65 | H26: =G26+I26 -> 0.697 | I26: =RANDBETWEEN(-30,90)/1000 -> 0.047 | J26: =+Chạy!K38 -> 0.76 | K26: =J26+L26 -> 0.841 | L26: =RANDBETWEEN(-30,90)/1000 -> 0.081 | M26: =+Chạy!N38 -> 13.75 | N26: =+M26+O26 -> 13.7593 | O26: =RANDBETWEEN(-105,115)/10000 -> 0.0093 | P26: =+Chạy!O38 -> 0.65 | Q26: =P26+R26 -> 0.692 | R26: =RANDBETWEEN(-30,90)/1000 -> 0.042 | T26: 20
A27: 6 | B27: 35 | C27: =+C26+T26 -> 692.61 | D27: =+Chạy!F46 -> -13.75 | E27: =+D27+F27 -> -13.7536 | F27: =RANDBETWEEN(-105,115)/10000 -> -0.0036 | G27: =+Chạy!G46 -> 0.65 | H27: =G27+I27 -> 0.664 | I27: =RANDBETWEEN(-30,90)/1000 -> 0.014 | J27: =+Chạy!K46 -> 0.77 | K27: =J27+L27 -> 0.829 | L27: =RANDBETWEEN(-30,90)/1000 -> 0.059 | M27: =+Chạy!N46 -> 13.75 | N27: =+M27+O27 -> 13.7513 | O27: =RANDBETWEEN(-105,115)/10000 -> 0.0013 | P27: =+Chạy!O46 -> 0.65 | Q27: =P27+R27 -> 0.672 | R27: =RANDBETWEEN(-30,90)/1000 -> 0.022 | T27: 20
A28: 7 | B28: 36 | C28: =+C27+T27 -> 712.61 | D28: =+Chạy!F54 -> -7.35 | E28: =+D28+F28 -> -7.3573 | F28: =RANDBETWEEN(-105,115)/10000 -> -0.0073 | G28: =+Chạy!G54 -> 0.65 | H28: =G28+I28 -> 0.737 | I28: =RANDBETWEEN(-30,90)/1000 -> 0.087 | J28: =+Chạy!K54 -> 0.77 | K28: =J28+L28 -> 0.786 | L28: =RANDBETWEEN(-30,90)/1000 -> 0.016 | M28: =+Chạy!N54 -> 13.75 | N28: =+M28+O28 -> 13.755 | O28: =RANDBETWEEN(-105,115)/10000 -> 0.005 | P28: =+Chạy!O54 -> 0.65 | Q28: =P28+R28 -> 0.658 | R28: =RANDBETWEEN(-30,90)/1000 -> 0.008 | T28: 11.5
A29: 8 | B29: 37 | C29: =+C28+T28 -> 724.11 | D29: =+Chạy!F62 -> -13.75 | E29: =+D29+F29 -> -13.7549 | F29: =RANDBETWEEN(-105,115)/10000 -> -0.0049 | G29: =+Chạy!G62 -> 0.65 | H29: =G29+I29 -> 0.73 | I29: =RANDBETWEEN(-30,90)/1000 -> 0.08 | J29: =+Chạy!K62 -> 0.77 | K29: =J29+L29 -> 0.767 | L29: =RANDBETWEEN(-30,90)/1000 -> -0.003 | M29: =+Chạy!N62 -> 13.75 | N29: =+M29+O29 -> 13.7568 | O29: =RANDBETWEEN(-105,115)/10000 -> 0.0068 | P29: =+Chạy!O62 -> 0.65 | Q29: =P29+R29 -> 0.66 | R29: =RANDBETWEEN(-30,90)/1000 -> 0.01
C63: NHÀ THẦU THI CÔNG | O63: TƯ VẤN GIÁM SÁT
C68: Nguyễn Xuân Hưng | O68: Lê Quốc Huy

Sheet 4.KL L4
A1: PHỤ LỤC KHỐI LƯỢNG
A2: ="Kèm theo BBNT số: "&VLOOKUP(AZ2,'[1]Tuyến XD8'!$A$2:$G$60,7,0)&VLOOKUP(AZ2,'[1]Tuyến XD8'!$A$2:$G$60,4,0) -> Kèm theo BBNT số: 94.NĐXD8/CVXD ngày 02 tháng 10 năm 2026 | AZ2: 94
A3: ='1.KTHH L1'!A3 -> Dự án: Xây dựng HTKT Khu tái định cư phục vụ di dân xã Hải Hà, thị xã Nghi Sơn, tỉnh Thanh Hóa.
A4: ='1.KTHH L1'!A4 -> Gói thầu số 12: Xây dựng HTKT khu vực Hải Bình và Xuân Lâm (bao gồm cả bảo hiểm xây dựng công trình)
A5: ='1.KTHH L1'!A5 -> Nhà thầu thi công: Công ty TNHH Hoàng Tuấn
A6: Hạng mục: Nền đường tuyến XD8
A7: - Đối tượng nghiệm thu: | D7: =VLOOKUP(AZ2,'[1]Tuyến XD8'!$A$2:$B$60,2,0) -> Đắp đất nền đường lớp 4 đoạn từ Km0+609,11 - Km0+724,11, độ chặt K>=0,95
A9: STT | B9: Tên cọc | C9: Lý trình | D9: K/c lẻ | M9: Khối lượng đắp đất | AB9: Ghi chú
N10: Diện tích | O10: Diện tích (m2) | P10: Diện tích | Q10: Diện tích | U10: Khối lượng | V10: Khối lượng | W10: Khối lượng (m3) | X10: Khối lượng | Y10: Khối lượng
A11: 1 | B11: ='4.KTHH L4'!B22 -> 31 | C11: ='4.KTHH L4'!C22 -> 609.11 | D11: ='4.KTHH L4'!T22 -> 11.75 | O11: =Chạy!E6 -> 8.39 | W11: =(O11+O12)*D11/2 -> 98.28875
A12: 2 | B12: ='4.KTHH L4'!B23 -> E10 | C12: ='4.KTHH L4'!C23 -> 620.86 | D12: ='4.KTHH L4'!T23 -> 11.75 | O12: =Chạy!E14 -> 8.34 | W12: =(O12+O13)*D12/2 -> 98.28875
A13: 3 | B13: ='4.KTHH L4'!B24 -> 32 | C13: ='4.KTHH L4'!C24 -> 632.61 | D13: ='4.KTHH L4'!T24 -> 20 | O13: =Chạy!E22 -> 8.39 | W13: =(O13+O14)*D13/2 -> 167.8
A14: 4 | B14: ='4.KTHH L4'!B25 -> 33 | C14: ='4.KTHH L4'!C25 -> 652.61 | D14: ='4.KTHH L4'!T25 -> 20 | O14: =Chạy!E30 -> 8.39 | W14: =(O14+O15)*D14/2 -> 167.8
A15: 5 | B15: ='4.KTHH L4'!B26 -> 34 | C15: ='4.KTHH L4'!C26 -> 672.61 | D15: ='4.KTHH L4'!T26 -> 20 | O15: =Chạy!E38 -> 8.39 | W15: =(O15+O16)*D15/2 -> 167.8
A16: 6 | B16: ='4.KTHH L4'!B27 -> 35 | C16: ='4.KTHH L4'!C27 -> 692.61 | D16: ='4.KTHH L4'!T27 -> 20 | O16: =Chạy!E46 -> 8.39 | W16: =(O16+O17)*D16/2 -> 147.4
A17: 7 | B17: ='4.KTHH L4'!B28 -> 36 | C17: ='4.KTHH L4'!C28 -> 712.61 | D17: ='4.KTHH L4'!T28 -> 11.5 | O17: =Chạy!E54 -> 6.35 | W17: =(O17+O18)*D17/2 -> 84.4675
A18: 8 | B18: ='4.KTHH L4'!B29 -> 37 | C18: ='4.KTHH L4'!C29 -> 724.11 | O18: =Chạy!E62 -> 8.34
A51: Tổng cộng (m3) | R51: =SUM(R11:R50) -> 0 | S51: =SUM(S11:S50) -> 0 | U51: =SUM(U11:U50) -> 0 | V51: =SUM(V11:V50) -> 0 | W51: =SUM(W11:W18) -> 931.845 | X51: =SUM(X11:X50) -> 0 | Y51: =SUM(Y11:Y50) -> 0 | Z51: =SUM(Z11:Z50) -> 0 | AA51: =SUM(AA11:AA50) -> 0
A53: NHÀ THẦU THI CÔNG | E53: TƯ VẤN GIÁM SÁT
A59: Nguyễn Xuân Hưng | M59: Lê Quốc Huy

Sheet 5.KTHH L5
A1: PHỤ LỤC KIỂM TRA CAO ĐỘ, KÍCH THƯỚC HÌNH HỌC
A2: ="Kèm theo BBNT số: "&VLOOKUP(AZ2,'[1]Tuyến XD8'!$A$2:$G$60,7,0)&VLOOKUP(AZ2,'[1]Tuyến XD8'!$A$2:$G$60,4,0) -> Kèm theo BBNT số: 95.NĐXD8/CVXD ngày 02 tháng 10 năm 2026 | AZ2: 95
A3: ='1.KTHH L1'!A3 -> Dự án: Xây dựng HTKT Khu tái định cư phục vụ di dân xã Hải Hà, thị xã Nghi Sơn, tỉnh Thanh Hóa.
A4: ='1.KTHH L1'!A4 -> Gói thầu số 12: Xây dựng HTKT khu vực Hải Bình và Xuân Lâm (bao gồm cả bảo hiểm xây dựng công trình)
A5: ='1.KTHH L1'!A5 -> Nhà thầu thi công: Công ty TNHH Hoàng Tuấn
A6: Hạng mục: Nền đường tuyến XD8
A7: - Đối tượng nghiệm thu: | G7: =VLOOKUP(AZ2,'[1]Tuyến XD8'!$A$2:$B$60,2,0) -> Đắp đất nền đường lớp 5 đoạn từ Km0+609,11 - Km0+724,11, độ chặt K>=0,95
A8: Sơ họa:
A20: TT | B20: Tên cọc | C20: Lý trình | D20: Bên trái (H1) | J20: Tim (H2) | M20: Bên phải (H3) | S20: Ghi chú
D21: KCTK | E21: KCTC | F21: Chênh KC (m) | G21: CDTK (m) | H21: CDTC (m) | I21: Chênh CD (m) | J21: CDTK (m) | K21: CDTC (m) | L21: Chênh CD (m) | M21: KCTK | N21: KCTC | O21: Chênh KC (m) | P21: CDTK (m) | Q21: CDTC (m) | R21: Chênh CD (m)
A22: 1 | B22: 31 | C22: 609.11 | D22: =+Chạy!F5 -> -13.3 | E22: =+D22+F22 -> -13.3059 | F22: =RANDBETWEEN(-105,115)/10000 -> -0.0059 | G22: =+Chạy!G5 -> 0.94 | H22: =G22+I22 -> 0.945 | I22: =RANDBETWEEN(-30,90)/1000 -> 0.005 | J22: =+Chạy!K5 -> 1.06 | K22: =J22+L22 -> 1.079 | L22: =RANDBETWEEN(-30,90)/1000 -> 0.019 | M22: =+Chạy!N5 -> 13.3 | N22: =+M22+O22 -> 13.3068 | O22: =RANDBETWEEN(-105,115)/10000 -> 0.0068 | P22: =+Chạy!O5 -> 0.94 | Q22: =P22+R22 -> 0.952 | R22: =RANDBETWEEN(-30,90)/1000 -> 0.012 | T22: 11.75
A23: 2 | B23: E10 | C23: =+C22+T22 -> 620.86 | D23: =+Chạy!F13 -> -13.3 | E23: =+D23+F23 -> -13.3084 | F23: =RANDBETWEEN(-105,115)/10000 -> -0.0084 | G23: =+Chạy!G13 -> 0.94 | H23: =G23+I23 -> 0.972 | I23: =RANDBETWEEN(-30,90)/1000 -> 0.032 | J23: =+Chạy!K13 -> 1.06 | K23: =J23+L23 -> 1.119 | L23: =RANDBETWEEN(-30,90)/1000 -> 0.059 | M23: =+Chạy!N13 -> 13.3 | N23: =+M23+O23 -> 13.2977 | O23: =RANDBETWEEN(-105,115)/10000 -> -0.0023 | P23: =+Chạy!O13 -> 0.94 | Q23: =P23+R23 -> 1.011 | R23: =RANDBETWEEN(-30,90)/1000 -> 0.071 | T23: 11.75
A24: 3 | B24: 32 | C24: =+C23+T23 -> 632.61 | D24: =+Chạy!F21 -> -13.3 | E24: =+D24+F24 -> -13.2967 | F24: =RANDBETWEEN(-105,115)/10000 -> 0.0033 | G24: =+Chạy!G21 -> 0.94 | H24: =G24+I24 -> 0.953 | I24: =RANDBETWEEN(-30,90)/1000 -> 0.013 | J24: =+Chạy!K21 -> 1.06 | K24: =J24+L24 -> 1.096 | L24: =RANDBETWEEN(-30,90)/1000 -> 0.036 | M24: =+Chạy!N21 -> 13.3 | N24: =+M24+O24 -> 13.2929 | O24: =RANDBETWEEN(-105,115)/10000 -> -0.0071 | P24: =+Chạy!O21 -> 0.94 | Q24: =P24+R24 -> 0.989 | R24: =RANDBETWEEN(-30,90)/1000 -> 0.049 | T24: 20
A25: 4 | B25: 33 | C25: =+C24+T24 -> 652.61 | D25: =+Chạy!F29 -> -13.3 | E25: =+D25+F25 -> -13.3031 | F25: =RANDBETWEEN(-105,115)/10000 -> -0.0031 | G25: =+Chạy!G29 -> 0.95 | H25: =G25+I25 -> 0.963 | I25: =RANDBETWEEN(-30,90)/1000 -> 0.013 | J25: =+Chạy!K29 -> 1.06 | K25: =J25+L25 -> 1.091 | L25: =RANDBETWEEN(-30,90)/1000 -> 0.031 | M25: =+Chạy!N29 -> 13.3 | N25: =+M25+O25 -> 13.3031 | O25: =RANDBETWEEN(-105,115)/10000 -> 0.0031 | P25: =+Chạy!O29 -> 0.95 | Q25: =P25+R25 -> 0.966 | R25: =RANDBETWEEN(-30,90)/1000 -> 0.016 | T25: 20
A26: 5 | B26: 34 | C26: =+C25+T25 -> 672.61 | D26: =+Chạy!F37 -> -13.3 | E26: =+D26+F26 -> -13.3044 | F26: =RANDBETWEEN(-105,115)/10000 -> -0.0044 | G26: =+Chạy!G37 -> 0.95 | H26: =G26+I26 -> 1.029 | I26: =RANDBETWEEN(-30,90)/1000 -> 0.079 | J26: =+Chạy!K37 -> 1.06 | K26: =J26+L26 -> 1.069 | L26: =RANDBETWEEN(-30,90)/1000 -> 0.009 | M26: =+Chạy!N37 -> 13.3 | N26: =+M26+O26 -> 13.3004 | O26: =RANDBETWEEN(-105,115)/10000 -> 0.0004 | P26: =+Chạy!O37 -> 0.95 | Q26: =P26+R26 -> 0.944 | R26: =RANDBETWEEN(-30,90)/1000 -> -0.006 | T26: 20
A27: 6 | B27: 35 | C27: =+C26+T26 -> 692.61 | D27: =+Chạy!F45 -> -13.3 | E27: =+D27+F27 -> -13.3004 | F27: =RANDBETWEEN(-105,115)/10000 -> -0.0004 | G27: =+Chạy!G45 -> 0.95 | H27: =G27+I27 -> 0.942 | I27: =RANDBETWEEN(-30,90)/1000 -> -0.008 | J27: =+Chạy!K45 -> 1.07 | K27: =J27+L27 -> 1.067 | L27: =RANDBETWEEN(-30,90)/1000 -> -0.003 | M27: =+Chạy!N45 -> 13.3 | N27: =+M27+O27 -> 13.3017 | O27: =RANDBETWEEN(-105,115)/10000 -> 0.0017 | P27: =+Chạy!O45 -> 0.95 | Q27: =P27+R27 -> 0.956 | R27: =RANDBETWEEN(-30,90)/1000 -> 0.006 | T27: 20
A28: 7 | B28: 36 | C28: =+C27+T27 -> 712.61 | D28: =+Chạy!F53 -> -7.65 | E28: =+D28+F28 -> -7.6513 | F28: =RANDBETWEEN(-105,115)/10000 -> -0.0013 | G28: =+Chạy!G53 -> 0.95 | H28: =G28+I28 -> 0.942 | I28: =RANDBETWEEN(-30,90)/1000 -> -0.008 | J28: =+Chạy!K53 -> 1.07 | K28: =J28+L28 -> 1.134 | L28: =RANDBETWEEN(-30,90)/1000 -> 0.064 | M28: =+Chạy!N53 -> 13.3 | N28: =+M28+O28 -> 13.2953 | O28: =RANDBETWEEN(-105,115)/10000 -> -0.0047 | P28: =+Chạy!O53 -> 0.95 | Q28: =P28+R28 -> 1.007 | R28: =RANDBETWEEN(-30,90)/1000 -> 0.057 | T28: 11.5
A29: 8 | B29: 37 | C29: =+C28+T28 -> 724.11 | D29: =+Chạy!F61 -> -13.3 | E29: =+D29+F29 -> -13.2975 | F29: =RANDBETWEEN(-105,115)/10000 -> 0.0025 | G29: =+Chạy!G61 -> 0.95 | H29: =G29+I29 -> 1.022 | I29: =RANDBETWEEN(-30,90)/1000 -> 0.072 | J29: =+Chạy!K61 -> 1.07 | K29: =J29+L29 -> 1.053 | L29: =RANDBETWEEN(-30,90)/1000 -> -0.017 | M29: =+Chạy!N61 -> 13.3 | N29: =+M29+O29 -> 13.3046 | O29: =RANDBETWEEN(-105,115)/10000 -> 0.0046 | P29: =+Chạy!O61 -> 0.95 | Q29: =P29+R29 -> 0.993 | R29: =RANDBETWEEN(-30,90)/1000 -> 0.043
C63: NHÀ THẦU THI CÔNG | O63: TƯ VẤN GIÁM SÁT
C68: Nguyễn Xuân Hưng | O68: Lê Quốc Huy

Sheet 5.KL L5
A1: PHỤ LỤC KHỐI LƯỢNG
A2: ="Kèm theo BBNT số: "&VLOOKUP(AZ2,'[1]Tuyến XD8'!$A$2:$G$60,7,0)&VLOOKUP(AZ2,'[1]Tuyến XD8'!$A$2:$G$60,4,0) -> Kèm theo BBNT số: 95.NĐXD8/CVXD ngày 02 tháng 10 năm 2026 | AZ2: 95
A3: ='1.KTHH L1'!A3 -> Dự án: Xây dựng HTKT Khu tái định cư phục vụ di dân xã Hải Hà, thị xã Nghi Sơn, tỉnh Thanh Hóa.
A4: ='1.KTHH L1'!A4 -> Gói thầu số 12: Xây dựng HTKT khu vực Hải Bình và Xuân Lâm (bao gồm cả bảo hiểm xây dựng công trình)
A5: ='1.KTHH L1'!A5 -> Nhà thầu thi công: Công ty TNHH Hoàng Tuấn
A6: Hạng mục: Nền đường tuyến XD8
A7: - Đối tượng nghiệm thu: | D7: =VLOOKUP(AZ2,'[1]Tuyến XD8'!$A$2:$B$60,2,0) -> Đắp đất nền đường lớp 5 đoạn từ Km0+609,11 - Km0+724,11, độ chặt K>=0,95
A9: STT | B9: Tên cọc | C9: Lý trình | D9: K/c lẻ | M9: Khối lượng đắp đất | AB9: Ghi chú
N10: Diện tích | O10: Diện tích (m2) | P10: Diện tích | Q10: Diện tích | U10: Khối lượng | V10: Khối lượng | W10: Khối lượng (m3) | X10: Khối lượng | Y10: Khối lượng
A11: 1 | B11: ='5.KTHH L5'!B22 -> 31 | C11: ='5.KTHH L5'!C22 -> 609.11 | D11: ='5.KTHH L5'!T22 -> 11.75 | O11: =Chạy!E5 -> 8.12 | W11: =(O11+O12)*D11/2 -> 95.41
A12: 2 | B12: ='5.KTHH L5'!B23 -> E10 | C12: ='5.KTHH L5'!C23 -> 620.86 | D12: ='5.KTHH L5'!T23 -> 11.75 | O12: =Chạy!E13 -> 8.12 | W12: =(O12+O13)*D12/2 -> 95.41
A13: 3 | B13: ='5.KTHH L5'!B24 -> 32 | C13: ='5.KTHH L5'!C24 -> 632.61 | D13: ='5.KTHH L5'!T24 -> 20 | O13: =Chạy!E21 -> 8.12 | W13: =(O13+O14)*D13/2 -> 162.4
A14: 4 | B14: ='5.KTHH L5'!B25 -> 33 | C14: ='5.KTHH L5'!C25 -> 652.61 | D14: ='5.KTHH L5'!T25 -> 20 | O14: =Chạy!E29 -> 8.12 | W14: =(O14+O15)*D14/2 -> 162.4
A15: 5 | B15: ='5.KTHH L5'!B26 -> 34 | C15: ='5.KTHH L5'!C26 -> 672.61 | D15: ='5.KTHH L5'!T26 -> 20 | O15: =Chạy!E37 -> 8.12 | W15: =(O15+O16)*D15/2 -> 162.4
A16: 6 | B16: ='5.KTHH L5'!B27 -> 35 | C16: ='5.KTHH L5'!C27 -> 692.61 | D16: ='5.KTHH L5'!T27 -> 20 | O16: =Chạy!E45 -> 8.12 | W16: =(O16+O17)*D16/2 -> 144.3
A17: 7 | B17: ='5.KTHH L5'!B28 -> 36 | C17: ='5.KTHH L5'!C28 -> 712.61 | D17: ='5.KTHH L5'!T28 -> 11.5 | O17: =Chạy!E53 -> 6.31 | W17: =(O17+O18)*D17/2 -> 82.9725
A18: 8 | B18: ='5.KTHH L5'!B29 -> 37 | C18: ='5.KTHH L5'!C29 -> 724.11 | O18: =Chạy!E61 -> 8.12
A51: Tổng cộng (m3) | R51: =SUM(R11:R50) -> 0 | S51: =SUM(S11:S50) -> 0 | U51: =SUM(U11:U50) -> 0 | V51: =SUM(V11:V50) -> 0 | W51: =SUM(W11:W18) -> 905.2925 | X51: =SUM(X11:X50) -> 0 | Y51: =SUM(Y11:Y50) -> 0 | Z51: =SUM(Z11:Z50) -> 0 | AA51: =SUM(AA11:AA50) -> 0
A53: NHÀ THẦU THI CÔNG | E53: TƯ VẤN GIÁM SÁT
A59: Nguyễn Xuân Hưng | M59: Lê Quốc Huy

Sheet 6.KTHH L6
A1: PHỤ LỤC KIỂM TRA CAO ĐỘ, KÍCH THƯỚC HÌNH HỌC
A2: ="Kèm theo BBNT số: "&VLOOKUP(AZ2,'[1]Tuyến XD8'!$A$2:$G$60,7,0)&VLOOKUP(AZ2,'[1]Tuyến XD8'!$A$2:$G$60,4,0) -> Kèm theo BBNT số: 96.NĐXD8/CVXD ngày 03 tháng 10 năm 2026 | AZ2: 96
A3: ='1.KTHH L1'!A3 -> Dự án: Xây dựng HTKT Khu tái định cư phục vụ di dân xã Hải Hà, thị xã Nghi Sơn, tỉnh Thanh Hóa.
A4: ='1.KTHH L1'!A4 -> Gói thầu số 12: Xây dựng HTKT khu vực Hải Bình và Xuân Lâm (bao gồm cả bảo hiểm xây dựng công trình)
A5: ='1.KTHH L1'!A5 -> Nhà thầu thi công: Công ty TNHH Hoàng Tuấn
A6: Hạng mục: Nền đường tuyến XD8
A7: - Đối tượng nghiệm thu: | G7: =VLOOKUP(AZ2,'[1]Tuyến XD8'!$A$2:$B$60,2,0) -> Đắp đất nền đường lớp 6 đoạn từ Km0+609,11 - Km0+724,11, độ chặt K>=0,95
A8: Sơ họa:
A20: TT | B20: Tên cọc | C20: Lý trình | D20: Bên trái (H1) | J20: Tim (H2) | M20: Bên phải (H3) | S20: Ghi chú
D21: KCTK | E21: KCTC | F21: Chênh KC (m) | G21: CDTK (m) | H21: CDTC (m) | I21: Chênh CD (m) | J21: CDTK (m) | K21: CDTC (m) | L21: Chênh CD (m) | M21: KCTK | N21: KCTC | O21: Chênh KC (m) | P21: CDTK (m) | Q21: CDTC (m) | R21: Chênh CD (m)
A22: 1 | B22: 31 | C22: 609.11 | D22: =+Chạy!F4 -> -12.85 | E22: =+D22+F22 -> -12.8591 | F22: =RANDBETWEEN(-105,115)/10000 -> -0.0091 | G22: =+Chạy!G4 -> 1.24 | H22: =G22+I22 -> 1.247 | I22: =RANDBETWEEN(-30,90)/1000 -> 0.007 | J22: =+Chạy!K4 -> 1.36 | K22: =J22+L22 -> 1.347 | L22: =RANDBETWEEN(-30,90)/1000 -> -0.013 | M22: =+Chạy!N4 -> 12.85 | N22: =+M22+O22 -> 12.8474 | O22: =RANDBETWEEN(-105,115)/10000 -> -0.0026 | P22: =+Chạy!O4 -> 1.24 | Q22: =P22+R22 -> 1.272 | R22: =RANDBETWEEN(-30,90)/1000 -> 0.032 | T22: 11.75
A23: 2 | B23: E10 | C23: =+C22+T22 -> 620.86 | D23: =+Chạy!F12 -> -12.85 | E23: =+D23+F23 -> -12.8471 | F23: =RANDBETWEEN(-105,115)/10000 -> 0.0029 | G23: =+Chạy!G12 -> 1.24 | H23: =G23+I23 -> 1.317 | I23: =RANDBETWEEN(-30,90)/1000 -> 0.077 | J23: =+Chạy!K12 -> 1.36 | K23: =J23+L23 -> 1.413 | L23: =RANDBETWEEN(-30,90)/1000 -> 0.053 | M23: =+Chạy!N12 -> 12.85 | N23: =+M23+O23 -> 12.8446 | O23: =RANDBETWEEN(-105,115)/10000 -> -0.0054 | P23: =+Chạy!O12 -> 1.24 | Q23: =P23+R23 -> 1.273 | R23: =RANDBETWEEN(-30,90)/1000 -> 0.033 | T23: 11.75
A24: 3 | B24: 32 | C24: =+C23+T23 -> 632.61 | D24: =+Chạy!F20 -> -12.85 | E24: =+D24+F24 -> -12.857 | F24: =RANDBETWEEN(-105,115)/10000 -> -0.007 | G24: =+Chạy!G20 -> 1.24 | H24: =G24+I24 -> 1.272 | I24: =RANDBETWEEN(-30,90)/1000 -> 0.032 | J24: =+Chạy!K20 -> 1.36 | K24: =J24+L24 -> 1.35 | L24: =RANDBETWEEN(-30,90)/1000 -> -0.01 | M24: =+Chạy!N20 -> 12.85 | N24: =+M24+O24 -> 12.8495 | O24: =RANDBETWEEN(-105,115)/10000 -> -0.0005 | P24: =+Chạy!O20 -> 1.24 | Q24: =P24+R24 -> 1.23 | R24: =RANDBETWEEN(-30,90)/1000 -> -0.01 | T24: 20
A25: 4 | B25: 33 | C25: =+C24+T24 -> 652.61 | D25: =+Chạy!F28 -> -12.85 | E25: =+D25+F25 -> -12.8505 | F25: =RANDBETWEEN(-105,115)/10000 -> -0.0005 | G25: =+Chạy!G28 -> 1.25 | H25: =G25+I25 -> 1.252 | I25: =RANDBETWEEN(-30,90)/1000 -> 0.002 | J25: =+Chạy!K28 -> 1.36 | K25: =J25+L25 -> 1.41 | L25: =RANDBETWEEN(-30,90)/1000 -> 0.05 | M25: =+Chạy!N28 -> 12.85 | N25: =+M25+O25 -> 12.8528 | O25: =RANDBETWEEN(-105,115)/10000 -> 0.0028 | P25: =+Chạy!O28 -> 1.25 | Q25: =P25+R25 -> 1.315 | R25: =RANDBETWEEN(-30,90)/1000 -> 0.065 | T25: 20
A26: 5 | B26: 34 | C26: =+C25+T25 -> 672.61 | D26: =+Chạy!F36 -> -12.85 | E26: =+D26+F26 -> -12.848 | F26: =RANDBETWEEN(-105,115)/10000 -> 0.002 | G26: =+Chạy!G36 -> 1.25 | H26: =G26+I26 -> 1.278 | I26: =RANDBETWEEN(-30,90)/1000 -> 0.028 | J26: =+Chạy!K36 -> 1.36 | K26: =J26+L26 -> 1.346 | L26: =RANDBETWEEN(-30,90)/1000 -> -0.014 | M26: =+Chạy!N36 -> 12.85 | N26: =+M26+O26 -> 12.8419 | O26: =RANDBETWEEN(-105,115)/10000 -> -0.0081 | P26: =+Chạy!O36 -> 1.25 | Q26: =P26+R26 -> 1.273 | R26: =RANDBETWEEN(-30,90)/1000 -> 0.023 | T26: 20
A27: 6 | B27: 35 | C27: =+C26+T26 -> 692.61 | D27: =+Chạy!F44 -> -12.85 | E27: =+D27+F27 -> -12.8574 | F27: =RANDBETWEEN(-105,115)/10000 -> -0.0074 | G27: =+Chạy!G44 -> 1.25 | H27: =G27+I27 -> 1.248 | I27: =RANDBETWEEN(-30,90)/1000 -> -0.002 | J27: =+Chạy!K44 -> 1.37 | K27: =J27+L27 -> 1.361 | L27: =RANDBETWEEN(-30,90)/1000 -> -0.009 | M27: =+Chạy!N44 -> 12.85 | N27: =+M27+O27 -> 12.8533 | O27: =RANDBETWEEN(-105,115)/10000 -> 0.0033 | P27: =+Chạy!O44 -> 1.25 | Q27: =P27+R27 -> 1.262 | R27: =RANDBETWEEN(-30,90)/1000 -> 0.012 | T27: 20
A28: 7 | B28: 36 | C28: =+C27+T27 -> 712.61 | D28: =+Chạy!F52 -> -7.95 | E28: =+D28+F28 -> -7.9429 | F28: =RANDBETWEEN(-105,115)/10000 -> 0.0071 | G28: =+Chạy!G52 -> 1.25 | H28: =G28+I28 -> 1.221 | I28: =RANDBETWEEN(-30,90)/1000 -> -0.029 | J28: =+Chạy!K52 -> 1.37 | K28: =J28+L28 -> 1.438 | L28: =RANDBETWEEN(-30,90)/1000 -> 0.068 | M28: =+Chạy!N52 -> 12.85 | N28: =+M28+O28 -> 12.846 | O28: =RANDBETWEEN(-105,115)/10000 -> -0.004 | P28: =+Chạy!O52 -> 1.25 | Q28: =P28+R28 -> 1.304 | R28: =RANDBETWEEN(-30,90)/1000 -> 0.054 | T28: 11.5
A29: 8 | B29: 37 | C29: =+C28+T28 -> 724.11 | D29: =+Chạy!F60 -> -12.85 | E29: =+D29+F29 -> -12.85 | F29: =RANDBETWEEN(-105,115)/10000 -> 0 | G29: =+Chạy!G60 -> 1.25 | H29: =G29+I29 -> 1.243 | I29: =RANDBETWEEN(-30,90)/1000 -> -0.007 | J29: =+Chạy!K60 -> 1.37 | K29: =J29+L29 -> 1.365 | L29: =RANDBETWEEN(-30,90)/1000 -> -0.005 | M29: =+Chạy!N60 -> 12.85 | N29: =+M29+O29 -> 12.8521 | O29: =RANDBETWEEN(-105,115)/10000 -> 0.0021 | P29: =+Chạy!O60 -> 1.25 | Q29: =P29+R29 -> 1.299 | R29: =RANDBETWEEN(-30,90)/1000 -> 0.049
C63: NHÀ THẦU THI CÔNG | O63: TƯ VẤN GIÁM SÁT
C68: Nguyễn Xuân Hưng | O68: Lê Quốc Huy

Sheet 6.KL L6
A1: PHỤ LỤC KHỐI LƯỢNG
A2: ="Kèm theo BBNT số: "&VLOOKUP(AZ2,'[1]Tuyến XD8'!$A$2:$G$60,7,0)&VLOOKUP(AZ2,'[1]Tuyến XD8'!$A$2:$G$60,4,0) -> Kèm theo BBNT số: 96.NĐXD8/CVXD ngày 03 tháng 10 năm 2026 | AZ2: 96
A3: ='1.KTHH L1'!A3 -> Dự án: Xây dựng HTKT Khu tái định cư phục vụ di dân xã Hải Hà, thị xã Nghi Sơn, tỉnh Thanh Hóa.
A4: ='1.KTHH L1'!A4 -> Gói thầu số 12: Xây dựng HTKT khu vực Hải Bình và Xuân Lâm (bao gồm cả bảo hiểm xây dựng công trình)
A5: ='1.KTHH L1'!A5 -> Nhà thầu thi công: Công ty TNHH Hoàng Tuấn
A6: Hạng mục: Nền đường tuyến XD8
A7: - Đối tượng nghiệm thu: | D7: =VLOOKUP(AZ2,'[1]Tuyến XD8'!$A$2:$B$60,2,0) -> Đắp đất nền đường lớp 6 đoạn từ Km0+609,11 - Km0+724,11, độ chặt K>=0,95
A9: STT | B9: Tên cọc | C9: Lý trình | D9: K/c lẻ | M9: Khối lượng đắp đất | AB9: Ghi chú
N10: Diện tích | O10: Diện tích (m2) | P10: Diện tích | Q10: Diện tích | U10: Khối lượng | V10: Khối lượng | W10: Khối lượng (m3) | X10: Khối lượng | Y10: Khối lượng
A11: 1 | B11: ='6.KTHH L6'!B22 -> 31 | C11: ='6.KTHH L6'!C22 -> 609.11 | D11: ='6.KTHH L6'!T22 -> 11.75 | O11: =Chạy!E4 -> 7.85 | W11: =(O11+O12)*D11/2 -> 92.2375
A12: 2 | B12: ='6.KTHH L6'!B23 -> E10 | C12: ='6.KTHH L6'!C23 -> 620.86 | D12: ='6.KTHH L6'!T23 -> 11.75 | O12: =Chạy!E12 -> 7.85 | W12: =(O12+O13)*D12/2 -> 92.2375
A13: 3 | B13: ='6.KTHH L6'!B24 -> 32 | C13: ='6.KTHH L6'!C24 -> 632.61 | D13: ='6.KTHH L6'!T24 -> 20 | O13: =Chạy!E20 -> 7.85 | W13: =(O13+O14)*D13/2 -> 157
A14: 4 | B14: ='6.KTHH L6'!B25 -> 33 | C14: ='6.KTHH L6'!C25 -> 652.61 | D14: ='6.KTHH L6'!T25 -> 20 | O14: =Chạy!E28 -> 7.85 | W14: =(O14+O15)*D14/2 -> 157
A15: 5 | B15: ='6.KTHH L6'!B26 -> 34 | C15: ='6.KTHH L6'!C26 -> 672.61 | D15: ='6.KTHH L6'!T26 -> 20 | O15: =Chạy!E36 -> 7.85 | W15: =(O15+O16)*D15/2 -> 157
A16: 6 | B16: ='6.KTHH L6'!B27 -> 35 | C16: ='6.KTHH L6'!C27 -> 692.61 | D16: ='6.KTHH L6'!T27 -> 20 | O16: =Chạy!E44 -> 7.85 | W16: =(O16+O17)*D16/2 -> 141.1
A17: 7 | B17: ='6.KTHH L6'!B28 -> 36 | C17: ='6.KTHH L6'!C28 -> 712.61 | D17: ='6.KTHH L6'!T28 -> 11.5 | O17: =Chạy!E52 -> 6.26 | W17: =(O17+O18)*D17/2 -> 81.1325
A18: 8 | B18: ='6.KTHH L6'!B29 -> 37 | C18: ='6.KTHH L6'!C29 -> 724.11 | O18: =Chạy!E60 -> 7.85
A51: Tổng cộng (m3) | R51: =SUM(R11:R50) -> 0 | S51: =SUM(S11:S50) -> 0 | U51: =SUM(U11:U50) -> 0 | V51: =SUM(V11:V50) -> 0 | W51: =SUM(W11:W18) -> 877.7075 | X51: =SUM(X11:X50) -> 0 | Y51: =SUM(Y11:Y50) -> 0 | Z51: =SUM(Z11:Z50) -> 0 | AA51: =SUM(AA11:AA50) -> 0
A53: NHÀ THẦU THI CÔNG | E53: TƯ VẤN GIÁM SÁT
A59: Nguyễn Xuân Hưng | M59: Lê Quốc Huy

Sheet 7.KTHH L7
A1: PHỤ LỤC KIỂM TRA CAO ĐỘ, KÍCH THƯỚC HÌNH HỌC
A2: ="Kèm theo BBNT số: "&VLOOKUP(AZ2,'[1]Tuyến XD8'!$A$2:$G$60,7,0)&VLOOKUP(AZ2,'[1]Tuyến XD8'!$A$2:$G$60,4,0) -> Kèm theo BBNT số: 97.NĐXD8/CVXD ngày 03 tháng 10 năm 2026 | AZ2: 97
A3: =+'1.KTHH L1'!A3 -> Dự án: Xây dựng HTKT Khu tái định cư phục vụ di dân xã Hải Hà, thị xã Nghi Sơn, tỉnh Thanh Hóa.
A4: =+'1.KTHH L1'!A4 -> Gói thầu số 12: Xây dựng HTKT khu vực Hải Bình và Xuân Lâm (bao gồm cả bảo hiểm xây dựng công trình)
A5: =+'1.KTHH L1'!A5 -> Nhà thầu thi công: Công ty TNHH Hoàng Tuấn
A6: Hạng mục: Nền đường tuyến XD8
A7: - Đối tượng nghiệm thu: | G7: =VLOOKUP(AZ2,'[1]Tuyến XD8'!$A$2:$B$60,2,0) -> Đắp đất nền đường lớp 7 đoạn từ Km0+609,11 - Km0+724,11, độ chặt K>=0,95
A8: Sơ họa:
A20: TT | B20: Tên cọc | C20: Lý trình | D20: Bên trái (H1) | J20: Tim (H2) | M20: Bên phải (H3) | S20: Ghi chú
D21: KCTK | E21: KCTC | F21: Chênh KC (m) | G21: CDTK (m) | H21: CDTC (m) | I21: Chênh CD (m) | J21: CDTK (m) | K21: CDTC (m) | L21: Chênh CD (m) | M21: KCTK | N21: KCTC | O21: Chênh KC (m) | P21: CDTK (m) | Q21: CDTC (m) | R21: Chênh CD (m)
A22: 1 | B22: 31 | C22: 609.11 | D22: =+Chạy!F3 -> -12.4 | E22: =+D22+F22 -> -12.3888 | F22: =RANDBETWEEN(-105,115)/10000 -> 0.0112 | G22: =+Chạy!G3 -> 1.54 | H22: =G22+I22 -> 1.559 | I22: =RANDBETWEEN(-30,90)/1000 -> 0.019 | J22: =+Chạy!K3 -> 1.66 | K22: =J22+L22 -> 1.65 | L22: =RANDBETWEEN(-30,90)/1000 -> -0.01 | M22: =+Chạy!N3 -> 12.4 | N22: =+M22+O22 -> 12.396 | O22: =RANDBETWEEN(-105,115)/10000 -> -0.004 | P22: =+Chạy!O3 -> 1.54 | Q22: =P22+R22 -> 1.563 | R22: =RANDBETWEEN(-30,90)/1000 -> 0.023 | T22: 11.75
A23: 2 | B23: E10 | C23: =+C22+T22 -> 620.86 | D23: =+Chạy!F11 -> -12.4 | E23: =+D23+F23 -> -12.4083 | F23: =RANDBETWEEN(-105,115)/10000 -> -0.0083 | G23: =+Chạy!G11 -> 1.54 | H23: =G23+I23 -> 1.562 | I23: =RANDBETWEEN(-30,90)/1000 -> 0.022 | J23: =+Chạy!K11 -> 1.66 | K23: =J23+L23 -> 1.692 | L23: =RANDBETWEEN(-30,90)/1000 -> 0.032 | M23: =+Chạy!N11 -> 12.4 | N23: =+M23+O23 -> 12.3965 | O23: =RANDBETWEEN(-105,115)/10000 -> -0.0035 | P23: =+Chạy!O11 -> 1.54 | Q23: =P23+R23 -> 1.597 | R23: =RANDBETWEEN(-30,90)/1000 -> 0.057 | T23: 11.75
A24: 3 | B24: 32 | C24: =+C23+T23 -> 632.61 | D24: =+Chạy!F19 -> -12.4 | E24: =+D24+F24 -> -12.3962 | F24: =RANDBETWEEN(-105,115)/10000 -> 0.0038 | G24: =+Chạy!G19 -> 1.54 | H24: =G24+I24 -> 1.554 | I24: =RANDBETWEEN(-30,90)/1000 -> 0.014 | J24: =+Chạy!K19 -> 1.66 | K24: =J24+L24 -> 1.647 | L24: =RANDBETWEEN(-30,90)/1000 -> -0.013 | M24: =+Chạy!N19 -> 12.4 | N24: =+M24+O24 -> 12.4003 | O24: =RANDBETWEEN(-105,115)/10000 -> 0.0003 | P24: =+Chạy!O19 -> 1.54 | Q24: =P24+R24 -> 1.607 | R24: =RANDBETWEEN(-30,90)/1000 -> 0.067 | T24: 20
A25: 4 | B25: 33 | C25: =+C24+T24 -> 652.61 | D25: =+Chạy!F27 -> -12.4 | E25: =+D25+F25 -> -12.4075 | F25: =RANDBETWEEN(-105,115)/10000 -> -0.0075 | G25: =+Chạy!G27 -> 1.55 | H25: =G25+I25 -> 1.521 | I25: =RANDBETWEEN(-30,90)/1000 -> -0.029 | J25: =+Chạy!K27 -> 1.66 | K25: =J25+L25 -> 1.72 | L25: =RANDBETWEEN(-30,90)/1000 -> 0.06 | M25: =+Chạy!N27 -> 12.4 | N25: =+M25+O25 -> 12.3976 | O25: =RANDBETWEEN(-105,115)/10000 -> -0.0024 | P25: =+Chạy!O27 -> 1.55 | Q25: =P25+R25 -> 1.57 | R25: =RANDBETWEEN(-30,90)/1000 -> 0.02 | T25: 20
A26: 5 | B26: 34 | C26: =+C25+T25 -> 672.61 | D26: =+Chạy!F35 -> -12.4 | E26: =+D26+F26 -> -12.408 | F26: =RANDBETWEEN(-105,115)/10000 -> -0.008 | G26: =+Chạy!G35 -> 1.55 | H26: =G26+I26 -> 1.526 | I26: =RANDBETWEEN(-30,90)/1000 -> -0.024 | J26: =+Chạy!K35 -> 1.66 | K26: =J26+L26 -> 1.674 | L26: =RANDBETWEEN(-30,90)/1000 -> 0.014 | M26: =+Chạy!N35 -> 12.4 | N26: =+M26+O26 -> 12.3936 | O26: =RANDBETWEEN(-105,115)/10000 -> -0.0064 | P26: =+Chạy!O35 -> 1.55 | Q26: =P26+R26 -> 1.606 | R26: =RANDBETWEEN(-30,90)/1000 -> 0.056 | T26: 20
A27: 6 | B27: 35 | C27: =+C26+T26 -> 692.61 | D27: =+Chạy!F43 -> -12.4 | E27: =+D27+F27 -> -12.4015 | F27: =RANDBETWEEN(-105,115)/10000 -> -0.0015 | G27: =+Chạy!G43 -> 1.55 | H27: =G27+I27 -> 1.568 | I27: =RANDBETWEEN(-30,90)/1000 -> 0.018 | J27: =+Chạy!K43 -> 1.67 | K27: =J27+L27 -> 1.702 | L27: =RANDBETWEEN(-30,90)/1000 -> 0.032 | M27: =+Chạy!N43 -> 12.4 | N27: =+M27+O27 -> 12.3899 | O27: =RANDBETWEEN(-105,115)/10000 -> -0.0101 | P27: =+Chạy!O43 -> 1.55 | Q27: =P27+R27 -> 1.615 | R27: =RANDBETWEEN(-30,90)/1000 -> 0.065 | T27: 20
A28: 7 | B28: 36 | C28: =+C27+T27 -> 712.61 | D28: =+Chạy!F51 -> -12.4 | E28: =+D28+F28 -> -12.4056 | F28: =RANDBETWEEN(-105,115)/10000 -> -0.0056 | G28: =+Chạy!G51 -> 1.55 | H28: =G28+I28 -> 1.638 | I28: =RANDBETWEEN(-30,90)/1000 -> 0.088 | J28: =+Chạy!K51 -> 1.67 | K28: =J28+L28 -> 1.684 | L28: =RANDBETWEEN(-30,90)/1000 -> 0.014 | M28: =+Chạy!N51 -> 12.4 | N28: =+M28+O28 -> 12.392 | O28: =RANDBETWEEN(-105,115)/10000 -> -0.008 | P28: =+Chạy!O51 -> 1.55 | Q28: =P28+R28 -> 1.618 | R28: =RANDBETWEEN(-30,90)/1000 -> 0.068 | T28: 11.5
A29: 8 | B29: 37 | C29: =+C28+T28 -> 724.11 | D29: =+Chạy!F59 -> -12.4 | E29: =+D29+F29 -> -12.3905 | F29: =RANDBETWEEN(-105,115)/10000 -> 0.0095 | G29: =+Chạy!G59 -> 1.55 | H29: =G29+I29 -> 1.625 | I29: =RANDBETWEEN(-30,90)/1000 -> 0.075 | J29: =+Chạy!K59 -> 1.67 | K29: =J29+L29 -> 1.665 | L29: =RANDBETWEEN(-30,90)/1000 -> -0.005 | M29: =+Chạy!N59 -> 12.4 | N29: =+M29+O29 -> 12.3905 | O29: =RANDBETWEEN(-105,115)/10000 -> -0.0095 | P29: =+Chạy!O59 -> 1.55 | Q29: =P29+R29 -> 1.537 | R29: =RANDBETWEEN(-30,90)/1000 -> -0.013
C63: NHÀ THẦU THI CÔNG | O63: TƯ VẤN GIÁM SÁT
C68: Nguyễn Xuân Hưng | O68: Lê Quốc Huy

Sheet 7.KL L7
A1: PHỤ LỤC KHỐI LƯỢNG
A2: ="Kèm theo BBNT số: "&VLOOKUP(AZ2,'[1]Tuyến XD8'!$A$2:$G$60,7,0)&VLOOKUP(AZ2,'[1]Tuyến XD8'!$A$2:$G$60,4,0) -> Kèm theo BBNT số: 97.NĐXD8/CVXD ngày 03 tháng 10 năm 2026 | AZ2: 97
A3: =+'1.KTHH L1'!A3 -> Dự án: Xây dựng HTKT Khu tái định cư phục vụ di dân xã Hải Hà, thị xã Nghi Sơn, tỉnh Thanh Hóa.
A4: =+'1.KTHH L1'!A4 -> Gói thầu số 12: Xây dựng HTKT khu vực Hải Bình và Xuân Lâm (bao gồm cả bảo hiểm xây dựng công trình)
A5: =+'1.KTHH L1'!A5 -> Nhà thầu thi công: Công ty TNHH Hoàng Tuấn
A6: Hạng mục: Nền đường tuyến XD8
